{{Structure info}}

== Materials ==
{| class="wikitable"
|-
! Name !! Total !! Stack
|-
| {{BlockSprite|obsidian|link=Obsidian|text=Obsidian}}
| 684 <ref group="Note">For endspike that are 9 blocks in diameter and 12 blocks tall.</ref>
| 10 + 44 Blocks
|-
| {{BlockSprite|iron bars|link=Iron Bars|text=Iron Bars}}
| 57
|
|-
| {{BlockSprite|bedrock|link=Bedrock|text=Bedrock}}
| 1
|
|-
| {{EntitySprite|end crystal|link=End Crystal|text=End Crystal}}
| 1
|
|-
|}
<references group="Note"/>

==Blueprint==
<!--DO NOT change the layer number, even though the heights vary-->
'''Note:''' The endspike' diameters can vary from 4 to 9 blocks. The heights can vary too from 6 blocks to 37 blocks.<br />
<!--DO NOT remove the Iron Bars, even though not all Pillars have them-->
'''Note:''' Only the 2nd and 3rd smallest endspike have Iron Bars. <br />
<table><tr><td style="width:250px;">
{{layered blueprint|name=endspike|default=Layer 14
|O=Obsidian|I=Iron Bars|B=Bedrock|E=EntitySprite:End Crystal
|----Layer 1 - 12|
   OOO
  OOOOO
 OOOOOOO
OOOOOOOOO
OOOOOOOOO
OOOOOOOOO
 OOOOOOO
  OOOOO
   OOO
|----Layer 13|
 
 
  IIIII
  I   I
  I B I
  I   I
  IIIII
 
 
|----Layer 14|
 
 
  IIIII
  I   I
  I E I  
  I   I
  IIIII
 
 
|----Layer 15|
 
 
  IIIII
  IIIII
  IIIII
  IIIII
  IIIII
 
 
}}
</td><td style="width:250px;">{{layered blueprint|name=endspike Areas|default=3-block radius
|O=Obsidian
|----6-block radius|
    OOO
  OOOOOOO
 OOOOOOOOO
 OOOOOOOOO
OOOOOOOOOOO
OOOOOOOOOOO
OOOOOOOOOOO
 OOOOOOOOO
 OOOOOOOOO
  OOOOOOO
    OOO
|----5-block radius|
 
    OOO
   OOOOO
  OOOOOOO
 OOOOOOOOO
 OOOOOOOOO
 OOOOOOOOO
  OOOOOOO
   OOOOO
    OOO
 
|----4-block radius|
 
 
    OOO
   OOOOO
  OOOOOOO
  OOOOOOO
  OOOOOOO
   OOOOO
    OOO
 
 
|----3-block radius|
 
 
 
    OOO
   OOOOO
   OOOOO
   OOOOO
    OOO
 
 
 
}}</td><td style="vertical-align:top;">
[[File:End spike.png|100px|right]]
</td></tr></table>