<noinclude>{{structure info}}</noinclude>

====Materials====
{| class="wikitable"
|-
! Name!!Total!!Stack
|-
|{{BlockLink|Nether Bricks}}
|505
|7 + 57
|-
|{{BlockLink|Nether Brick Fence}}
|24
|0 + 24
|-
|}

==== Blueprint====
{{layered blueprint|name=Bridge|default=Layer 1
|N=Nether Bricks|F=Nether Brick Fence
|----Layer -5 to ground|
NNNNN
NNNNN
NNNNN
     
     
     
     
     
     
     
     
     
     
     
     
     
NNNNN
NNNNN
NNNNN
|----Layer -4|
NNNNN
NNNNN
NNNNN
NNNNN
     
     
     
     
     
     
     
     
     
     
     
NNNNN
NNNNN
NNNNN
NNNNN
|----Layer -3|
NNNNN
FNNNF
NNNNN
NNNNN
     
     
     
     
     
     
     
     
     
     
     
NNNNN
NNNNN
FNNNF
NNNNN
|----Layer -2|
NNNNN
FNNNF
NNNNN
NNNNN
NNNNN
NNNNN
     
     
     
     
     
     
     
NNNNN
NNNNN
NNNNN
NNNNN
FNNNF
NNNNN
|----Layer -1 & 0|
NNNNN
FNNNF
NNNNN
NNNNN
FNNNF
NNNNN
NNNNN
NNNNN
NNNNN
NNNNN
NNNNN
NNNNN
NNNNN
NNNNN
FNNNF
NNNNN
NNNNN
FNNNF
NNNNN
|----Layer 1|
N   N
N   N
N   N
N   N
N   N
N   N
N   N
N   N
N   N
N   N
N   N
N   N
N   N
N   N
N   N
N   N
N   N
N   N
N   N
}}