{{Structure info}}

==Materials==
{| class="wikitable"
|-
! Name !! Total !! Stack
|-
| {{BlockLink|Stone}}
| 49
|
|-
| {{LegacyBlockSprite|mossy cobblestone je1 be1|text=[[Mossy Cobblestone]]}}
| 119
| 1 + 55 blocks
|-
| {{BlockLink|Oak Planks}}
| 119
| 1 + 55 blocks
|-
| {{BlockLink|Torch}}
| 3
|
|-
| {{LegacyBlockSprite|chest top je1 be1|text=[[Chest]]}}
| 6
|
|-
|}

== Blueprints ==
; Indev House ([[Indev 20100124]])
<table><tr><td style="width: 300px;">
{{layered blueprint|name=Indev House ([[Indev 20100124]])|default=Layer 2
|T=Torch-rot90|t=Torch-rot270|M=LegacyBlockSprite:mossy cobblestone+je1 be1|C=LegacyBlockSprite:chest+top je1 be1
|----Layer 0 (Ground)|
MMMMMMM
MMMMMMM
MMMMMMM
MMMMMMM
MMMMMMM
MMMMMMM
MMMMMMM
|----Layer 1|
MMMMMMM
M     M
M     M
M     M
MC    M
MC   CM
MMM MMM
|----Layer 2|
MMMMMMM
M     M
M     M
MT   tM
M     M
M     M
MMM MMM
|----Layer 3|
MMMMMMM
M     M
M     M
M     M
M     M
M     M
MMMMMMM
|----Layer 4|
MMMMMMM
MMMMMMM
MMMMMMM
MMMMMMM
MMMMMMM
MMMMMMM
MMMMMMM
}}
</td><td style="vertical-align:top;">
[[File:MossyCobblestoneIndev.png|200px|right]]
</td></tr></table>

; Indev House ([[Indev 20100125-1]])
<table><tr><td style="width: 300px;">
{{layered blueprint|name=Indev House ([[Indev 20100125-1]])|default=Layer 2
|T=Torch-rot90|t=Torch-rot270|M=LegacyBlockSprite:mossy cobblestone+je1 be1|C=LegacyBlockSprite:chest+top je1 be1
|----Layer 0 (Ground)|
MMMMMMM
MMMMMMM
MMMMMMM
MMMMMMM
MMMMMMM
MMMMMMM
MMMMMMM
|----Layer 1|
MMMMMMM
M  CC M
M     M
M     M
MC    M
MC   CM
MMM MMM
|----Layer 2|
MMMMMMM
M     M
M     M
MT   tM
M     M
M     M
MMM MMM
|----Layer 3|
MMMMMMM
M     M
M     M
M     M
M     M
M     M
MMMMMMM
|----Layer 4|
MMMMMMM
MMMMMMM
MMMMMMM
MMMMMMM
MMMMMMM
MMMMMMM
MMMMMMM
}}
</td><td style="vertical-align:top;">
[[File:MossyCobblestoneIndev.png|200px|right]]
</td></tr></table>

; Indev House ([[Indev 20100125-2]])
<table><tr><td style="width: 300px;">
{{layered blueprint|name=Indev House ([[Indev 20100125-2]])|default=Layer 2
|T=Torch-rot90|t=Torch-rot270|M=LegacyBlockSprite:mossy cobblestone+je1 be1|C=LegacyBlockSprite:chest+top je1 be1
|----Layer 0 (Ground)|
MMMMMMM
MMMMMMM
MMMMMMM
MMMMMMM
MMMMMMM
MMMMMMM
MMMMMMM
|----Layer 1|
MMMMMMM
M  CC M
MC    M
M     M
MC    M
MC   CM
MMM MMM
|----Layer 2|
MMMMMMM
M     M
M     M
MT   tM
M     M
M     M
MMM MMM
|----Layer 3|
MMMMMMM
M     M
M     M
M     M
M     M
M     M
MMMMMMM
|----Layer 4|
MMMMMMM
MMMMMMM
MMMMMMM
MMMMMMM
MMMMMMM
MMMMMMM
MMMMMMM
}}
</td><td style="vertical-align:top;">
[[File:MossyCobblestoneIndev.png|200px|right]]
</td></tr></table>

; Indev House ([[Indev 20100129]])
<table><tr><td style="width: 300px;">
{{layered blueprint|name=Indev House ([[Indev 20100129]])|default=Layer 2
|T=Torch-rot90|t=Torch-rot270|M=LegacyBlockSprite:mossy cobblestone+je1 be1|C=LegacyBlockSprite:chest+top je1 be1
|----Layer 0 (Ground)|
MMMMMMM
MMMMMMM
MMMMMMM
MMMMMMM
MMMMMMM
MMMMMMM
MMMMMMM
|----Layer 1|
MMMMMMM
M     M
M     M
M     M
MC    M
MC   CM
MMM MMM
|----Layer 2|
MMMMMMM
M     M
M     M
MT   tM
M     M
M     M
MMM MMM
|----Layer 3|
MMMMMMM
M     M
M     M
M     M
M     M
M     M
MMMMMMM
|----Layer 4|
MMMMMMM
MMMMMMM
MMMMMMM
MMMMMMM
MMMMMMM
MMMMMMM
MMMMMMM
}}
</td><td style="vertical-align:top;">
[[File:MossyCobblestoneIndev.png|200px|right]]
</td></tr></table>

; Indev House ([[Indev 20100130]])
<table><tr><td style="width: 300px;">
{{layered blueprint|name=Indev House ([[Indev 20100130]])|default=Layer 2
|T=Torch-rot90|t=Torch-rot270|M=LegacyBlockSprite:mossy cobblestone+je1 be1
|----Layer 0 (Ground)|
MMMMMMM
MMMMMMM
MMMMMMM
MMMMMMM
MMMMMMM
MMMMMMM
MMMMMMM
|----Layer 1|
MMMMMMM
M     M
M     M
M     M
M     M
M     M
MMM MMM
|----Layer 2|
MMMMMMM
M     M
M     M
MT   tM
M     M
M     M
MMM MMM
|----Layer 3|
MMMMMMM
M     M
M     M
M     M
M     M
M     M
MMMMMMM
|----Layer 4|
MMMMMMM
MMMMMMM
MMMMMMM
MMMMMMM
MMMMMMM
MMMMMMM
MMMMMMM
}}
</td><td style="vertical-align:top;">
[[File:MossyCobblestoneIndev.png|200px|right]]
</td></tr></table>

; Indev House ([[Indev 20100214-1]])
<table><tr><td style="width: 300px;">
{{layered blueprint|name=Indev House ([[Indev 20100214-1]])|default=Layer 2
|S=LegacyBlockSprite:stone+je1 be1|T=Torch-rot90|t=Torch-rot270|O=LegacyBlockSprite:oak planks+je3 be1
|----Layer 0 (Ground)|
SSSSSSS
SSSSSSS
SSSSSSS
SSSSSSS
SSSSSSS
SSSSSSS
SSSSSSS
|----Layer 1|
OOOOOOO
O     O
O     O
O     O
O     O
O     O
OOO OOO
|----Layer 2|
OOOOOOO
O     O
O     O
OT   tO
O     O
O     O
OOO OOO
|----Layer 3|
OOOOOOO
O     O
O     O
O     O
O     O
O     O
OOOOOOO
|----Layer 4|
OOOOOOO
OOOOOOO
OOOOOOO
OOOOOOO
OOOOOOO
OOOOOOO
OOOOOOO
}}
</td><td style="vertical-align:top;">
[[File:Indev_House.png|200px|right]]
</td></tr></table>

[[ja:Indevの家/構造]]