<noinclude>{{structure info}}</noinclude>
Stronghold large rooms can have up to four exits (including the entrance to the room) and come in four variants: empty room, stone pillar room, fountain room and storeroom. Therefore, each variant will be shown in the build.

==== Blueprints ====
'''NOTICE:''' Since there is multiple exits possible, the build will show multiple variants as "Layer 2a" and "Layer 2b." "a" is for no entrance, "b" for wooden doors, "c" for iron doors, "d" for iron bars, and "e" for a plain entrance. The sides can be mixed and matched.

;Empty Room

{{layered blueprint|name=Large Room|default=Ground Layer a|S=Stone Bricks|I=Iron Bars|i=Iron Door+Bottom|j=Iron Door+Top|w=Oak Door+Bottom|W=Oak Door+Top|B=Stone Button
|----Ground Layer a|
             
             
  SSSSSSSSSSS
  SSSSSSSSSSS
  SSSSSSSSSSS
  SSSSSSSSSSS
  SSSSSSSSSSS
  SSSSSSSSSSS
  SSSSSSSSSSS
  SSSSSSSSSSS
  SSSSSSSSSSS
  SSSSSSSSSSS
  SSSSSSSSSSS
|----Ground Layer b, c, d, and e|
     SSSSS      
     SSSSS      
  SSSSSSSSSSS   
  SSSSSSSSSSS   
  SSSSSSSSSSS   
SSSSSSSSSSSSSSS
SSSSSSSSSSSSSSS
SSSSSSSSSSSSSSS
SSSSSSSSSSSSSSS
SSSSSSSSSSSSSSS
  SSSSSSSSSSS   
  SSSSSSSSSSS   
  SSSSSSSSSSS   
     SSSSS      
     SSSSS      
|----Layer 1a|
              
              
  SSSSSSSSSSS
  S         S
  S         S
  S         S
  S         S
  S         S
  S         S
  S         S
  S         S
  S         S
  SSSSSSSSSSS
|----Layer 1b|
     S   S     
     SSwSS     
  SSSS   SSSS  
  S         S  
  S         S  
SSS         SSS
 S           S 
 w           w 
 S           S 
SSS         SSS
  S         S  
  S         S  
  SSSS   SSSS  
     SSwSS     
     S   S     
|----Layer 1c|
     S   S     
     SSiSS     
  SSSS   SSSS  
  S         S  
  S         S  
SSS         SSS
 S           S
 i           i 
 S           S 
SSS         SSS
  S         S  
  S         S  
  SSSS   SSSS  
     SSiSS     
     S   S     
|----Layer 1d|
     S   S     
     SI IS     
  SSSS   SSSS  
  S         S  
  S         S  
SSS         SSS
 I           I 
               
 I           I 
SSS         SSS
  S         S  
  S         S  
  SSSS   SSSS  
     SI IS     
     S   S     
|----Layer 1e|
     S   S     
     S   S     
  SSSS   SSSS  
  S         S  
  S         S  
SSS         SSS
               
               
               
SSS         SSS
  S         S  
  S         S  
  SSSS   SSSS  
     S   S     
     S   S     
|----Layer 2a|
              
              
  SSSSSSSSSSS
  S         S
  S         S
  S         S
  S         S
  S         S
  S         S
  S         S
  S         S
  S         S
  SSSSSSSSSSS
|----Layer 2b|
     S   S     
     SSWSS     
  SSSS   SSSS  
  S         S  
  S         S  
SSS         SSS
 S           S 
 W           W 
 S           S 
SSS         SSS
  S         S  
  S         S  
  SSSS   SSSS  
     SSWSS     
     S   S   
|----Layer 2c|
     S  BS     
     SSjSS     
  SSSS  BSSSS  
  S         S  
  S         S  
SSS         SSS
BSB          S
 j           j 
 S          BSB
SSS         SSS
  S         S  
  S         S  
  SSSSB  SSSS  
     SSjSS     
     SB  S     
|----Layer 2d|
     S   S     
     SI IS     
  SSSS   SSSS  
  S         S  
  S         S  
SSS         SSS
 I           I 
               
 I           I 
SSS         SSS
  S         S  
  S         S  
  SSSS   SSSS  
     SI IS     
     S   S     
|----Layer 2e|
     S   S     
     S   S     
  SSSS   SSSS  
  S         S  
  S         S  
SSS         SSS
               
               
               
SSS         SSS
  S         S  
  S         S  
  SSSS   SSSS  
     S   S     
     S   S     
|----Layer 3a|
              
              
  SSSSSSSSSSS
  S         S
  S         S
  S         S
  S         S
  S         S
  S         S
  S         S
  S         S
  S         S
  SSSSSSSSSSS
|----Layer 3b|
     S   S     
     SSSSS     
  SSSS   SSSS  
  S         S  
  S         S  
SSS         SSS
 S           S 
 S           S 
 S           S 
SSS         SSS
  S         S  
  S         S  
  SSSS   SSSS  
     SSSSS     
     S   S   
|----Layer 3c|
     S   S     
     SSSSS     
  SSSS   SSSS  
  S         S  
  S         S  
SSS         SSS
 S           S
 S           S 
 S           S 
SSS         SSS
  S         S  
  S         S  
  SSSS   SSSS  
     SSSSS     
     S   S     
|----Layer 3d|
     S   S     
     SIIIS     
  SSSS   SSSS  
  S         S  
  S         S  
SSS         SSS
 I           I 
 I           I 
 I           I 
SSS         SSS
  S         S  
  S         S  
  SSSS   SSSS  
     SIIIS     
     S   S     
|----Layer 3e|
     S   S     
     S   S     
  SSSS   SSSS  
  S         S  
  S         S  
SSS         SSS
               
               
               
SSS         SSS
  S         S  
  S         S  
  SSSS   SSSS  
     S   S     
     S   S     
|----Layer 4a|
              
              
  SSSSSSSSSSS
  S         S
  S         S
  S         S
  S         S
  S         S
  S         S
  S         S
  S         S
  S         S
  SSSSSSSSSSS
|----Layer 4, variants b, c, d, and e|
     SSSSS     
     SSSSS     
  SSSSSSSSSSS  
  S         S  
  S         S  
SSS         SSS
SSS         SSS
SSS         SSS
SSS         SSS
SSS         SSS
  S         S  
  S         S  
  SSSSSSSSSSS  
     SSSSS     
     SSSSS     
|----Layer 5, all variants|
             
             
  SSSSSSSSSSS
  S         S
  S         S
  S         S
  S         S
  S         S
  S         S
  S         S
  S         S
  S         S
  SSSSSSSSSSS
|----Layer 6, all variants|
              
              
  SSSSSSSSSSS
  SSSSSSSSSSS
  SSSSSSSSSSS
  SSSSSSSSSSS
  SSSSSSSSSSS
  SSSSSSSSSSS
  SSSSSSSSSSS
  SSSSSSSSSSS
  SSSSSSSSSSS
  SSSSSSSSSSS
  SSSSSSSSSSS
}}

;Pillar Room
This room is exactly like the empty room but with a decoration in the middle, so for simplicity's sake, the entrances is not shown.

{{layered blueprint|name=Pillar Room|default=Ground Layer|S=Stone Bricks|s=Smooth Stone Slab|T=Torch
|----Ground Layer|
SSSSSSSSSSS
SSSSSSSSSSS
SSSSSSSSSSS
SSSSSSSSSSS
SSSSSSSSSSS
SSSSSSSSSSS
SSSSSSSSSSS
SSSSSSSSSSS
SSSSSSSSSSS
SSSSSSSSSSS
SSSSSSSSSSS
|----Layer 1|
SSSSSSSSSSS
S         S
S         S
S         S
S   sss   S
S   sSs   S
S   sss   S
S         S
S         S
S         S
SSSSSSSSSSS
|----Layer 2|
SSSSSSSSSSS
S         S
S         S
S         S
S         S
S    S    S
S         S
S         S
S         S
S         S
SSSSSSSSSSS
|----Layer 3|
SSSSSSSSSSS
S         S
S         S
S         S
S    T    S
S   TST   S
S    T    S
S         S
S         S
S         S
SSSSSSSSSSS
|----Layers 4 & 5|
SSSSSSSSSSS
S         S
S         S
S         S
S         S
S         S
S         S
S         S
S         S
S         S
SSSSSSSSSSS
|----Layer 6|
SSSSSSSSSSS
SSSSSSSSSSS
SSSSSSSSSSS
SSSSSSSSSSS
SSSSSSSSSSS
SSSSSSSSSSS
SSSSSSSSSSS
SSSSSSSSSSS
SSSSSSSSSSS
SSSSSSSSSSS
SSSSSSSSSSS

}}
;Fountain Room
This room is exactly like the empty room but with a decoration in the middle, so for simplicity's sake, the entrances is not shown.

{{layered blueprint|name=Fountain Room|default=Ground Layer|S=Stone Bricks|W=Water
|----Ground Layer|
SSSSSSSSSSS
SSSSSSSSSSS
SSSSSSSSSSS
SSSSSSSSSSS
SSSSSSSSSSS
SSSSSSSSSSS
SSSSSSSSSSS
SSSSSSSSSSS
SSSSSSSSSSS
SSSSSSSSSSS
SSSSSSSSSSS
|----Layer 1|
SSSSSSSSSSS
S         S
S         S
S  SSSSS  S
S  S   S  S
S  S S S  S
S  S   S  S
S  SSSSS  S
S         S
S         S
SSSSSSSSSSS
|----Layer 2|
SSSSSSSSSSS
S         S
S         S
S         S
S         S
S    S    S
S         S
S         S
S         S
S         S
SSSSSSSSSSS
|----Layer 3|
SSSSSSSSSSS
S         S
S         S
S         S
S         S
S    W    S
S         S
S         S
S         S
S         S
SSSSSSSSSSS
|----Layers 4 & 5|
SSSSSSSSSSS
S         S
S         S
S         S
S         S
S         S
S         S
S         S
S         S
S         S
SSSSSSSSSSS
|----Layer 6|
SSSSSSSSSSS
SSSSSSSSSSS
SSSSSSSSSSS
SSSSSSSSSSS
SSSSSSSSSSS
SSSSSSSSSSS
SSSSSSSSSSS
SSSSSSSSSSS
SSSSSSSSSSS
SSSSSSSSSSS
SSSSSSSSSSS
}}
;Storeroom
This room is separated into two levels by a layer of oak planks and cobblestone, with a cobblestone structure in the middle connecting the two. The second floor contains a single loot chest, and can be accessed by ladders placed against one side of the wall. For simplicity's sake, the entrances is not shown.

{{layered blueprint|name=Storeroom|default=Ground Layer|S=Stone Bricks|C=Cobblestone|P=Oak Planks|L=Ladder|c=chest
|----Ground Layer|
SSSSSSSSSSS
SSSSSSSSSSS
SSSSSSSSSSS
SSSSSSSSSSS
SSSSSSSSSSS
SSSSSSSSSSS
SSSSSSSSSSS
SSSSSSSSSSS
SSSSSSSSSSS
SSSSSSSSSSS
SSSSSSSSSSS
|----Layer 1|
SSSSSSSSSSS
S         S
S         S
S         S
S   CCC   S
S   C C   S
S   CCC   S
SL        S
S         S
S         S
SSSSSSSSSSS
|----Layer 2|
SSSSSSSSSSS
S         S
S         S
S         S
S   C C   S
S         S
S   C C   S
SL        S
S         S
S         S
SSSSSSSSSSS
|----Layer 3|
SSSSSSSSSSS
SCCCCCCCCCS
SCPPPPPPPCS
SCPPPPPPPCS
SCPPCCCPPCS
SCPPC CPPCS
SCPPCCCPPCS
SLPPPPPPPCS
SCPPPPPPPCS
SCCCCCCCCCS
SSSSSSSSSSS
|----Layer 4|
SSSSSSSSSSS
S         S
S      c  S
S         S
S         S
S         S
S         S
S         S
S         S
S         S
SSSSSSSSSSS
|----Layer 5|
SSSSSSSSSSS
S         S
S         S
S         S
S         S
S         S
S         S
S         S
S         S
S         S
SSSSSSSSSSS
|----Layer 6|
SSSSSSSSSSS
SSSSSSSSSSS
SSSSSSSSSSS
SSSSSSSSSSS
SSSSSSSSSSS
SSSSSSSSSSS
SSSSSSSSSSS
SSSSSSSSSSS
SSSSSSSSSSS
SSSSSSSSSSS
SSSSSSSSSSS
}}