<noinclude>{{structure info}}</noinclude>
Stronghold Spiral Staircases are naturally generated components of [[strongholds]].  They are composed of [[stone bricks]], mossy stone bricks, cracked stone bricks, and stone [[slab]]s, with the possibility of containing wood or iron [[door]]s, [[iron bars]] and stone [[button]]s.  The type of stone brick used in each position is random along with the possibility of that position being filled with [[Infested Block|infested stone bricks]].  The top and bottom entrances to the staircase can be any combination of four entrance variants.  They can either be completely open, be surrounded by iron bars, have a wooden door entrance, or an iron door entrance with one or two buttons.  When the door variants are present, the doors are flush with the outside face of the staircase on the bottom, and the inside face on the top.  When the iron bars variant is in place, the bars can either be located in the same row that a door would be, or could be located one row closer to the center of the staircase.

==== Materials ====

{| class="wikitable"
|-
! Name
! Amount
|-
| Stone bricks or variants
| 215-229
|-
| Stone slabs
| 6
|-
| Iron Bars
| 0-14
|-
| Wood doors
| 0-2
|-
| Iron doors
| 0-2
|-
| Buttons
| 0-4
|-
|}

==== Blueprint ====
The entrances and exits for this can vary, so they are split into multiple parts, labeled "Layer 1a" and "Layer 1b." For these purposes, "a" means a wooden door entrance, "b" means an iron door entrance, "c" means an entrance with an iron bar rim, and "d" means a plain entrance.

{{layered blueprint|name=Spiral Staircase|default=Ground Layer, all variants|S=Stone Bricks|I=Iron Bars|i=Iron Door+Bottom|j=Iron Door+Top|w=Oak Door+Bottom|W=Oak Door+Top|B=Stone Button|s=Smooth Stone Slab
|----Ground Layer, all variants|
     
SSSSS
SSSSS
SSSSS
SSSSS
SSSSS
|----Layer 1a|
     
SSSSS
S  SS
S  SS
S  sS
SSwSS
|----Layer 1b|
     
SSSSS
S  SS
S  SS
S  sS
SSiSS
|----Layer 1c|
     
SSSSS
S  SS
S  SS
S  sS
SI IS
|----Layer 1d|
     
SSSSS
S  SS
S  SS
S  sS
S   S

|----Layer 2a & 2b|
     
SSSSS
SSSsS
S   S
S   S
SSSSS
|----Layer 2c|
     
SSSSS
SSSsS
S   S
S   S
SI IS
|----Layer 2d|
     
SSSSS
SSSsS
S   S
S   S
S   S
|----Layer 3a & 3b|
     
SSSSS
Ss  S
SS  S
SS  S
SSSSS
|----Layer 3c|
     
SSSSS
Ss  S
SS  S
SS  S
SIIIS
|----Layer 3d|
     
SSSSS
Ss  S
SS  S
SS  S
S   S
|----Layer 4, all variants|
     
SSSSS
S   S
S   S
SsSSS
SSSSS
|----Layer 5, all variants|
     
SSSSS
S  SS
S  SS
S  sS
SSSSS
|----Layer 6, all variants|
     
SSSSS
S SsS
S   S
S   S
SSSSS
|----Layer 7a|
     
SSwSS
S   S
S   S
S   S
SSSSS
|----Layer 7b|
     
SSiSS
S   S
S   S
S   S
SSSSS
|----Layer 7c|
     
S   S
SI IS
S   S
S   S
SSSSS
|----Layer 7d|
     
S   S
S   S
S   S
S   S
SSSSS
|----Layer 8a|
     
SSWSS
S   S
S   S
S   S
SSSSS
|----Layer 8b|
   B 
SSjSS
S  BS
S   S
S   S
SSSSS
|----Layer 8c|
     
S   S
SI IS
S   S
S   S
SSSSS
|----Layer 8d|
     
S   S
S   S
S   S
S   S
SSSSS
|----Layer 9a & 9b|
     
SSSSS
S   S
S   S
S   S
SSSSS
|----Layer 9c|
     
S   S
SIIIS
S   S
S   S
SSSSS
|----Layer 9d|
     
S   S
S   S
S   S
S   S
SSSSS
|----Layer 10, all variants|
     
SSSSS
SSSSS
SSSSS
SSSSS
SSSSS
}}