<noinclude>{{structure info}}</noinclude>
Please note that the stone bricks shown have the possibility of being the mossy, cracked, or [[Infested Block|infested version]] of regular stone bricks instead.

==== Materials ====
{| class="wikitable"
|-
! Name
! Amount
|-
| Stone bricks or variants
| 704
|-
| Stone Brick Stairs
| 8
|-
| Iron Bars
| 39
|-
| Lava
| 15
|-
| End Portal Frame
| 12
|-
| Silverfish Monster Spawner
| 1
|-
|}

==== Blueprint ====
<table><tr><td style="width:300px;">
{{layered blueprint|name=End Portal Room|default=Ground Layer|S=Stone Bricks|L=Lava|T=Stone Brick Stairs|I=Iron Bars|E=End Portal Frame|s=Monster Spawner
|----Ground Layer|
SSSSSSSSSSS
SSSSSSSSSSS
SSSSSSSSSSS
SSSSSSSSSSS
SSSSSSSSSSS
SSSSSSSSSSS
SSSSSSSSSSS
SSSSSSSSSSS
SSSSSSSSSSS
SSSSSSSSSSS
SSSSSSSSSSS
SSSSSSSSSSS
SSSSSSSSSSS
SSSSSSSSSSS
SSSSSSSSSSS
SSSSSSSSSSS
|----Layer 1|
SSSSSSSSSSS
S         S
S         S
S  SSSSS  S
S  SLLLS  S
S  SLLLS  S
S  SLLLS  S
S  SSSSS  S
S   SSS   S
S   SSS   S
S   SSS   S
SSS TTT SSS
SLS     SLS
SLS     SLS
SLS     SLS
SSSSI ISSSS
|----Layer 2|
SSSSSSSSSSS
S         S
S         S
S         S
S         S
S         S
S         S
S         S
S   SSS   S
S   SSS   S
S   TTT   S
S         S
S         S
S         S
S         S
SSSSI ISSSS
|----Layer 3|
SSISISISISS
S         S
I         I
S   EEE   S
I  E   E  I
S  E   E  S
I  E   E  I
S   EEE   S
I   SSS   I
S   TsT   S
I         I
S         S
I         I
S         S
S         S
SSSSIIISSSS
|----Layer 4|
SSISISISISS
S         S
I         I
S         S
I         I
S         S
I         I
S         S
I         I
S         S
I         I
S         S
I         I
S         S
S         S
SSSSSSSSSSS
|----Layer 5|
SSSSSSSSSSS
S         S
S         S
S         S
S         S
S         S
S         S
S         S
S         S
S         S
S         S
S         S
S         S
S         S
S         S
SSSSSSSSSSS
|----Layer 6|
SSSSSSSSSSS
SSSSSSSSSSS
SS       SS
SS       SS
SS       SS
SS       SS
SS       SS
SS       SS
SS       SS
SS       SS
SS       SS
SS       SS
SS       SS
SSSSSSSSSSS
SSSSSSSSSSS
SSSSSSSSSSS
|----Layer 7|
SSSSSSSSSSS
SSSSSSSSSSS
SSSSSSSSSSS
SSSSSSSSSSS
SSSSSSSSSSS
SSSSSSSSSSS
SSSSSSSSSSS
SSSSSSSSSSS
SSSSSSSSSSS
SSSSSSSSSSS
SSSSSSSSSSS
SSSSSSSSSSS
SSSSSSSSSSS
SSSSSSSSSSS
SSSSSSSSSSS
SSSSSSSSSSS
}}
</td><td style="vertical-align:top;">
[[File:StrongholdPortalRoom.png|400px|right]]
</td></tr></table>