<noinclude>{{structure info}}</noinclude>
Jail cells are sometimes found in strongholds. They are composed of [[stone bricks]] (which can be randomly exchanged for mossy stone bricks or cracked stone bricks), [[iron door]], and [[iron bars]].

==== Materials ====
{| class="wikitable"
|-
! Name
! Total Amount
|-
| Stone Bricks
| 282
|-
| Iron Bars
| 20
|-
| Iron Door
| 2
|-
|}

The stone brick structure in Strongholds is made out of 50% Stone Bricks, 20% Cracked Stone Bricks and 30% Mossy Stone Bricks

==== Blueprints ====
{{layered blueprint|name=Jail Cell|default=Ground Layer|s=Stone Bricks|b=Iron Bars|a=Iron Door+Bottom|c=Iron Door+Top
|----Ground Layer|
sssssssssss
sssssssssss
sssssssssss
sssssssssss
sssssssssss
sssssssssss
sssssssssss
sssssssssss
sssssssssss
|----Layer 1|
sssssssssss
s    b    s
s    b    s
s    b    s
ssasbbbsass



sssssssssss
|----Layer 2|
sssssssssss
s    b    s
s    b    s
s    b    s
sscsbbbscss



sssssssssss
|----Layer 3|
sssssssssss
s    b    s
s    b    s
s    b    s
ssbsbbbsbss



sssssssssss
|----Layer 4|
sssssssssss
sssssssssss
sssssssssss
sssssssssss
sssssssssss
sssssssssss
sssssssssss
sssssssssss
sssssssssss
}}