<noinclude>{{structure info}}</noinclude>
Loot altars are sometimes found in strongholds. They are composed of [[stone bricks]] and a [[chest]].

==== Materials ====

{| class="wikitable"
|-
! Name
! Total Amount
|-
| Stone bricks or variants
| 115
|-
| Stone brick slabs
| 7
|-
| Chests
| 1
|}

==== Blueprints ====
{{layered blueprint|name=Loot Altar|default=Ground Layer|s=Stone Bricks|c=Chest|S=Stone Brick Slab
|----Ground Layer|
sssssss
sssssss
sssssss
sssssss
sssssss
|----Layer 1|
sssssss
 SsssS
  SSS 
     
sssssss
|----Layer 2|
sssssss
  ScS  
     
     
sssssss
|----Layer 3|
sssssss
     
     
     
sssssss
|----Layer 4|
sssssss
sssssss
sssssss
sssssss
sssssss
}}