This tutorial documents simple build ideas. You can use these if you don't know what to build, or are just looking for some cool ideas to play around with! (still in progress)

=== Netherite beacon shrine ===

A beacon on a pyramid with ender crystals surrounding it. Use this to show your prestige and provide special bonuses in Survival!

(''Place end crystals on top of the obsidian blocks'')

{{layered blueprint|name=netherite beacon shrine|default=Layer 1
|O=obsidian|N=block of netherite|B=beacon

|----Layer 1|

  O         O
   NNNNNNNNN
   NNNNNNNNN
   NNNNNNNNN
   NNNNNNNNN
   NNNNNNNNN
   NNNNNNNNN
   NNNNNNNNN
   NNNNNNNNN
   NNNNNNNNN
  O         O

|----Layer 2|

    

    NNNNNNN
    NNNNNNN
    NNNNNNN
    NNNNNNN
    NNNNNNN
    NNNNNNN
    NNNNNNN

|----Layer 3|

     


     NNNNN
     NNNNN
     NNNNN
     NNNNN
     NNNNN

|----Layer 4|



  



      NNN
      NNN
      NNN

|----Layer 5|

       




       B
}}