This page seeks to teach you how to make designs and patterns using the [[glazed terracotta]] block, introduced in snapshot [[17w06a]] of update [[Java Edition 1.12]]. This will also cover how you can make it easier to share your patterns such that other people can easily recreate them.

== Making Patterns ==
These suggestions are based on opinion.

=== Matching the Corners ===
To start off, place one block of terracotta on its own, and pay attention to the corner designs. When putting together patterns, the corners take center stage, with different combinations of corner textures being the main factor in what is aesthetically pleasing. If you see a corner part you like, place more blocks as the player spins around that corner, revealing the design that comes out when they are put together.

Most terracotta blocks have a "centerpiece" in one of the corners. This could be anything that stands out from the rest of the block, such as the flower petals on the orange and white terracotta, the rings on the green terracotta, and the creeper face on the cyan terracotta. Generally, the prettiest 2x2 patterns come from either putting these "centerpieces" on the inside, thus creating a flower in the middle for orange and white terracotta, or putting the "centerpieces" on the outside corners.

When making a design larger than 2x2, keep in mind that there will end up being two patterns that repeat and are merged by the corner textures.

=== Combining Different Colors ===
When putting together designs with multiple colors of terracotta, keep in mind that the "centerpieces" of each color matter a lot. For example, wide curves (seen on the lime and light gray terracottas) tend to go well next to other wide curves. Light gray terracotta makes a nice corner design. Flower-y designs (seen on the white, orange, pink, and light blue terracottas) complete each other well and are often put in the center of the design. Brown terracotta is a nice way to subtly guide the viewer's eye. Putting brighter colors together also makes for aesthetically pleasing patterns. Magenta terracotta sticks out like a sore thumb and should not be used for aesthetically pleasing patterns. Its role is limited to non-decoration functions.

== Sharing the Patterns ==
Magenta glazed terracotta has an arrow that points in the direction the player was facing when it was placed. This can be used to share the different rotations of terracotta pattern. There is a single-color and multi-color example below. On one layer, there is the pattern, and the second layer has the magenta terracotta "key," which tells the player which direction they should face when placing the terracotta blocks.

Single-Color:
{{layered blueprint|name=singlecolor design|default=Design|M=Magenta Glazed Terracotta|n=Magenta Glazed Terracotta-rot90|m=Magenta Glazed Terracotta-rot180|N=Magenta Glazed Terracotta-rot270|o=Orange Glazed Terracotta|r=Orange Glazed Terracotta-rot90|O=Orange Glazed Terracotta-rot180|R=Orange Glazed Terracotta-rot270
|----Design|
   or
  oORr
 oOroRr
oORorORr
RroROroO
 RrORoO
  RroO
   RO
|----Key|
   Mn
  MmNn
 MmnMNn
MmNMnmNn
NnMNmnMm
 NnmNMm
  NnMm
   Nm
}}

Multi-Color:
{{layered blueprint|name=multicolor design|default=Design|
m=Magenta Glazed Terracotta    |n=Magenta Glazed Terracotta-rot90    |M=Magenta Glazed Terracotta-rot180    |N=Magenta Glazed Terracotta-rot270|
B=Black Glazed Terracotta      |l=Black Glazed Terracotta-rot90      |b=Black Glazed Terracotta-rot180      |L=Black Glazed Terracotta-rot270|
r=Red Glazed Terracotta        |e=Red Glazed Terracotta-rot90        |R=Red Glazed Terracotta-rot180        |E=Red Glazed Terracotta-rot270|
G=Green Glazed Terracotta      |c=Green Glazed Terracotta-rot90      |g=Green Glazed Terracotta-rot180      |C=Green Glazed Terracotta-rot270|
u=Blue Glazed Terracotta       |A=Blue Glazed Terracotta-rot90       |U=Blue Glazed Terracotta-rot180       |a=Blue Glazed Terracotta-rot270|
y=Gray Glazed Terracotta       |z=Gray Glazed Terracotta-rot90       |Y=Gray Glazed Terracotta-rot180       |Z=Gray Glazed Terracotta-rot270|
i=Light Gray Glazed Terracotta |t=Light Gray Glazed Terracotta-rot90 |I=Light Gray Glazed Terracotta-rot180 |T=Light Gray Glazed Terracotta-rot270|
O=Yellow Glazed Terracotta     |w=Yellow Glazed Terracotta-rot90     |o=Yellow Glazed Terracotta-rot180     |W=Yellow Glazed Terracotta-rot270|
J=Lime Glazed Terracotta       |k=Lime Glazed Terracotta-rot90       |j=Lime Glazed Terracotta-rot180       |K=Lime Glazed Terracotta-rot270|
P=Orange Glazed Terracotta     |q=Orange Glazed Terracotta-rot90     |p=Orange Glazed Terracotta-rot180     |Q=Orange Glazed Terracotta-rot270|
s=White Glazed Terracotta      |V=White Glazed Terracotta-rot90      |S=White Glazed Terracotta-rot180      |v=White Glazed Terracotta-rot270|
h=Light Blue Glazed Terracotta |f=Light Blue Glazed Terracotta-rot90 |H=Light Blue Glazed Terracotta-rot180 |F=Light Blue Glazed Terracotta-rot270|
X=Brown Glazed Terracotta      |$=Brown Glazed Terracotta-rot90      |x=Brown Glazed Terracotta-rot180      |&=Brown Glazed Terracotta-rot270


|----Design|
ERlBlBlBlBlBlBER
rebLbLbLbLbLbLre
LbgCgCgCgCgCgCLb
BlcXiuuuuuuT$GBl
LbgIFYzYzYzHtCLb
BlcaYxojKW&zAGBl
LbgaZojpQKWyACLb
BlcaYjpSvQKzAGBl
LbgaZkqVsPJyACLb
BlcaYwkqPJOzAGBl
LbgaZ$wkJOXyACLb
BlcThZyZyZyfiGBl
Lbg&tUUUUUUIxCLb
BlcGcGcGcGcGcGBl
eRlBlBlBlBlBlBER
rEbLbLbLbLbLbLre
|----Key|
NMnMnMnMnMnMnMNM
mnmNmNmNmNmNmNmn
NmmNmNmNmNmNmNNm
MnnMMmmmmmmNnMMn
NmmmNMnMnMnMnNNm
MnnnMmmmNNNnNMMn
NmmnNmmmNNmmNNNm
MnnnMmmMnNNnNMMn
NmmnNnnNmMMmNNNm
MnnnMnnnMMMnNMMn
NmmnNnnnMMMmNNNm
MnnNmNmNmNmnMMMn
NmmNnMMMMMMmmNNm
MnnMnMnMnMnMnMMn
NMnMnMnMnMnMnMNM
mnmNmNmNmNmNmNmn
}}

If the design is vertical, then the magenta terracotta "key" will have to be given to you in layers. For some people, it actually makes it easier to recreate the design. The key will be next to the design on each layer. This design is the same as the single-color example above.
{{layered blueprint|name=Layered design|default=Layer 1|m=Magenta Glazed Terracotta|n=Magenta Glazed Terracotta-rot90|M=Magenta Glazed Terracotta-rot180|N=Magenta Glazed Terracotta-rot270|o=Orange Glazed Terracotta|r=Orange Glazed Terracotta-rot90|O=Orange Glazed Terracotta-rot180|R=Orange Glazed Terracotta-rot270
|----Layer 1|
   RO
 
   Nm
|----Layer 2|
  RroO
 
  NnMm
|----Layer 3|
 RrORoO
 
 NnmNMm
|----Layer 4|
RroROroO
 
NnMNmnMm
|----Layer 5|
oORorORr
 
MmNMnmNn
|----Layer 6|
 oOroRr
 
 MmnMNn
|----Layer 7|
  oORr
 
  MmNn
|----Layer 8|
   or
 
   Nm
}}

== Gallery of example patterns ==

=== Color-associated patterns ===

<gallery>
File:BrownTerracottaPatterns.png|Several repeating 2&times;2 brown terracotta patterns.
File:LightGreyTerracottaDesign.png|A complex light gray terracotta pattern.
File:LimeTerracottaPatterns.png|Several intricate lime terracotta patterns.
File:PurpleTerracottaPatterns.png|A couple 36m² purple terracotta patterns.
File:WhiteTerracottaPatterns.png|A few white 36m² terracotta patterns.
File:OrangeTerracottaPatterns.png|Some orange 36m² terracotta patterns.
File:MagentaTerracottaPatterns.png|Several 36m² magenta terracotta patterns.
File:LightBlueTerracottaPatterns.png|A few 36m² light blue terracotta patterns.
</gallery>

=== 6×6 patterns ===
{{main|/6×6 Patterns 1|/6×6 Patterns 2}}
<!-- '''Note''': due to technical complexity these patterns are kept on separate pages and should not be moved to this page. -->

{{tutorials}}

[[Category:Modernized tutorial]]

[[fr:Tutoriels/Motifs en terre cuite émaillée]]
[[zh:教程/带釉陶瓦的图案]]