{{see also|Tutorials/Village mechanics#Artificial Village Defenses}} 

'''[[Villager]]s''' are useful passive mobs. [[Player]]s can get items that are normally hard to obtain (like enchanted diamond [[armor]]) or downright impossible ([[bottle o' enchanting]]) via [[trading]] with villagers using [[emerald]]s as currency. However, finding a village with live villagers can sometimes be difficult, but there is a simple solution - to make your own village.

== Housing ==

A [[villager]] needs a house to stay in and be sheltered from threats such as [[illagers]] and [[zombies]], which attack villagers on sight. Below are a few houses that you can make for them. Please note that as of [[Java Edition 1.14|1.14]], villagers consider a bed to be a house.

=== Simple ===

This is for those who want the [[villager]]s to start [[breeding]], or are low on supplies.

;Materials
* 1 [[bed]]

;Procedure
# Place a bed.
# Make sure it is not obstructed.
# Wait for a villager to come and sleep.

=== Hut ===
{{See also|Village/Structure/Blueprints}}

;Materials
* 59 [[planks]]
* 3 [[glass]] blocks or [[Glass Pane|panes]]
* 1 [[wooden door]]
* 20 [[log|wood]]
* [[Torch]]es or [[glowstone]]
* 1 Bed

;Procedure
# Dig out a 5×5 area and fill it with 25 planks.
# Chop out the corners and replace them with wood.
# Pillar jump 4 times on each corner.
# Fill in the walls with planks, then replace the block in the middle with the glass.
# Get rid of the middle and lower blocks. Place the door from the outside.
# Finish the roof.
# Light up the inside and outside with torches or glowstone.
# Place a bed inside.

=== Breeding huts ===

An easy way to make buildings that can make your [[villager]]s multiply a lot. They're designed to be practical more than attractive, though.

;Procedure
# Place 10 [[bed]]s.
# Place a [[bell]] where villagers can gather.
# Place at least one [[Composter]] to make at least one villager adopt the profession of farmer.
# Dig a hole and fill it with water, then make some farmlands and give the farmer some seeds (wheat or beetroot), potatoes or carrots, so they can plant and harvest crops to share food with other villagers, which makes them willing to breed.
# Decorate the building if desired.

Another way to do this:
# Make a 6×6 square, with walls, out of your building material.
# Place 1 door, then a line of cobblestone, then another door for the entrance.
# Transform two zombie villagers back into villagers.
# Place two beds
# At night, the villagers go inside and sleep (they won't breed if villagers are not willing)<!-- this way is useless without making villager willing -->

=== Trading hall ===

Skipping to the advanced version, you can make a large building to house (imprison) many villagers for convenient trading.  Entry should be blocked by fence gates or iron doors to prevent escapes, and the entire building needs to be well-lit and otherwise defended from invading monsters; otherwise the design and appearance is up to you.  The core of the trading hall is the series of cubicles where the villagers spend their lives. 

These can be separated by walls, fences or blocks, with a fence-gate for you to get in or let a villager in or out. These need to have at least four blocks of floor space each:  Two for a bed, one for a job site block, and one for the villager to stand. The open space should be between the head of the bed and the fence gate.  Ceilings should be three blocks high to allow iron golems to move around, and allow villagers to breed. You can also add beds to many, if not most Villager rooms in the Trading Hall once you get enough resources. You may also have a "breeding hall" or dorm with several beds, to breed yet-unemployed villagers.  Use fence gates to block off any stairs you may need, and trapdoors to block any ladders.

== Defense ==
Artificial Villages can be attacked by [[zombie siege]]s and illager [[raid]]s too, so you need to establish defenses for them as well, and you can do it before bringing the first Villagers there! (note: if you already have an artificial village populated with Villagers, refer to regular Village Defenses)

Firstly, you need to build a wall around the area where you plan to build the artificial Village. As the player selects the terrain, and there is no rush, you may incorporate erratic terrain to your liking, but make sure safety accommodations are made for the villagers including lakes/rivers, lava lakes (most important), caves, and two block or more holes/4 or more block drops. Also, make sure you use fence gates to get in and out of the walled area. It is also a good idea to put a block or two out from the top of the wall so spiders can't climb in, so you would be safer.

Next, you need to light up the area inside the Village to minimize hostile mob spawning at night. After that, make sure that you placed at least one bell, making sure it has a considerable distance from the wall. Afterward, make sure there are at least 10 beds inside the wall. (It is advised to move the beds inside houses with wooden doors later if they are not already.)

Next, it is time to bring in the villagers. make sure there are at least two, and that you have spawned an iron golem inside (note you can also kidnap iron golems via boats).
Next, do some rapid breeding (or bring in more Villagers) until there are at least five Villagers (more if the enclosure is more than 80 blocks long or wide or tall (only include tall if you use the air for a multi-level village).

After that, you can build the village to your heart's desire, but make sure that additional areas are also walled, and don't tear down the preexisting wall until the new walls are up and the new area is well lit.

You can also spawn [[Iron Golem|iron golems]] using blocks to defend the villagers from hostile mobs. You can spawn iron golems by placing 4 iron blocks in a T-shape with a carved pumpkin on top. Iron golems spawned this way will not attack the player. Iron golems can also be spawned when a villager is fleeing from a zombie, or when villagers gossip.

== Obtaining villagers ==
There are two general ways to obtain [[villager]]s from the surrounding natural environment.  Once free, villagers are hard to control, but you can lead them around by placing a job site block for them, then once they have reached it and taken a profession, you can break the job block and place it further along where you want them to go.  Once you have actually traded with a villager, their profession can't change, so for those, you'll need the ''right'' job-site block for their profession.  Once you've installed them in their home, place the job-site block for the profession you want them to have, and then trade with them to make that profession permanent.

=== Kidnapping from a village ===

An easy way to obtain villagers involves using a [[boat]] to move villagers from the nearest village to a more convenient place. Boats can be moved on level ground (without water). A villager can be made to enter the boat by pushing the villager into the conveyance (or driving it into the villager), and the villager does not leave until the boat is broken. However, boats can move only downward but not upward. You can, however, push a boat upward using a piston and a redstone torch.

=== Curing a zombie villager ===

Catching and curing a [[zombie villager]] is another way to obtain a villager. Zombie villagers can be found in [[igloo]] basements, or in [[Village#Abandoned villages|abandoned villages]], but occasionally they can be found anywhere in the overworld. It is recommended to build traps (like large holes 2 or 3 blocks deep) to hunt them. They do not spawn in other cases where normal [[zombie]]s may spawn; e.g. from [[spawner]]s or as a reinforcement spawned by an attacked [[zombie]] or [[Zombified Piglin|zombified piglin]].

When found, zombie villagers must be detained and covered with a roof (or soaked in [[water]]) to prevent them from burning in sunlight. They can be cured with a [[splash potion]] of [[Weakness]] and a [[golden apple]]. At this point, they can be carried to their [[village]] with [[minecart]]s (but recommended to settle their village in the vicinity after having them).

Additionally, if you're in a snowy biome and haven't found a [[village]], you can start up your own by finding an [[igloo]] with a basement. This is a reliable method for creating your own village in a snowy biome. In the basement of the igloo, there is a [[zombie villager]] and a [[Villager|cleric]] (in [[Bedrock Edition]], the villager may be any profession). By curing the zombie villager, you'll have two villagers (one of them transforms into a leatherworker, due to the cauldron being their [[job site]] block), which you can transport to the top of the igloo via Minecarts or upward [[Bubble Column]]. 

Next, place down at least 6 valid beds around the two villagers, and give them some food (3 pieces of bread each) to make them "willing" to breed. After the two villagers breed and create a [[baby villager]], you can create a simple infinite villager breeder. Note that villagers cannot infinitely breed without stopping, because they also need to rest at home, sleep, gossip, and work (or wander around if they are a nitwit). Additionally, they need food in order to be willing.

== Expansion ==

To get more [[villager]]s, one can repeatedly add in more houses to let the villagers breed more and make more villagers. After obtaining two villagers, place down at least 3 valid beds around them and give them some food (3 pieces of bread each) to make them "willing" to breed. If the conditions are met the two villagers will eventually breed and create a [[baby villager]]. 

To assign a profession, just place their [[job site]] block; see [[Villager#Professions|Professions]] for more information. 

Also, if the villagers are gossiping a lot, an [[iron golem]] can spawn, which can be an aid in defense or serve as a source of [[iron]]. [[Villager#Gossip|Gossip]] is based on certain player actions (curing, attacking, killing, or trading).

Please note that the larger your village is, the more prone it is to a [[zombie siege]]. In order for a zombie siege to occur, there must be at least 10 beds or 20 villagers and the [[player]] must be present in the village.

If you build a village in a biome where an [[illager patrol]] can spawn, be careful; they will try to kill villagers, and killing the patrol captain triggers a [[raid]] in your own village. Fences or walls can keep them out easily, or let an iron golem kill the captain; otherwise, you can equip yourself with a [[milk bucket]] and/or try to kill everyone but the captain (if you accidentally kill the captain in the village, drink the milk immediately and hope for the best). Then lead the captain well away from the village (over 32 blocks from the nearest bed) to kill them, and drink the milk before returning to the village. Another option is to put the captain into a trap, like a hole in the ground.

== Tips ==

* You can recreate natural [[village]] buildings as much as possible, but for example, building another temple does not create more clerics; for that you need to add more brewing stands, that being a cleric's [[job site]] block.  More [[villager]]s simply means the babies produced have an equal chance of getting any of the occupations that depend on the job site blocks in the village.
* You may be interested in building a villager farm; they produce villagers in extremely high densities, making it worthwhile to enclose the entire villager farm to keep out hostile mobs and make it easier to light up and navigate.
* Villagers tend to be careless. They can fall off from high places, take damage on [[cacti]] or even swim in [[lava]] pools. Restrict them from such areas as much as possible by placing fences or any other kind of barricade (other than cacti, fire, or lava).
* You can add fountains, [[tree]]s, parks, and the like to beautify the village.
* When night falls, villagers fail to scatter around so that they all go into a different house. Villagers seek unclaimed beds, which means if a villager cannot find any unclaimed beds, most of them would probably fail to get into the safety of their houses. To prevent this, one can make a big house with more than one bed. However, another way of protecting them is to simply sleep before hostile [[mob]]s spawn.
* Create lamp posts. This reduces the number of mobs that spawn. A plains village lamp post is usually 2 fences and a block of stripped oak wood on top, with torches on the sides of the wood. Another design could consist of (savanna village design) acacia fences and torch on top of it, (desert village design) [[terracotta]] on top of 2 [[sandstone|cut sandstone]] with a torch on top of terracotta, (taiga and snowy taiga design) [[wall|cobblestone wall]] with a torch on it, (snowy tundra design) 3 block height of spruce fence with 1 to 4 [[lantern]] attached to the bottom of sided fence (or if you are lazy, just place a torch every 10 blocks).  Once you've gotten pumpkins (the [[Wandering Trader]] can help), jack-o-lanterns become an option.

== Sample Village Buildings ==
This information is about a sample village and its buildings. You can grab inspiration from these simple designs OR simply build them with a different material.

=== Well ===
{{layered blueprint|scale=2|name=well|s=cobblestone|w=water|f=oak fence|b=bell
|----Layer -5|
sssss
sssss
sssss
sssss
sssss
|----Layers -4 - 0|
sssss
swwws
swwws
swwws
sssss
|----Layer 1|
sssss
s   s
s   s
s   s
sssss
|----Layer 2|
f   f
     
     
     
f   f
|----Layer 3|
f   f
     
  b  
     
f   f
|----Layer 4|
sssss
sssss
sssss
sssss
sssss
}}

=== Hut ===
''Note: Change the crafting table for the villagers job site block.''
{{layered blueprint|scale=2|name=hut|p=oak planks|w=oak log+top|c=crafting table|B=red bed+top head-rot270|b=red bed+top foot-rot270|s=oak stairs|f=oak fence|g=glass pane|G=glass pane-rot 90|d=oak door+bottom|D=oak door+top|P=oak pressure plate|t=torch
|----Layer 0|
       
 ppppp 
 ppppp 
 ppppp 
 ppppp 
 ppppp 
   p   
|----Layer 1|
wpppppw
pc   Bp
p    bp
p     p
psf   p
pss   p
wppdppw
|----Layer 2|
wpGpGpw
p     p
g     g
p     p
g P   g
p     p
wppDppw
|----Layer 3|
wpppppw
p t t p
pt   tp
p     p
pt   tp
p t t p
wpppppw
|----Layer 4|
sssssss
sppppps
sppppps
sppppps
sppppps
sppppps
sssssss
}}

=== Workshop ===
''Note: Replace the anvil with the job site block (preferably one for professions like weaponsmith).''
{{layered blueprint|scale=2|name=workshop|c=cobblestone|a=anvil|d=oak door+bottom|D=oak door+top|l=lantern|t=crafting table|w=lava|o=oak planks
|----Layer 0|
         
 ccccccc 
 ccccccc 
 ccccccc 
 ccccccc 
    c    
|----Layer 1|
ccccccccc
cwc   atc
cwc     c
ccc     c
c       c
ccccdcccc
|----Layer 2|
ccccccccc
c       c
c       c
c       c
c       c
ccccDcccc
|----Layer 3|
ccccccccc
c       c
c  l l  c
c  l l  c
c       c
ccccccccc
|----Layer 4|
ccccccccc
ccccccccc
ccccccccc
ccccccccc
ccccccccc
ccccccccc}}

''Note: you could also do this:'' 
{{layered blueprint|scale=2|name=workshop2|c=cobblestone|a=anvil|d=oak door+bottom|D=oak door+top|l=lantern|t=crafting table|w=lava|o=oak planks|B=red bed+top head-rot270|b=red bed+top foot-rot270
|----Layer 0|
        
 ccccccc 
 ccccccc 
 ccccccc
 ccccccc
    c   
|----Layer 1|
ccccccccc
coo   atc
co      c
c       c
c       c
cccdccccc
|----Layer 2|
coooooooc
o       o
o       o
o       o
o       o
cooDooooc
|----Layer 3|
ooooooooo
ol     lo
o       o
o       o
ol     lo
ooooooooo
|----Layer 4|
ccccccccc
ccccccccc
ccccccccc
ccccccccc
ccccccccc
ccccccccc| 
}}

=== Stone Hut ===
''Note: replace the anvil with the job site block''
|{{Layered blueprint|scale = 2|name=Stone Hut|s=cobblestone|a=anvil|d=oak door+bottom|D=oak door+top|l=lantern|t=crafting table|w=lava|o=oak planks|B=red bed+top head-rot270|b=red bed+top foot-rot270
|----Layer 0|
     
 sss 
 sss 
 sss 
  s  
|----Layer 1|
sssss
sa Bs
s  bs
s   s
ssdss
|----Layer 2|
sssss
s   s
s   s
s   s
ssDss
|----Layer 3|
sssss
s   s
s l s
s   s
sssss
|----Layer 4|
 sss 
 sss 
 sss 
 sss 
 sss 
}}

=== Farm ===
''Note: you can replace the wheat with any other crop.''
{{layered blueprint|scale=2|name=farm|f=farmland|w=water|W=wheat|c=composter
|----Layer 0|
ffwff
ffwff
ffwff
ffwff
ffwff
|----Layer 1|
WW WW
WW WW
WW WW
WW WW
WW Wc
}}

== Other decorative buildings ==

=== Town Center ===
{{layered blueprint|scale=2|name=TownCenter|c=cobblestone|b=bell|g=glass pane|G=glass pane -rot 90|a=anvil|A=air|w=oak planks|s=cobblestone stairs|l=lantern
|----Layer 0|
ccccccc
ccccccc
ccccccc
ccccccc
ccccccc
 lsssl  
|----Layer 1|
cwwwwwc
w     w
w  c  w
w     w
cw   wc
|----Layer 2|
cGGcGGc
w     w
g  b  g
w     w
cw   wc
|----Layer 3|
cGGwGGc
wl   lw
g     g
wl   lw
cw   wc
|----Layer 4|
ccccccc
ccccccc
ccccccc
ccccccc
ccccccc
|----Layer 5|
 sssss
scccccs
scccccs
scccccs
 sssss
|----Layer 6|
A
 scccs 
 scccs
 scccs
A
|----Layer 7|
A
  scs
  scs
  scs
A  
|----Layer 8|
A
AAAc
AAAc
AAAc
A
|----Layer 9|
A
A
   a
A
A
}}

=== Dock ===

''Replace the red wool with a custom flag''
{{Layered blueprint|scale=2|name=dock|o=Oak Log|w=Water|p=Oak Planks|d=Oak Door+bottom|b=Barrel|F=Oak Fence Gate|f=Oak Fence|D=Oak Door+top|c=Chest|t=Furnace|W=Crafting Table|x=White Bed+top-head-rot180|X=White Bed+top-foot-rot180|v=Torch|s=Oak Stairs|z=Red Wool
|----Layer 0|
wwwwwwwwwwwwwww
wowwwwowwwwwwww
wwwwwwwwwwwowww
wwwwwwwwwwwwwww
wwwwwwwwwwwwwww
wwwwwwwwwwwowww
wowwwwowwwwwwww
wwwwwwwwwwwwwww
|----Layer 1|
            
 oppppo   
pppppppppppo
pppppppppppp
pppppppppppp
pppppppppppo
 oppppo   


|----Layer 2|
 
 oppppo
 pttWWpffbff
 d    d    F
 d    d    F
 pXxxXpffbff
 oppppo
|----Layer 3|
 
 opffpo
 pcc  pv v v
 D    D
 D    D
 p    pv v v
 opffpo
|----Layer 4|

 opffpo
 p   vp
 pv   p
 pv   p
 p   vp
 opffpo
|----Roof (1)|
ssssssss
spppppps
sp    ps
sp    ps
sp    ps
sp    ps
spppppps
ssssssss
|----Roof (3)|
 
 ssssss
 spppps
 spppps
 spppps
 spppps
 ssssss
|----Roof (3)|
 
 
  ssss 
  spps
  spps
  ssss
|----Roof (4-5)|
 
 
 
   f
|----Roof (6)|
 
 
 
   z
}}

=== Hotel ===
''Build a building with multiple rooms. This is just to look good, because villagers can't get in.''

Hotel room (Sample):
''Replace the wool with any color you want''
''The floor and downstairs ceiling have to be two different layers.
{{Layered blueprint|scale =2|name = hotel room|
w=red wool|
a=air|
l=oak log|
p=oak planks|
t=oak trapdoor|
W=water|
o=hopper|
b=red bed+top head-rot180|
B=red bed+top foot-rot180|
g=glass pane-rot90|
G=glass pane-rot180|
v=glass|
s=shroomlight|
z=oak door+bottom|
Z=oak door+top|
q=block of quartz|
e=end rod|
c=chest|
h=crafting table|
u=furnace|
i=EntitySprite:painting|
d=oak stairs|
A=EntitySprite:armor stand|
r=lever
|----Layer 0|
lppppppppppl
pwwwwwwwqqqp
pwwwwwwwqqqp
pwwwwwwwqqqp
pwwwwwwwqqqp
pwwwwwwwqqtp
pwwwwwwwqqqp
pwwwwwwwwwwp
pwwwwwwwwwwp
pwwwwwwwwwwp
lppppppppppl
|----Layer 1|
ppggggpppppp
ph    hptWtp
pbB    z t p
pbB    p  op
ph    upzvvp
pbB   up   p
pbB   hppppp 
ph     pccAp
p      z   p
p      pAAAp
ppzzpggppppp
|----Layer 2|
ppggggpppppp
pe     p r p
pi     Z   p
pi     p   p
pe    upZvvp
pi    up   p
pi     ppppp
pe     pdd p
p      Z   p
p      p   p
ppZZpggppppp
|----Layer 3|
ppggggpppppp
ps     p   p
p      p   p
p      p   p
ps     pvvvp
p      p  rp
p      ppppp
ps     p   p
p      p   p
p      p   p
pppppggppppp
|----Ceiling|
pppppppppppp
pppssppppspp
pppppppppppp
pppppppppspp
pppssppppppp
pppppppppspp
pppppppppppp
pppssppppppp
ppppppppsssp
ppsspppppppp
pppppppppppp
}}

=== Jail ===

Inaccessible to villagers as they cannot get in. To put villagers in it, you need to use a boat/minecart to get them in, then lock the door.

Alternatively, can also be used to imprison zombie villagers for the purpose of curing them into human villagers again.

The bed can be any color

Jail Cell Example:
{{Layered blueprint|scale =2|name=jailCell|
b=Iron Bars|
c=Cobblestone|
w=White Bed+top-head-rot270|
W=White Bed+top-foot-rot270|
i=Iron Door+bottom|
I=Iron Door+top|
h=Hopper|
l=Lever|
C=Chest|
t=Torch|
a=Air|
v=Lava

|----Layer 0|
ccccc
ccccc
ccccc
ccccc
ccccc
|----Layer 1|
bbbbb
b  wb
bh Wb
b  Cb
bcicb
|----Layer 2|
bbbbb
b   b
b   b
b   b
bcIcb
   l
|----Layer 3|
bbbbb
ct tc
b   b
bt tb
bcccb
|----Layer 4|
ccccc
ccccc
ccccc
ccccc
ccccc
|----Layer 5 (Optional)|
aaaaa
aavaa
avava
aavaa
accca
}}

===School===
Decorative:
Teach villagers how to work. Don't forget the classrooms and lockers.

Classroom (Farming)

{{Layered blueprint|scale = 2|name = classroom1|
w= oak planks|
l= oak log|
f=farmland|
p=potatoes|
t=wheat|
c=carrots|
b=beetroots|
o=oak door+bottom|
O=oak door+top|
C= composter|
W=water|
k=black wool|
v=end rod|
n=chest|
z=lantern|
x=crafting table


|----Layer 0|
wwwwwwwwww
wwwwwwwwww
wwwwwwwwww
wwwwwwwwww
wwwwwwwwww
wwwwwwwwww
wwwwwwwwww
wwwwwwwwww
|----Layer 1|
wwwwwwwwww
wff vv ffw
wff    ffw
wWC    CWw
wff    ffw
wff    ffw
wxx    xxw
wwwwoowwww
|----Layer 2|
wwwwwwwwww
wttkkkkppw
wtt    ppw
wn      nw
wbb    ccw
wbb    ccw
wC      Cw
wwwwOOwwww
|----Layer 3|
wwwwwwwwww
w  kkkk  w
w  z  z  w
w        w
w  z  z  w
w        w
w  z  z  w
wwwwwwwwww
|----Ceiling|
wwwwwwwwww
wwwwwwwwww
wwwwwwwwww
wwwwwwwwww
wwwwwwwwww
wwwwwwwwww
wwwwwwwwww
wwwwwwwwww

}}
Hallway:
''replace the terracotta with classrooms and add more lockers to extend the hallway''

{{Layered blueprint|scale = 2|name = hallway|
w=oak planks|
d=oak door+bottom|
D=oak door+top|
l=lever|
c=chest|
C=trapped chest|
x=crafting table|
f=furnace|
m=magenta glazed terracotta|
M=magenta glazed terracotta-rot90|
v=magenta glazed terracotta-rot180|
V=magenta glazed terracotta-rot270|
s=shroomlight

|----Layer 0|
wwwwwwwwwwwwwwww
wwwwwwwwwwwwwwww
wwwwwwwwwwwwwwww
wwwwwwwwwwwwwwww
wwwwwwwwwwwwwwww
wwwwwwwwwwwwwwww
wwwwwwwwwwwwwwww
wwwwwwwwwwwwwwww
|----Layer 1|
wwwwwwwwwwwwmmmm
wxxxxxxxxxxw   M
wddddddddddw   M
V
V
wddddddddddw   M
wxxxxxxxxxxw   M
wwwwwwwwwwwwvvvv
|----Layer 2|
wwwwwwwwwwwwmmmm
wcCcCcCcCcCw   M
wDDDDDDDDDDw   M
V
V
wDDDDDDDDDDw   M
wcCcCcCcCcCw   M
wwwwwwwwwwwwvvvv
|----Layer 3|
wwwwwwwwwwwwmmmm
wfffffffffff   M
wlllllllllll   M
V
V
wlllllllllll   M
wfffffffffff   M
wwwwwwwwwwwwvvvv

|----Layer 4|
wwwwwwwwwwwwmmmm
wwwwwwwwwwww   M
wwwwwwwwwwww   M
Vwwswwswwswws 
Vwwswwswwswws
wwwwwwwwwwww   M
wwwwwwwwwwww   M
wwwwwwwwwwwwmmmm
}}

=== Honey House ===
Tip: having beehives near crops speeds up the growth of the crops.
{{Layered blueprint|scale = 2|name=honeyHouse|
w=birch planks|
h=beehive|
-=air|
f=birch fence|
c=campfire|
C=crafting table|
x=chest|
b=birch door+bottom|
B=birch door+top|
g=glass pane|
G=glass pane-rot 270|
d=grass block|
F=dandelion|
t=torch

|----Layer 0|

wwwwwwwwwwww
wwccwccwccww
wwwwwwwwwwcw
wwwwwwwwwwcw
wwwwwwwwwwww
wwwwwwwwdddw
wwwwwwwwdddw
wwwwwwwwwwww

|----Layer 1|
wGGwwGGwwGGw
wf  f  f  fw
wx         w
gx         g
gx        fg
wx      FFFw
wC      FFFw
wwwwwbbwwwww
|----Layer 2|
wGGwwGGwwGGw
wfhhfhhfhhfw
wx        hw
gx        hg
gx        fg
wx         w
w          w
wwwwwBBwwwww
|----Layer 3|
wGGwwGGwwGGw
w  tt  tt  w
w          w
g          g
g          g
w          w
w  tt  tt  w
wwwwwwwwwwww
|----Layer 4|
wwwwwwwwwwww
wwwwwwwwwwww
wwwwwwwwwwww
wwwwwwwwwwww
wwwwwwwwwwww
wwwwwwwwwwww
wwwwwwwwwwww
wwwwwwwwwwww
}}

''Add a roof''

==Village House Additions (Recommended for large house)==

Grill:
{{Layered blueprint|scale = 2|name = grill|
c=campfire|
i=oak trapdoor|
f=block of coal|
t=iron trapdoor|
s=spruce wood stairs|
-=air


|----Layer 0|
-
-ff
 ii
|----Layer 1|
-ii
icci
 ii
|----Layer 2|
-
-tt
|----Layer 3|
-
-ss
}}

Trampoline:

''The carpet can be any color''
{{Layered blueprint|scale = 2|name=trampoline|
t=spruce trapdoor|
s=slime block|
c=black Carpet|
a=air

|----Layer 1|
 tt
tsst
tsst
 tt
|----Layer 2|
a
 cc
 cc

}}
Alternate version: Baby villagers can jump on it.

Don't let a villager sleep inside it.


{{Layered blueprint|scale = 2|name=trampoline2|
t=spruce trapdoor|
s=black Bed+top head-rot270|
S=black Bed+top foot-rot270|
c=black Carpet|
a=air

|----Layer 1|
 tt
tsst
tSSt
 tt

}}

Stable (pig or horse)

{{Layered blueprint|scale =2|name=stable|

o=oak log|
p=oak wood planks|
f=oak fence|
F=oak fence gate|
h=hay bale|
c=chest|
C=crafting table

|----Layer 1|
ffffffffff
f  f  f  f
f  f  f  f
fFFfFFfFFf
f        f
fc     hhf
fc     hhf
fC     hhf
f        f
fFFfffffff
|----Layer 2-4|
f  f  f  f


f  f  f  f

       hh
       hh
       hh
|----Layer 5|
oooooooooo
oppffffppo
oppffffppo
oooooooooo

}}
Spleef arena (Only for very large houses and mansions) (Remove scaffolding after everyone is on the snow layer, before game starts)

{{Layered blueprint|scale = 2|name=spleef|
s=snow block|
p=carved pumpkin|
c=chest|
v=cobblestone|
-=air|
x=scaffolding|
l=lantern

|----Layer 0|
xvvvvvvvvvvvvvvvvvvvvx
-vvvvvvvvvvvvvvvvvvvv
-vvvvvvvvvvvvvvvvvvvv
-vvvvvvvvvvvvvvvvvvvv
xvvvvvvvvvvvvvvvvvvvvx
xvvvvvvvvvvvvvvvvvvvvx
-vvvvvvvvvvvvvvvvvvvv
-vvvvvvvvvvvvvvvvvvvv
-vvvvvvvvvvvvvvvvvvvv
xvvvvvvvvvvvvvvvvvvvvx
|----Layers 1-3|
x                    x
-
-
-
x                    x
x                    x
-
-
-
x                    x
|----Layer 4|

xvvvvssssssssssssvvvvx
-vvvvssssssssssssvvvv
-vvvvssssssssssssvvvv
-vvvvssssssssssssvvvv
xvvvvssssssssssssvvvvx
xvvvvssssssssssssvvvvx
-vvvvssssssssssssvvvv
-vvvvssssssssssssvvvv
-vvvvssssssssssssvvvv
xvvvvssssssssssssvvvvx
|----Layer 5|
-
-c-s              s-c
-c-s              s-c
-
-c-s              s-c
-c-s              s-c
-
-c-s              s-c
-c-s              s-c
-
|----Layer 6|
-
- -s              s--
- -s              s-
-
- -s              s-
- -s              s-
-
- -s              s-
- -s              s-
-
|----Layer 7|
-
- -p              p--
- -p              p-
-
- -p              p-
- -p              p-
-
- -p              p-
- -p              p-
-
|----Layer 8|
-
---l    l    l    l
---l    l    l    l
-
---l    l    l    l
---l    l    l    l
-
---l    l    l    l
---l    l    l    l

|----Layer 9|
 vvvvvvvvvvvvvvvvvvvv
-vvvvvvvvvvvvvvvvvvvv
-vvvvvvvvvvvvvvvvvvvv
-vvvvvvvvvvvvvvvvvvvv
 vvvvvvvvvvvvvvvvvvvv
 vvvvvvvvvvvvvvvvvvvv 
-vvvvvvvvvvvvvvvvvvvv
-vvvvvvvvvvvvvvvvvvvv
-vvvvvvvvvvvvvvvvvvvv
 vvvvvvvvvvvvvvvvvvvv 
|----Layer 10|
-
---l    l    l    l
---l    l    l    l
-
---l    l    l    l
---l    l    l    l
-
---l    l    l    l
---l    l    l    l

}}


{{Tutorials}}

[[cs:Návody/Vytvoření vesnice]]
[[pl:Poradniki/Zakładanie wioski]]
[[zh:教程/创建村庄]]