{{Layered blueprint
|name=Glazed Terracotta Patterns 2
|a=Light Gray Glazed Terracotta
|A=Light Gray Glazed Terracotta-rot90
|b=Light Gray Glazed Terracotta-rot180
|B=Light Gray Glazed Terracotta-rot270
|c=Cyan Glazed Terracotta
|C=Cyan Glazed Terracotta-rot90
|d=Cyan Glazed Terracotta-rot180
|D=Cyan Glazed Terracotta-rot270
|e=Purple Glazed Terracotta
|E=Purple Glazed Terracotta-rot90
|f=Purple Glazed Terracotta-rot180
|F=Purple Glazed Terracotta-rot270
|g=Blue Glazed Terracotta
|G=Blue Glazed Terracotta-rot90
|h=Blue Glazed Terracotta-rot180
|H=Blue Glazed Terracotta-rot270
|i=Brown Glazed Terracotta
|I=Brown Glazed Terracotta-rot90
|j=Brown Glazed Terracotta-rot180
|J=Brown Glazed Terracotta-rot270
|k=Green Glazed Terracotta
|K=Green Glazed Terracotta-rot90
|l=Green Glazed Terracotta-rot180
|L=Green Glazed Terracotta-rot270
|m=Red Glazed Terracotta
|M=Red Glazed Terracotta-rot90
|n=Red Glazed Terracotta-rot180
|N=Red Glazed Terracotta-rot270
|o=Black Glazed Terracotta
|O=Black Glazed Terracotta-rot90
|p=Black Glazed Terracotta-rot180
|P=Black Glazed Terracotta-rot270
|----Light Gray|
aaaaaa aAaAaA aBaBaB ababab
aaaaaa aAaAaA aBaBaB ababab
aaaaaa aAaAaA aBaBaB ababab
aaaaaa aAaAaA aBaBaB ababab
aaaaaa aAaAaA aBaBaB ababab
aaaaaa aAaAaA aBaBaB ababab

aAaAaA ababab aaaAAA bbbBBB
AaAaAa bababa aaaAAA bbbBBB
aAaAaA ababab aaaAAA bbbBBB
AaAaAa bababa BBBbbb AAAaaa
aAaAaA ababab BBBbbb AAAaaa
AaAaAa bababa BBBbbb AAAaaa

bBbBbB aAaAaA bAbAbA ABABAB
AaAaAa bBbBbB BaBaBa ababab
bBbBbB aAaAaA bAbAbA ABABAB
AaAaAa bBbBbB BaBaBa ababab
bBbBbB aAaAaA bAbAbA ABABAB
AaAaAa bBbBbB BaBaBa ababab
|----Cyan|
cccccc cCcCcC cDcDcD cdcdcd
cccccc cCcCcC cDcDcD cdcdcd
cccccc cCcCcC cDcDcD cdcdcd
cccccc cCcCcC cDcDcD cdcdcd
cccccc cCcCcC cDcDcD cdcdcd
cccccc cCcCcC cDcDcD cdcdcd

cCcCcC cdcdcd cccCCC dddDDD
CcCcCc dcdcdc cccCCC dddDDD
cCcCcC cdcdcd cccCCC dddDDD
CcCcCc dcdcdc DDDddd CCCccc
cCcCcC cdcdcd DDDddd CCCccc
CcCcCc dcdcdc DDDddd CCCccc

dDdDdD cCcCcC dCdCdC CDCDCD
CcCcCc dDdDdD DcDcDc cdcdcd
dDdDdD cCcCcC dCdCdC CDCDCD
CcCcCc dDdDdD DcDcDc cdcdcd
dDdDdD cCcCcC dCdCdC CDCDCD
CcCcCc dDdDdD DcDcDc cdcdcd
|----Purple|
eeeeee eEeEeE eFeFeF efefef
eeeeee eEeEeE eFeFeF efefef
eeeeee eEeEeE eFeFeF efefef
eeeeee eEeEeE eFeFeF efefef
eeeeee eEeEeE eFeFeF efefef
eeeeee eEeEeE eFeFeF efefef

eEeEeE efefef eeeEEE fffFFF
EeEeEe fefefe eeeEEE fffFFF
eEeEeE efefef eeeEEE fffFFF
EeEeEe fefefe FFFfff EEEeee
eEeEeE efefef FFFfff EEEeee
EeEeEe fefefe FFFfff EEEeee

fFfFfF eEeEeE fEfEfE EFEFEF
EeEeEe fFfFfF FeFeFe efefef
fFfFfF eEeEeE fEfEfE EFEFEF
EeEeEe fFfFfF FeFeFe efefef
fFfFfF eEeEeE fEfEfE EFEFEF
EeEeEe fFfFfF FeFeFe efefef
|----Blue|
gggggg gGgGgG gHgHgH ghghgh
gggggg gGgGgG gHgHgH ghghgh
gggggg gGgGgG gHgHgH ghghgh
gggggg gGgGgG gHgHgH ghghgh
gggggg gGgGgG gHgHgH ghghgh
gggggg gGgGgG gHgHgH ghghgh

gGgGgG ghghgh gggGGG hhhHHH
GgGgGg hghghg gggGGG hhhHHH
gGgGgG ghghgh gggGGG hhhHHH
GgGgGg hghghg HHHhhh GGGggg
gGgGgG ghghgh HHHhhh GGGggg
GgGgGg hghghg HHHhhh GGGggg

hHhHhH gGgGgG hGhGhG GHGHGH
GgGgGg hHhHhH HgHgHg ghghgh
hHhHhH gGgGgG hGhGhG GHGHGH
GgGgGg hHhHhH HgHgHg ghghgh
hHhHhH gGgGgG hGhGhG GHGHGH
GgGgGg hHhHhH HgHgHg ghghgh
|----Brown|
iiiiii iIiIiI iJiJiJ ijijij
iiiiii iIiIiI iJiJiJ ijijij
iiiiii iIiIiI iJiJiJ ijijij
iiiiii iIiIiI iJiJiJ ijijij
iiiiii iIiIiI iJiJiJ ijijij
iiiiii iIiIiI iJiJiJ ijijij

iIiIiI ijijij iiiIII jjjJJJ
IiIiIi jijiji iiiIII jjjJJJ
iIiIiI ijijij iiiIII jjjJJJ
IiIiIi jijiji JJJjjj IIIiii
iIiIiI ijijij JJJjjj IIIiii
IiIiIi jijiji JJJjjj IIIiii

jJjJjJ iIiIiI jIjIjI IJIJIJ
IiIiIi jJjJjJ JiJiJi ijijij
jJjJjJ iIiIiI jIjIjI IJIJIJ
IiIiIi jJjJjJ JiJiJi ijijij
jJjJjJ iIiIiI jIjIjI IJIJIJ
IiIiIi jJjJjJ JiJiJi ijijij
|----Green|
kkkkkk kKkKkK kLkLkL klklkl
kkkkkk kKkKkK kLkLkL klklkl
kkkkkk kKkKkK kLkLkL klklkl
kkkkkk kKkKkK kLkLkL klklkl
kkkkkk kKkKkK kLkLkL klklkl
kkkkkk kKkKkK kLkLkL klklkl

kKkKkK klklkl kkkKKK lllLLL
KkKkKk lklklk kkkKKK lllLLL
kKkKkK klklkl kkkKKK lllLLL
KkKkKk lklklk LLLlll KKKkkk
kKkKkK klklkl LLLlll KKKkkk
KkKkKk lklklk LLLlll KKKkkk

lLlLlL kKkKkK lKlKlK KLKLKL
KkKkKk lLlLlL LkLkLk klklkl
lLlLlL kKkKkK lKlKlK KLKLKL
KkKkKk lLlLlL LkLkLk klklkl
lLlLlL kKkKkK lKlKlK KLKLKL
KkKkKk lLlLlL LkLkLk klklkl
|----Red|
mmmmmm mMmMmM mNmNmN mnmnmn
mmmmmm mMmMmM mNmNmN mnmnmn
mmmmmm mMmMmM mNmNmN mnmnmn
mmmmmm mMmMmM mNmNmN mnmnmn
mmmmmm mMmMmM mNmNmN mnmnmn
mmmmmm mMmMmM mNmNmN mnmnmn

mMmMmM mnmnmn mmmMMM nnnNNN
MmMmMm nmnmnm mmmMMM nnnNNN
mMmMmM mnmnmn mmmMMM nnnNNN
MmMmMm nmnmnm NNNnnn MMMmmm
mMmMmM mnmnmn NNNnnn MMMmmm
MmMmMm nmnmnm NNNnnn MMMmmm

nNnNnN mMmMmM nMnMnM MNMNMN
MmMmMm nNnNnN NmNmNm mnmnmn
nNnNnN mMmMmM nMnMnM MNMNMN
MmMmMm nNnNnN NmNmNm mnmnmn
nNnNnN mMmMmM nMnMnM MNMNMN
MmMmMm nNnNnN NmNmNm mnmnmn
|----Black|
oooooo oOoOoO oPoPoP opopop
oooooo oOoOoO oPoPoP opopop
oooooo oOoOoO oPoPoP opopop
oooooo oOoOoO oPoPoP opopop
oooooo oOoOoO oPoPoP opopop
oooooo oOoOoO oPoPoP opopop

oOoOoO opopop oooOOO pppPPP
OoOoOo popopo oooOOO pppPPP
oOoOoO opopop oooOOO pppPPP
OoOoOo popopo PPPppp OOOooo
oOoOoO opopop PPPppp OOOooo
OoOoOo popopo PPPppp OOOooo

pPpPpP oOoOoO pOpOpO OPOPOP
OoOoOo pPpPpP PoPoPo opopop
pPpPpP oOoOoO pOpOpO OPOPOP
OoOoOo pPpPpP PoPoPo opopop
pPpPpP oOoOoO pOpOpO OPOPOP
OoOoOo pPpPpP PoPoPo opopop
}}