Glass-room base.

{{layered blueprint|s=Stone|g=Glass|l=Ladder|t=Torch|default=Layer 3|name=Glass mining base|scale=2
|----Floor|
gggs
gggl
gggs
|----Layer 1|
   s
t  l s
   s
|----Layer 2|
   s
   l s
   s
|----Layer 3|
   s
t  l s
   s
|----Celing|
gggs
gggl
gggs
}}

[[Category:Ajax loaded pages]]