This is an example design of a double-story storage room, with a ladder to traverse between floors.

{{layered blueprint|name=Storage room|default=Layer 1
|P=Purpur Block
|E=End Stone Bricks
|+=Magenta Stained Glass
|L=Ladder
|e=Ender Chest
|S=Shulker Box
|p=Purpur Pillar-top
|s=Purpur Stairs
|R=End Rod

|----Layer 0|

 

   PPPPPPPPPPP
   PPPPPPPPPPP
   PPPPPPPPPPP
   PPPPPPPPPPP
   PPPPPPPPPPP
   PPPPPPPPPPP
   PPPPPPPPPPP
   PPPPPPPPPPP
   PPPPPPPPPPP
   PPPPPPPPPPP
   PPPPPPPPPPP



|----Layer 1|

 

   pEEEE EEEEp
   Ee S   S eE
   E         E
   ES       SE
   E    L    E
   E   LpL   E
   E    L    E
   ES       SE
   E         E
   Ee S   S eE
   pEEEEEEEEEp



|----Layer 2|

 

   pEEEE EEEEp
   E         E
   E         E
   E         E
   E    L    E
   +   LpL   +
   E    L    E
   E         E
   E         E
   E         E
   pEEEEEEEEEp



|----Layer 3|

 

   pEEEEEEEEEp
   E         E
   E         E
   E         E
   E    L    E
   E   LpL   E
   E    L    E
   E         E
   E         E
   E         E
   pEEEEEEEEEp



|----Layer 4|

 sssssssssssssss
 sPPPPPPPPPPPPPs
 sPPPPPPPPPPPPPs
 sPPPPPPPPPPPPPs
 sPPPPPPPPPPPPPs
 sPPPPPPPPPPPPPs
 sPPPPPPLPPPPPPs
 sPPPPPLpLPPPPPs
 sPPPPPPLPPPPPPs
 sPPPPPPPPPPPPPs
 sPPPPPPPPPPPPPs
 sPPPPPPPPPPPPPs
 sPPPPPPPPPPPPPs
 sPPPPPPPPPPPPPs
 sssssssssssssss

|----Layer 5|

 R             R
  pEEEEEEEEEEEp
  ES e  S  e SE
  E           E
  Ee S     S eE
  E           E
  E     L     E
  E    LpL    E
  E     L     E
  E           E
  Ee S     S eE
  E           E
  ES e  S  e SE
  pEEEEEEEEEEEp
 R             R

|----Layer 6|

 
  pEEEE+E+EEEEp
  E           E
  E           E
  E           E
  E           E
  +     L     +
  +    LpL    +
  +     L     +
  E           E
  E           E
  E           E
  E           E
  pEEEE+E+EEEEp


|----Layer 7|

 
  pEEEEEEEEEEEp
  E           E
  E           E
  E           E
  E           E
  E     L     E
  E    LpL    E
  E     L     E
  E           E
  E           E
  E           E
  E           E
  pEEEEEEEEEEEp

|----Layer 8|
sssssssssssssssss
sPPPPPPPPPPPPPPPs
sPPPPPPPPPPPPPPPs
sPPPPPPPPPPPPPPPs
sPPPPPPPPPPPPPPPs
sPPPPPPPPPPPPPPPs
sPPPPPPPPPPPPPPPs
sPPPPPPPPPPPPPPPs
sPPPPPPPPPPPPPPPs
sPPPPPPPPPPPPPPPs
sPPPPPPPPPPPPPPPs
sPPPPPPPPPPPPPPPs
sPPPPPPPPPPPPPPPs
sPPPPPPPPPPPPPPPs
sPPPPPPPPPPPPPPPs
sssssssssssssssss
|----Layer 9|
R               R














R               R
}}