<noinclude>{{structure info}}</noinclude>

[[File:Plains Temple 4.png|thumb|Temple 1 (Plains)]]



==== Blueprint ====

{{layered blueprint
|name=Temple 1
|default=Layer 1
|C=Cobblestone
|L=Ladder
|P=Glass Pane
|p=Glass Pane-rot90
|S=Cobblestone Stairs
|Y=Yellow Stained Glass Pane
|y=Yellow Stained Glass Pane-rot90
|W=White Stained Glass Pane
|w=White Stained Glass Pane-rot90
|T=Torch
|s=Cobblestone Slab
|D=Oak Door+top
|d=Oak Door+bottom
|B=Brewing Stand
|c=Cobblestone Wall
|x=Dirt
|----Layer 1|
         
   CCC   
  CCCCC  
  CCCCC  
  CCCCC  
  CCCCC  
 CCCCCCC 
 CCCSCCC 
 CCC CCC 
  CCdCC  
  C   C  
|----Layer 2|
         
   CCC   
  CCCCC  
  CCSCC  
  CS SC  
  C   C  
 CCB LCC 
 CS   SC 
 CC   CC 
  CCDCC  
  c   c  
|----Layer 3|
         
   CyC   
  CS SC  
  Y   Y  
  C   C  
  C   C  
 CC  LCC 
 Y     Y 
 CC T CC 
  CCCCC  
  T   T  
|----Layer 4|
         
   CwC   
  C   C  
  W   W  
  C   C  
  C   C  
 CC  LCC 
 W     W 
 CC   CC 
  CCyCC  
|----Layer 5|
         
   CCC   
  C T C  
  CT TC  
  C T C  
  CCCCC 
 SC  LCS 
 CC   CC 
 SC   CS 
  SCwCS  
|----Layer 6|
         
         
   CCC   
   CCC   
   CCC   
   CCC   
  CCCLC  
 sCCCCCs 
  CCCCC  
   CCC   
|----Layer 7|
         
         
         
    T    
         
   CCC   
  C  LC  
  C   C  
  C   C  
   CCC   
|----Layer 8|
         
         
         
         
         
   CyC   
  C  LC  
  Y   Y  
  CT TC  
   CyC   
|----Layer 9|
         
         
         
         
         
  SCwCS  
  C  LC  
  W   W  
  C   C  
  SCwCS  
|----Layer 10|
         
         
         
         
         
  CCCCC  
  CCCLC  
  CCCCC  
  CCCCC  
  CCCCC  
|----Layer 11|
         
         
         
         
         
   CCC   
  C  LC  
  C T C  
  C   C  
   CCC   
|----Layer 12|
         
         
         
         
         
    C    
         
  C   C  
         
    C    
}}

This structure resembles the [[Village/Structure (old)/Blueprints/Church|old Church]] seen in [[Village/Structure (old)/Blueprints |pre-1.14 villages]], with some minor changes.

==== Materials ====

{| class="wikitable sortable mw-collapsible"
|-
! Name !! Total !! Layer 1 !! Layer 2 !! Layer 3 !! Layer 4 !! Layer 5 !! Layer 6 !! Layer 7 !! Layer 8 !! Layer 9 !! Layer 10 !! Layer 11 !! Layer 12 
|-
| {{BlockSprite|brewing-stand|link=Brewing Stand|text=Brewing Stand}} || 1 || - || 1 || - || - || - || - || - || - || - || - || - || - 
|-
| {{BlockSprite|cobblestone|link=Cobblestone|text=Cobblestone}} || 237 || 48 || 30 || 21 || 20 || 21 || 29 || 12 || 8 || 8 || 24 || 12 || 4 
|-
| {{BlockSprite|cobblestone-slab|link=Slab|text=Cobblestone Slab}} || 2 || - || - || - || - || - || 2 || - || - || - || - || - || - 
|-
| {{BlockSprite|cobblestone-stairs|link=Stairs|text=Cobblestone Stairs}} || 18 || 1 || 5 || 2 || - || 6 || - || - || || 4 || - || - || - 
|-
| {{BlockSprite|cobblestone-wall|link=Wall|text=Cobblestone Wall}} || 2 || - || 2 || - || - || - || - || - || - || - || - || - || - 
|-
| {{BlockSprite|ladder|link=Ladder|text=Ladder}} || 10 || - || 1 || 1 || 1 || 1 || 1 || 1 || 1 || 1 || 1 || 1 || - 
|-
| {{ItemSprite|oak-door|link=Door|text=Oak Door}} || 1 || 1 || - || - || - || - || - || - || - || - || - || - || - 
|-
| {{BlockSprite|torch|link=Torch|text=Torch}} || 10 || - || - || 3 || - || 3 || - || 1 || 2 || - || - || 1 || - 
|-
| {{BlockSprite|white-stained-glass-pane|link=Glass Pane|text=White Stained Glass Pane}} || 10 || - || - || - || 5 || 1 || - || - || - || 4 || - || - || - 
|-
| {{BlockSprite|yellow-stained-glass-pane|link=Glass Pane|text=Yellow Stained Glass Pane}} || 10 || - || - || 5 || 1 || - || - || - || 4 || - || - || - || - 
|}





[[Category:Village blueprints]]