<noinclude>{{structure info}}</noinclude>

[[File:Desert Farm 2.png|thumb|Farm 2 (Desert)]]



==== Blueprint ====

{{layered blueprint|name=Village Desert Houses desert_farm_2
|default=Layer 2
|S=Smooth Sandstone Stairs
|R=Smooth Sandstone Stairs-rot90
|B=Smooth Sandstone Stairs-rot180
|r=Smooth Sandstone Stairs-rot270
|c=Composter
|s=Smooth Sandstone
|T=Jungle Trapdoor
|F=Farmland+moist
|W=Water+top
|w=Wheat Crops
|----Layer 0|
            
            
            
    s       
    s       
    s       
            
            
            
|----Layer 1|
            
 RBBBBBr    
 RFFFFFr    
 RFFFFFrBBB 
 RFFWFFsssr 
 RFFFFFrSSr 
 RFFFFFr    
 SSSSSSr    
            
|----Layer 2|
            
            
  wwwww     
  wwwww  T  
  ww ww TcT 
  wwwww  T  
  wwwww     
            
            
}}



==== Materials ====

{| class="wikitable sortable mw-collapsible"
|-
! Name !! Total !! Layer 0 !! Layer 1 !! Layer 2 
|-
| {{BlockSprite|composter|link=Composter|text=Composter}} || 1 || - || - || 1 
|-
| {{BlockSprite|farmland|link=Farmland|text=Farmland}} || 24 || - || 24 || - 
|-
| {{BlockSprite|jungle-trapdoor|link=Trapdoor|text=Jungle Trapdoor}} || 4 || - || - || 4 
|-
| {{BlockSprite|smooth-sandstone|link=Sandstone|text=Smooth Sandstone}} || 6 || 3 || 3 || - 
|-
| {{BlockSprite|smooth-sandstone-stairs|link=Stairs|text=Smooth Sandstone Stairs}} || 30 || - || 30 || - 
|-
| {{BlockSprite|water|link=Water|text=Water}} || 1 || - || 1 || - 
|-
| {{BlockSprite|wheat|link=Wheat Seeds|text=Wheat}} || 24 || - || - || 24 
|}





[[Category:Village blueprints]]