<noinclude>{{structure info}}</noinclude>

[[File:Snowy Tundra Cartographer House 1.png|thumb|Cartographer house 1 (Snowy tundra)]]



==== Blueprint ====

{{layered blueprint
|name=Snowy Cartographer House 1 snowy_cartographer_house_1
|default=Layer 2
|l=Stripped Spruce Log+top
|L=Stripped Spruce Log
|t=Stripped Spruce Log-rot90
|p=Spruce Planks
|S=Snow
|s=Spruce Slab
|c=Cartography Table-rot180
|C=Chest-rot180
|g=Glass Pane-rot90
|o=Spruce Door+bottom
|O=Spruce Door+top
|w=Spruce Stairs
|x=Spruce Stairs-rot90
|y=Spruce Stairs-rot180
|z=Spruce Stairs-rot270
|W=Torch
|X=Torch-rot90
|Y=Torch-rot180
|Z=Torch-rot270
             
|----Layer 1|
             
             
  lllllllll  
  tlllllllt  
  llpplppll  
  tlplllplt  
  lllppplll  
 S  xwwwz    
             
|----Layer 2|
             
             
  lLllLllLl  
  l       l  
  t       t  
  lcClolyyl  
  lLl   lLl  
             
             
|----Layer 3|
             
             
  lgllgllgl  
  t       t  
  l       l  
  t  lOl  t  
  lglY Ylgl  
             
             
|----Layer 4|
             
 p   s s   p 
 plLllLllLlp 
 pt   Y   tp 
 pt       tp 
 pt  lLl  tp 
 plLl   lLlp 
 p   s s   p 
             
|----Layer 5|
             
 ps spsps sp 
 plllptplllp 
 pl  p p  lp 
 ptX p p Ztp 
 pt  plp  tp 
 plllp plllp 
 ps spsps sp 
             
|----Layer 6|
             
  pspspspsp  
  plp p plp  
  p p p p p  
  p p p p p  
  p p p p p  
  plp p plp  
  pspspspsp  
             
|----Layer 7|
             
   p     p   
   p     p   
   p     p   
   p     p   
   p     p   
   p     p   
   p     p   
             
}}

4 middle spruce slabs in layer 6 are bottom slabs, while the rest are top slabs.



==== Materials ====

{| class="wikitable sortable mw-collapsible"
|-
! Name !! Total !! Layer 1 !! Layer 2 !! Layer 3 !! Layer 4 !! Layer 5 !! Layer 6 !! Layer 7 
|-
| {{BlockSprite|cartography-table|link=Cartography Table|text=Cartography Table}} || 1 || - || 1 || - || - || - || - || - 
|-
| {{BlockSprite|chest|link=Chest|text=Chest}} || 1 || - || 1 || - || - || - || - || - 
|-
| {{BlockSprite|glass-pane|link=Glass Pane|text=Glass Pane}} || 5 || - || - || 5 || - || - || - || - 
|-
| {{BlockSprite|snow|link=Snow|text=Snow}} || 1 || 1 || - || - || - || - || - || - 
|-
| {{ItemSprite|spruce-door|link=Door|text=Spruce Door}} || 1 || - || 1 || - || - || - || - || - 
|-
| {{BlockSprite|spruce-planks|link=Planks|text=Spruce Planks}} || 100 || 9 || - || - || 14 || 28 || 35 || 14 
|-
| {{BlockSprite|spruce-slab|link=Slab|text=Spruce Slab}} || 22 || - || - || - || 4 || 10 || 8 || - 
|-
| {{BlockSprite|spruce-stairs|link=Stairs|text=Spruce Stairs}} || 7 || 5 || 2 || - || - || - || - || - 
|-
| {{BlockSprite|stripped-spruce-log|link=Log|text=Stripped Spruce Log}} || 125 || 36 || 23 || 18 || 24 || 20 || 4 || - 
|-
| {{BlockSprite|torch|link=Torch|text=Torch}} || 5 || - || - || 2 || 1 || 2 || - || - 
|}





[[Category:Village blueprints]]