<noinclude>{{structure info}}</noinclude>

[[File:Savanna Meeting Point 2.png|thumb|Meeting Point 2 (Savanna)]]



==== Blueprint ====

{{layered blueprint|name=
Savanna Meeting Point 2|default=Layer 1
|D=Dirt
|G=Grass Block+top
|Y=Yellow Terracotta
|O=Orange Terracotta
|B=Bell
|R=Brown Wall Banner
|A=Dirt Path+top
|T=Torch
|W=Water+top
|S=Grass
             
|----Layer 1|
             
    GAAAG    
  DGGAAAGGD  
  GGAAAAAGG  
  GAADDDAAGG 
 AAADGGGDAAA 
 AAADGAGDAAA 
 AAADGGGDAAA 
   AADDDAAGG 
    AAAAAGG  
  D GAAAGGA  
     AAAG    
             
|----Layer 2|
             
             
  Y       Y  
             
     OYO     
    OWWWO    
    YWYWY    
    OWWWO    
     OYO   S 
         SS  
  Y     S Y  
        S    
             
|----Layer 3|
             
             
  T       B  
             
             
             
      Y      
             
             
             
  B       T  
             
             
|----Layer 4|
             
             
             
             
             
             
      Y      
             
             
             
             
             
             
|----Layer 5|
             
             
             
             
             
      R      
     ROR     
      R      
             
             
             
             
             
|----Layer 6|
             
             
             
             
             
             
      Y      
             
             
             
             
             
             
}}



==== Materials ====

{| class="wikitable sortable mw-collapsible"
|-
! Name !! Total !! Layer 1 !! Layer 2 !! Layer 3 !! Layer 4 !! Layer 5 !! Layer 6 
|-
| {{BlockSprite|bell|link=Bell|text=Bell}} || 2 || - || - || 2 || - || - || - 
|-
| {{BlockSprite|brown-wall-banner|link=Brown Wall Banner|text=Brown Wall Banner}} || 4 || - || - || - || - || 4 || - 
|-
| {{BlockSprite|dirt|link=Dirt|text=Dirt}} || 15 || 15 || - || - || - || - || - 
|-
| {{BlockSprite|grass|link=Grass|text=Grass}} || 5 || - || 5 || - || - || - || - 
|-
| {{BlockSprite|grass-block|link=Grass Block|text=Grass Block}} || 29 || 29 || - || - || - || - || - 
|-
| {{BlockSprite|dirt-path|link=Dirt Path|text=Dirt Path}} || 50 || 50 || - || - || - || - || - 
|-
| {{BlockSprite|orange-terracotta|link=Orange Terracotta|text=Orange Terracotta}} || 9 || - || 8 || - || - || 1 || - 
|-
| {{BlockSprite|torch|link=Torch|text=Torch}} || 2 || - || - || 2 || - || - || - 
|-
| {{BlockSprite|water|link=Water|text=Water}} || 8 || - || 8 || - || - || - || - 
|-
| {{BlockSprite|yellow-terracotta|link=Yellow Terracotta|text=Yellow Terracotta}} || 12 || - || 9 || 1 || 1 || - || 1 
|}





[[Category:Village blueprints]]