<noinclude>{{structure info}}</noinclude>

[[File:Snowy Tundra Medium House 2.png|thumb|Medium house 2 (Snowy tundra)]]



==== Blueprint ====

{{layered blueprint
|name=Snowy Medium House 2 snowy_medium_house_2
|default=Layer 2
|s=Snow Block
|S=Snow
|w=Stripped Spruce Wood
|p=Spruce Planks
|L=Spruce Slab
|l=Spruce Slab+top
|x=Spruce Stairs
|y=Spruce Stairs-rot90
|z=Spruce Stairs-rot270
|t=Torch-rot180
|X=Torch-rot90
|Y=Torch-rot270
|f=Furnace-rot90
|b=Blue Bed+top-head-rot270
|B=Blue Bed+top-foot-rot270
|r=Red Bed+top-head-rot270
|R=Red Bed+top-foot-rot270
|g=Glass Pane-rot90
|d=Spruce Door+bottom
|D=Spruce Door+top
                
|----Layer 1|
                
 SSSSSSSSSSSSSS 
 sSSSSSssSSSSSS 
 SswwwwwwwwwsSS 
 sswpppppppwssS 
 sswpppppppwsSS 
 sswwwwwwwwwssS 
 SsSSxSsSxSSSSS 
                
|----Layer 2|
                
                
 S    Ss        
  SwwwwwwwwwS   
 Sswb     rwsS  
 SSwB pz  RwS   
  SwwdwwwdwwS   
  S             
                
|----Layer 3|
                
                
                
   wgwgwgwgw    
   w   t t w    
   w  z    w    
   wwDwwwDww    
                
|----Layer 4|
                
                
  lplplplplpl   
   wwwwwwwww    
   wlllllllw    
   wlz   llw    
   wwwwwwwww    
  lplplplplpl   
                
|----Layer 5|
                
                
  ppppppppppp   
  lwwwwwwwww    
   w      fw    
   w      yw    
  lwwwwwwwww    
  ppppppppppp   
                
|----Layer 6|
                
                
  SL LLSLL LS   
  ppgppgppgpp   
   wX     Yw    
   wX     Yw    
  ppgppgppgpp   
  SLSLLSLL LS   
                
|----Layer 7|
                
                
  ppppppppppp   
  lw       w    
  lw       w    
  ppppppppppp   
                
|----Layer 8|
                
                
  SSLSSLSSLSS   
  ppppppppppp   
  ppppppppppp   
  SSLSSLSSLSS   
                
|----Layer 9|
                
                
  SSSSSSSSSSS   
  SSSSSSSSSSS   
                
}}

The spruce slabs in layer 6 and layer 8 are bottom slabs, while the rest in the blueprint are top slabs.



==== Materials ====

{| class="wikitable sortable mw-collapsible"
|-
! Name !! Total !! Layer 1 !! Layer 2 !! Layer 3 !! Layer 4 !! Layer 5 !! Layer 6 !! Layer 7!! Layer 8!! Layer 9 
|-
| {{BlockSprite|blue bed|link=Bed|text=Blue Bed}} || 1 || - || 1 || - || - || - || - || - || - || - 
|-
| {{BlockSprite|furnace|link=Furnace|text=Furnace}} || 1 || - || - || - || - || 1 || - || - || - || - 
|-
| {{BlockSprite|glass pane|link=Glass Pane|text=Glass Pane}} || 10 || - || - || 4 || - || - || 6 || - || - || - 
|-
| {{BlockSprite|red bed|link=Bed|text=Red Bed}} || 1 || - || 1 || - || - || - || - || - || - || - 
|-
| {{BlockSprite|snow|link=Snow|text=Snow}} || 180 || 104 || 28 || - || - || - || 7 || - || 19 || 22 
|-
| {{BlockSprite|snow block|link=Snow Block|text=Snow Block}} || 22 || 19 || 3 || - || - || - || - || - || - || - 
|-
| {{ItemSprite|spruce door|link=Door|text=Spruce Door}} || 2 || - || 2 || - || - || - || - || - || - || - 
|-
| {{BlockSprite|spruce planks|link=Planks|text=Spruce Planks}} || 103 || 14 || 1 || - || 10 || 22 || 12 || 22 || 22 || - 
|-
| {{BlockSprite|spruce slab|link=Slab|text=Spruce Slab}} || 44 || - || - || - || 22 || 2 || 12 || 2 || 6 || - 
|-
| {{BlockSprite|spruce stairs|link=Stairs|text=Spruce Stairs}} || 6 || 2 || 1 || 1 || 1 || 1 || - || - || - || - 
|-
| {{BlockSprite|stripped spruce wood|link=Wood|text=Stripped Spruce Wood}} || 110 || 22 || 20 || 16 || 22 || 22 || 4 || 4 || - || - 
|-
| {{BlockSprite|torch|link=Torch|text=Torch}} || 5 || - || - || 1 || - || - || 4 || - || - || - 
|}





[[Category:Village blueprints]]