<noinclude>{{structure info}}</noinclude>

[[File:Savanna Temple 2.png|thumb|Temple 2 (Savanna)]]



==== Blueprint ====

{{layered blueprint|name=
Savanna Temple 2|default=Layer 1
|D=Dirt
|A=Acacia Wood
|C=Acacia Planks
|R=Red Terracotta
|Y=Yellow Terracotta
|B=Brewing Stand
|I=Acacia Stairs
|G=Glass Pane
|W=Wall Torch
|L=Glass Pane-rot-90
|S=Dirt Path+top
|O=Acacia Door+bottom
|c=Acacia Door+top
|T=Wall Torch-rot-180
           
|----Layer 1|
           
           
   DDDDD   
  DAARAAD  
  DAARAAD  
  DAARAAD  
   DDADD   
     S     
           
|----Layer 2|
           
           
   AAAAA   
  A    IA  
  AB   IA  
  A    IA  
   AAOAA   
           
           
|----Layer 3|
           
           
   ALALA   
  A  T  A  
  G     G  
  A W W A  
   AAcAA   
           
           
|----Layer 4|
           
           
   AAAAA   
  A     A  
  A     A  
  A     A  
   AAAAA   
           
           
|----Layer 5|
           
  II W II  
 ICCRYRCCI 
 ICCY YCCI 
 ICCR RCCI 
 ICCY YCCI 
 ICCRYRCCI 
  II T II  
           
|----Layer 6|
           
           
    AAA    
    A A    
    A A    
    A A    
    AAA    
           
           
|----Layer 7|
           
    III    
   ICCCI   
   ICCCI   
   ICCCI   
   ICCCI   
   ICCCI   
    III    
           
}}



==== Materials ====

{| class="wikitable sortable mw-collapsible"
|-
! Name !! Total !! Layer 1 !! Layer 2 !! Layer 3 !! Layer 4 !! Layer 5 !! Layer 6 !! Layer 7 
|-
| {{BlockSprite|acacia-door|link=Acacia Door|text=Acacia Door}} || 1 || - || 1 || - || - || - || - || - 
|-
| {{BlockSprite|acacia-planks|link=Acacia Planks|text=Acacia Planks}} || 35 || - || - || - || - || 20 || - || 15 
|-
| {{BlockSprite|acacia-stairs|link=Acacia Stairs|text=Acacia Stairs}} || 37 || - || 3 || - || - || 18 || - || 16 
|-
| {{BlockSprite|acacia-wood|link=Acacia Wood|text=Acacia Wood}} || 67 || 13 || 15 || 11 || 16 || - || 12 || - 
|-
| {{BlockSprite|brewing-stand|link=Brewing Stand|text=Brewing Stand}} || 1 || - || 1 || - || - || - || - || - 
|-
| {{BlockSprite|dirt|link=Dirt|text=Dirt}} || 15 || 15 || - || - || - || - || - || - 
|-
| {{BlockSprite|glass-pane|link=Glass Pane|text=Glass Pane}} || 4 || - || - || 4 || - || - || - || - 
|-
| {{BlockSprite|dirt-path|link=Dirt Path|text=Dirt Path}} || 1 || 1 || - || - || - || - || - || - 
|-
| {{BlockSprite|red-terracotta|link=Red Terracotta|text=Red Terracotta}} || 9 || 3 || - || - || - || 6 || - || - 
|-
| {{BlockSprite|torch|link=Torch|text=Torch}} || 5 || - || - || 3 || - || 2 || - || - 
|-
| {{BlockSprite|yellow-terracotta|link=Yellow Terracotta|text=Yellow Terracotta}} || 6 || - || - || - || - || 6 || - || - 
|}





[[Category:Village blueprints]]