<noinclude>{{structure info}}</noinclude>

[[File:Plains Stable 2.png|thumb|Stable 2 (Plains)]]



==== Blueprint ====

{{layered blueprint
|name=Stable 2 stable-2
|default=Layer 1
|w=White Terracotta
|o=Oak Log+top
|d=Dirt
|g=Grass Block+top
|p=Dirt Path+top
|P=Oak Planks
|s=Oak Slab
|h=Hay Bale+top
|H=Hay Bale-rot90
|W=Water+top
|O=Oak Log
|f=Oak Fence
|i=Oak Door+bottom
|I=Oak Door+top
|a=Glass Pane
|A=Glass Pane-rot90
|t=Torch
|r=Torch-rot90
|R=Torch-rot270
|v=Oak Stairs
|x=Oak Stairs-rot90
|y=Oak Stairs-rot180
|z=Oak Stairs-rot270
                  
|----Layer 0|
                   
                   
 gggggddddddddddd  
 gggggggdddgggdgd  
 gggggggggggggdgd  
 ggggggdggggggdgd  
 gggggdddddgddddd  
 ggggggggggpggggg  
                   
|----Layer 1|
                   
                   
 fffffowwowwwowwo  
 f      hhH   OWw  
 f            OWw  
 f     h      OWw  
 fffffowwowiwowwo  
                   
                   
|----Layer 2|
                   
                   
   f  owwowAwowwo  
         h      w  
                a  
                w  
   f  owwowIwowwo  
                   
                   
|----Layer 3|
                   
     yyyyyz xyyyyy 
   f vowwowwwowwov 
      O         w  
     ROr        w  
      O    t    w  
   f yowwowwwowwoy 
     vvvvvz xvvvvv 
                   
|----Layer 4|
                   
          yyy      
   yyyyyyyPPPyyyyy 
   PPPw         wv 
   sssw         w  
   PPPw         wy 
   vvvvvvvPPPvvvvv 
          vvv      
                   
|----Layer 5|
                   
                   
                   
     yyyyyyyyyyyyy 
   ssPPPPPPPPPPPPP 
     vvvvvvvvvvvvv 
                   
                   
                   
}}

The oak slabs in layer 4 are all top slabs, while the ones in layer 5 are bottom slabs.



==== Materials ====

{| class="wikitable sortable mw-collapsible"
|-
! Name !! Total !! Layer 0 !! Layer 1 !! Layer 2 !! Layer 3 !! Layer 4 !! Layer 5 
|-
| {{BlockSprite|dirt|link=Dirt|text=Dirt}} || 31 || 31 || - || - || - || - || - 
|-
| {{BlockSprite|dirt-path|link=Dirt Path|text=Dirt Path}} || 1 || 1 || - || - || - || - || - 
|-
| {{BlockSprite|glass-pane|link=Glass Pane|text=Glass Pane}} || 2 || - || - || 2 || - || - || - 
|-
| {{BlockSprite|grass-block|link=Grass Block|text=Grass Block}} || 64 || 64 || - || - || - || - || - 
|-  
| {{BlockSprite|hay-bale|link=Hay Bale|text=Hay Bale}} || 5 || - || 4 || 1 || - || - || - 
|-
| {{ItemSprite|oak-door|link=Door|text=Oak Door}} || 1 || - || 1 || - || - || - || - 
|-
| {{BlockSprite|oak-fence|link=Fence|text=Oak Fence}} || 17 || - || 13 || 2 || 2 || - || - 
|-
| {{BlockSprite|oak-log|link=Log|text=Oak Log}} || 30 || - || 11 || 8 || 11 || - || - 
|-
| {{BlockSprite|oak-planks|link=Planks|text=Oak Planks}} || 25 || - || - || - || - || 12 || 13 
|-
| {{BlockSprite|oak-slab|link=Slab|text=Oak Slab}} || 5 || - || - || - || - || 3 || 2 
|-
| {{BlockSprite|oak-stairs|link=Stairs|text=Oak Stairs}} || 87 || - || - || - || 28 || 32 || 26 
|-
| {{BlockSprite|torch|link=Torch|text=Torch}} || 3 || - || - || - || 3 || - || - 
|-
| {{BlockSprite|water|link=Water|text=Water}} || 3 || - || 3 || - || - || - || - 
|-
| {{BlockSprite|white-terracotta|link=Terracotta|text=White Terracotta}} || 53 || - || 16 || 14 || 17 || 6 || - 
|}





[[Category:Village blueprints]]