<noinclude>{{structure info}}</noinclude>

[[File:Taiga Fletcher House 1.png|thumb|Fletcher House 1 (Taiga)]]



==== Blueprint ====

{{layered blueprint|name=
Taiga Fletcher House 1|default=Layer 1
|S=Spruce Log-rot-90
|C=Cobblestone
|P=Spruce Log+top
|G=Grass Block+top
|R=Spruce Log
|U=Spruce Planks
|F=Fletching Table
|H=Chest-rot-180
|E=Spruce Trapdoor
|T=Spruce Stairs
|L=Glass Pane-rot-90
|O=Poppy
|W=Wall Torch-rot-180
|N=Spruce Fence
|A=Purple Carpet
|B=Cobblestone Stairs
|D=Spruce Door+bottom
|p=Spruce Door+top
|a=Wall Torch
             
|----Layer 1|
             
             
  CCCCCCCCC  
  CPPUUUPPC  
  CPPUUUPPC  
  CCCPUPCCC  
     CUC     
     CCC     
    E B E    
   EGE EGE   
    E   E    
             
|----Layer 2|
             
             
  CCCCCCCCC  
  CT NFN TC  
  CT     TC  
  CCCH  CCC  
     C C     
     CDC     
             
    O   O    
             
             
|----Layer 3|
             
   E E E E   
  CCLCLCLCC  
  C  A A  C  
  C       C  
  CLC   CLC  
  E EC CE E  
     CpC     
     W W     
             
             
             
|----Layer 4|
             
 SSSSSSSSSSS 
  CCCCCCCCC  
  C W   W C  
  C       C  
  CCC   CCC  
 SSSRCaCRSSS 
    RCCCR    
    R   R    
             
             
             
|----Layer 5|
             
             
 SSSSSSSSSSS 
  C       C  
  C       C  
 SSSSSSSSSSS 
     RCR     
     RCR     
     R R     
             
             
             
|----Layer 6|
             
             
             
 SSSSSSSSSSS 
 SSSSSSSSSSS 
      R      
      R      
      R      
      R      
             
             
             
}}



==== Materials ====

{| class="wikitable sortable mw-collapsible"
|-
! Name !! Total !! Layer 1 !! Layer 2 !! Layer 3 !! Layer 4 !! Layer 5 !! Layer 6 
|-
| {{BlockSprite|Chest|link=Chest|text=Chest}} || 1 || - || 1 || - || - || - || - 
|-
| {{BlockSprite|Cobblestone|link=Cobblestone|text=Cobblestone}} || 95 || 24 || 23 || 18 || 24 || 6 || - 
|-
| {{BlockSprite|Cobblestone Stairs|link=Cobblestone Stairs|text=Cobblestone Stairs}} || 1 || 1 || - || - || - || - || - 
|-
| {{BlockSprite|Fletching Table|link=Fletching Table|text=Fletching Table}} || 1 || - || 1 || - || - || - || - 
|-
| {{BlockSprite|Glass Pane|link=Glass Pane|text=Glass Pane}} || 5 || - || - || 5 || - || - || - 
|-
| {{BlockSprite|Grass Block|link=Grass Block|text=Grass Block}} || 2 || 2 || - || - || - || - || - 
|-
| {{BlockSprite|Poppy|link=Poppy|text=Poppy}} || 2 || - || 2 || - || - || - || - 
|-
| {{BlockSprite|Purple Carpet|link=Purple Carpet|text=Purple Carpet}} || 2 || - || - || 2 || - || - || - 
|-
| {{BlockSprite|Spruce Door|link=Spruce Door|text=Spruce Door}} || 1 || - || 1 || - || - || - || - 
|-
| {{BlockSprite|Spruce Fence|link=Spruce Fence|text=Spruce Fence}} || 2 || - || 2 || - || - || - || - 
|-
| {{BlockSprite|Spruce Log|link=Spruce Log|text=Spruce Log}} || 87 || 10 || - || - || 23 || 28 || 26 
|-
| {{BlockSprite|Spruce Planks|link=Spruce Planks|text=Spruce Planks}} || 8 || 8 || - || - || - || - || - 
|-
| {{BlockSprite|Spruce Stairs|link=Spruce Stairs|text=Spruce Stairs}} || 4 || - || 4 || - || - || - || - 
|-
| {{BlockSprite|Spruce Trapdoor|link=Spruce Trapdoor|text=Spruce Trapdoor}} || 16 || 8 || - || 8 || - || - || - 
|-
| {{BlockSprite|Torch|link=Torch|text=Torch}} || 5 || - || - || 2 || 3 || - || - 
|}





[[Category:Village blueprints]]