<noinclude>{{structure info}}</noinclude>

[[File:Plains weaponsmith 1.png|thumb|Weaponsmith 1 (Plains)]]



==== Blueprints ====
{{layered blueprint
|name=Village Plains Houses plains_weaponsmith_1
|default=Layer 2
|C=Cobblestone
|c=Cobblestone Stairs
|O=Oak Log+top
|L=Oak Log-rot90
|l=Oak Log
|P=Oak Planks
|g=glass Pane
|G=glass Pane-rot90
|d=Oak Door+bottom
|D=Oak Door+top
|s=Oak Stairs
|>=Oak Stairs-rot270
|<=Oak Stairs-rot90
|o=Cobblestone Wall
|$=Smooth Stone Slab
|T=torch
|t=Torch-rot180
|[=Torch-rot90
|]=Torch-rot270
|I=Iron Bars
|f=Oak Fence
|R=Oak Pressure Plate
|B=Furnace
|n=Grindstone
|V=Lava+top
|U=Chest
            
|----Layer 1|
             
             
 CCCCCCOCCO  
 CCCCCCCCCC  
 CCCCCCCCCC  
 CCCCCCCCCC  
 CCCCCCCCCC  
 CCCCCCCCCC  
 CCCCCCOCCO  
  ccc        
            
|----Layer 2|
            
             
 CCCCCCOPPO  
 CVVCU  sPP  
 CCCC   f<P  
    CCO   P  
       P  P  
  n    d  P  
 f   f OPPO  
             
            
|----Layer 3|
            
  T         
 CCCLGLOPPO  
 I  C    tP  
 I  C   R g  
    BCO   P[ 
      ]P  g  
       D  P  
 f   f OPPO  
             
            
|----Layer 4|
            
            
 CCCCCCOPPO  
 CCCC     P  
 CCCC     P  
    BCO   P  
       P  P  
       P  P  
 f   f OPPO  
             
|----Layer 5|
            
            
 CCCCCCOLLO  
 CCCCCCCCCl  
 CCCCCCCCCl  
 CCCCCCCCCl  
 CCCCCCCCCl  
 CCCCCCCCCl  
 CCCCCCOLLO  
             
|----Layer 6|
            
      <>  <> 
 $$$$$<OPPO> 
 $CC  <   P> 
 $    <   P> 
 $  T <   P> 
 $    <   P> 
 $    <   P> 
 $$$$$<OPPO> 
      <>  <> 
            
|----Layer 7|
            
       <><>  
       <PP>  
  o    <  >  
       <  >  
       <  >  
       <  >  
       <  >  
       <PP>  
       <><>  
            
|----Layer 8|
            
        <>   
        <>   
        <>   
        <>   
        <>   
        <>   
        <>   
        <>   
        <>   
            
}}

This structure resembles the [[Village/Structure (old)/Blueprints/Blacksmith|old Blacksmith]] seen in [[Village/Structure (old)/Blueprints |pre-1.14 villages]], with some changes like the addition of a roof. All of the slabs on layer 6 are bottom slabs.



==== Materials ====

{| class="wikitable sortable mw-collapsible"
|-
! Name !! Total !! Layer 1 !! Layer 2 !! Layer 3 !! Layer 4 !! Layer 5 !! Layer 6 !! Layer 7 !! Layer 8 
|-
|Wooden Chest
| 1 || - || 1 || - || - || - || - || - || - 
|-
| {{BlockSprite|cobblestone|link=Cobblestone|text=Cobblestone}} || 160 || 66 || 14 || 6 || 15 || 57 || 2 || - || - 
|-
| {{BlockSprite|cobblestone-stairs|link=Stairs|text=Cobblestone Stairs}} || 3 || 3 || - || - || - || - || - || - || - 
|-
| {{BlockSprite|cobblestone-wall|link=Wall|text=Cobblestone Wall}} || 1 || - || - || - || - || - || - || 1 || - 
|-
| {{BlockSprite|furnace|link=Furnace|text=Furnace}} || 2 || - || - || 1 || 1 || - || - || - || - 
|-
| {{BlockSprite|glass-pane|link=Glass Pane|text=Glass Pane}} || 3 || - || - || 3 || - || - || - || - || - 
|-
| {{BlockSprite|grindstone|link=Grindstone|text=Grindstone}} || 1 || - || 1 || - || - || - || - || - || - 
|-
| {{BlockSprite|iron-bars|link=Iron Bars|text=Iron Bars}} || 2 || - || - || 2 || - || - || - || - || - 
|-
| {{BlockSprite|lava|link=Lava|text=Lava}} || 2 || - || 2 || - || - || - || - || - || - 
|-
| {{ItemSprite|oak-door|link=Door|text=Oak Door}} || 1 || - || 1 || - || - || - || - || - || - 
|-
| {{BlockSprite|oak-log|link=Log|text=Oak Log}} || 38 || 4 || 5 || 7 || 5 || 13 || 4 || - || - 
|-
| {{BlockSprite|oak-fence|link=Fence|text=Oak Fence}} || 7 || - || 3 || 2 || 2 || - || - || - || - 
|-
| {{BlockSprite|oak-planks|link=Planks|text=Oak Planks}} || 43 || - || 11 || 8 || 11 || - || 9 || 4 || - 
|-
| {{BlockSprite|oak-pressure-plate|link=Pressure Plate|text=Oak Pressure Plate}} || 1 || - || - || 1 || - || - || - || - || - 
|-
| {{BlockSprite|oak-stairs|link=Stairs|text=Oak Stairs}} || 64 || - || 2 || - || - || - || 22 || 22 || 18 
|-
| {{BlockSprite|smooth-stone-slab|link=Slab|text=Smooth Stone Slab}} || 15 || - || - || - || - || - || 15 || - || - 
|-
| {{BlockSprite|torch|link=Torch|text=Torch}} || 5 || - || - || 4 || - || - || 1 || - || - 
|}





[[Category:Village blueprints]]