<noinclude>{{structure info}}</noinclude>

[[File:Savanna Small House 5.png|thumb|Small House 5 (Savanna)]]



==== Blueprint ====

{{layered blueprint|name=Savanna Small House 5|default=Layer 1
|G=Grass Block+top
|D=Dirt
|A=Acacia Log+top
|C=Acacia Log
|c=Acacia Log-rot-90
|Y=Yellow Terracotta
|I=Acacia Planks
|O=Orange Bed+side+foot
|R=Orange Bed+side+head
|F=Acacia Fence
|S=Grass
|L=Acacia Slab
|P=Glass Pane
|s=Acacia Stairs
|>=Acacia Stairs-rot-90
|^=Acacia Stairs-rot-180
|<=Acacia Stairs-rot-270
|E=Acacia Pressure Plate
|H=Dirt Path+top
|d=Acacia Door+bottom
|N=Glass Pane-rot-90
|a=Acacia Door+top
|W=Wall Torch
|l=Wall Torch-rot-180
         
|----Layer 1|
         
 GGGHGGG 
 GGDIDGG 
 GDIIIDG 
 GDIIIDG 
 GDIIIDG 
 GGDDDGG 
 GGGGGGG 
         
|----Layer 2|
         
 SFS SFS 
 F AdASF 
  A   AS 
 SC   A  
  AFORAS 
 F AAA F 
  F   FS 
         
|----Layer 3|
         
  F   F  
 F AaA F 
  A   A  
  P   P  
  AE  A  
 F ANA F 
  F   F  
         
|----Layer 4|
         
  F W F  
 F AcA F 
  A l A  
  C   C  
  A W A  
 F AcA F 
  F   F  
         
|----Layer 5|
         
  F   F  
 F YYY F 
  Y   Y  
  Y   Y  
  Y   Y  
 F YYY F 
  F   F  
         
|----Layer 6|
         
  LLLLL  
 LLLLLLL 
 LLYYYLL 
 LLY YLL 
 LLYYYLL 
 LLLLLLL 
  LLLLL  
         
|----Layer 7|
         
         
         
   YFY   
   F F   
   YFY   
         
         
         
|----Layer 8|
         
         
         
   YYY   
   Y Y   
   YYY   
         
         
         
|----Layer 9|
         
         
  ^^^^>  
  <III>  
  <III>  
  <III>  
  <ssss  
         
         
|----Layer 10|
         
         
         
   <^^   
   <I>   
   ss>   
         
         
         
}}



==== Materials ====

{| class="wikitable sortable mw-collapsible"
|-
! Name !! Total !! Layer 1 !! Layer 2 !! Layer 3 !! Layer 4 !! Layer 5 !! Layer 6 !! Layer 7 !! Layer 8 !! Layer 9 !! Layer 10 
|-
| {{BlockSprite|acacia-door|link=Acacia Door|text=Acacia Door}} || 1 || - || 1 || - || - || - || - || - || - || - || - 
|-
| {{BlockSprite|acacia-fence|link=Acacia Fence|text=Acacia Fence}} || 37 || - || 9 || 8 || 8 || 8 || - || 4 || - || - || - 
|-
| {{BlockSprite|acacia-log|link=Acacia Log|text=Acacia Log}} || 31 || - || 11 || 8 || 12 || - || - || - || - || - || - 
|-
| {{BlockSprite|acacia-planks|link=Acacia Planks|text=Acacia Planks}} || 20 || 10 || - || - || - || - || - || - || - || 9 || 1 
|-
| {{BlockSprite|acacia-pressure-plate|link=Acacia Pressure Plate|text=Acacia Pressure Plate}} || 1 || - || - || 1 || - || - || - || - || - || - || - 
|-
| {{BlockSprite|acacia-slab|link=Acacia Slab|text=Acacia Slab}} || 36 || - || - || - || - || - || 36 || - || - || - || - 
|-
| {{BlockSprite|acacia-stairs|link=Acacia Stairs|text=Acacia Stairs}} || 24 || - || - || - || - || - || - || - || - || 16 || 8 
|-
| {{BlockSprite|dirt|link=Dirt|text=Dirt}} || 11 || 11 || - || - || - || - || - || - || - || - || - 
|-
| {{BlockSprite|glass-pane|link=Glass Pane|text=Glass Pane}} || 3 || - || - || 3 || - || - || - || - || - || - || - 
|-
| {{BlockSprite|grass|link=Grass|text=Grass}} || 9 || - || 9 || - || - || - || - || - || - || - || - 
|-
| {{BlockSprite|grass-block|link=Grass Block|text=Grass Block}} || 27 || 27 || - || - || - || - || - || - || - || - || - 
|-
| {{BlockSprite|dirt-path|link=Dirt Path|text=Dirt Path}} || 1 || 1 || - || - || - || - || - || - || - || - || - 
|-
| {{BlockSprite|orange-bed|link=Orange Bed|text=Orange Bed}} || 1 || - || 1 || - || - || - || - || - || - || - || - 
|-
| {{BlockSprite|torch|link=Torch|text=Torch}} || 3 || - || - || - || 3 || - || - || - || - || - || - 
|-
| {{BlockSprite|yellow-terracotta|link=Yellow Terracotta|text=Yellow Terracotta}} || 32 || - || - || - || - || 12 || 8 || 4 || 8 || - || - 
|}





[[Category:Village blueprints]]