<noinclude>{{structure info}}</noinclude>

[[File:Plains Small House 4.png|thumb|Small house 4 (Plains)]]



==== Blueprint ====

{{layered blueprint
|name=Village Plains Houses plains_small_house_4
|default=Layer 2
|P=Oak Planks
|O=Oak Log+top
|L=Oak Log-rot90
|l=Oak Log
|B=White Bed+top foot-rot270
|b=White Bed+top head-rot270
|C=Cobblestone
|c=Cobblestone Stairs-rot90
|s=Oak Stairs
|<=Oak Stairs-rot90
|>=Oak Stairs-rot270
|d=Oak Door+bottom
|D=Oak Door+top
|g=glass Pane
|G=glass Pane-rot90
|T=torch-rot180
|----Layer 1|
         
         
  OCCCO  
  CPPPC  
  CPPPC  
  CPPPC  
  OCCCO  
    s    
|----Layer 2|
         
         
  OCCCO  
  Cb cC  
  CB cC  
  C  cC  
  OCdCO  
         
|----Layer 3|
         
         
  OCGCO  
  l   l  
  g   g  
  l   l  
  OCDCO  
         
|----Layer 4|
         
         
  OCCCO  
  C T C  
  C   C  
  C   C  
  OCCCO  
    T    
|----Layer 5|
         
 <>   <> 
 <OLLLO> 
 <P   P> 
 <P   P> 
 <P   P> 
 <OLLLO> 
 <>   <> 
|----Layer 6|
         
  <> <>  
  <CCC>  
  <PPP>  
  <P P>  
  <PPP>  
  <CCC>  
  <> <>  
|----Layer 7|
         
   <P>   
   <P>   
   <P>   
   <P>   
   <P>   
   <P>   
   <P>   
}}


This structure resembles the [[Village/Structure (old)/Blueprints/Small house|old Small House]] seen in [[Village/Structure (old)/Blueprints |pre-1.14 villages]], with multiple changes, such as the gable roof, furniture and a bed.



==== Materials ====

{| class="wikitable sortable mw-collapsible"
|-
! Name !! Total !! Layer 1 !! Layer 2 !! Layer 3 !! Layer 4 !! Layer 5 !! Layer 6 !! Layer 7 
|-
| {{BlockSprite|cobblestone|link=Cobblestone|text=Cobblestone}} || 45 || 12 || 11 || 4 || 12 || - || 6 || - 
|-
| {{BlockSprite|cobblestone-stairs|link=Stairs|text=Cobblestone Stairs}} || 3 || - || 3 || - || - || - || - || - 
|-
| {{BlockSprite|glass-pane|link=Glass Pane|text=Glass Pane}} || 3 || - || - || 3 || - || - || - || - 
|-
| {{ItemSprite|oak-door|link=Door|text=Oak Door}} || 1 || - || 1 || - || - || - || - || - 
|-
| {{BlockSprite|oak-log|link=Log|text=Oak Log}} || 30 || 4 || 4 || 8 || 4 || 10 || - || - 
|-
| {{BlockSprite|oak-planks|link=Planks|text=Oak Planks}} || 30 || 9 || - || - || - || 6 || 8 || 7 
|-
| {{BlockSprite|oak-stairs|link=Stairs|text=Oak Stairs}} || 51 || 1 || - || - || - || 18 || 18 || 14 
|-
| {{BlockSprite|torch|link=Torch|text=Torch}} || 2 || - || - || - || 2 || - || - || - 
|-
| {{BlockSprite|white-bed|link=Bed|text=White Bed}} || 1 || - || 1 || - || - || - || - || - 
|}





[[Category:Village blueprints]]