<noinclude>{{structure info}}</noinclude>

[[File:Desert Meeting Point 3.png|thumb|Meeting point 3 (Desert)]]



==== Blueprint ====

{{layered blueprint|name=Desert Meeting Point 3
|default=Layer 1
|S=Sand
|M=Smooth Sandstone
|W=White Glazed Terracotta-rot-180
|X=White Glazed Terracotta-rot-90
|Y=White Glazed Terracotta-rot-270
|Z=White Glazed Terracotta
|H=Hay Bale
|h=Hay Bale+top
|C=Cut Sandstone
|T=Terracotta
|B=Bell+ceiling
|A=Sandstone Wall
|O=Smooth Sandstone Slab
|P=Potted Cactus
|R=Torch
|E=Potted Dead Bush
|N=Sandstone Slab
|a=Water+top
|D=Smooth Sandstone Stairs
                 
|----Layer 0|
                 
        SSSSSS   
     SSSSSSSSS S 
     SSSSSSSSS S 
  SSSSSSSSSSSSS  
   SSSSSSSSSSSSS 
 SSSSSSSSSSSSSSS 
 SSSSSSSSSSSSSSS 
 MMMMMSSSSSSSSSS 
 SMSMMMMMMMSSSSS 
 SMSMMSSSSMSSSSS 
 MMMMMSMMSMSSSS  
 SSSSMSMMSMSSSS  
  SSSMSSSSMSSSS  
 SSSSMMMMMMSSS   
    SSSMSMSSS    
                 
|----Layer 1|
                 
        P        
     EADA        
      ECE        
   H   CP        
      EC    A  A 
 h    ADA    WX  
             YZ  
 A A        A  A 
 W X             
 Y Z  CMMC       
 A A  MaaM       
      MaaM       
      CMMC       
                 
    C            
                 
|----Layer 2|
                 
                 
      A A        
       P         
       E         
       P    A  A 
      A A        
                 
 A A        A  A 
                 
   P  N  N       
 A A             
                 
      N  N       
                 
    C            
                 
|----Layer 3|
                 
                 
      A A        
                 
                 
            A  A 
      A A        
                 
 A A        A  A 
   B             
                 
 A A             
                 
                 
                 
    T            
                 
|----Layer 4|
                 
                 
      A A        
                 
                 
            OOOO 
      A A   O  O 
            O  O 
 OOO        OOOO 
 O O             
 O O             
 OOO             
                 
                 
                 
    R            
                 
|----Layer 5|
                 
                 
      OOO        
      O O        
      O O        
      O O        
      OOO        
                 
                 
                 
                 
                 
                 
                 
                 
                 
                 
}}



==== Materials ====

{| class="wikitable sortable mw-collapsible"
|-
! Name !! Total !! Layer 0 !! Layer 1 !! Layer 2 !! Layer 3 !! Layer 4 !! Layer 5 
|-
| {{BlockSprite|Bell|link=Bell|text=Bell}} || 1 || - || - || - || 1 || - || - 
|-
| {{BlockSprite|Cut Sandstone|link=Sandstone|text=Cut Sandstone}} || 9 || - || 8 || 1 || - || - || - 
|-
| {{BlockSprite|Hay Bale|link=Hay Bale|text=Hay Bale}} || 2 || - || 2 || - || - || - || - 
|-
| {{BlockSprite|Potted Cactus|link=Flower Pot|text=Potted Cactus}} || 5 || - || 2 || 3 || - || - || - 
|-
| {{BlockSprite|Potted Dead Bush|link=Flower Pot|text=Potted Dead Bush}} || 5 || - || 4 || 1 || - || - || - 
|-
| {{BlockSprite|Sand|link=Sand|text=Sand}} || 151 || 151 || - || - || - || - || - 
|-
| {{BlockSprite|Sandstone Slab|link=Slab|text=Sandstone Slab}} || 4 || - || - || 4 || - || - || - 
|-
| {{BlockSprite|Sandstone Wall|link=Wall|text=Sandstone Wall}} || 40 || - || 12 || 12 || 12 || 4 || - 
|-
| {{BlockSprite|Smooth Sandstone|link=Sandstone|text=Smooth Sandstone}} || 47 || 39 || 8 || - || - || - || - 
|-
| {{BlockSprite|Smooth Sandstone Slab|link=Slab|text=Smooth Sandstone Slab}} || 34 || - || - || - || - || 22 || 12 
|-
| {{BlockSprite|Smooth Sandstone Stairs|link=Stairs|text=Smooth Sandstone Stairs}} || 2 || - || 2 || - || - || - || - 
|-
| {{BlockSprite|Terracotta|link=Terracotta|text=Terracotta}} || 1 || - || - || - || 1 || - || - 
|-
| {{BlockSprite|Torch|link=Torch|text=Torch}} || 1 || - || - || - || - || 1 || - 
|-
| {{BlockSprite|Water|link=Water|text=Water}} || 4 || - || 4 || - || - || - || - 
|-
| {{BlockSprite|White Glazed Terracotta|link=Glazed Terracotta|text=White Glazed Terracotta}} || 8 || - || 8 || - || - || - || - 
|}





[[Category:Village blueprints]]