<noinclude>{{structure info}}</noinclude>

[[File:Plains animal pen 2.png|thumb|Animal pen 2 (Plains)]]



==== Blueprint ====

{{layered blueprint
|name=Animal Pen 2 animal_pen_2
|default=Layer 1
|g=Grass Block+top
|f=Oak Fence
|F=Oak Fence Gate
|h=Hay bale+top
|G=Grass
|t=Tall Grass+bottom
|T=Tall Grass
|d=Dandelion
             
|----Layer 0|
             
 ggggggggggg 
 ggggggggggg 
 ggggggggggg 
 ggggggggggg 
 ggggggggggg 
 ggggggggggg 
 ggggggggggg 
             
|----Layer 1|
             
 fffffffffff 
 fG   G  G f 
 f  G     Gf 
 fGt    h  f 
 fG  G    df 
 ftG    G tf 
 fffffFfffff 
             
|----Layer 2|
             
             
             
             
   T         
             
  T       T  
             
             
}}



==== Materials ====

{| class="wikitable sortable mw-collapsible"
|-
! Name !! Total !! Layer 0 !! Layer 1 
|-
| {{BlockSprite|dandelion|link=Flower|text=Dandelion}} || 1 || - || 1 
|-
| {{BlockSprite|grass|link=Grass|text=Grass}} || 10 || - || 10 
|-
| {{BlockSprite|grass block|link=Grass Block|text=Grass Block}} || 77 || 77 || - 
|-
| {{BlockSprite|hay bale|link=Hay Bale|text=Hay Bale}} || 1 || - || 1 
|-
| {{BlockSprite|oak fence|link=Fence|text=Oak Fence}} || 31 || - || 31 
|-
| {{BlockSprite|oak fence gate|link=Fence Gate|text=Oak Fence Gate}} || 1 || - || 1 
|-
| {{BlockSprite|tall grass|link=Grass|text=Tall Grass}} || 3 || - || 3 
|}





[[Category:Village blueprints]]