<noinclude>{{structure info}}</noinclude>

[[File:Savanna Medium House 2.png|thumb|Medium House 2 (Savanna)]]



==== Blueprint ====

{{layered blueprint|name=
Savanna Medium House 2|default=Layer 1
|D=Dirt
|A=Acacia Wood
|C=Acacia Planks
|R=Crafting Table
|O=Orange Bed+top+foot-rot-90
|N=Orange Bed+top+head-rot-90
|G=Orange Bed+side+head-rot-180
|H=Chest-rot-90
|E=Orange Bed+side+foot-rot-180
|I=Acacia Stairs
|L=Glass Pane
|S=Acacia Slab
|P=Dirt Path+top
|c=Acacia Door+bottom
|a=Acacia Door+top
|l=Glass Pane-rot-90
|W=Wall Torch-rot-180
|T=Potted Dandelion
|F=Farmland
|t=Water+top
|h=Wheat
|o=Wall Torch-rot-270
|B=Grass Block+top
             
|----Layer 1|
             
             
       DDD   
   B  DCCCD  
      DCCCAP 
   DDDDCCCDP 
  DCCCDDDD P 
  DCCCDtFFP  
  DCCCDFFPP  
   DAD PP    
    PPDP     
             
|----Layer 2|
             
             
       AAA   
      AH  A  
      A   c  
   AAAAGEIA  
  AN CAAAA   
  AO IA hh   
  AR IAhh    
   AcA       
             
             
|----Layer 3|
             
             
       AlA   
      A   A  
      L   a  
   AlAA   A  
  A  TAAlA   
  L   L      
  A   A      
   AaA       
             
             
|----Layer 4|
             
             
       AAA   
      A   A  
      Ao  A  
   AAAA   A  
  A W AAAA   
  A   A      
  A   A      
   AAA       
             
             
|----Layer 5|
             
      IIIII  
     ICCCCCI 
     IC   CI 
  IIIIC   CI 
 ICCCCC   CI 
 IC   CCCCCI 
 IC   CIIII  
 IC   CI     
 ICCCCCI     
  IIIII      
             
|----Layer 6|
             
             
      IIIII  
      ISSSI  
      ISSSI  
  IIIIISSSI  
  ISSSIIIII  
  ISSSI      
  ISSSI      
  IIIII      
             
             
}}



==== Materials ====

{| class="wikitable sortable mw-collapsible"
|-
! Name !! Total !! Layer 1 !! Layer 2 !! Layer 3 !! Layer 4 !! Layer 5 !! Layer 6 !! Layer 7 !! Layer 8 
|-
| {{BlockSprite|acacia-door|link=Acacia Door|text=Acacia Door}} || 2 || - || 2 || - || - || - || - || - || - 
|-
| {{BlockSprite|acacia-planks|link=Acacia Planks|text=Acacia Planks}} || 49 || 18 || 1 || - || - || 30 || - || - || - 
|-
| {{BlockSprite|acacia-slab|link=Acacia Slab|text=Acacia Slab}} || 18 || - || - || - || - || - || 18 || - || - 
|-
| {{BlockSprite|acacia-stairs|link=Acacia Stairs|text=Acacia Stairs}} || 65 || - || 3 || - || - || 32 || 30 || - || - 
|-
| {{BlockSprite|acacia-wood|link=Acacia Wood|text=Acacia Wood}} || 64 || 2 || 22 || 16 || 24 || - || - || - || - 
|-
| {{BlockSprite|chest|link=Chest|text=Chest}} || 1 || - || 1 || - || - || - || - || - || - 
|-
| {{BlockSprite|crafting-table|link=Crafting Table|text=Crafting Table}} || 1 || - || 1 || - || - || - || - || - || - 
|-
| {{BlockSprite|dirt|link=Dirt|text=Dirt}} || 23 || 23 || - || - || - || - || - || - || - 
|-
| {{BlockSprite|farmland|link=Farmland|text=Farmland}} || 4 || 4 || - || - || - || - || - || - || - 
|-
| {{BlockSprite|glass-pane|link=Glass Pane|text=Glass Pane}} || 6 || - || - || 6 || - || - || - || - || - 
|-
| {{BlockSprite|grass-block|link=Grass Block|text=Grass Block}} || 1 || 1 || - || - || - || - || - || - || - 
|-
| {{BlockSprite|dirt-path|link=Dirt Path|text=Dirt Path}} || 11 || 11 || - || - || - || - || - || - || - 
|-
| {{BlockSprite|orange-bed|link=Orange Bed|text=Orange Bed}} || 2 || - || 2 || - || - || - || - || - || - 
|-
| {{BlockSprite|potted-dandelion|link=Potted Dandelion|text=Potted Dandelion}} || 1 || - || - || 1 || - || - || - || - || - 
|-
| {{BlockSprite|torch|link=Torch|text=Torch}} || 2 || - || - || - || 2 || - || - || - || - 
|-
| {{BlockSprite|water|link=Water|text=Water}} || 1 || 1 || - || - || - || - || - || - || - 
|-
| {{BlockSprite|wheat|link=Wheat|text=Wheat}} || 4 || - || 4 || - || - || - || - || - || - 
|}





[[Category:Village blueprints]]