<noinclude>{{structure info}}</noinclude>

[[File:Plains temple 3.png|thumb|Temple 2 (Plains)]]



==== Blueprint ====

{{layered blueprint
|name=Plains Temple 2
|default=Layer 2
|O=Oak Log+top
|o=Oak Log-rot90
|C=Cobblestone
|W=White Terracotta
|A=Oak Planks
|B=Brewing Stand
|K=Oak Stairs
|i=Oak Stairs-rot90
|S=Oak Stairs-rot-180
|r=Oak Stairs-rot270
|L=Cobblestone Wall
|T=Torch
|Y=Yellow Stained Glass Pane
|H=White Stained Glass Pane
|E=Cobblestone Stairs
|<=Cobblestone Stairs-rot90
|>=Cobblestone Stairs-rot270
|D=Oak Door+bottom
|R=Oak Door+top
|I=Yellow Stained Glass Pane-rot-90
|a=Wall Torch
|l=Wall Torch-rot-180
         
|----Layer 1|
         
         
  OCCCO  
  CAAAC  
  CAAAC  
  CAAAC  
  OAAAO  
  CAAAC  
  CAAAC  
  CAAAC  
  OCCCO  
  L<E>L  
         
|----Layer 2|
         
         
  OWWWO  
  W   W  
  W B W  
  W   W  
  Or iO  
  Wr iW  
  Wr iW  
  Wr iW  
  OWDWO  
  T   T  
         
|----Layer 3|
         
         
  OWIWO  
  W   W  
  Y   Y  
  W   W  
  O   O  
  W   W  
  Y   Y  
  W   W  
  OWRWO  
         
         
|----Layer 4|
         
    a    
  OWWWO  
  W   W  
  H   H  
  W   W  
  O   O  
  W   W  
  H   H  
  W   W  
  OWWWO  
         
         
|----Layer 5|
         
 ir   ir 
 iOOWOOr 
 KW l WK 
  W   W  
 SW   WS 
 iO   Or 
 KW   WK 
  W   W  
 SW a WS 
 iOOWOOr 
 ir   ir 
         
|----Layer 6|
         
  ir ir  
  iooor  
 SA   AS 
 iA   Ar 
 KA   AK 
  i   r  
 SA   AS 
 iA   Ar 
 KA   AK 
  iooor  
  ir ir  
         
|----Layer 7|
         
   iAr   
   iAr   
   iAr   
   iAr   
   iAr   
   iAr   
   iAr   
   iAr   
   iAr   
   iAr   
   iAr   
         
}}



==== Materials ====

{| class="wikitable sortable mw-collapsible"
|-
! Name !! Total !! Layer 1 !! Layer 2 !! Layer 3 !! Layer 4 !! Layer 5 !! Layer 6 !! Layer 7 
|-
| {{BlockSprite|Brewing Stand|link=Brewing Stand|text=Brewing Stand}} || 1 || - || 1 || - || - || - || - || - 
|-
| {{BlockSprite|Cobblestone|link=Cobblestone|text=Cobblestone}} || 18 || 18 || - || - || - || - || - || - 
|-
| {{BlockSprite|Cobblestone Stairs|link=Stairs|text=Cobblestone Stairs}} || 3 || 3 || - || - || - || - || - || - 
|-
| {{BlockSprite|Cobblestone Wall|link=Wall|text=Cobblestone Wall}} || 2 || 2 || - || - || - || - || - || - 
|-
| {{ItemSprite|Oak Door|link=Door|text=Oak Door}} || 1 || - || 1 || - || - || - || - || - 
|-
| {{BlockSprite|Oak Log|link=Log|text=Oak Log}} || 40 || 6 || 6 || 6 || 6 || 10 || 6 || - 
|-
| {{BlockSprite|Oak Planks|link=Planks|text=Oak Planks}} || 44 || 21 || - || - || - || - || 12 || 11 
|-
| {{BlockSprite|Oak Stairs|link=Stairs|text=Oak Stairs}} || 78 || - || 8 || - || - || 22 || 26 || 22 
|-
| {{BlockSprite|Torch|link=Torch|text=Torch}} || 5 || - || 2 || - || 1 || 2 || - || - 
|-
| {{BlockSprite|White Stained Glass Pane|link=Glass Pane|text=White Stained Glass Pane}} || 4 || - || - || - || 4 || - || - || - 
|-
| {{BlockSprite|White Terracotta|link=Terracotta|text=White Terracotta}} || 57 || - || 17 || 12 || 14 || 14 || - || - 
|-
| {{BlockSprite|Yellow Stained Glass Pane|link=Glass Pane|text=Yellow Stained Glass Pane}} || 5 || - || - || 5 || - || - || - || - 
|}





[[Category:Village blueprints]]