<noinclude>{{structure info}}</noinclude>

[[File:Plains Animal Pen 3.png|thumb|Animal pen 3 (Plains)]]



==== Blueprint ====

{{layered blueprint
|name=Animal Pen 3 animal_pen_3
|default=Layer 1
|g=Grass Block+top
|f=Oak Fence
|F=Oak Fence Gate
|w=Water+top
|t=Torch
             
|----Layer 0|
             
 ggggggggggg 
 gggggggwggg 
 ggggggwwwgg 
 gggggggwggg 
 ggggggggggg 
 ggggggggggg 
 ggggggggggg 
 ggggggggggg 
             
|----Layer 1|
             
    ffffffff 
 ffff      f 
 f         f 
 f         f 
 f       fff 
 fff     f   
   f     f   
   fffFfff   
             
|----Layer 2|
             
             
             
             
             
             
             
             
     t t     
             
}}



==== Materials ====

{| class="wikitable sortable mw-collapsible"
|-
! Name !! Total !! Layer 0 !! Layer 1 !! Layer 2
|-
| {{BlockSprite|grass block|link=Grass Block|text=Grass Block}} || 83 || 83 || - || - 
|-
| {{BlockSprite|oak fence|link=Fence|text=Oak Fence}} || 33 || - || 33 || - 
|-
| {{BlockSprite|oak fence gate|link=Fence Gate|text=Oak Fence Gate}} || 1 || - || 1 || - 
|-
| {{BlockSprite|torch|link=Torch|text=Torch}} || 2 || - || - || 2 
|-
| {{BlockSprite|water|link=Water|text=Water}} || 5 || 5 || - || - 
|}





[[Category:Village blueprints]]