<noinclude>{{structure info}}</noinclude>

[[File:Savanna Animal Pen 3.png|thumb|Animal Pen 3 (Savanna)]]



==== Blueprint ====

{{layered blueprint|name=
Savanna Animal Pen 3|default=Layer 2
|G=grass block+top
|A=acacia slab
|C=acacia fence
|F=acacia fence
|E=acacia fence
|N=acacia fence
|T=torch
|S=acacia slab
|a=acacia fence
|R=grass
|c=acacia fence
|i=acacia fence gate
|f=acacia fence
           
|----Layer 1|
           
 GGGGGGGGG 
 GGGGGGGGG 
 GGGGGGGGG 
 GGGGGGGGG 
 GGGGGGGGG 
 GGGGGGGGG 
 GGGGGGGGG 
 GGGGGGGGG 
           
|----Layer 2|
           
 Eaaaaaaaf 
 FR R  RRF 
 F  NR R F 
 FRR     C 
 F RR  R F 
 F RNRR  i 
 F RR    F 
 Caaaaaaac 
           
|----Layer 3|
           
           
           
 N  N      
 T         
 T         
 N  N      
           
           
           
|----Layer 4|
           
           
           
 N  N      
           
           
 N  N      
           
           
           
|----Layer 5|
           
           
           
 SSSS      
 SAAS      
 SAAS      
 SSSS      
           
           
           
}}



==== Materials ====

{| class="wikitable sortable mw-collapsible"
|-
! Name !! Total !! Layer 1 !! Layer 2 !! Layer 3 !! Layer 4 !! Layer 5 
|-
| {{BlockSprite|acacia-fence|link=Acacia Fence|text=Acacia Fence}} || 39 || - || 31 || 4 || 4 || - 
|-
| {{BlockSprite|acacia-fence-gate|link=Acacia Fence Gate|text=Acacia Fence Gate}} || 1 || - || 1 || - || - || - 
|-
| {{BlockSprite|acacia-slab|link=Acacia Slab|text=Acacia Slab}} || 16 || - || - || - || - || 16 
|-
| {{BlockSprite|grass|link=Grass|text=Grass}} || 16 || - || 16 || - || - || - 
|-
| {{BlockSprite|grass-block|link=Grass Block|text=Grass Block}} || 72 || 72 || - || - || - || - 
|-
| {{BlockSprite|torch|link=Torch|text=Torch}} || 2 || - || - || 2 || - || - 
|}





[[Category:Village blueprints]]