<noinclude>{{structure info}}</noinclude>

[[File:Plains Meeting Point 1.png|thumb|Meeting point 1 (Plains)]]



==== Blueprint ====

{{layered blueprint
|name=Meeting Point 1 meeting_point_1
|default=Layer 2
|p=Dirt Path+top
|d=Dirt
|c=Cobblestone
|w=Water+top
|f=Oak Fence
|b=Bell
|t=Torch
            
|----Layer 0|
            
     pp     
  pppppppp  
  pddddddp  
  pdccccdp  
 ppdcwwcdpp 
 ppdcwwcdpp 
  pdccccdp  
  pddddddp  
  pppppppp  
     pp     
            
|----Layer 1|
            
            
            
   cccccc   
   cccccc   
   ccwwcc   
   ccwwcc   
   cccccc   
   cccccc   
            
            
            
|----Layer 2|
            
            
            
       b    
    cccc    
    c  c    
    c  c    
    cccc    
            
            
            
            
|----Layer 3|
            
            
            
            
    f  f    
            
            
    f  f    
            
            
            
            
|----Layer 4|
            
            
            
            
    f  f    
            
            
    f  f    
            
            
            
            
|----Layer 5|
            
            
            
            
    cccc    
    cccc    
    cccc    
    cccc    
            
            
            
            
|----Layer 6|
            
            
            
            
    t  t    
            
            
    t  t    
            
            
            
            
}}

The structure resembles the [[Village/Structure (old)/Blueprints/Well|old Well]] seen in [[Village/Structure (old)/Blueprints |pre-1.14 villages]], with some minor additions.



==== Materials ====

{| class="wikitable sortable mw-collapsible"
|-
! Name !! Total !! Layer 0 !! Layer 1 !! Layer 2 !! Layer 3 !! Layer 4 !! Layer 5 !! Layer 6 
|-
| {{BlockSprite|bell|link=Bell|text=Bell}} || 1 || - || - || 1 || - || - || - || - 
|-
| {{BlockSprite|dirt|link=Dirt|text=Dirt}} || 20 || 20 || - || - || - || - || - || - 
|-
| {{BlockSprite|dirt path|link=Dirt Path|text=Dirt Path}} || 36 || 36 || - || - || - || - || - || - 
|-
| {{BlockSprite|cobblestone|link=Cobblestone|text=Cobblestone}} || 72 || 12 || 32 || 12 || - || - || 16 || - 
|-
| {{BlockSprite|oak-fence|link=Fence|text=Oak Fence}} || 8 || - || - || - || 4 || 4 || - || - 
|-
| {{BlockSprite|torch|link=Torch|text=Torch}} || 4 || - || - || - || - || - || - || 4 
|-
| {{BlockSprite|water|link=Water|text=Water}} || 8 || 4 || 4 || - || - || - || - || - 
|}





[[Category:Village blueprints]]