<noinclude>{{structure info}}</noinclude>

[[File:Desert Armorer 1.png|thumb|Armorer 1 (Desert)]]



==== Blueprint ====

{{layered blueprint|name=Desert Armorer 1
|default=Layer 1
|S=Sand
|C=Cut Sandstone
|M=Smooth Sandstone
|O=Smooth Sandstone Slab+bottom
|o=Double Smooth Sandstone Slab
|G=Granite
|B=Blast Furnace
|T=Smooth Sandstone Stairs-rot90
|t=Smooth Sandstone Stairs-rot270
|J=Jungle Fence
|W=Wall Torch-rot-90
|N=Stone Button
|R=Granite Stairs-rot90
|r=Granite Stairs-rot270
|U=Jungle Door+bottom
|L=Jungle Door+top
|A=Wall Torch
|I=Granite Wall
|H=Wall Torch-rot-270
         
|----Layer 0|
         
 SSSSSSS 
 SMSSSMS 
 SMMMMMS 
 SMMMMMS 
 SSMMMSS 
  SMMMS  
  SSMSS  
         
|----Layer 1|
         
 CMMMMMC 
 M GBG M 
 M     M 
 Mt   TM 
 CM   MC 
  M   M  
  CMUMC  
         
|----Layer 2|
         
 CMMMMMC 
 MWGGGHM 
 M NNN M 
 M     M 
 CM   MC 
  J   J  
  CMLMC  
         
|----Layer 3|
         
 CMMMMMC 
 M RGr M 
 M     M 
 M     M 
 CM   MC 
  M A M  
  CMMMC  
         
|----Layer 4|
         
 CMMMMMC 
 M  G  M 
 M     M 
 M     M 
 CMMMMMC 
  OOOOO  
  COoOC  
         
|----Layer 5|
         
 COoOoOC 
 OOOIOOO 
 oOOOOOo 
 OOOOOOO 
 COoOoOC 
         
         
         
|----Layer 6|
         
         
    I    
         
         
         
         
         
         
}}



==== Materials ====

{| class="wikitable sortable mw-collapsible"
|-
! Name !! Total !! Layer 0 !! Layer 1 !! Layer 2 !! Layer 3 !! Layer 4 !! Layer 5 !! Layer 6 
|-
| {{BlockSprite|Blast Furnace|link=Blast Furnace|text=Blast Furnace}} || 1 || - || 1 || - || - || - || - || - 
|-
| {{BlockSprite|Cut Sandstone|link=Sandstone|text=Cut Sandstone}} || 28 || - || 6 || 6 || 6 || 6 || 4 || - 
|-
| {{BlockSprite|Granite|link=Granite|text=Granite}} || 7 || - || 2 || 3 || 1 || 1 || - || - 
|-
| {{BlockSprite|Granite Stairs|link=Stairs|text=Granite Stairs}} || 2 || - || - || - || 2 || - || - || - 
|-
| {{BlockSprite|Granite Wall|link=Wall|text=Granite Wall}} || 2 || - || - || - || - || - || 1 || 1 
|-
| {{ItemSprite|Jungle Door|link=Door|text=Jungle Door}} || 1 || - || 1 || - || - || - || - || - 
|-
| {{BlockSprite|Jungle Fence|link=Fence|text=Jungle Fence}} || 2 || - || - || 2 || - || - || - || - 
|-
| {{BlockSprite|Sand|link=Sand|text=Sand}} || 26 || 26 || - || - || - || - || - || - 
|-
| {{BlockSprite|Smooth Sandstone|link=Sandstone|text=Smooth Sandstone}} || 85 || 19 || 17 || 15 || 18 || 16 || - || - 
|-
| {{BlockSprite|Smooth Sandstone Slab|link=Slab|text=Smooth Sandstone Slab}} || 45 || - || - || - || - || 9 || 36 || - 
|-
| {{BlockSprite|Smooth Sandstone Stairs|link=Stairs|text=Smooth Sandstone Stairs}} || 2 || - || 2 || - || - || - || - || - 
|-
| {{BlockSprite|Stone Button|link=Button|text=Stone Button}} || 3 || - || - || 3 || - || - || - || - 
|-
| {{BlockSprite|Torch|link=Torch|text=Torch}} || 3 || - || - || 2 || 1 || - || - || - 
|}





[[Category:Village blueprints]]