<noinclude>{{structure info}}</noinclude>

[[File:Savanna Large Farm 2.png|thumb|Large Farm 2 (Savanna)]]



==== Blueprint ====

{{layered blueprint|name=
Savanna Large Farm 2|default=Layer 1
|G=Grass Block+top
|D=Dirt
|F=Farmland
|W=Wheat
|T=Tall Grass
|t=Tall Grass+bottom
|A=Water+top
|R=Dirt Path+top
|S=Grass
|C=Composter
          
|----Layer 1|
          
   GGGGGD 
  GGDDGGG 
  DGGGGGD 
 DGGDDGGG 
 DDGGGDGG 
 GGGDGGDD 
  DDGDGGG 
  DGGGGGD 
 GGGDGDGG 
  D DG    
          
|----Layer 2|
          
   RFFRRG 
  RFAGRFA 
  GFFFFFG 
 GFFGGFFR 
 DAFFFARF 
 FFFFFRGG 
  GGRFFFF 
  GRFFFFA 
 FFFARGFF 
  G GR    
          
|----Layer 3|
          
    WW  S 
   W t W  
  SWWWWWt 
 tWW SWW  
   WWW  W 
 WWWWW tS 
  tC WWWW 
  S WWWW  
 WWW  tWW 
  S S     
          
|----Layer 4|
          
          
     T    
        T 
 T        
          
       T  
  T       
          
      T   
          
          
}}

Note: This farm follows the topography of the existing terrain. The water sources may end up washing away planted crops that spawn down-hill.



==== Materials ====

{| class="wikitable sortable mw-collapsible"
|-
! Name !! Total !! Layer 1 !! Layer 2 !! Layer 3 
|-
| {{BlockSprite|composter|link=Composter|text=Composter}} || 1 || - || - || 1 
|-
| {{BlockSprite|dirt|link=Dirt|text=Dirt}} || 24 || 23 || 1 || - 
|-
| {{BlockSprite|farmland|link=Farmland|text=Farmland}} || 35 || - || 35 || - 
|-
| {{BlockSprite|grass|link=Grass|text=Grass}} || 7 || - || - || 7 
|-
| {{BlockSprite|grass-block|link=Grass Block|text=Grass Block}} || 61 || 46 || 15 || - 
|-
| {{BlockSprite|dirt-path|link=Dirt Path|text=Dirt Path}} || 12 || - || 12 || - 
|-
| {{BlockSprite|tall-grass|link=Tall Grass|text=Tall Grass}} || 6 || - || - || 6 
|-
| {{BlockSprite|water|link=Water|text=Water}} || 6 || - || 6 || - 
|-
| {{BlockSprite|wheat|link=Wheat|text=Wheat}} || 35 || - || - || 35 
|}





[[Category:Village blueprints]]