<noinclude>{{structure info}}</noinclude>

[[File:Plains Small House 2.png|thumb|Small house 2 (Plains)]]



==== Blueprint ====

{{layered blueprint
|name=Village Plains Houses plains_small_house_2
|default=Layer 2
|P=Oak Planks
|S=Stripped Oak Log+top
|C=Cobblestone
|W=White Terracotta
|B=Yellow Bed+top foot-rot270
|b=Yellow Bed+top head-rot270
|g=Glass Pane
|^=Oak Stairs-rot270
|s=Oak Stairs-rot180
|d=Oak Door+bottom
|D=Oak Door+top
|G=glass Pane-rot90
|T=torch-rot180
         
|----Layer 1|
         
         
  SCCCS  
  CPPPC  
  CPPPC  
  CPPPC  
  SCCCS  
    s    
         
|----Layer 2|
         
         
  SWWWS  
  Ws bW  
  WP BW  
  W^  W  
  SWdWS  
         
         
|----Layer 3|
         
         
  SWGWS  
  W   W  
  g   g  
  W   W  
  SWDWS  
         
         
|----Layer 4|
         
         
  SWWWS  
  W T W  
  W   W  
  W   W  
  SWWWS  
    T    
         
|----Layer 5|
         
 PPPPPPP 
 PPPPPPP 
 PP   PP 
 PP   PP 
 PP   PP 
 PPPPPPP 
 PPPPPPP 
         
|----Layer 6|
         
         
  PPPPP  
  PPPPP  
  PP PP  
  PPPPP  
  PPPPP  
         
         
|----Layer 7|
         
         
         
   PPP   
   PPP   
   PPP   
         
         
         
}}



==== Materials ====

{| class="wikitable sortable mw-collapsible"
|-
! Name !! Total !! Layer 1 !! Layer 2 !! Layer 3 !! Layer 4 !! Layer 5 !! Layer 6 !! Layer 7 
|-
| {{BlockSprite|cobblestone|link=Cobblestone|text=Cobblestone}} || 12 || 12 || - || - || - || - || - || - 
|-
| {{BlockSprite|glass-pane|link=Glass Pane|text=Glass Pane}} || 3 || - || - || 3 || - || - || - || - 
|-
| {{ItemSprite|oak-door|link=Door|text=Oak Door}} || 1 || - || 1 || - || - || - || - || - 
|-
| {{BlockSprite|oak-planks|link=Planks|text=Oak Planks}} || 83 || 9 || 1 || - || - || 40 || 24 || 9 
|-
| {{BlockSprite|oak-stairs|link=Stairs|text=Oak Stairs}} || 3 || 1 || 2 || - || - || - || - || - 
|-
| {{BlockSprite|stripped-oak-log|link=Log|text=Stripped Oak Log}} || 16 || 4 || 4 || 4 || 4 || - || - || - 
|-
| {{BlockSprite|torch|link=Torch|text=Torch}} || 2 || - || - || - || 2 || - || - || - 
|-
| {{BlockSprite|white-terracotta|link=Terracotta|text=White Terracotta}} || 31 || - || 11 || 8 || 12 || - || - || - 
|-
| {{BlockSprite|yellow-bed|link=Bed|text=Yellow Bed}} || 1 || - || 1 || - || - || - || - || - 
|}





[[Category:Village blueprints]]