<noinclude>{{structure info}}</noinclude>

[[File:Desert Large Farm 1.png|thumb|Large farm 1 (Desert)]]



==== Blueprint ====

{{layered blueprint|name=Desert Large Farm 1
|default=Layer 3
|S=Sand
|H=Hay Bale
|h=Hay Bale-rot90
|z=Hay Bale+top
|M=Smooth Sandstone
|O=Smooth Sandstone Stairs
|W=Water+top
|F=Farmland+moist
|E=Wheat
|C=Composter
               
|----Layer 1|
               
 SSSSSSSSSSSSS 
 SSSSSSSSSSSSS 
 SSSSSSSSSSSSS 
 SSSSSSSSSSSSS 
 SSSSSSSSSSSSS 
 SSSSSSSSSSSSS 
 SSSSSSSSSSSSS 
 SSSSSSSSSSSSS 
 SSSSSSSSSSSSS 
 SSSSSSSSSSSSS 
 SSSSSSSSSSSSS 
               
|----Layer 2|
               
   SSSSSSSS    
  SSSSSSSSSS   
  SMMMSFFFFSSS 
  SSSSSSFWFFFS 
  SSFFFFFFFFSS 
  SSSFFFFFSSSS 
  SSSSFFFFFSSS 
  SSSFFFFFSSSS 
   SFFFWFFFSSS 
   SSSFFFSSS   
   S  SSS      
               
|----Layer 3|
               
        z      
  OMMMOH  h    
  MWWWMEEEE    
  OMMMO E EEEh 
    EEEEEEEE   
  z  EEEEECz z 
   hChEEEEEHzh 
  h HEEEEEh z  
    EEE EEE  H 
      EEE      
   h           
               
|----Layer 4|
               
               
               
               
               
               
               
   z        h  
               
               
               
               
               
}}



==== Materials ====

{| class="wikitable sortable mw-collapsible"
|-
! Name !! Total !! Layer 1 !! Layer 2 !! Layer 3 !! Layer 4 
|-
| {{BlockSprite|Composter|link=Composter|text=Composter}} || 2 || - || - || 2 || - 
|-
| {{BlockSprite|Farmland|link=Farmland|text=Farmland}} || 40 || - || 40 || - || - 
|-
| {{BlockSprite|Hay Bale|link=Hay Bale|text=Hay Bale}} || 20 || - || - || 18 || 2 
|-
| {{BlockSprite|Sand|link=Sand|text=Sand}} || 212 || 143 || 69 || - || - 
|-
| {{BlockSprite|Smooth Sandstone|link=Sandstone|text=Smooth Sandstone}} || 11 || - || 3 || 8 || - 
|-
| {{BlockSprite|Smooth Sandstone Stairs|link=Stairs|text=Smooth Sandstone Stairs}} || 4 || - || - || 4 || - 
|-
| {{BlockSprite|Water|link=Water|text=Water}} || 5 || - || 2 || 3 || - 
|-
| {{BlockSprite|Wheat|link=Wheat Seeds|text=Wheat}} || 40 || - || - || 40 || - 
|}





[[Category:Village blueprints]]