<noinclude>{{structure info}}</noinclude>

[[File:Snowy Tundra Armorer House 2.png|thumb|Armorer house 2 (Snowy tundra)]]



==== Blueprint ====

{{layered blueprint
|name=Snowy Armorer House 2 snowy_armorer_house_2
|default=Layer 2
|w=Stripped Spruce Wood
|p=Spruce Planks
|S=Snow
|o=Spruce Door+bottom
|O=Spruce Door+top
|s=Spruce Slab
|C=Cobblestone
|c=Cobblestone Wall
|b=Blast Furnace
|g=Glass Pane
|G=Glass Pane-rot90
|l=Lantern
|f=Spruce Fence
|h=Spruce Stairs
|i=Spruce Stairs-rot90
|j=Spruce Stairs-rot180
|k=Spruce Stairs-rot270
         
|----Layer 1|
         
 SSSSSSS 
 SwwwwwS 
 SwpppwS 
 SwCppwS 
 SwpppwS 
 SwwwwwS 
 SSihkSS 
         
|----Layer 2|
         
 s     s 
 pwwwwwp 
 swb hws 
 pw   wp 
 sw  jws 
 pwwowwp 
 s     s 
         
|----Layer 3|
         
 ps   sp 
 pwwwwwp 
 pwc  wp 
 pw   wp 
 pw   wp 
 pwwOwwp 
 p     p 
         
|----Layer 4|
         
 sp   ps 
 SpwGwpS 
 spc  ps 
 Sg   gS 
 sp   ps 
 SpwwwpS 
 sp   ps 
         
|----Layer 5|
         
  ps sp  
  pwwwp  
  pcl p  
  p   p  
  p l p  
  pwwwp  
  pslsp  
         
|----Layer 6|
         
  SpspS  
  SpwpS  
   CfpS  
  sp ps  
  SpfpS  
  SpwpS  
  SpppS  
         
|----Layer 7|
         
   Sp    
   Sp    
   cp    
   Sp    
   Sp    
   Sp    
   Sp    
         
|----Layer 8|
         
    S    
    S    
   cS    
    S    
    S    
    S    
    S    
         
}}



==== Materials ====

{| class="wikitable sortable mw-collapsible"
|-
! Name !! Total !! Layer 1 !! Layer 2 !! Layer 3 !! Layer 4 !! Layer 5 !! Layer 6 !! Layer 7 !! Layer 8 
|-
| {{BlockSprite|blast-furnace|link=Blast Furnace|text=Blast Furnace}} || 1 || - || 1 || - || - || - || - || - || - 
|-
| {{BlockSprite|cobblestone|link=Cobblestone|text=Cobblestone}} || 2 || 1 || - || - || - || - || 1 || - || - 
|-
| {{BlockSprite|cobblestone-wall|link=Wall|text=Cobblestone Wall}} || 5 || - || - || 1 || 1 || 1 || - || 1 || 1 
|-
| {{BlockSprite|glass-pane|link=Glass Pane|text=Glass Pane}} || 3 || - || - || - || 3 || - || - || - || - 
|-
| {{BlockSprite|lantern|link=Lantern|text=Lantern}} || 3 || - || - || - || - || 3 || - || - || - 
|-
| {{BlockSprite|snow|link=Snow|text=Snow}} || 58 || 21 || - || - || 6 || - || 11 || 13 || 7 
|-
| {{ItemSprite|spruce-door|link=Door|text=Spruce Door}} || 1 || - || 1 || - || - || - || - || - || - 
|-
| {{BlockSprite|spruce-fence|link=Fence|text=Spruce Fence}} || 2 || - || - || - || - || - || 2 || - || - 
|-
| {{BlockSprite|spruce-planks|link=Planks|text=Spruce Planks}} || 75 || 8 || 6 || 14 || 12 || 14 || 14 || 7 || - 
|-
| {{BlockSprite|spruce-slab|link=Slab|text=Spruce Slab}} || 25 || - || 8 || 2 || 8 || 4 || 3 || - || - 
|-
| {{BlockSprite|spruce-stairs|link=Stairs|text=Spruce Stairs}} || 5 || 3 || 2 || - || - || - || - || - || - 
|-
| {{BlockSprite|stripped-spruce-wood|link=Wood|text=Stripped Spruce Wood}} || 59 || 16 || 15 || 15 || 5 || 6 || 2 || - || - 
|}





[[Category:Village blueprints]]