<noinclude>{{structure info}}</noinclude>

[[File:Desert Tool Smith 1.png|thumb|Tool smith 1 (Desert)]]



==== Blueprint ====

{{layered blueprint|name=Desert Tool Smith 1
|default=Layer 1
|S=Sand
|M=Smooth Sandstone
|T=Terracotta
|O=Smooth Sandstone Slab
|o=Double Smooth Sandstone Slab
|L=Light Blue Glazed Terracotta
|X=Light Blue Glazed Terracotta-rot-90
|Y=Light Blue Glazed Terracotta-rot-180
|Z=Light Blue Glazed Terracotta-rot-270
|I=Smithing Table
|C=Chest
|H=Smooth Sandstone Stairs
|J=Jungle Button
|W=Wall Torch-rot-180
|A=Wall Torch
|U=Jungle Door+bottom
|N=Jungle Door+top
|P=Potted Cactus
|----Layer -2|
 SSSSSSSSS 
 MLZLSSSSS 
 MXYXSSSSS 
 MLZLMSSSS 
 MXYXSSSSS 
 SSSSSSSSS 
 SSSSSSSSS 
 SSSSSSSSS 
 SSSSSSSSS 
|----Layer -1|
 MMMMSSSSS 
 M   MSSSS 
 M   MSSSS 
 M    HSSS 
 M   MSSSS 
 MMMMSSSSS 
 SSSSSSSSS 
 SSSSSSSSS 
 SSSSSSSSS 
           
|----Layer 0|
           
 MMMMS     
 MJJJMSSSS 
 MJ JMMMMS 
 MJ    HMS 
 MJJJMMMMS 
 MMMMSSMSS 
 SSSSS M S 
 SSSSS MS  
 SSSSSSM   
           
|----Layer 1|
           
 MMMMM     
 M W MMMMM 
 M   M   M 
 M       M 
 M A M   M 
 MMMMMMUMM 
 HMMMH   P 
 HMMMH  P  
 HHHHH     
           
|----Layer 2|
           
 MMMMM     
 MMMMMMMMM 
 MMMMM W M 
 MMMMM   M 
 MMMMM   M 
 MMMMMMNMM 
  HMH W W  
  HHH      
           
           
|----Layer 3|
           
 MMMMM     
 MC  MMMMM 
 MI  MOOOM 
 M   MOOOM 
 M   MOOOM 
 MMUMMMMMM 
           
           
           
           
|----Layer 4|
           
 MTTTM     
 T W M O O 
 T   M     
 T   M   O 
 T   M     
 MMNMM O O 
  W W      
           
           
           
|----Layer 5|
           
 MMMMM     
 oOOOM     
 oOOOM     
 oOOOM     
 oOOOM     
 MMMMM     
           
           
           
           
|----Layer 6|
           
 O O O     
           
 O   O     
 O   O     
           
 O O O     
           
           
           
           
}}



==== Materials ====

{| class="wikitable sortable mw-collapsible"
|-
! Name !! Total !! Layer -2 !! Layer -1 !! Layer 0 !! Layer 1 !! Layer 2 !! Layer 3 !! Layer 4 !! Layer 5 !! Layer 6 
|-
| {{BlockSprite|Chest|link=Chest|text=Chest}} || 1 || - || - || - || - || - || 1 || - || - || - 
|-
| {{BlockSprite|Jungle Button|link=Button|text=Jungle Button}} || 9 || - || - || 9 || - || - || - || - || - || - 
|-
| {{ItemSprite|Jungle Door|link=Door|text=Jungle Door}} || 2 || - || - || - || 1 || - || 1 || - || - || - 
|-
| {{BlockSprite|Light Blue Glazed Terracotta|link=Glazed Terracotta|text=Light Blue Glazed Terracotta}} || 12 || 12 || - || - || - || - || - || - || - || - 
|-
| {{BlockSprite|Potted Cactus|link=Flower Pot|text=Potted Cactus}} || 2 || - || - || - || 2 || - || - || - || - || - 
|-
| {{BlockSprite|Sand|link=Sand|text=Sand}} || 146 || 64 || 52 || 30 || - || - || - || - || - || - 
|-
| {{BlockSprite|Smithing Table|link=Smithing Table|text=Smithing Table}} || 1 || - || - || - || - || - || 1 || - || - || - 
|-
| {{BlockSprite|Smooth Sandstone|link=Sandstone|text=Smooth Sandstone}} || 172 || 5 || 15 || 26 || 33 || 41 || 28 || 10 || 14 || - 
|-
| {{BlockSprite|Smooth Sandstone Slab|link=Slab|text=Smooth Sandstone Slab}} || 44 || - || - || - || - || - || 9 || 5 || 20 || 10 
|-
| {{BlockSprite|Smooth Sandstone Stairs|link=Stairs|text=Smooth Sandstone Stairs}} || 16 || - || 1 || 1 || 9 || 5 || - || - || - || - 
|-
| {{BlockSprite|Terracotta|link=Terracotta|text=Terracotta}} || 7 || - || - || - || - || - || - || 7 || - || - 
|-
| {{BlockSprite|Torch|link=Torch|text=Torch}} || 8 || - || - || - || 2 || 3 || - || 3 || - || - 
|}





[[Category:Village blueprints]]