<noinclude>{{structure info}}</noinclude>

[[File:Plains Stable 1.png|thumb|Stable 1 (Plains)]]



==== Blueprint ====

{{layered blueprint
|name=Stable 1 stable-1
|default=Layer 1
|g=Grass Block+top
|P=Dirt Path+top
|d=Dirt
|i=Oak Door+bottom
|I=Oak Door+top
|p=Glass Pane
|a=Glass Pane-rot90
|c=Cobblestone
|h=Hay Bale+top
|t=Torch
|T=Torch-rot180
|r=Torch-rot270
|R=Torch-rot90
|o=Oak Log
|O=Oak Log-rot90
|w=Water+top
|f=Oak Fence
|l=Oak Planks
|x=Cobblestone Stairs
|X=Cobblestone Stairs-rot180
|y=Oak Stairs
|Y=Oak Stairs-rot180
                 
|----Layer 0|
                  
 gggggg           
 gggggg           
 gggggdddddddddd  
 gggggdggggggdgd  
 ggggggggggggdgd  
 gggdggggddggdgd  
 gggggddgddddddd  
 gggggggPggggggg  
 gggggggPggggggg  
                  
|----Layer 1|
                  
 ffffff           
 f    f           
 f    cccccccccc  
 f    h      owc  
 f           owc  
 f  h    hh  owc  
 f    cciccccccc  
 f    f           
 ffffff           
                  
|----Layer 2|
                  
 t    t           
                  
      cccOaOaOcc  
               o  
               p  
         h     o  
      ccIcOaOaOc  
                  
 t    t           
                  
|----Layer 3|
                  
                  
                  
      cccccccccc  
      x        c  
               c  
      X        c  
      cccccccccc  
                  
                  
                  
|----Layer 4|
                  
                  
     YYYYYYYYYYYY 
     yccccccccccy 
      c    T   c  
     rcR      rc  
      c    t   c  
     YccccccccccY 
     yyyyyyyyyyyy 
                  
                  
|----Layer 5|
                  
                  
                  
     YYYYYYYYYYYY 
     yc        cy 
      c        cR 
     Yc        cY 
     yyyyyyyyyyyy 
                  
                  
                  
|----Layer 6|
                  
                  
                  
                  
     YYYYYYYYYYYY 
     llllllllllll 
     yyyyyyyyyyyy 
                  
                  
                  
                  
}}

The cobblestone stairs in layer 3 are upside down.

==== Materials ====

{| class="wikitable sortable mw-collapsible"
|-
! Name !! Total !! Layer 0 !! Layer 1 !! Layer 2 !! Layer 3 !! Layer 4 !! Layer 5 !! Layer 6 
|-
| {{BlockSprite|cobblestone|link=Cobblestone|text=Cobblestone}} || 86 || - || 22 || 9 || 23 || 26 || 6 || - 
|-
| {{BlockSprite|cobblestone-stairs|link=Stairs|text=Cobblestone Stairs}} || 2 || - || - || - || 2 || - || - || - 
|-
| {{BlockSprite|dirt|link=Dirt|text=Dirt}} || 29 || 29 || - || - || - || - || - || - 
|-
| {{BlockSprite|dirt-path|link=Dirt Path|text=Dirt Path}} || 2 || 2 || - || - || - || - || - || - 
|-
| {{BlockSprite|glass-pane|link=Glass Pane|text=Glass Pane}} || 5 || - || - || 5 || - || - || - || - 
|-
| {{BlockSprite|grass-block|link=Grass Block|text=Grass Block}} || 86 || 86 || - || - || - || - || - || - 
|-  
| {{BlockSprite|hay-bale|link=Hay Bale|text=Hay Bale}} || 5 || - || 4 || 1 || - || - || - || - 
|-
| {{ItemSprite|oak-door|link=Door|text=Oak Door}} || 1 || - || 1 || - || - || - || - || - 
|-
| {{BlockSprite|oak-fence|link=Fence|text=Oak Fence}} || 21 || - || 21 || - || - || - || - || - 
|-
| {{BlockSprite|oak-log|link=Log|text=Oak Log}} || 11 || - || 3 || 8 || - || - || - || - 
|-
| {{BlockSprite|oak-planks|link=Planks|text=Oak Planks}} || 12 || - || - || - || - || - || - || 12 
|-
| {{BlockSprite|oak-stairs|link=Stairs|text=Oak Stairs}} || 80 || - || - || - || - || 28 || 28 || 24 
|-
| {{BlockSprite|torch|link=Torch|text=Torch}} || 10 || - || - || 4 || - || 5 || 1 || - 
|-
| {{BlockSprite|water|link=Water|text=Water}} || 3 || - || 3 || - || - || - || - || - 
|}





[[Category:Village blueprints]]