<noinclude>{{structure info}}</noinclude>

[[File:Snowy Tundra Masons House 2.png|thumb|Masons house 2 (Snowy tundra)]]

==== Blueprint ====

{{layered blueprint
|name=Snowy Masons House 2 snowy_masons_house_2
|defaut=Layer 2
|S=Snow
|s=Spruce Slab
|w=Stripped Spruce Wood
|p=Spruce Planks
|d=Diorite
|D=Diorite Wall
|T=Stonecutter-rot90
|f=Furnace
|x=Spruce Stairs
|a=Diorite Stairs-rot90
|A=Diorite Stairs-rot270
|l=Lantern
|o=Spruce Door+bottom
|O=Spruce Door+top
|i=Stripped Spruce Log
|I=Stripped Spruce Log
           
|----Layer 1|
           
 SSSSSSSSS 
 SSSdddSSS 
 SwwdddwwS 
 SwpdddpwS 
 SwpppppwS 
 SwwpppwwS 
 SSSwwwSSS 
 SSSwwwSSS 
 SSSxxxSSS 
           
|----Layer 2|
           
           
    ddd    
  wwdfdww  
  wA   aw  
  wT   aw  
  ww   ww  
    wow    
           
|----Layer 3|
           
 p       p 
 p  ddd  p 
 pww Dlwwp 
 pw     wp 
 pw     wp 
 pww   wwp 
 p pwOwp p 
   p   p   
   p   p   
           
|----Layer 4|
           
 p       p 
 p  ddd  p 
 pww D wwp 
 pi     ip 
 pi     ip 
 pww   wwp 
 p pwIwp p 
   p   p   
   pl lp   
           
|----Layer 5|
           
 sp     ps 
 sp adA ps 
 spwwdwwps 
 sp     ps 
 sp     ps 
 spwwwwwps 
 spspwpsps 
   sp ps   
   sp ps   
           
|----Layer 6|
           
  pp   pp  
  pp d pp  
  ppwdwpp  
  pp   pp  
  pp   pp  
  ppwIwpp  
  ppspspp  
    sps    
    sps    
           
|----Layer 7|
           
   pplpp   
   ppdpp   
   ppdpp   
   pp pp   
   pplpp   
   ppwpp   
   pp pp   
           
|----Layer 8|
           
   sppps   
   sppps   
   spdps   
   sppps   
   sppps   
   sppps   
   sppps   
           
|----Layer 9|
           
    sps    
    sps    
    sds    
    sps    
    sps    
    sps    
    sps    
           
|----Layer 10|
           
           
          
     D     
}}

All spruce slabs are bottom slabs.

==== Materials ====

{| class="wikitable sortable mw-collapsible"
|-
! Name !! Total !! Layer 1 !! Layer 2 !! Layer 3 !! Layer 4 !! Layer 5 !! Layer 6 !! Layer 7 !! Layer 8 !! Layer 9 !! Layer 10 
|-
| {{BlockSprite|diorite|link=Diorite|text=Diorite}} || 28 || 9 || 5 || 3 || 3 || 2 || 2 || 2 || 1 || 1 || - 
|-
| {{BlockSprite|diorite-stairs|link=Stairs|text=Diorite Stairs}} || 5 || - || 3 || - || - || 2 || - || - || - || - || - 
|-
| {{BlockSprite|diorite-wall|link=Wall|text=Diorite Wall}} || 3 || - || - || 1 || 1 || - || - || - || - || - || 1 
|-
| {{BlockSprite|furnace|link=Furnace|text=Furnace}} || 1 || - || 1 || - || - || - || - || - || - || - || - 
|-
| {{BlockSprite|lantern|link=Lantern|text=Lantern}} || 5 || - || - || 1 || 2 || - || - || 2 || - || - || - 
|-
| {{BlockSprite|snow|link=Snow|text=Snow}} || 41 || 41 || - || - || - || - || - || - || - || - || - 
|-
| {{ItemSprite|spruce-door|link=Door|text=Spruce Door}} || 1 || - || 1 || - || - || - || - || - || - || - || - 
|-
| {{BlockSprite|spruce-planks|link=Planks|text=Spruce Planks}} || 155 || 10 || - || 20 || 20 || 20 || 31 || 28 || 20 || 6 || - 
|-
| {{BlockSprite|spruce-slab|link=Slab|text=Spruce Slab}} || 48 || - || - || - || - || 20 || 6 || - || 14 || 14 || - 
|-
| {{BlockSprite|stonecutter|link=Stonecutter|text=Stonecutter}} || 1 || - || 1 || - || - || - || - || - || - || - || - 
|-
| {{BlockSprite|stripped-spruce-log|link=Log|text=Stripped Spruce Log}} || 6 || - || - || - || 5 || - || 1 || - || - || - || - 
|-
| {{BlockSprite|stripped-spruce-wood|link=Wood|text=Stripped Spruce Wood}} || 67 || 18 || 14 || 14 || 10 || 10 || 4 || 1 || - || - || - 
|}

[[Category:Village blueprints]]