<noinclude>{{structure info}}</noinclude>

[[File:Savanna Medium House 1.png|thumb|Medium House 1 (Savanna)]]



==== Blueprint ====

{{layered blueprint|name=
Savanna Medium House 1|default=Layer 1
|D=Dirt
|A=Acacia Log+top
|C=Acacia Log
|c=Acacia Log-rot-90
|I=Acacia Planks
|G=Grass Block+top
|R=Crafting Table
|W=Acacia Wood
|H=Chest-rot-90
|O=Orange Bed+top+foot-rot-90
|N=Orange Bed+top+head-rot-90
|s=Acacia Stairs
|>=Acacia Stairs-rot-90
|^=Acacia Stairs-rot-180
|<=Acacia Stairs-rot-270
|L=Glass Pane
|P=Dirt Path+top
|d=Acacia Door+bottom
|a=Acacia Door+top
|E=Glass Pane-rot-90
|T=Wall Torch-rot-180
|F=Acacia Fence
|o=Torch
|M=Farmland
|h=Wheat
|l=Wall Torch-rot-270
|t=Water+top
|r=Grass
|!=Wall Torch-rot-90
                
|----Layer 1|
                
    GGGGGGG     
    GMMtMMG     
  DDDMMMMMDDD   
 DIIIDGGGDIIID  
 DIIIIGGGIIIID  
 DIIIDGGGDIIID  
  DIDGGGG DID   
   PGGGDG  P    
                
|----Layer 2|
                
    FFFFFFF     
    Fhh hhF     
  AAAhhhhhAAA   
 AN RA   AW NA  
 AO  d   d  OA  
 AH  AFFFA   A  
  AdA  r  AdA   
                
                
|----Layer 3|
                
    o     o     
                
  AEA     AEA   
 A   A   Ao  A  
 L   a   a   L  
 A   A   A   A  
  AaA     AaA   
                
                
|----Layer 4|
                
                
                
  AcA     AcA   
 A T A   A   A  
 C   Cl !C   C  
 A   A   A   A  
  AcA     AcA   
   T       T    
                
|----Layer 5|
                
                
 ^^^^^   ^^^^^  
<IIIII> <IIIII> 
<I   I> <I   I> 
<I   I> <I   I> 
<I   I> <I   I> 
<IIIII> <IIIII> 
 sssss   sssss  
                
|----Layer 6|
                
                
                
 ^^^^^   ^^^^^  
 <III>   <III>  
 <III>   <III>  
 <III>   <III>  
 sssss   sssss  
                
                
|----Layer 7|
                
                
                
                
  <^>     ^^>   
  <I>     <I>   
  ss>     sss   
                
                
                
}}



==== Materials ====

{| class="wikitable sortable mw-collapsible"
|-
! Name !! Total !! Layer 1 !! Layer 2 !! Layer 3 !! Layer 4 !! Layer 5 !! Layer 6 !! Layer 7 
|-
| {{BlockSprite|acacia-door|link=Acacia Door|text=Acacia Door}} || 4 || - || 4 || - || - || - || - || - 
|-
| {{BlockSprite|acacia-fence|link=Acacia Fence|text=Acacia Fence}} || 12 || - || 12 || - || - || - || - || - 
|-
| {{BlockSprite|acacia-log|link=Acacia Log|text=Acacia Log}} || 60 || - || 20 || 16 || 24 || - || - || - 
|-
| {{BlockSprite|acacia-planks|link=Acacia Planks|text=Acacia Planks}} || 74 || 22 || - || - || - || 32 || 18 || 2 
|-
| {{BlockSprite|acacia-stairs|link=Acacia Stairs|text=Acacia Stairs}} || 88 || - || - || - || - || 40 || 32 || 16 
|-
| {{BlockSprite|acacia-wood|link=Acacia Wood|text=Acacia Wood}} || 1 || - || 1 || - || - || - || - || - 
|-
| {{BlockSprite|chest|link=Chest|text=Chest}} || 1 || - || 1 || - || - || - || - || - 
|-
| {{BlockSprite|crafting-table|link=Crafting Table|text=Crafting Table}} || 1 || - || 1 || - || - || - || - || - 
|-
| {{BlockSprite|dirt|link=Dirt|text=Dirt}} || 21 || 21 || - || - || - || - || - || - 
|-
| {{BlockSprite|farmland|link=Farmland|text=Farmland}} || 9 || 9 || - || - || - || - || - || - 
|-
| {{BlockSprite|glass-pane|link=Glass Pane|text=Glass Pane}} || 4 || - || - || 4 || - || - || - || - 
|-
| {{BlockSprite|grass|link=Grass|text=Grass}} || 1 || - || 1 || - || - || - || - || - 
|-
| {{BlockSprite|grass-block|link=Grass Block|text=Grass Block}} || 26 || 26 || - || - || - || - || - || - 
|-
| {{BlockSprite|dirt-path|link=Dirt Path|text=Dirt Path}} || 2 || 2 || - || - || - || - || - || - 
|-
| {{BlockSprite|orange-bed|link=Orange Bed|text=Orange Bed}} || 2 || - || 2 || - || - || - || - || - 
|-
| {{BlockSprite|torch|link=Torch|text=Torch}} || 8 || - || - || 3 || 5 || - || - || - 
|-
| {{BlockSprite|water|link=Water|text=Water}} || 1 || 1 || - || - || - || - || - || - 
|-
| {{BlockSprite|wheat|link=Wheat|text=Wheat}} || 9 || - || 9 || - || - || - || - || - 
|}





[[Category:Village blueprints]]