<noinclude>{{structure info}}</noinclude>

[[File:Taiga Armorer House 1.png|thumb|Armorer House 1 (Taiga)]]



==== Blueprint ====

{{layered blueprint|name=
Taiga Armorer House 1|default=Layer 1
|S=Spruce Log
|G=Grass Block+top
|D=Dirt
|C=Cobblestone
|P=Spruce Planks
|B=Blast Furnace
|O=Poppy
|R=Spruce Trapdoor
|A=Dirt Path+top
|U=Spruce Door+bottom
|E=Spruce Door+top
|L=Glass Pane-rot-90
|W=Wall Torch-rot-180
|T=Wall Torch
|N=Cobblestone Stairs
|o=Cobblestone Wall
         
|----Layer 1|
         
         
  DDDDD  
  DPPPD  
  DPCDD  
  DPCDD  
  DPCDD  
  DPCDD  
  DPPPD  
  DDCDD  
  G A  G 
         
|----Layer 2|
         
         
  CCCCC  
  C   C  
  C  CC  
  C  BC  
  C  BC  
  C  CC  
  C   C  
  CCUCC  
  O    O 
         
|----Layer 3|
         
 S R R S 
 SCCLCCS 
 SC   CS 
 SC  NCS 
 SC  CCS 
 SC  CCS 
 SC  NCS 
 SC   CS 
 SCCECCS 
 S     S 
         
|----Layer 4|
         
  S   S  
  SCCCS  
  S W S  
  S   S  
  S  CS  
  S  CS  
  S   S  
  S T S  
  SCCCS  
  S W S  
         
|----Layer 5|
         
   S S   
   SCS   
   S S   
   S S   
   S C   
   S S   
   S S   
   S S   
   SCS   
   S S   
         
|----Layer 6|
         
    S    
    S    
    S    
    S    
    So   
    S    
    S    
    S    
    S    
    S    
         
|----Layer 7|
         
         
         
         
         
     o   
         
         
         
         
         
         
}}



==== Materials ====

{| class="wikitable sortable mw-collapsible"
|-
! Name !! Total !! Layer 1 !! Layer 2 !! Layer 3 !! Layer 4 !! Layer 5 !! Layer 6 !! Layer 7 
|-
| {{BlockSprite|Blast Furnace|link=Blast Furnace|text=Blast Furnace}} || 2 || - || 2 || - || - || - || - || - 
|-
| {{BlockSprite|Cobblestone|link=Cobblestone|text=Cobblestone}} || 61 || 5 || 23 || 22 || 8 || 3 || - || - 
|-
| {{BlockSprite|Cobblestone Stairs|link=Cobblestone Stairs|text=Cobblestone Stairs}} || 2 || - || - || 2 || - || - || - || - 
|-
| {{BlockSprite|Cobblestone Wall|link=Cobblestone Wall|text=Cobblestone Wall}} || 2 || - || - || - || - || - || 1 || 1 
|-
| {{BlockSprite|Dirt|link=Dirt|text=Dirt}} || 25 || 25 || - || - || - || - || - || - 
|-
| {{BlockSprite|Glass Pane|link=Glass Pane|text=Glass Pane}} || 1 || - || - || 1 || - || - || - || - 
|-
| {{BlockSprite|Grass Block|link=Grass Block|text=Grass Block}} || 2 || 2 || - || - || - || - || - || - 
|-
| {{BlockSprite|Dirt Path|link=Dirt Path|text=Dirt Path}} || 1 || 1 || - || - || - || - || - || - 
|-
| {{BlockSprite|Poppy|link=Poppy|text=Poppy}} || 2 || - || 2 || - || - || - || - || - 
|-
| {{BlockSprite|Spruce Door|link=Spruce Door|text=Spruce Door}} || 1 || - || 1 || - || - || - || - || - 
|-
| {{BlockSprite|Spruce Log|link=Spruce Log|text=Spruce Log}} || 69 || - || - || 20 || 20 || 19 || 10 || - 
|-
| {{BlockSprite|Spruce Planks|link=Spruce Planks|text=Spruce Planks}} || 10 || 10 || - || - || - || - || - || - 
|-
| {{BlockSprite|Spruce Trapdoor|link=Spruce Trapdoor|text=Spruce Trapdoor}} || 2 || - || - || 2 || - || - || - || - 
|-
| {{BlockSprite|Torch|link=Torch|text=Torch}} || 3 || - || - || - || 3 || - || - || - 
|}





[[Category:Village blueprints]]