<noinclude>{{structure info}}</noinclude>

[[File:Desert Fisher 1.png|thumb|Fisher 1 (Desert)]]



==== Blueprint ====

{{layered blueprint|name=Village Desert Houses desert_fisher_1|default=Layer 1
|s=Sand
|S=Smooth Sandstone
|H=Hay Bale
|h=Hay Bale-rot90
|z=Hay Bale+top
|C=Cut Sandstone
|W=Water+top
|F=Potted Dead Bush
|f=Potted Cactus
|d=Jungle Door+bottom
|D=Jungle Door+top
|L=Smooth Sandstone Slab
|T=torch-rot270
|t=torch-rot180
|w=Barrel
|b=Barrel-rot90
|B=Barrel+top
|+=torch
|----Layer 0|
          
 ssssssss 
 ssssssss 
 sCCCssss 
 sCCCssss 
 sssssSSs 
 s ssSSSs 
 s ssSSSs 
 SSSSSSSs 
  sssSSSs 
 s ssssss 
 s        
|----Layer 1|
          
 CCCCC    
 CWWWC    
 CWWWC    
 CWWWCCSC 
 CCCCCSBS 
 F wCS  S 
   fS   S 
    d   S 
  h S bbS 
   zCSSSC 
 H        
|----Layer 2|
          
    FC    
          
 f   C    
      CSC 
 C C CStS 
   BCS  S 
    S   S 
    D   S 
    S +wS 
   HCSSSC 
          
|----Layer 3|
          
     C    
          
     C    
      CSC 
 C C CS S 
    CS  L 
    S   S 
   TS   L 
    S   S 
    CSLSC 
          
|----Layer 4|
          
     C    
          
     C    
      CLC 
 C C CLLL 
    CLLLL 
    LLLLL 
    LLLLL 
    LLLLL 
    CLLLC 
          
|----Layer 5|
          
     C    
     L    
     C    
     L    
 CLCLC    
          
          
          
          
          
          
          
}}



==== Materials ====

{| class="wikitable sortable mw-collapsible"
|-
! Name !! Total !! Layer 0 !! Layer 1 !! Layer 2 !! Layer 3 !! Layer 4 !! Layer 5 
|-
| {{BlockSprite|barrel|link=Barrel|text=Barrel}} || 6 || - || 4 || 2 || - || - || - 
|-
| {{BlockSprite|cut sandstone|link=Sandstone|text=Cut Sandstone}} || 62 || 6 || 21 || 10 || 10 || 10 || 5 
|-
| {{BlockSprite|hay bale|link=Hay Bale|text=Hay Bale}} || 4 || - || 3 || 1 || - || - || - 
|-
| {{ItemSprite|jungle door|link=Door|text=Jungle Door}} || 1 || - || 1 || - || - || - || - 
|-
| {{BlockSprite|potted cactus|link=Flower Pot|text=Potted Cactus}} || 2 || - || 1 || 1 || - || - || - 
|-
| {{BlockSprite|potted dead bush|link=Flower Pot|text=Potted Dead Bush}} || 2 || - || 1 || 1 || - || - || - 
|-
| {{BlockSprite|sand|link=Sand|text=Sand}} || 53 || 53 || - || - || - || - || - 
|-
| {{BlockSprite|smooth sandstone|link=Sandstone|text=Smooth Sandstone}} || 55 || 18 || 13 || 13 || 11 || - || - 
|-
| {{BlockSprite|smooth sandstone slab|link=Slab|text=Smooth Sandstone Slab}} || 33 || - || - || - || 3 || 26 || 4 
|-
| {{BlockSprite|torch|link=Torch|text=Torch}} || 3 || - || - || 2 || 1 || - || - 
|-
| {{BlockSprite|water|link=Water|text=Water}} || 9 || - || 9 || - || - || - || - 
|}





[[Category:Village blueprints]]