<noinclude>{{structure info}}</noinclude>

[[File:Desert Meeting Point 2.png|thumb|Meeting point 2 (Desert)]]



==== Blueprint ====

{{layered blueprint|name=Desert Meeting Point 2
|default=Layer 1
|S=Smooth Sandstone
|A=Sand
|C=Cut Sandstone
|M=Smooth Sandstone Slab
|p=Double Smooth Sandstone Slab
|B=Bell
|W=Water+top
|T=Torch
              
|----Layer 0|
              
      SSS     
  SSSSSSSSSS  
  SSSSSSSSSS  
  SSAAAAAASS  
 SSSAAAAAASS  
 SSSAAAAAASSS 
 SSSAAAAAASSS 
  SSAAAAAASSS 
  SSAAAAAASS  
  SSSSSSSSSS  
  SSSSSSSSSS  
     SSS      
              
|----Layer 1|
              
              
              
              
    SSSSSS    
    SCWWCS    
    SWWWWS    
    SWWWWS    
    SCWWCS    
  B SSSSSS    
              
              
              
|----Layer 2-3|
              

              
              
              
     C  C     
              
              
     C  C     
              
              
              
              
|----Layer 4|
              
              
              
              
              
     CMMC     
     MppM     
     MppM     
     CMMC     
              
              
              
              
              
|----Layer 5|
              
              
              
              
              
     T  T     
              
              
     T  T     
              
              
              
              
              
}}



==== Materials ====

{| class="wikitable sortable mw-collapsible"
|-
! Name !! Total !! Layer 0 !! Layer 1 !! Layer 2 !! Layer 3 !! Layer 4 !! Layer 5 
|-
| {{BlockSprite|Bell|link=Bell|text=Bell}} || 1 || - || 1 || - || - || - || - 
|-
| {{BlockSprite|Cut Sandstone|link=Sandstone|text=Cut Sandstone}} || 16 || - || 4 || 4 || 4 || 4 || - 
|-
| {{BlockSprite|Sand|link=Sand|text=Sand}} || 36 || 36 || - || - || - || - || - 
|-
| {{BlockSprite|Smooth Sandstone|link=Sandstone|text=Smooth Sandstone}} || 96 || 76 || 20 || - || - || - || - 
|-
| {{BlockSprite|Smooth Sandstone Slab|link=Slab|text=Smooth Sandstone Slab}} || 16 || - || - || - || - || 16 || - 
|-
| {{BlockSprite|Torch|link=Torch|text=Torch}} || 4 || - || - || - || - || - || 4 
|-
| {{BlockSprite|Water|link=Water|text=Water}} || 12 || - || 12 || - || - || - || - 
|}





[[Category:Village blueprints]]