<noinclude>{{structure info}}</noinclude>

[[File:Plains Meeting Point 2.png|thumb|Meeting point 2 (Plains)]]



==== Blueprint ====

{{layered blueprint
|name=Meeting Point 2 meeting_point_2
|default=Layer 2
|p=Dirt Path+top
|g=Grass Block+top
|G=Grass
|d=Dirt
|o=Oak Planks
|s=Oak Slab
|f=Oak Fence
|t=Torch
|w=White Wool
|y=Yellow Wool
|b=Bell
                 
|----Layer 0|
                 
 ggppggggggggggg 
 pgpppggggggggpp 
 ppppgddddgdgppp 
 pppgpggpgpppppg 
 gdgpppppgpgggdg 
 gdppppgppgpgpdg 
 gdppgpgppggppdg 
 gdgpppppppgpgdg 
                 
|----Layer 1|
                 
         G       
      f Gf   G   
      oooo o     
      f  f       
 fof       GGfof 
  o           o  
  o           o  
 fof         fof 
                 
|----Layer 2|
                 
                 
      f  f       
      t  t b     
      f  f       
 ftf         ftf 
                 
                 
 ftf         ftf 
                 
|----Layer 3|
                 
                 
      f  f       
                 
      f  f       
 f f         f f 
                 
                 
 f f         f f 
                 
|----Layer 4|
                 
                 
      syws       
      swys       
      syws       
 sss         sss 
 ywy         ywy 
 wyw         wyw 
 sss         sss 
                 
}}

All oak slabs are bottom slabs.



==== Materials ====

{| class="wikitable sortable mw-collapsible"
|-
! Name !! Total !! Layer 0 !! Layer 1 !! Layer 2 !! Layer 3 !! Layer 4 
|-
| {{BlockSprite|bell|link=Bell|text=Bell}} || 1 || - || - || 1 || - || - 
|-
| {{BlockSprite|dirt|link=Dirt|text=Dirt}} || 13 || 13 || - || - || - || - 
|-
| {{BlockSprite|dirt path|link=Dirt Path|text=Dirt Path}} || 53 || 53 || - || - || - || - 
|-
| {{BlockSprite|grass|link=Grass|text=Grass}} || 5 || - || 5 || - || - || - 
|-
| {{BlockSprite|grass block|link=Grass Block|text=Grass Block}} || 54 || 54 || - || - || - || - 
|-
| {{BlockSprite|oak fence|link=Fence|text=Oak Fence}} || 36 || - || 12 || 12 || 12 || - 
|-
| {{BlockSprite|oak planks|link=Planks|text=Oak Planks}} || 13 || - || 13 || - || - || - 
|-
| {{BlockSprite|oak slab|link=Slab|text=Oak Slab}} || 18 || - || - || - || - || 18 
|-
| {{BlockSprite|torch|link=Torch|text=Torch}} || 6 || - || - || 6 || - || - 
|-
| {{BlockSprite|white wool|link=Wool|text=White Wool}} || 9 || - || - || - || - || 9 
|-
| {{BlockSprite|yellow wool|link=Wool|text=Yellow Wool}} || 9 || - || - || - || - || 9 
|}





[[Category:Village blueprints]]