<noinclude>{{structure info}}</noinclude>

[[File:Taiga Fisher Cottage 1.png|thumb|Fisher Cottage 1 (Taiga)]]



==== Blueprint ====

{{layered blueprint|name=
Taiga Fisher Cottage 1|default=Layer 1
|D=Dirt
|S=Sand
|G=Gravel
|R=Grass Block+top
|P=Spruce Planks
|U=Spruce Log-rot-90
|C=Spruce Log+top
|E=Spruce Log
|L=Clay
|O=Cobblestone
|B=Barrel
|W=Water+top
|A=Large Fern
|b=Large Fern+bottom
|T=Spruce Trapdoor
|H=Wall Torch-rot-90
|p=Spruce Door+bottom
|r=Spruce Door+top
|F=Spruce Fence
|a=Wall Torch-rot-270
|N=Fern
|s=Dirt Path+top
|Y=Poppy
              
|----Layer 1|
              
 DGSSSSSSRRRD 
 GGGGRRRSRRRR 
 GGGGRSRLRDRR 
 GGGGGLLDDDDD 
 SGGGDLDDDDRD 
 SGGGDDDDDDRR 
 DGDDDDDDDDDR 
 DDDDDDDDDDDR 
 DDDDDDDDRDDR 
 DRDDRDDRDRRR 
              
|----Layer 2|
              
 RRRRDRRR   R 
 RDRWWWWR     
 RDWWWCWR D   
 RWWWCODDDDDR 
 RWWWWOOPOD R 
 RWPPPOOPOOss 
 RWWWWOOPODR  
 RWWWCDDDDDD  
 RRWWRD   DR  
 R RR RR R    
              
|----Layer 3|
              
     B        
  B           
      C   C   
     COOOOOCb 
     TOWWWO   
      pTTTp   
     TOF  OY  
     COOOOOC  
  b   C   Cb  
       b N    
              
|----Layer 4|
              
              
              
      C   C   
     COOOOOCA 
     HO  HOa  
      r   r   
     HOT HOa  
     COOOOOC  
  A   C   CA  
       A      
              
|----Layer 5|
              
              
              
    UUUUUUUUU 
     COOOOOC  
      O   O   
      O   O   
      O   O   
     COOOOOC  
    UUUUUUUUU 
              
              
|----Layer 6|
              
              
              
              
    UUUUUUUUU 
     EO   O   
     EOa  F   
     EO   O   
    UUUUUUUUU 
              
              
              
|----Layer 7|
              
              
              
              
              
    UUUUUUUUU 
      O   O   
    UUUUUUUUU 
              
              
              
              
|----Layer 8|
              
              
              
              
              
              
    UUUUUUUUU 
              
              
              
              
              
}}



==== Materials ====

{| class="wikitable sortable mw-collapsible"
|-
! Name !! Total !! Layer 1 !! Layer 2 !! Layer 3 !! Layer 4 !! Layer 5 !! Layer 6 !! Layer 7 !! Layer 8 
|-
| {{BlockSprite|Barrel|link=Barrel|text=Barrel}} || 2 || - || - || 2 || - || - || - || - || - 
|-
| {{BlockSprite|Clay|link=Clay|text=Clay}} || 4 || 4 || - || - || - || - || - || - || - 
|-
| {{BlockSprite|Cobblestone|link=Cobblestone|text=Cobblestone}} || 62 || - || 11 || 14 || 14 || 16 || 5 || 2 || - 
|-
| {{BlockSprite|Dirt|link=Dirt|text=Dirt}} || 76 || 57 || 19 || - || - || - || - || - || - 
|-
| {{BlockSprite|Fern|link=Fern|text=Fern}} || 1 || - || - || 1 || - || - || - || - || - 
|-
| {{BlockSprite|Grass Block|link=Grass Block|text=Grass Block}} || 59 || 28 || 31 || - || - || - || - || - || - 
|-
| {{BlockSprite|Dirt Path|link=Dirt Path|text=Dirt Path}} || 2 || - || 2 || - || - || - || - || - || - 
|-
| {{BlockSprite|Gravel|link=Gravel|text=Gravel}} || 21 || 21 || - || - || - || - || - || - || - 
|-
| {{BlockSprite|Large Fern|link=Large Fern|text=Large Fern}} || 8 || - || - || 4 || 4 || - || - || - || - 
|-
| {{BlockSprite|Poppy|link=Poppy|text=Poppy}} || 1 || - || - || 1 || - || - || - || - || - 
|-
| {{BlockSprite|Sand|link=Sand|text=Sand}} || 10 || 10 || - || - || - || - || - || - || - 
|-
| {{BlockSprite|Spruce Door|link=Spruce Door|text=Spruce Door}} || 2 || - || - || 2 || - || - || - || - || - 
|-
| {{BlockSprite|Spruce Fence|link=Spruce Fence|text=Spruce Fence}} || 2 || - || - || 1 || - || - || 1 || - || - 
|-
| {{BlockSprite|Spruce Log|link=Spruce Log|text=Spruce Log}} || 89 || - || 3 || 8 || 8 || 22 || 21 || 18 || 9 
|-
| {{BlockSprite|Spruce Planks|link=Spruce Planks|text=Spruce Planks}} || 6 || - || 6 || - || - || - || - || - || - 
|-
| {{BlockSprite|Spruce Trapdoor|link=Spruce Trapdoor|text=Spruce Trapdoor}} || 6 || - || - || 5 || 1 || - || - || - || - 
|-
| {{BlockSprite|Torch|link=Torch|text=Torch}} || 7 || - || - || - || 6 || - || 1 || - || - 
|-
| {{BlockSprite|Water|link=Water|text=Water}} || 28 || - || 25 || 3 || - || - || - || - || - 
|}





[[Category:Village blueprints]]