<noinclude>{{structure info}}</noinclude>

[[File:Savanna Butchers Shop 2.png|thumb|Butchers Shop 2 (Savanna)]]



==== Blueprint ====

{{layered blueprint|name=
Savanna Butchers Shop 2|default=Layer 1
|G=Grass Block+top
|A=Acacia Planks
|C=Acacia Wood
|D=Dirt
|S=Smoker
|H=Chest-rot-270
|R=Grass
|I=Acacia Fence
|T=Torch
|c=Acacia Stairs
|L=Glass Pane
|B=Acacia Slab
|W=Wall Torch-rot-180
|O=Acacia Door+bottom
|a=Acacia Door+top
|l=Wall Torch
           
|----Layer 1|
           
 GGGGGGGGG 
 GGGGGGGGG 
 GGGGGGDGG 
 GGGGGGGGG 
 GGGGGGGGG 
 GGGGGGGGG 
 GGGGGGGGG 
 GGGGGGGGG 
 GGGGGGGGG 
 GGGGGGG G 
 GGGGGGG R 
 GGGDDDG R 
 GGGDDDGR  
           
|----Layer 2|
           
 IIIIIIIII 
 I RR RR I 
 IR RRRcRI 
 IR R RBRI 
 IR  RI RI 
 IRI I I I 
 I    RRRI 
 IR RT RRI 
 III I III 
  RI   I   
  RI   I   
 R IAAAI   
  RRcccR   
           
|----Layer 3|
           
 T       T 
           
           
       c   
      IB   
   I I I   
           
           
   I I I T 
           
    BBB    
    ccc    
           
           
|----Layer 4|
           
           
           
           
           
    BBc    
   AACAA   
   AAAAA   
   AAAAA   
   AACAA   
    AAA    
    ccc    
           
           
           
|----Layer 5|
           
           
           
           
           
    S      
   CCOCC   
   Cc HC   
   Cc  C   
   CCOCC   
           
           
           
           
           
|----Layer 6|
           
           
           
           
           
           
   CCaCC   
   L   L   
   L   L   
   CCaCC   
    W W    
           
           
           
           
|----Layer 7|
           
           
           
           
           
     l     
   CCCCC   
   C W C   
   C   C   
   CCCCC   
           
           
           
           
           
|----Layer 8|
           
           
           
           
           
   ccccc   
  cAAAAAc  
  cA   Ac  
  cA   Ac  
  cAAAAAc  
   ccccc   
           
           
           
           
|----Layer 9|
           
           
           
           
           
           
   ccccc   
   cAAAc   
   cAAAc   
   ccccc   
           
           
           
           
           
}}



==== Materials ====

{| class="wikitable sortable mw-collapsible"
|-
! Name !! Total !! Layer 1 !! Layer 2 !! Layer 3 !! Layer 4 !! Layer 5 !! Layer 6 !! Layer 7 !! Layer 8 !! Layer 9 
|-
| {{BlockSprite|acacia-door|link=Acacia Door|text=Acacia Door}} || 2 || - || - || - || - || 2 || - || - || - || - 
|-
| {{BlockSprite|acacia-fence|link=Acacia Fence|text=Acacia Fence}} || 47 || - || 40 || 7 || - || - || - || - || - || - 
|-
| {{BlockSprite|acacia-planks|link=Acacia Planks|text=Acacia Planks}} || 44 || - || 3 || - || 21 || - || - || - || 14 || 6 
|-
| {{BlockSprite|acacia-slab|link=Acacia Slab|text=Acacia Slab}} || 7 || - || 1 || 4 || 2 || - || - || - || - || - 
|-
| {{BlockSprite|acacia-stairs|link=Acacia Stairs|text=Acacia Stairs}} || 46 || - || 4 || 4 || 4 || 2 || - || - || 18 || 14 
|-
| {{BlockSprite|acacia-wood|link=Acacia Wood|text=Acacia Wood}} || 36 || - || - || - || 2 || 12 || 8 || 14 || - || - 
|-
| {{BlockSprite|chest|link=Chest|text=Chest}} || 1 || - || - || - || - || 1 || - || - || - || - 
|-
| {{BlockSprite|dirt|link=Dirt|text=Dirt}} || 7 || 7 || - || - || - || - || - || - || - || - 
|-
| {{BlockSprite|glass-pane|link=Glass Pane|text=Glass Pane}} || 4 || - || - || - || - || - || 4 || - || - || - 
|-
| {{BlockSprite|grass|link=Grass|text=Grass}} || 33 || 3 || 30 || - || - || - || - || - || - || - 
|-
| {{BlockSprite|grass-block|link=Grass Block|text=Grass Block}} || 103 || 103 || - || - || - || - || - || - || - || - 
|-
| {{BlockSprite|smoker|link=Smoker|text=Smoker}} || 1 || - || - || - || - || 1 || - || - || - || - 
|-
| {{BlockSprite|torch|link=Torch|text=Torch}} || 8 || - || 1 || 3 || - || - || 2 || 2 || - || - 
|}





[[Category:Village blueprints]]