<noinclude>{{structure info}}</noinclude>

[[File:Desert Tannery 1.png|thumb|Tannery 1 (Desert)]]



==== Blueprint ====

{{layered blueprint|name=Desert Tannery 1
|default=Layer 1
|S=Sand
|M=Smooth Sandstone
|C=Cut Sandstone
|T=Terracotta
|P=Potted Cactus
|W=Wall Torch-rot180
|J=Jungle Door+bottom
|U=Jungle Door+top
|A=Wall Torch-rot270
|L=Wall Torch-rot90
|w=Water Cauldron
|O=Smooth Sandstone Stairs-rot270
|H=Smooth Sandstone Slab+bottom
|N=Sandstone Slab+top
|----Layer -1|
 SSSSSSS 
 SSSSSSS 
 SSSSSSS 
 SSSSSSS 
 SSSSSSS 
 SSSSSSS 
         
|----Layer 0|
         
 SSSSSSS 
  SSMMMS 
  MMMMMS 
  M M MS 
  MMMMMS 
 MMMMMMM 
         
|----Layer 1|
         
 MMMMMMM 
 MMMO wM 
 M     M 
 MJMJMJM 
 M     M 
 M M M M 
         
|----Layer 2|
         
 MMMMMMM 
 MMO  AM 
 M     M 
 MUMUMUM 
 M W W M 
 M M M M 
         
|----Layer 3|
         
 CCCCCCC 
 CO   MM 
 CMMMMMM 
 CMMMMMM 
 CMMMMMM 
 CCCCCCC 
         
|----Layer 4|
         
 MHMHMHM 
 M     M 
 M     M 
 MMJMJMM 
      P  
  P      
         
|----Layer 5|
         
 MNMNMNM 
 M     M 
 ML   AM 
 MMUMUMM 
  W   W  
         
|----Layer 6|
         
 CMMMMMM 
 C     M 
 C     M 
 CCCCCCC 
         
|----Layer 7|
         
 TMTMTMT 
 MMMMMMM 
 MMMMMMM 
 TMTMTMT 
         
|----Layer 8|
         
  TMTMT  
  M   M  
  M   M  
  TMTMT  
         
}}



==== Materials ====

{| class="wikitable sortable mw-collapsible"
|-
! Name !! Total !! Layer -1 !! Layer 0 !! Layer 1 !! Layer 2 !! Layer 3 !! Layer 4 !! Layer 5 !! Layer 6 !! Layer 7 !! Layer 8 
|-
| {{BlockSprite|Cut Sandstone|link=Sandstone|text=Cut Sandstone}} || 28 || - || - || - || - || 18 || - || - || 10 || - || - 
|-
| {{ItemSprite|Jungle Door|link=Door|text=Jungle Door}} || 5 || - || - || 3 || - || - || 2 || - || - || - || - 
|-
| {{BlockSprite|Potted Cactus|link=Flower Pot|text=Potted Cactus}} || 2 || - || - || - || - || - || 2 || - || - || - || - 
|-
| {{BlockSprite|Sand|link=Sand|text=Sand}} || 55 || 42 || 13 || - || - || - || - || - || - || - || - 
|-
| {{BlockSprite|Sandstone Slab|link=Slab|text=Sandstone Slab}} || 3 || - || - || - || - || - || - || 3 || - || - || - 
|-
| {{BlockSprite|Smooth Sandstone|link=Sandstone|text=Smooth Sandstone}} || 150 || - || 23 || 23 || 22 || 20 || 13 || 13 || 8 || 20 || 8 
|-
| {{BlockSprite|Smooth Sandstone Slab|link=Slab|text=Smooth Sandstone Slab}} || 3 || - || - || - || - || - || 3 || - || - || - || - 
|-
| {{BlockSprite|Smooth Sandstone Stairs|link=Stairs|text=Smooth Sandstone Stairs}} || 3 || - || - || 1 || 1 || 1 || - || - || - || - || - 
|-
| {{BlockSprite|Terracotta|link=Terracotta|text=Terracotta}} || 14 || - || - || - || - || - || - || - || - || 8 || 6 
|-
| {{BlockSprite|Torch|link=Torch|text=Torch}} || 7 || - || - || - || 3 || - || - || 4 || - || - || - 
|-
| {{BlockSprite|Water Cauldron|link=Cauldron|text=Water Cauldron}} || 1 || - || - || 1 || - || - || - || - || - || - || - 
|}





[[Category:Village blueprints]]