<noinclude>{{structure info}}</noinclude>

[[File:Savanna Tool Smith 1.png|thumb|Tool Smith 1 (Savanna)]]



==== Blueprint ====

{{layered blueprint|name=
Savanna Tool Smith 1|default=Layer 1
|G=Grass Block+top
|A=Acacia Planks
|D=Dirt
|C=Acacia Log+top
|I=Acacia Log
|S=Smithing Table
|B=Brown Wall Banner
|R=Grass
|F=Acacia Fence
|L=Acacia Slab
|O=Acacia Door+bottom
|c=Acacia Door+top
|T=Acacia Stairs
|P=Dirt Path+top
|N=Glass Pane-rot-90
|W=Wall Torch-rot-180
             
|----Layer 1|
             
 GGGGGGGGGGG 
 GGGGDDDGGGG 
 GGGDAAADGGG 
 GGGAAAAAGGG 
 GGGDAAADGGG 
 GGGGDADGGGG 
 GGGGDPGGGGG 
             
|----Layer 2|
             
     RRRR  R 
   R CCCRRRR 
  FRCTSTCRFR 
  R O   OR R 
  F C   CRF  
    RCOCR RR 
 R  R   RRR  
             
|----Layer 3|
             
             
     CNC     
  F C   C F  
    c   c    
  F C   C F  
     CcC     
             
             
|----Layer 4|
             
             
     CIC     
  F C W C F  
    I   I    
  F C   C F  
     CIC     
      W      
             
|----Layer 5|
             
    TTTTT    
  BBAAAAABB  
 BAAA   AAAB 
 BALA   ALAB 
 BAAA   AAAB 
  BBAAAAABB  
    TTTTT    
             
|----Layer 6|
             
             
    TTTTT    
    TAAAT    
    TAAAT    
    TAAAT    
    TTTTT    
             
             
|----Layer 7|
             
             
             
     TTT     
     TAT     
     TTT     
             
             
             
}}



==== Materials ====

{| class="wikitable sortable mw-collapsible"
|-
! Name !! Total !! Layer 1 !! Layer 2 !! Layer 3 !! Layer 4 !! Layer 5 !! Layer 6 !! Layer 7 
|-
| {{BlockSprite|acacia-door|link=Acacia Door|text=Acacia Door}} || 3 || - || 3 || - || - || - || - || - 
|-
| {{BlockSprite|acacia-fence|link=Acacia Fence|text=Acacia Fence}} || 12 || - || 4 || 4 || 4 || - || - || - 
|-
| {{BlockSprite|acacia-log|link=Acacia Log|text=Acacia Log}} || 29 || - || 9 || 8 || 12 || - || - || - 
|-
| {{BlockSprite|acacia-planks|link=Acacia Planks|text=Acacia Planks}} || 48 || 12 || - || - || - || 26 || 9 || 1 
|-
| {{BlockSprite|acacia-slab|link=Acacia Slab|text=Acacia Slab}} || 2 || - || - || - || - || 2 || - || - 
|-
| {{BlockSprite|acacia-stairs|link=Acacia Stairs|text=Acacia Stairs}} || 36 || - || 2 || - || - || 10 || 16 || 8 
|-
| {{BlockSprite|brown-wall-banner|link=Brown Wall Banner|text=Brown Wall Banner}} || 14 || - || - || - || - || 14 || - || - 
|-
| {{BlockSprite|dirt|link=Dirt|text=Dirt}} || 10 || 10 || - || - || - || - || - || - 
|-
| {{BlockSprite|glass-pane|link=Glass Pane|text=Glass Pane}} || 1 || - || - || 1 || - || - || - || - 
|-
| {{BlockSprite|grass|link=Grass|text=Grass}} || 26 || - || 26 || - || - || - || - || - 
|-
| {{BlockSprite|grass-block|link=Grass Block|text=Grass Block}} || 54 || 54 || - || - || - || - || - || - 
|-
| {{BlockSprite|dirt-path|link=Dirt Path|text=Dirt Path}} || 1 || 1 || - || - || - || - || - || - 
|-
| {{BlockSprite|smithing-table|link=Smithing Table|text=Smithing Table}} || 1 || - || 1 || - || - || - || - || - 
|-
| {{BlockSprite|torch|link=Torch|text=Torch}} || 2 || - || - || - || 2 || - || - || - 
|}





[[Category:Village blueprints]]