<noinclude>{{structure info}}</noinclude>

[[File:Snowy Tundra Tool Smith 1.png|thumb|Tool smith 1 (Snowy tundra)]]



==== Blueprint ====

{{layered blueprint
|name=Snowy Tool Smith 1 snowy_tool_smith_1
|default=Layer 2
|S=Snow
|s=Spruce Slab
|w=Spruce Slab+top
|l=Stripped Spruce Log+top
|a=Stripped Spruce Log
|A=Stripped Spruce Log-rot90
|L=Lantern
|i=Smithing Table-rot270
|o=Spruce Door+bottom
|O=Spruce Door+top
|p=Spruce Planks
|x=Spruce Stairs-rot90
|y=Spruce Stairs
|z=Spruce Stairs-rot270
         
|----Layer 1|
         
 SSSSSSS 
 SlllllS 
 SlppplS 
 SlppplS 
 SlllplS 
 SSSlplS 
 SSSlllS 
 SSSxyzS 
         
|----Layer 2|
         
         
  lllll  
  li  l  
  lp  l  
  lll l  
    l l  
    lol  
         
|----Layer 3|
         
 p     p 
 plllllp 
 pl   lp 
 plL  lp 
 plll lp 
 pppl lp 
   plOlp 
   p   p 
         
|----Layer 4|
         
 p     p 
 plaAalp 
 pa   ap 
 pA   Ap 
 plAa ap 
 pppA Ap 
   plalp 
   p   p 
         
|----Layer 5|
         
 sp   ps 
 splllps 
 sp   ps 
 sp   ps 
 sppp ps 
 syyp ps 
   xplps 
   sp ps 
         
|----Layer 6|
         
  p   p  
  plllp  
  p   p  
  p  Lp  
  ppp p  
    p p  
    plp  
    p p  
         
|----Layer 7|
         
  spwps  
  splps  
  sppps  
  sppps  
  syyps  
    xps  
    sps  
    sps  
         
|----Layer 8|
         
    p    
    p    
    p    
         
}}

The spruce slab on the top row, the middle column in layer 7 is top slab, while the rest are bottom slabs.



==== Materials ====

{| class="wikitable sortable mw-collapsible"
|-
! Name !! Total !! Layer 1 !! Layer 2 !! Layer 3 !! Layer 4 !! Layer 5 !! Layer 6 !! Layer 7 !! Layer 8 
|-
| {{BlockSprite|lantern|link=Lantern|text=Lantern}} || 2 || - || - || 1 || - || - || 1 || - || - 
|-
| {{BlockSprite|smithing-table|link=Smithing Table|text=Smithing Table}} || 1 || - || 1 || - || - || - || - || - || - 
|-
| {{BlockSprite|snow|link=Snow|text=Snow}} || 28 || 28 || - || - || - || - || - || - || - 
|-
| {{ItemSprite|spruce-door|link=Door|text=Spruce Door}} || 1 || - || 1 || - || - || - || - || - || - 
|-
| {{BlockSprite|spruce-planks|link=Planks|text=Spruce Planks}} || 98 || 8 || 1 || 18 || 18 || 18 || 18 || 14 || 3 
|-
| {{BlockSprite|spruce-slab|link=Slab|text=Spruce Slab}} || 31 || - || - || - || - || 15 || - || 16 || - 
|-
| {{BlockSprite|spruce-stairs|link=Stairs|text=Spruce Stairs}} || 9 || 3 || - || - || - || 3 || - || 3 || - 
|-
| {{BlockSprite|stripped-spruce-log|link=Log|text=Stripped Spruce Log}} || 79 || 18 || 17 || 17 || 18 || 4 || 4 || 1 || - 
|}





[[Category:Village blueprints]]