<noinclude>{{structure info}}</noinclude>

[[File:Taiga Medium House 2.png|thumb|Medium House 2 (Taiga)]]



==== Blueprint ====

{{layered blueprint|name=
Taiga Medium House 2|default=Layer 1
|D=Dirt
|G=Grass Block+top
|S=Spruce Log-rot-90
|P=Spruce Planks
|R=Spruce Log
|C=Cobblestone
|A=Crafting Table
|U=Purple Bed+top+head-rot-270
|L=Purple Bed+top+foot-rot-270
|H=Chest
|B=Blue Bed+top+foot-rot-90
|E=Blue Bed+top+head-rot-90
|T=Dirt Path+top
|W=Wall Torch-rot-90
|O=Spruce Door+bottom
|I=Spruce Stairs
|p=Spruce Door+top
|r=Spruce Stairs-rot-180
|u=Spruce Trapdoor
|N=Glass Pane
|a=Wall Torch-rot-270
|l=Wall Torch
|o=Wall Torch-rot-180
          
|----Layer 1|
          
 TDG      
 GGGDDDD  
 DDDDCCD  
 TPPCCCD  
  DDDCCD  
    DDDD  
          
          
|----Layer 2|
          
  Ir      
    CCCC  
  PPC EC  
  O O BC  
  PPC AC  
    CCCC  
          
          
|----Layer 3|
          
   Ir     
 SSSCCCCu 
  PPC  N  
  p p  Cu 
  PPC  N  
 SSSCCCCu 
          
          
|----Layer 4|
          
    Ir    
    CCCC  
 SSSC  C  
 WPWCa C  
 SSSC  C  
    CCCC  
          
          
|----Layer 5|
          
     IP   
    CCCC  
    CPPC  
 SSSCPPC  
    CPPC  
    CCCC  
          
          
|----Layer 6|
          
          
    CCOC  
    CH C  
    CL C  
    CU C  
    CCCC  
          
          
|----Layer 7|
          
     l    
   uCCpCu 
    N  N  
   uC  Cu 
    N  N  
   uCCCCu 
          
          
|----Layer 8|
          
          
    CCCC  
    C  C  
    C  C  
    C  C  
    CCCC  
          
          
|----Layer 9|
          
   R    R 
   RCCCCR 
   RC  CR 
   RC  CR 
   RC  CR 
   RCCCCR 
   R    R 
          
|----Layer 10|
          
    R  R  
    RCCR  
    RooR  
    R  R  
    RllR  
    RCCR  
    R  R  
          
|----Layer 11|
          
     RR   
     RR   
     RR   
     RR   
     RR   
     RR   
     RR   
          
}}



==== Materials ====

{| class="wikitable sortable mw-collapsible"
|-
! Name !! Total !! Layer 1 !! Layer 2 !! Layer 3 !! Layer 4 !! Layer 5 !! Layer 6 !! Layer 7 !! Layer 8 !! Layer 9 !! Layer 10 !! Layer 11 
|-
| {{BlockSprite|Blue Bed|link=Blue Bed|text=Blue Bed}} || 1 || - || 1 || - || - || - || - || - || - || - || - || - 
|-
| {{BlockSprite|Chest|link=Chest|text=Chest}} || 1 || - || - || - || - || - || 1 || - || - || - || - || - 
|-
| {{BlockSprite|Cobblestone|link=Cobblestone|text=Cobblestone}} || 113 || 7 || 13 || 11 || 14 || 14 || 13 || 9 || 14 || 14 || 4 || - 
|-
| {{BlockSprite|Crafting Table|link=Crafting Table|text=Crafting Table}} || 1 || - || 1 || - || - || - || - || - || - || - || - || - 
|-
| {{BlockSprite|Dirt|link=Dirt|text=Dirt}} || 19 || 19 || - || - || - || - || - || - || - || - || - || - 
|-
| {{BlockSprite|Glass Pane|link=Glass Pane|text=Glass Pane}} || 6 || - || - || 2 || - || - || - || 4 || - || - || - || - 
|-
| {{BlockSprite|Grass Block|link=Grass Block|text=Grass Block}} || 4 || 4 || - || - || - || - || - || - || - || - || - || - 
|-
| {{BlockSprite|Dirt Path|link=Dirt Path|text=Dirt Path}} || 2 || 2 || - || - || - || - || - || - || - || - || - || - 
|-
| {{BlockSprite|Purple Bed|link=Purple Bed|text=Purple Bed}} || 1 || - || - || - || - || - || 1 || - || - || - || - || - 
|-
| {{BlockSprite|Spruce Door|link=Spruce Door|text=Spruce Door}} || 3 || - || 2 || - || - || - || 1 || - || - || - || - || - 
|-
| {{BlockSprite|Spruce Log|link=Spruce Log|text=Spruce Log}} || 57 || - || - || 6 || 6 || 3 || - || - || - || 14 || 14 || 14 
|-
| {{BlockSprite|Spruce Planks|link=Spruce Planks|text=Spruce Planks}} || 18 || 2 || 4 || 4 || 1 || 7 || - || - || - || - || - || - 
|-
| {{BlockSprite|Spruce Stairs|link=Spruce Stairs|text=Spruce Stairs}} || 7 || - || 2 || 2 || 2 || 1 || - || - || - || - || - || - 
|-
| {{BlockSprite|Spruce Trapdoor|link=Spruce Trapdoor|text=Spruce Trapdoor}} || 9 || - || - || 3 || - || - || - || 6 || - || - || - || - 
|-
| {{BlockSprite|Torch|link=Torch|text=Torch}} || 8 || - || - || - || 3 || - || - || 1 || - || - || 4 || - 
|}





[[Category:Village blueprints]]