<noinclude>{{structure info}}</noinclude>

[[File:Snowy Tundra Butchers Shop 1.png|thumb|Butchers shop 1 (Snowy tundra)]]



==== Blueprint ====

{{layered blueprint
|name=Snowy Butchers Shop 1 snowy_butchers_shop_1
|default=Layer 2
|w=Stripped Spruce Wood
|p=Spruce Planks
|f=Spruce Fence
|o=Spruce Door+bottom
|O=Spruce Door+top
|S=Snow
|m=Smoker
|C=Cobblestone
|c=Cobblestone Wall
|s=Spruce Slab
|v=Spruce Slab+top
|l=Lantern
|g=Grass Block+top
|G=Glass Pane
|A=Smooth Stone
|a=Smooth Stone Slab+top
|x=Spruce Stairs-rot90
|y=Spruce Stairs
|z=Spruce Stairs-rot270
         
|----Layer 1|
         
 SwwwwwS 
 SwgggwS 
 SwgggwS 
 SwwwwwS 
 SwpaawS 
 SwCa wS 
 SwpaawS 
 SwwwwwS 
 SSxyzSS 
         
|----Layer 2|
         
  fffff  
  f   f  
 vfS Sfv 
 pwwowwp 
 vwm  wv 
 pw  Awp 
 vw   wv 
 pwwowwp 
 v     v 
         
|----Layer 3|
         
         
         
 pv   vp 
 pwwOwwp 
 pwc  wp 
 pw   wp 
 pw   wp 
 pwwOwwp 
 p     p 
         
|----Layer 4|
         
         
    l    
 sp   ps 
 SpwwwpS 
 spc  ps 
 SG   GS 
 sp   ps 
 SpwwwpS 
 sp   ps 
         
|----Layer 5|
         
         
    f    
  pvfvp  
  pwwwp  
  pcl p  
  p   p  
  p l p  
  pwwwp  
  pvlvp  
         
|----Layer 6|
         
         
         
  SpvpS  
  SpwpS  
   CfpS  
  sp ps  
  SpfpS  
  SpwpS  
  SpppS  
         
|----Layer 7|
         
         
         
   SpS   
   SpS   
   cpS   
   SpS   
   SpS   
   SpS   
   SpS   
         
|----Layer 8|
         
         
         
    S    
    S    
   cS    
    S    
    S    
    S    
    S    
         
}}

The spruce slabs in layer 4 and 2 spruce slabs in layer 6 are all bottom slabs. The other spruce slabs and the smooth stone slabs in layer 1 are all top slabs.



==== Materials ====

{| class="wikitable sortable mw-collapsible"
|-
! Name !! Total !! Layer 1 !! Layer 2 !! Layer 3 !! Layer 4 !! Layer 5 !! Layer 6 !! Layer 7 !! Layer 8 
|-
| {{BlockSprite|cobblestone|link=Cobblestone|text=Cobblestone}} || 2 || 1 || - || - || - || - || 1 || - || - 
|-
| {{BlockSprite|cobblestone-wall|link=Wall|text=Cobblestone Wall}} || 5 || - || - || 1 || 1 || 1 || - || 1 || 1 
|-
| {{BlockSprite|glass-pane|link=Glass Pane|text=Glass Pane}} || 2 || - || - || - || 2 || - || - || - || - 
|-
| {{BlockSprite|lantern|link=Lantern|text=Lantern}} || 4 || - || - || - || 1 || 3 || - || - || - 
|-
| {{BlockSprite|smoker|link=Smoker|text=Smoker}} || 1 || - || 1 || - || - || - || - || - || - 
|-
| {{BlockSprite|smooth-stone|link=Stone|text=Smooth Stone}} || 1 || - || 1 || - || - || - || - || - || - 
|-
| {{BlockSprite|smooth-stone-slab|link=Slab|text=Smooth Stone Slab}} || 5 || 5 || - || - || - || - || - || - || - 
|-
| {{BlockSprite|snow|link=Snow|text=Snow}} || 59 || 20 || 2 || - || 6 || - || 11 || 13 || 7 
|-
| {{ItemSprite|spruce-door|link=Door|text=Spruce Door}} || 2 || - || 2 || - || - || - || - || - || - 
|-
| {{BlockSprite|spruce-fence|link=Fence|text=Spruce Fence}} || 13 || - || 9 || - || - || 2 || 2 || - || - 
|-
| {{BlockSprite|spruce-planks|link=Planks|text=Spruce Planks}} || 69 || 2 || 6 || 14 || 12 || 14 || 14 || 7 || - 
|-
| {{BlockSprite|spruce-slab|link=Slab|text=Spruce Slab}} || 25 || - || 8 || 2 || 8 || 4 || 3 || - || - 
|-
| {{BlockSprite|spruce-stairs|link=Stairs|text=Spruce Stairs}} || 3 || 3 || - || - || - || - || - || - || - 
|-
| {{BlockSprite|stripped-spruce-wood|link=Wood|text=Stripped Spruce Wood}} || 64 || 22 || 14 || 14 || 6 || 6 || 2 || - || - 
|}





[[Category:Village blueprints]]