<noinclude>{{structure info}}</noinclude>

[[File:Savanna Meeting Point 4.png|thumb|Meeting Point 4 (Savanna)]]



==== Blueprint ====

{{layered blueprint|name=
Savanna Meeting Point 4|default=Layer 1
|A=Acacia Wood
|C=Double Acacia Slab
|B=Bell
|D=Dirt Path+top
|T=Torch
|W=Water+top
|I=Acacia Fence
|S=Acacia Stairs
|R=Grass Block+top
           
|----Layer 1|
           
 R  DDD    
  DDDDDDDR 
  DDDDDDD  
 DDDDADDDD 
 DDDAAADDD 
 DDDDADDDD 
  DDDDDDD  
  DDDDDDD  
    DDD    
           
|----Layer 2|
           
           
           
    AAA    
   AAWAA   
   AWWWA   
   AAWAA   
    AAA    
           
           
           
|----Layer 3|
           
           
           
     T     
    I I    
   T   T   
    I I    
     T     
           
           
           
|----Layer 4|
           
           
           
           
    I I    
     B     
    I I    
           
           
           
           
|----Layer 5|
           
           
           
           
    SSS    
    SCS    
    SSS    
           
           
           
           
}}



==== Materials ====

{| class="wikitable sortable mw-collapsible"
|-
! Name !! Total !! Layer 1 !! Layer 2 !! Layer 3 !! Layer 4 !! Layer 5 
|-
| {{BlockSprite|acacia-fence|link=Acacia Fence|text=Acacia Fence}} || 8 || - || - || 4 || 4 || - 
|-
| {{BlockSprite|acacia-slab|link=Acacia Slab|text=Acacia Slab}} || 2 || - || - || - || - || 2 
|-
| {{BlockSprite|acacia-stairs|link=Acacia Stairs|text=Acacia Stairs}} || 8 || - || - || - || - || 8 
|-
| {{BlockSprite|acacia-wood|link=Acacia Wood|text=Acacia Wood}} || 21 || 5 || 16 || - || - || - 
|-
| {{BlockSprite|bell|link=Bell|text=Bell}} || 1 || - || - || - || 1 || - 
|-
| {{BlockSprite|grass-block|link=Grass Block|text=Grass Block}} || 2 || 2 || - || - || - || - 
|-
| {{BlockSprite|dirt-path|link=Dirt Path|text=Dirt Path}} || 56 || 56 || - || - || - || - 
|-
| {{BlockSprite|torch|link=Torch|text=Torch}} || 4 || - || - || 4 || - || - 
|-
| {{BlockSprite|water|link=Water|text=Water}} || 5 || - || 5 || - || - || - 
|}





[[Category:Village blueprints]]