<noinclude>{{structure info}}</noinclude>

[[File:Savanna Small House 6.png|thumb|Small House 6 (Savanna)]]



==== Blueprint ====

{{layered blueprint|name=Savanna Small House 6|default=Layer 1
|D=Dirt
|A=Acacia Log+top
|C=Acacia Log
|c=Acacia Log-rot-90
|I=Acacia Planks
|W=Acacia Wood
|G=Grass Block+top
|O=Orange Bed+top+foot-rot-90
|R=Orange Bed+top+head-rot-90
|s=Acacia Stairs
|>=Acacia Stairs-rot-90
|^=Acacia Stairs-rot-180
|<=Acacia Stairs-rot-270
|L=Glass Pane
|P=Dirt Path+top
|d=Acacia Door+bottom
|a=Acacia Door+top
|N=Glass Pane-rot-90
|T=Wall Torch-rot-180
|r=Grass
        
|----Layer 1|
        
   G    
  DDD   
 DIIID  
 DIIIDG 
 DIIID  
  DID   
   PG   
        
|----Layer 2|
        
        
  AAA   
 As RA  
 AW OAr 
 A^  A  
  AdA   
    r   
        
|----Layer 3|
        
        
  CNC   
 c   c  
 L   L  
 c   c  
  CaC   
        
        
|----Layer 4|
        
        
  AcA   
 A T A  
 C   C  
 A   A  
  AcA   
        
        
|----Layer 5|
        
 ^^^^^  
<IIIII> 
<I   I> 
<I   I> 
<I   I> 
<IIIII> 
 sssss  
        
|----Layer 6|
        
        
 ^^^^^  
 <III>  
 <III>  
 <III>  
 ssss>  
        
        
|----Layer 7|
        
        
        
  ^^>   
  <I>   
  ss>   
        
        
        
}}



==== Materials ====

{| class="wikitable sortable mw-collapsible"
|-
! Name !! Total !! Layer 1 !! Layer 2 !! Layer 3 !! Layer 4 !! Layer 5 !! Layer 6 !! Layer 7 
|-
| {{BlockSprite|acacia-door|link=Acacia Door|text=Acacia Door}} || 1 || - || 1 || - || - || - || - || - 
|-
| {{BlockSprite|acacia-log|link=Acacia Log|text=Acacia Log}} || 31 || - || 11 || 8 || 12 || - || - || - 
|-
| {{BlockSprite|acacia-planks|link=Acacia Planks|text=Acacia Planks}} || 36 || 10 || - || - || - || 16 || 9 || 1 
|-
| {{BlockSprite|acacia-stairs|link=Acacia Stairs|text=Acacia Stairs}} || 46 || - || 2 || - || - || 20 || 16 || 8 
|-
| {{BlockSprite|acacia-wood|link=Acacia Wood|text=Acacia Wood}} || 1 || - || 1 || - || - || - || - || - 
|-
| {{BlockSprite|dirt|link=Dirt|text=Dirt}} || 11 || 11 || - || - || - || - || - || - 
|-
| {{BlockSprite|glass-pane|link=Glass Pane|text=Glass Pane}} || 3 || - || - || 3 || - || - || - || - 
|-
| {{BlockSprite|grass|link=Grass|text=Grass}} || 2 || - || 2 || - || - || - || - || - 
|-
| {{BlockSprite|grass-block|link=Grass Block|text=Grass Block}} || 3 || 3 || - || - || - || - || - || - 
|-
| {{BlockSprite|dirt-path|link=Dirt Path|text=Dirt Path}} || 1 || 1 || - || - || - || - || - || - 
|-
| {{BlockSprite|orange-bed|link=Orange Bed|text=Orange Bed}} || 1 || - || 1 || - || - || - || - || - 
|-
| {{BlockSprite|torch|link=Torch|text=Torch}} || 1 || - || - || - || 1 || - || - || - 
|}





[[Category:Village blueprints]]