<noinclude>{{structure info}}</noinclude>

[[File:Savanna Temple 1.png|thumb|Temple 1 (Savanna)]]



==== Blueprint ====

{{layered blueprint|name=
Savanna Temple 1|default=Layer 1
|G=Grass Block+top
|D=Dirt
|O=Orange Terracotta
|Y=Yellow Terracotta
|A=Acacia Log+top
|C=Acacia Log
|I=Acacia Planks
|W=Acacia Wood
|B=Brewing Stand
|R=Brown Wall Banner
|S=Grass
|T=Acacia Stairs
|N=Orange Stained Glass Pane
|E=Yellow Stained Glass Pane
|P=Red Carpet
|H=Dirt Path+top
|L=Orange Stained Glass Pane-rot-90
|e=Yellow Stained Glass Pane-rot-90
|a=Wall Torch-rot-180
|c=Acacia Door+bottom
|i=Acacia Door+top
|l=Wall Torch
           
|----Layer 1|
           
 GGGGGGGGG 
 GGDDDDDGG 
 GDIIIIIDG 
 GDIIIIIDG 
 GDIIIIIDG 
 GGDDCDDGG 
 GGGGHGGGG 
 GGGHHHGGG 
 DGGHGHGGD 
 GGGHHHGGG 
 GGGGHGGGG 
 GGDGHGDGG 
 GGGGHGGGG 
           
|----Layer 2|
           
  SS SSSSS 
 S AAAAAS  
  AW   TA  
 SAW   WA  
 SAW   TAS 
 SSAAcAAS  
 S  S S  S 
 SS     S  
 O S     O 
 SS    SSS 
  SSS   S  
 S O   OSS 
  S S S    
           
|----Layer 3|
           
           
   ALALA   
  AB    A  
  NP   PN  
  AP    A  
   AAiAA   
           
           
 O       O 
           
           
   O   O   
           
           
|----Layer 4|
           
           
   AeAeA   
  A     A  
  E     E  
  A  l  A  
   AAAAA   
           
           
 Y       Y 
           
           
   Y   Y   
   R   R   
           
|----Layer 5|
           
           
   ACACA   
  A a a A  
  C     C  
  A     A  
   CCCCC   
           
           
           
           
           
           
           
           
|----Layer 6|
           
  TTTTTTT  
 TIIIIIIIT 
 TI     IT 
 TI     IT 
 TI     IT 
 TIIIIIIIT 
  TTTTTTT  
           
           
           
           
           
           
           
|----Layer 7|
           
           
  TTTTTTT  
  TIIIIIT  
  TIIIIIT  
  TIIIIIT  
  TTTTTTT  
           
           
           
           
           
           
           
           
}}



==== Materials ====

{| class="wikitable sortable mw-collapsible"
|-
! Name !! Total !! Layer 1 !! Layer 2 !! Layer 3 !! Layer 4 !! Layer 5 !! Layer 6 !! Layer 7 
|-
| {{BlockSprite|acacia-door|link=Acacia Door|text=Acacia Door}} || 1 || - || 1 || - || - || - || - || - 
|-
| {{BlockSprite|acacia-log|link=Acacia Log|text=Acacia Log}} || 55 || 1 || 15 || 11 || 12 || 16 || - || - 
|-
| {{BlockSprite|acacia-planks|link=Acacia Planks|text=Acacia Planks}} || 50 || 15 || - || - || - || - || 20 || 15 
|-
| {{BlockSprite|acacia-stairs|link=Acacia Stairs|text=Acacia Stairs}} || 46 || - || 2 || - || - || - || 24 || 20 
|-
| {{BlockSprite|acacia-wood|link=Acacia Wood|text=Acacia Wood}} || 4 || - || 4 || - || - || - || - || - 
|-
| {{BlockSprite|brewing-stand|link=Brewing Stand|text=Brewing Stand}} || 1 || - || - || 1 || - || - || - || - 
|-
| {{BlockSprite|brown-wall-banner|link=Brown Wall Banner|text=Brown Wall Banner}} || 2 || - || - || - || 2 || - || - || - 
|-
| {{BlockSprite|dirt|link=Dirt|text=Dirt}} || 19 || 19 || - || - || - || - || - || - 
|-
| {{BlockSprite|grass|link=Grass|text=Grass}} || 38 || - || 38 || - || - || - || - || - 
|-
| {{BlockSprite|grass-block|link=Grass Block|text=Grass Block}} || 70 || 70 || - || - || - || - || - || - 
|-
| {{BlockSprite|dirt-path|link=Dirt Path|text=Dirt Path}} || 12 || 12 || - || - || - || - || - || - 
|-
| {{BlockSprite|orange-stained-glass-pane|link=Orange Stained Glass Pane|text=Orange Stained Glass Pane}} || 4 || - || - || 4 || - || - || - || - 
|-
| {{BlockSprite|orange-terracotta|link=Orange Terracotta|text=Orange Terracotta}} || 8 || - || 4 || 4 || - || - || - || - 
|-
| {{BlockSprite|red-carpet|link=Red Carpet|text=Red Carpet}} || 3 || - || - || 3 || - || - || - || - 
|-
| {{BlockSprite|torch|link=Torch|text=Torch}} || 3 || - || - || - || 1 || 2 || - || - 
|-
| {{BlockSprite|yellow-stained-glass-pane|link=Yellow Stained Glass Pane|text=Yellow Stained Glass Pane}} || 4 || - || - || - || 4 || - || - || - 
|-
| {{BlockSprite|yellow-terracotta|link=Yellow Terracotta|text=Yellow Terracotta}} || 4 || - || - || - || 4 || - || - || - 
|}





[[Category:Village blueprints]]