<noinclude>{{structure info}}</noinclude>

[[File:Plains meeting point 5.png|thumb|Meeting point 5 (Plains)]]



==== Blueprint ====

{{layered blueprint
|name=Meeting Point 5 meeting_point_5
|default=Layer 1
|p=Dirt Path+top
|g=Grass Block+top
|G=Grass
|d=Dirt
|o=Oak Planks
|b=Bell+ceiling
|f=Oak Fence
|w=White Wool
|y=Yellow Wool
|t=Torch-rot180
|r=Torch-rot90
|R=Torch-rot270
|s=Oak Slab
|z=Tall Grass
|T=Tall Grass+bottom
             
|----Layer 0|
             
 ggggggggggg 
 ggggggggggg 
 ggggdddgpgp 
 ggpggpgpppg 
 gggpppgpgpg 
 gdggppppgdg 
 gdpppgpppdg 
 gdgpppppgdg 
 ggggppgppgg 
 gpgpgpppgpg 
             
|----Layer 1|
             
 G  G  GG G  
  G GfTfT    
  G  oooG G  
 GG  f f     
  GG     G   
 fof     fof 
  o       o  
 fof     fof 
  G       GG 
 G G     G   
             
|----Layer 2|
             
             
     fzfz    
             
     f f     
             
 f f     f f 
             
 f f     f f 
             
             
             
|----Layer 3|
             
             
     f f     
      b      
     f f     
             
 f f     f f 
             
 f f     f f 
             
             
             
|----Layer 4|
             
             
     sws     
     sys     
     sws     
      t      
 sss     sss 
 ywyr   Rywy 
 sss     sss 
             
             
             
}}

All oak slabs are bottom slabs. Some of [[grass block]]s are not included, therefore some of the those blocks could be replaced by other blocks such as [[sand]].



==== Materials ====

{| class="wikitable sortable mw-collapsible"
|-
! Name !! Total !! Layer 0 !! Layer 1 !! Layer 2 !! Layer 3 !! Layer 4 
|-
| {{BlockSprite|bell|link=Bell|text=Bell}} || 1 || - || - || - || 1 || - 
|-
| {{BlockSprite|dirt|link=Dirt|text=Dirt}} || 9 || 9 || - || - || - || - 
|-
| {{BlockSprite|dirt path|link=Dirt Path|text=Dirt Path}} || 37 || 37 || - || - || - || - 
|-
| {{BlockSprite|grass|link=Grass|text=Grass}} || 21 || - || 21 || - || - || - 
|-
| {{BlockSprite|grass block|link=Grass Block|text=Grass Block}} || 64 || 64 || - || - || - || - 
|-
| {{BlockSprite|oak fence|link=Fence|text=Oak Fence}} || 36 || - || 12 || 12 || 12 || - 
|-
| {{BlockSprite|oak planks|link=Planks|text=Oak Planks}} || 9 || - || 9 || - || - || - 
|-
| {{BlockSprite|oak slab|link=Slab|text=Oak Slab}} || 18 || - || - || - || - || 18 
|-
| {{BlockSprite|tall grass|link=Grass|text=Tall Grass}} || 2 || - || 2 || - || - || - 
|-
| {{BlockSprite|torch|link=Torch|text=Torch}} || 3 || - || - || - || - || 3 
|-
| {{BlockSprite|white wool|link=Wool|text=White Wool}} || 4 || - || - || - || - || 4 
|-
| {{BlockSprite|yellow wool|link=Wool|text=Yellow Wool}} || 5 || - || - || - || - || 5 
|}





[[Category:Village blueprints]]