<noinclude>{{structure info}}</noinclude>

[[File:Taiga Small House 4.png|thumb|Small House 4 (Taiga)]]



==== Blueprint ====

{{layered blueprint|name=
Taiga Small House 4|default=Layer 1
|S=Spruce Log
|I=Spruce Log-rot-90
|D=Dirt
|C=Cobblestone
|R=Crafting Table
|P=Spruce Planks
|B=Blue Bed+side+head-rot-180
|L=Blue Bed+side+foot-rot-180
|U=Spruce Trapdoor
|G=Glass Pane
|W=Wall Torch-rot-270
|A=Wall Torch-rot-90
|E=Spruce Door+bottom
|O=Spruce Door+top
|T=Dirt Path+top
|K=Grass Block+top
          
|----Layer 1|
          
          
  DDDD    
  DCCDDD  
  DCCCPPT 
  DCCDDD  
  DDDD    
       K  
          
|----Layer 2|
          
          
  CCCC    
  CBLCPP  
  C  E E  
  CR CPP  
  CCCC    
          
          
|----Layer 3|
          
          
 UCCCC    
  G  CPP  
 UC  O O  
  G  CPP  
 UCCCC    
          
          
|----Layer 4|
          
 S    S   
 SCCCCIII 
 SC  CPP  
 SC  CPPW 
 SC  CPP  
 SCCCCIII 
 S    S   
          
|----Layer 5|
          
  S  S    
  SCCS    
  S  SIII 
  SWASPP  
  S  SIII 
  SCCS    
  S  S    
          
|----Layer 6|
          
   SS     
   SS     
   SS     
   SSIIII 
   SS     
   SS     
   SS     
          
}}



==== Materials ====

{| class="wikitable sortable mw-collapsible"
|-
! Name !! Total !! Layer 1 !! Layer 2 !! Layer 3 !! Layer 4 !! Layer 5 !! Layer 6 
|-
| {{BlockSprite|Blue Bed|link=Blue Bed|text=Blue Bed}} || 1 || - || 1 || - || - || - || - 
|-
| {{BlockSprite|Cobblestone|link=Cobblestone|text=Cobblestone}} || 49 || 7 || 13 || 11 || 14 || 4 || - 
|-
| {{BlockSprite|Crafting Table|link=Crafting Table|text=Crafting Table}} || 1 || - || 1 || - || - || - || - 
|-
| {{BlockSprite|Dirt|link=Dirt|text=Dirt}} || 17 || 17 || - || - || - || - || - 
|-
| {{BlockSprite|Glass Pane|link=Glass Pane|text=Glass Pane}} || 2 || - || - || 2 || - || - || - 
|-
| {{BlockSprite|Grass Block|link=Grass Block|text=Grass Block}} || 1 || 1 || - || - || - || - || - 
|-
| {{BlockSprite|Dirt Path|link=Dirt Path|text=Dirt Path}} || 1 || 1 || - || - || - || - || - 
|-
| {{BlockSprite|Spruce Door|link=Spruce Door|text=Spruce Door}} || 2 || - || 2 || - || - || - || - 
|-
| {{BlockSprite|Spruce Log|link=Spruce Log|text=Spruce Log}} || 53 || - || - || - || 15 || 20 || 18 
|-
| {{BlockSprite|Spruce Planks|link=Spruce Planks|text=Spruce Planks}} || 18 || 2 || 4 || 4 || 6 || 2 || - 
|-
| {{BlockSprite|Spruce Trapdoor|link=Spruce Trapdoor|text=Spruce Trapdoor}} || 3 || - || - || 3 || - || - || - 
|-
| {{BlockSprite|Torch|link=Torch|text=Torch}} || 3 || - || - || - || 1 || 2 || - 
|}





[[Category:Village blueprints]]