<noinclude>{{structure info}}</noinclude>

[[File:Snowy Tundra Weapon Smith 1.png|thumb|Weapon smith 1 (Snowy tundra)]]



==== Blueprint ====

{{layered blueprint
|name=Snowy Weapon Smith 1 snowy_weapon_smith_1
|default=Layer 2
|d=Diorite
|D=Diorite Wall
|x=Diorite Stairs
|y=Diorite Stairs-rot90
|i=Iron Bars
|l=Stripped Spruce Log+top
|a=Stripped Spruce Log
|A=Stripped Spruce Log-rot90
|p=Spruce Planks
|L=Lantern
|t=Torch
|T=Torch-rot180
|I=Lava
|c=Chest-rot90
|g=Grindstone
|o=Spruce Door+bottom
|O=Spruce Door+top
|X=Spruce Stairs-rot90
|P=Spruce Slab
|s=Spruce Slab+top
|S=Snow
            
|----Layer 1|
            
 SSSSSSSSSS 
 SSSSSSSSSS 
 SllllllllS 
 ddddldddlS 
 ddddldddlS 
 ddddllpllS 
 ddddlplplS 
 ddddlllllS 
 DxxDSSSSSS 
            
|----Layer 2|
            
            
 spspspspsp 
  llllllll  
 ddddd g A  
 dIIdd   A  
 ddddl   A  
 D   o  cA  
 Dg Tlllll  
 D  pspspsp 
            
|----Layer 3|
            
            
 pppppppppp 
 sllllllll  
 ddddd   l  
 i  dd   l  
 i ddl   l  
 i   O   l  
     lllll  
 t  ppppppp 
            
|----Layer 4|
            
            
  P P P P P 
 pppppppppp 
 ddddd   A  
 i  dd   A  
 i ydl   A  
 i   l   A  
    ppppppp 
    P P P P 
            
|----Layer 5|
            
            
            
 PXpppppppp 
 PXaad L ls 
    yd   l  
    yl   l  
    sl L ls 
    ppppppp 
            
|----Layer 6|
            
            
            
   Pppppppp 
    sl   ls 
    sl   ls 
    ppppppp 
            
|----Layer 7|
            
            
            
    ppppppp 
    ppppppp 
            
}}

The pair of spruce slabs in layers 4, 5, and 6 are bottom slabs, while the rest are top slabs.



==== Materials ====

{| class="wikitable sortable mw-collapsible"
|-
! Name !! Total !! Layer 1 !! Layer 2 !! Layer 3 !! Layer 4 !! Layer 5 !! Layer 6 !! Layer 7 
|-
| {{BlockSprite|chest|link=Chest|text=Chest}} || 1 || - || 1 || - || - || - || - || - 
|-
| {{BlockSprite|diorite|link=Diorite|text=Diorite}} || 57 || 26 || 12 || 9 || 8 || 2 || - || - 
|-
| {{BlockSprite|diorite-stairs|link=Stairs|text=Diorite Stairs}} || 5 || 2 || - || - || 1 || 2 || - || - 
|-
| {{BlockSprite|diorite-wall|link=Wall|text=Diorite Wall}} || 5 || 2 || 3 || - || - || - || - || - 
|-
| {{BlockSprite|grindstone|link=Grindstone|text=Grindstone}} || 2 || - || 2 || - || - || - || - || - 
|-
| {{BlockSprite|iron-bars|link=Iron Bars|text=Iron Bars}} || 6 || - || - || 3 || 3 || - || - || - 
|-
| {{BlockSprite|lantern|link=Lantern|text=Lantern}} || 2 || - || - || - || - || 2 || - || - 
|-
| {{BlockSprite|lava|link=Lava|text=Lava}} || 2 || - || 2 || - || - || - || - || - 
|-
| {{BlockSprite|snow|link=Snow|text=Snow}} || 33 || 33 || - || - || - || - || - || - 
|-
| {{ItemSprite|spruce-door|link=Door|text=Spruce Door}} || 1 || - || 1 || - || - || - || - || - 
|-
| {{BlockSprite|spruce-planks|link=Planks|text=Spruce Planks}} || 92 || 6 || 9 || 17 || 17 || 15 || 14 || 14 
|-
| {{BlockSprite|spruce-slab|link=Slab|text=Spruce Slab}} || 28 || - || 8 || 1 || 9 || 5 || 5 || - 
|-
| {{BlockSprite|spruce-stairs|link=Stairs|text=Spruce Stairs}} || 2 || - || - || - || - || 2 || - || - 
|-
| {{BlockSprite|stripped-spruce-log|link=Log|text=Stripped Spruce Log}} || 78 || 24 || 18 || 18 || 6 || 8 || 4 || - 
|-
| {{BlockSprite|torch|link=Torch|text=Torch}} || 2 || - || 1 || 1 || - || - || - || - 
|}





[[Category:Village blueprints]]