<noinclude>{{structure info}}</noinclude>

[[File:Snowy Tundra Small House 4.png|thumb|Small house 4 (Snowy tundra)]]



==== Blueprint ====

{{layered blueprint
|name=Snowy Small House 4 snowy_small_house_4
|default=Layer 1
|i=Dirt
|g=Grass Block+top
|S=Snow
|s=Snow Block
|w=White Bed+top-head-rot270
|W=White Bed+top-foot-rot270
|f=Furnace-rot90
|a=Spruce Stairs-rot90
|d=Spruce Door+bottom
|D=Spruce Door+top
|t=Torch
|l=Lantern
         
|----Layer 0|
         
 ggiiggg 
 ggigigg 
 ggigigg 
 giggiig 
 iiggiig 
 giggiig 
 giigiig 
 ggggigg 
         
|----Layer 1|
         
 SSssSSS 
 SSs sSS 
 SSs sSS 
 Ssw asS 
 ssW fsS 
 Ss  asS 
 SssdssS 
 SSSSsSS 
         
|----Layer 2|
         
    s    
   sls   
   s s   
  s   s  
  s   s  
  st ts  
   sDsS  
         
|----Layer 3|
         
    S    
   SsS   
   SsS   
   sssS  
   sssS  
   sssS  
   sss   
         
|----Layer 4|
         
         
    S    
         
   Ss    
   Ss    
    s    
     S   
         
}}



==== Materials ====

{| class="wikitable sortable mw-collapsible"
|-
! Name !! Total !! Layer 0 !! Layer 1 !! Layer 2 !! Layer 3 !! Layer 4 
|-
| {{BlockSprite|dirt|link=dirt|text=Dirt}} || 21 || 21 || - || - || - || - 
|-
| {{BlockSprite|furnace|link=Furnace|text=Furnace}} || 1 || - || 1 || - || - || - 
|-
| {{BlockSprite|grass-block|link=Grass Block|text=Grass Block}} || 35 || 35 || - || - || - || - 
|-
| {{BlockSprite|lantern|link=Lantern|text=Lantern}} || 1 || - || - || 1 || - || - 
|-
| {{BlockSprite|snow|link=Snow|text=Snow}} || 72 || - || 56 || 2 || 8 || 6 
|-
| {{BlockSprite|snow-block|link=Snow Block|text=Snow Block}} || 48 || - || 18 || 13 || 14 || 3 
|-
| {{ItemSprite|spruce-door|link=Door|text=Spruce Door}} || 1 || - || 1 || - || - || - 
|-
| {{BlockSprite|spruce-stairs|link=Stairs|text=Spruce Stairs}} || 2 || - || 2 || - || - || - 
|-
| {{BlockSprite|torch|link=Torch|text=Torch}} || 2 || - || - || 2 || - || - 
|-
| {{BlockSprite|white-bed|link=Bed|text=White Bed}} || 1 || - || 1 || - || - || - 
|}





[[Category:Village blueprints]]