<noinclude>{{structure info}}</noinclude>

[[File:Taiga Shepherds House 1.png|thumb|Shepherds House 1 (Taiga)]]



==== Blueprint ====

{{layered blueprint|name=
Taiga Shepherds House 1|default=Layer 1
|S=Spruce Log
|D=Dirt
|P=Spruce Log+top
|C=Cobblestone
|R=Spruce Planks
|L=Loom
|U=Spruce Log-rot-90
|G=Grass Block+top
|E=Spruce Fence
|T=Spruce Trapdoor
|O=Torch
|A=Dirt Path+top
|B=Cobblestone Stairs
|p=Spruce Door+bottom
|r=Spruce Door+top
|N=Glass Pane-rot-90
|W=Wall Torch-rot-180
|u=Purple Carpet
|H=White Carpet
|a=Wall Torch-rot-90
|l=Wall Torch-rot-270
|c=Spruce Pressure Plate
             
|----Layer 1|
             
   DDDDDDD   
 G DDDDDDD   
   DDDDDDD   
   DDDDDDD   
  DDDDDDDDD  
  DDDDDDDDD  
  DDDDDDDDD  
  DDDDDDDDD  
  D G D G D  
    A   A    
             
|----Layer 2|
             
   CCCCCCC   
   CGGGGGC   
   CGGGGGC   
   CGGGGGC   
  CCCCCCCCC  
  CRRRRRRRC  
  CRRRRRRRC  
  CCCCCCCCC  
  P B P B P  
             
             
|----Layer 3|
             
   EEEEEEE   
   E     E   
   E     E   
   E     E   
  CCCCpCCCC  
  CL HuH EC  
  CL uHu EC  
  CCpCCCpCC  
  P   P   P  
             
             
|----Layer 4|
             
   O     O   
             
             
 S T T T T S 
 SRRNRrRNRRS 
 SR      cRS 
 SR      cRS 
 SRRrRRRrRRS 
 SP   P   PS 
 S         S 
             
|----Layer 5|
             
             
             
             
  S   S   S  
  SRRRSRRRS  
  S   S   S  
  S  aSl  S  
  SRRRSRRRS  
  SUUUSUUUS  
  S   S   S  
             
|----Layer 6|
             
             
             
             
   S S S S   
   SRS SRS   
   S S S S   
   S S S S   
   SRS SRS   
   SWS SWS   
   S S S S   
             
|----Layer 7|
             
             
             
             
    S   S    
    S   S    
    S   S    
    S   S    
    S   S    
    S   S    
    S   S    
             
}}



==== Materials ====

{| class="wikitable sortable mw-collapsible"
|-
! Name !! Total !! Layer 1 !! Layer 2 !! Layer 3 !! Layer 4 !! Layer 5 !! Layer 6 !! Layer 7 
|-
| {{BlockSprite|Cobblestone|link=Cobblestone|text=Cobblestone}} || 54 || - || 35 || 19 || - || - || - || - 
|-
| {{BlockSprite|Cobblestone Stairs|link=Cobblestone Stairs|text=Cobblestone Stairs}} || 2 || - || 2 || - || - || - || - || - 
|-
| {{BlockSprite|Dirt|link=Dirt|text=Dirt}} || 67 || 67 || - || - || - || - || - || - 
|-
| {{BlockSprite|Glass Pane|link=Glass Pane|text=Glass Pane}} || 2 || - || - || - || 2 || - || - || - 
|-
| {{BlockSprite|Grass Block|link=Grass Block|text=Grass Block}} || 18 || 3 || 15 || - || - || - || - || - 
|-
| {{BlockSprite|Dirt Path|link=Dirt Path|text=Dirt Path}} || 2 || 2 || - || - || - || - || - || - 
|-
| {{BlockSprite|Loom|link=Loom|text=Loom}} || 2 || - || - || 2 || - || - || - || - 
|-
| {{BlockSprite|Purple Carpet|link=Purple Carpet|text=Purple Carpet}} || 3 || - || - || 3 || - || - || - || - 
|-
| {{BlockSprite|Spruce Door|link=Spruce Door|text=Spruce Door}} || 3 || - || - || 3 || - || - || - || - 
|-
| {{BlockSprite|Spruce Fence|link=Spruce Fence|text=Spruce Fence}} || 15 || - || - || 15 || - || - || - || - 
|-
| {{BlockSprite|Spruce Log|link=Spruce Log|text=Spruce Log}} || 92 || - || 3 || 3 || 17 || 27 || 28 || 14 
|-
| {{BlockSprite|Spruce Planks|link=Spruce Planks|text=Spruce Planks}} || 47 || - || 14 || - || 17 || 12 || 4 || - 
|-
| {{BlockSprite|Spruce Pressure Plate|link=Spruce Pressure Plate|text=Spruce Pressure Plate}} || 2 || - || - || - || 2 || - || - || - 
|-
| {{BlockSprite|Spruce Trapdoor|link=Spruce Trapdoor|text=Spruce Trapdoor}} || 4 || - || - || - || 4 || - || - || - 
|-
| {{BlockSprite|Torch|link=Torch|text=Torch}} || 6 || - || - || - || 2 || 2 || 2 || - 
|-
| {{BlockSprite|White Carpet|link=White Carpet|text=White Carpet}} || 3 || - || - || 3 || - || - || - || - 
|}





[[Category:Village blueprints]]