<noinclude>{{structure info}}</noinclude>

[[File:Taiga Meeting Point 1.png|thumb|Meeting Point 1 (Taiga)]]



==== Blueprint ====

{{layered blueprint|name=
Taiga Meeting Point 1|default=Layer 1
|G=Grass Block+top
|S=Spruce Planks
|B=Bell
|R=Dirt Path+top
|P=Spruce Trapdoor
         
|----Layer 1|
         
  RGRRRR 
  RRGRRR 
  GGRGRG 
  GRGRGR 
 RRRRRRR 
 RRGRRGR 
 RRRGRRR 
  RRRRRR 
  GRGRGR 
  RGRRRR 
  RRGRGG 
   RRR   
         
|----Layer 2|
         
         
    P    
   PSP   
    P    
         
         
         
         
         
         
         
         
         
|----Layer 3|
         
         
         
    B    
         
         
         
         
         
         
         
         
         
         
}}



==== Materials ====

{| class="wikitable sortable mw-collapsible"
|-
! Name !! Total !! Layer 1 !! Layer 2 !! Layer 3 
|-
| {{BlockSprite|Bell|link=Bell|text=Bell}} || 1 || - || - || 1 
|-
| {{BlockSprite|Grass Block|link=Grass Block|text=Grass Block}} || 19 || 19 || - || - 
|-
| {{BlockSprite|Dirt Path|link=Dirt Path|text=Grass Path}} || 53 || 53 || - || - 
|-
| {{BlockSprite|Spruce Planks|link=Spruce Planks|text=Spruce Planks}} || 1 || - || 1 || - 
|-
| {{BlockSprite|Spruce Trapdoor|link=Spruce Trapdoor|text=Spruce Trapdoor}} || 4 || - || 4 || - 
|}





[[Category:Village blueprints]]