<noinclude>{{structure info}}</noinclude>

[[File:Taiga Small House 1.png|thumb|Small House 1 (Taiga)]]



==== Blueprint ====

{{layered blueprint|name=
Taiga Small House 1|default=Layer 1
|S=Spruce Log-rot-90
|q=Spruce Log
|D=Dirt
|G=Grass Block+top
|P=Spruce Log+top
|C=Cobblestone
|R=Spruce Planks
|U=Spruce Wall Sign
|L=Purple Bed+side+foot
|E=Purple Bed+side+head
|A=Dirt Path+top
|O=Cobblestone Wall
|B=Cobblestone Stairs
|T=Torch
|p=Spruce Door+bottom
|r=Spruce Door+top
|u=Spruce Trapdoor
|W=Wall Torch-rot-270
|I=Spruce Stairs
|N=Glass Pane-rot-90
|l=Glass Pane
           
|----Layer 1|
           
           
  DDDDDDD  
  GDDDDD   
 AGDDDDD   
  GDDDDD   
  DDDDDDD  
           
           
|----Layer 2|
           
           
  PPCCCPP  
  OCRRRC   
  BCRRRC   
  OCRRRC   
  PPCCCPP  
           
           
|----Layer 3|
           
           
  PPCCCPP  
  TCUIUC   
   p   C   
  TC LEC   
  PPCCCPP  
           
           
|----Layer 4|
           
    u u    
  PPCNCPP  
   C   Cu  
   r   l   
   C   Cu  
  PPCNCPP  
    u u    
           
|----Layer 5|
           
 SSSSSSSSS 
  PPCCCPP  
   C   C   
   C   C   
   C   C   
  PPCCCPP  
 SSSSSSSSS 
           
|----Layer 6|
           
           
 SSSSSSSSS 
  qq   qq  
  qqW  qq  
  qq   qq  
 SSSSSSSSS 
           
           
|----Layer 7|
           
           
           
 SSSSSSSSS 
   C   C   
 SSSSSSSSS 
           
           
           
|----Layer 8|
           
           
           
           
 SSSSSSSSS 
           
           
           
           
}}



==== Materials ====

{| class="wikitable sortable mw-collapsible"
|-
! Name !! Total !! Layer 1 !! Layer 2 !! Layer 3 !! Layer 4 !! Layer 5 !! Layer 6 !! Layer 7 !! Layer 8 
|-
| {{BlockSprite|Cobblestone|link=Cobblestone|text=Cobblestone}} || 45 || - || 12 || 11 || 8 || 12 || - || 2 || - 
|-
| {{BlockSprite|Cobblestone Stairs|link=Cobblestone Stairs|text=Cobblestone Stairs}} || 1 || - || 1 || - || - || - || - || - || - 
|-
| {{BlockSprite|Cobblestone Wall|link=Cobblestone Wall|text=Cobblestone Wall}} || 2 || - || 2 || - || - || - || - || - || - 
|-
| {{BlockSprite|Dirt|link=Dirt|text=Dirt}} || 29 || 29 || - || - || - || - || - || - || - 
|-
| {{BlockSprite|Glass Pane|link=Glass Pane|text=Glass Pane}} || 3 || - || - || - || 3 || - || - || - || - 
|-
| {{BlockSprite|Grass Block|link=Grass Block|text=Grass Block}} || 3 || 3 || - || - || - || - || - || - || - 
|-
| {{BlockSprite|Dirt Path|link=Dirt Path|text=Dirt Path}} || 1 || 1 || - || - || - || - || - || - || - 
|-
| {{BlockSprite|Purple Bed|link=Purple Bed|text=Purple Bed}} || 1 || - || - || 1 || - || - || - || - || - 
|-
| {{BlockSprite|Spruce Door|link=Spruce Door|text=Spruce Door}} || 1 || - || - || 1 || - || - || - || - || - 
|-
| {{BlockSprite|Spruce Log|link=Spruce Log|text=Spruce Log}} || 107 || - || 8 || 8 || 8 || 26 || 30 || 18 || 9 
|-
| {{BlockSprite|Spruce Planks|link=Spruce Planks|text=Spruce Planks}} || 9 || - || 9 || - || - || - || - || - || - 
|-
| {{BlockSprite|Spruce Stairs|link=Spruce Stairs|text=Spruce Stairs}} || 1 || - || - || 1 || - || - || - || - || - 
|-
| {{BlockSprite|Spruce Trapdoor|link=Spruce Trapdoor|text=Spruce Trapdoor}} || 6 || - || - || - || 6 || - || - || - || - 
|-
| {{BlockSprite|Spruce Wall Sign|link=Spruce Sign|text=Spruce Wall Sign}} || 2 || - || - || 2 || - || - || - || - || - 
|-
| {{BlockSprite|Torch|link=Torch|text=Torch}} || 3 || - || - || 2 || - || - || 1 || - || - 
|}





[[Category:Village blueprints]]