<noinclude>{{structure info}}</noinclude>

[[File:Savanna Fletcher House 1.png|thumb|Fletcher House 1 (Savanna)]]



==== Blueprint ====

{{layered blueprint|name=
Savanna Fletcher House 1|default=Layer 1
|G=Grass Block+top
|D=Dirt
|Y=Yellow Terracotta
|A=Acacia Log+top
|C=Acacia Planks
|I=Acacia Log
|F=Fletching Table
|S=Acacia Slab
|B=Brown Wall Banner
|R=Grass
|T=Acacia Stairs
|L=Glass Pane
|P=Poppy
|O=Torch
|E=Acacia Fence
|N=Glass Pane-rot-90
|U=Acacia Pressure Plate
|c=Acacia Door+bottom
|a=Acacia Door+top
|H=Dirt Path+top
|W=Wall Torch-rot-270
           
|----Layer 1|
           
 GGGGGGGGG 
 GGDDDGGGG 
 GDCCCDGGG 
 GDCCCCHHH 
 GDCCCDGGG 
 GDCCCDGGG 
 GDCCCDGGG 
 GDCCCCHHH 
 GDCCCDGGG 
 GGDDDGGGG 
 GGGGGGGGG 
           
|----Layer 2|
           
 RRRRRRR R 
   YYY  E  
  YTETY RR 
 RY   c    
 RYI  YRR  
  AF  ARE  
 RYI  YR   
 RY   c    
 RYTETYR R 
 R YYY  ER 
 RRPR RRR  
           
|----Layer 3|
           
           
   YNY  E  
  Y U Y    
  L   a    
  YO  Y    
  A   A E  
  YO  Y    
  L   a    
  Y U Y    
   YNY  E  
           
           
|----Layer 4|
           
           
   YNY  E  
  Y   Y    
  L   YW   
  Y   Y    
  A   A E  
  Y   Y    
  L   YW   
  Y   Y    
   YNY  E  
           
           
|----Layer 5|
           
    B      
   YYYSSSB 
  Y   YSS  
 BY   YSS  
  Y   YSS  
  A   ASSB 
  Y   YSS  
 BY   YSS  
  Y   YSS  
   YYYSSSB 
    B      
           
|----Layer 6|
           
 TTTTTTT   
 TCCCCCT   
 TC   CT   
 TC   CT   
 TC   CT   
 TC   CT   
 TC   CT   
 TC   CT   
 TC   CT   
 TCCCCCT   
 TTTTTTT   
           
|----Layer 7|
           
           
  TTTTT    
  TCCCT    
  TCCCT    
  TCCCT    
  TCCCT    
  TCCCT    
  TCCCT    
  TCCCT    
  TTTTT    
           
           
}}



==== Materials ====

{| class="wikitable sortable mw-collapsible"
|-
! Name !! Total !! Layer 1 !! Layer 2 !! Layer 3 !! Layer 4 !! Layer 5 !! Layer 6 !! Layer 7 
|-
| {{BlockSprite|acacia-door|link=Acacia Door|text=Acacia Door}} || 2 || - || 2 || - || - || - || - || - 
|-
| {{BlockSprite|acacia-fence|link=Acacia Fence|text=Acacia Fence}} || 11 || - || 5 || 3 || 3 || - || - || - 
|-
| {{BlockSprite|acacia-log|link=Acacia Log|text=Acacia Log}} || 10 || - || 4 || 2 || 2 || 2 || - || - 
|-
| {{BlockSprite|acacia-planks|link=Acacia Planks|text=Acacia Planks}} || 68 || 23 || - || - || - || - || 24 || 21 
|-
| {{BlockSprite|acacia-pressure-plate|link=Acacia Pressure Plate|text=Acacia Pressure Plate}} || 2 || - || - || 2 || - || - || - || - 
|-
| {{BlockSprite|acacia-slab|link=Acacia Slab|text=Acacia Slab}} || 20 || - || - || - || - || 20 || - || - 
|-
| {{BlockSprite|acacia-stairs|link=Acacia Stairs|text=Acacia Stairs}} || 60 || - || 4 || - || - || - || 32 || 24 
|-
| {{BlockSprite|brown-wall-banner|link=Brown Wall Banner|text=Brown Wall Banner}} || 7 || - || - || - || - || 7 || - || - 
|-
| {{BlockSprite|dirt|link=Dirt|text=Dirt}} || 18 || 18 || - || - || - || - || - || - 
|-
| {{BlockSprite|fletching-table|link=Fletching Table|text=Fletching Table}} || 1 || - || 1 || - || - || - || - || - 
|-
| {{BlockSprite|glass-pane|link=Glass Pane|text=Glass Pane}} || 8 || - || - || 4 || 4 || - || - || - 
|-
| {{BlockSprite|grass|link=Grass|text=Grass}} || 29 || - || 29 || - || - || - || - || - 
|-
| {{BlockSprite|grass-block|link=Grass Block|text=Grass Block}} || 52 || 52 || - || - || - || - || - || - 
|-
| {{BlockSprite|dirt-path|link=Dirt Path|text=Dirt Path}} || 6 || 6 || - || - || - || - || - || - 
|-
| {{BlockSprite|poppy|link=Poppy|text=Poppy}} || 1 || - || 1 || - || - || - || - || - 
|-
| {{BlockSprite|torch|link=Torch|text=Torch}} || 4 || - || - || 2 || 2 || - || - || - 
|-
| {{BlockSprite|yellow-terracotta|link=Yellow Terracotta|text=Yellow Terracotta}} || 60 || - || 16 || 12 || 14 || 18 || - || - 
|}





[[Category:Village blueprints]]