<noinclude>{{structure info}}</noinclude>

[[File:Plains Small House 8.png|thumb|Small house 8 (Plains)]]



==== Blueprint ====

{{layered blueprint
|name=Village Plains Houses plains_small_house_8
|default=Layer 2
|O=Oak Log+top
|L=Oak Log-rot90
|l=Oak Log
|C=Cobblestone
|c=Cobblestone Stairs
|d=Oak Door+bottom
|D=Oak Door+top
|)=Cobblestone Stairs-rot270
|(=Cobblestone Stairs-rot90
|T=torch-rot180
|t=torch
|\=Oak Stairs
|<=Oak Stairs-rot90
|/=Oak Stairs-rot270
|>=Oak Stairs-rot180
|g=glass Pane
|G=glass Pane-rot90
|P=Oak Planks
|W=White Bed+top foot-rot270
|o=White Bed+top head-rot270
|f=Farmland+moist
|w=Water+top
|q=Dirt
|b=Grass Block+top
|X=Oak Stairs
|z=Wheat Crops
            
|----Layer 0|
           
     b     
    fwf    
   qqqqq   
  fqqqqqf  
 bwqqqqqwb 
  fqqqqqf  
    qqq    
    qqq    
           
|----Layer 1|
           
           
    z z    
   OCCCO   
  zCPPPCz  
   CPPPC   
  zCPPPCz  
   OCCCO   
    (c)    
            
|----Layer 2|
           
           
           
   OCCCO   
   Co XC   
   CW  C   
   C   C   
   OCdCO   
           
|----Layer 3|
           
           
           
   OCgCO   
   C   C   
   g   g   
   C   C   
   OCDCO   
           
|----Layer 4|
           
           
           
   OCCCO   
   C   C   
   C   C   
   C   C   
   OCCCO   
     T     
           
|----Layer 5|
           
           
  /<   >\  
  /OLLLO\  
  /C T C\  
  /C   C\  
  /C   C\  
  /OLLLO\  
  /<   >\  
           
|----Layer 6|
           
           
   /< >\   
   /CCC\   
   P   P   
   g   g   
   P   P   
   /CCC\   
   /< >\   
           
|----Layer 7|
           
           
    /P\    
    /P\    
   /PPP\   
   /PPP\   
   /PPP\   
    /P\    
    /P\    
           
}}

The wheat crops won't replace to the [[carrot]], [[potato]], or [[beetroot]] crops. Also, the wheat crops always mature.

==== Materials ====

{| class="wikitable sortable mw-collapsible"
|-
! Name !! Total !! Layer 0 !! Layer 1 !! Layer 2 !! Layer 3 !! Layer 4 !! Layer 5 !! Layer 6 !! Layer 7 
|-
| {{BlockSprite|cobblestone|link=Cobblestone|text=Cobblestone}} || 55 || - || 12 || 11 || 8 || 12 || 6 || 6 || - 
|-
| {{BlockSprite|cobblestone-stairs|link=Stairs|text=Cobblestone Stairs}} || 3 || - || 3 || - || - || - || - || - || - 
|-
| {{BlockSprite|dirt|link=Dirt|text=Dirt}} || 26 || 26 || - || - || - || - || - || - || - 
|- 
| {{BlockSprite|farmland|link=Farmland|text=Farmland}} || 6 || 6 || - || - || - || - || - || - || - 
|-
| {{BlockSprite|glass-pane|link=Glass Pane|text=Glass Pane}} || 5 || - || - || - || 3 || - || - || 2 || - 
|-
| {{BlockSprite|grass-block|link=Grass Block|text=Grass Block}} || 3 || 3 || - || - || - || - || - || - || - 
|-
| {{ItemSprite|oak-door|link=Door|text=Oak Door}} || 1 || - || - || 1 || - || - || - || - || - 
|-
| {{BlockSprite|oak-log|link=Log|text=Oak Log}} || 26 || - || 4 || 4 || 4 || 4 || 10 || - || - 
|-
| {{BlockSprite|oak-planks|link=Planks|text=Oak Planks}} || 26 || - || 9 || - || - || - || - || 4 || 13 
|-
| {{BlockSprite|oak-stairs|link=Stairs|text=Oak Stairs}} || 45 || - || - || 1 || - || - || 18 || 12 || 14 
|-
| {{BlockSprite|torch|link=Torch|text=Torch}} || 2 || - || - || - || - || 1 || 1 || - || - 
|-
| {{BlockSprite|water|link=Water|text=Water}} || 3 || 3 || - || - || - || - || - || - || - 
|-
| {{BlockSprite|wheat|link=Wheat Seeds|text=Wheat}} || 6 || - || 6 || - || - || - || - || - || - 
|-
| {{BlockSprite|white-bed|link=Bed|text=White Bed}} || 1 || - || - || 1 || - || - || - || - || - 
|}





[[Category:Village blueprints]]