<noinclude>{{structure info}}</noinclude>
[[File:Plains Small House 1.png|thumb|Small House 1 (Plains)]]

==== Blueprint ====
{{layered blueprint
|name=Village Plains Houses plains_small_house_1
|default=Layer 3
|S=Stripped Oak Log+top
|C=Cobblestone
|P=Oak Planks
|B=White Bed+top foot-rot270
|b=White Bed+top head-rot270
|<=Oak Stairs-rot90
|^=Oak Stairs-rot270
|g=glass Pane
|s=Oak Stairs-rot180
|T=torch-rot180
|d=Oak Door+bottom
|D=Oak Door+top
|G=glass Pane-rot90
|>=Oak Stairs
|----Layer 1|

        
  SCCCS 
  CPPPC 
  CPPPC 
  CPPPC 
  SCCCS 
    s   

|----Layer 2|

        
  SCCCS 
  Cb sC 
  CB  C 
  C   C 
  SCdCS 
        

|----Layer 3|

        
  SCGCS 
  C   C 
  g   g 
  C   C 
  SCDCS 
   T T  

|----Layer 4|

        
  SCCCS 
  C T C 
  C   C 
  C   C 
  SCCCS 
        

|----Layer 5|

 ^^^^^^>
 <PPPPP>
 <P   P>
 <P   P>
 <P   P>
 <PPPPP>
 <ssssss

|----Layer 6|

        
  <^^^> 
  <PPP> 
  <P P> 
  <PPP> 
  sssss 
        

|----Layer 7|

        
        
   <^^  
   <P>  
   sss  
        
        

}}



==== Materials ====
{| class="wikitable sortable mw-collapsible" ! style="width: 100%"
|-
!Name !!Layer 1 !!Layer 2 !!Layer 3 !!Layer 4 !!Layer 5 !!Layer 6 !!Layer 7 !!Total
|-
| {{BlockSprite|stripped-oak-wood|link=Stripped Log|text=Stripped Oak Logs}} || 4 || 4 || 4 || 4 || - || - || - || 16
|-
| {{BlockSprite|cobblestone|link=Cobblestone|text=Cobblestone}} || 12 || 11 || 8 || 12 || - || - || - || 43
|-
| {{BlockSprite|oak-planks|link=Planks|text=Oak Planks}} || 9 || - || - || - || 16 || 8 || 1 || 34
|-
| {{BlockSprite|white-bed|link=Bed|text=White Bed}} || - || 1 || - || - || - || - || - || 1
|-
| {{BlockSprite|oak-stairs|link=Stairs|text=Oak Wood Stairs}} || 1 || 1 || - || - || 24 || 16 || 8 || 50
|-
| {{BlockSprite|glass-pane|link=Glass Pane|text=Glass Pane}} || - || - || 3 || - || - || - || - || 3
|-
| {{BlockSprite|torch|link=Torch|text=Torch}} || - || - || 2 || 1 || - || - || - || 3
|-
| {{ItemSprite|oak-door|link=Door|text=Oak Door}} || - || 1 || - || - || - || - || - || 1
|}