<noinclude>{{structure info}}</noinclude>

[[File:Snowy Tundra Meeting Point 2.png|thumb|Meeting point 2 (Snowy tundra)]]



==== Blueprint ====

{{layered blueprint
|name=Snowy Meeting Point 2 snowy_meeting_point_2
|default=Layer 1
|g=Grass Block+top
|d=Dirt
|p=Dirt Path+top
|i=Packed Ice
|B=Stone Bricks
|b=Bell
|s=Snow
|P=Spruce Planks
|t=Torch
|w=Spruce Stairs
|x=Spruce Stairs-rot90
|y=Spruce Stairs-rot180
|z=Spruce Stairs-rot270
             
|----Layer 0|
             
 ggggpppgggg 
 ggpppppppgg 
 gpppdddpppg 
 pppdBdddppp 
 pPpdddddppp 
 pppdddddppp 
 gpppdddpppg 
 gppppppppgg 
 ggggpppgggg 
             
|----Layer 1|
             
             
     yyz     
    yxizy    
  b xiiiz    
    wxiwz    
     xwz     
        s    
             
|----Layer 2|
             
             
      i      
     iii     
      i      
             
|----Layer 3|
             
             
      i      
             
|----Layer 4|
             
             
      t      
             
}}



==== Materials ====

{| class="wikitable sortable mw-collapsible"
|-
! Name !! Total !! Layer 0 !! Layer 1 !! Layer 2 !! Layer 3 !! Layer 4 
|-
| {{BlockSprite|bell|link=Bell|text=Bell}} || 1 || - || 1 || - || - || - 
|-
| {{BlockSprite|dirt|link=Dirt|text=Dirt}} || 20 || 20 || - || - || - || - 
|-
| {{BlockSprite|dirt-path|link=Dirt Path|text=Dirt Path}} || 50 || 50 || - || - || - || - 
|-
| {{BlockSprite|grass-block|link=Grass Block|text=Grass Block}} || 27 || 27 || - || - || - || - 
|-
| {{BlockSprite|packed-ice|link=Packed Ice|text=Packed Ice}} || 11 || - || 5 || 5 || 1 || - 
|-
| {{BlockSprite|snow|link=Snow|text=Snow}} || 1 || - || 1 || - || - || - 
|-
| {{BlockSprite|spruce-planks|link=Planks|text=Spruce Planks}} || 1 || 1 || - || - || - || - 
|-
| {{BlockSprite|spruce-stairs|link=Stairs|text=Spruce Stairs}} || 16 || - || 16 || - || - || - 
|-
| {{BlockSprite|stone-bricks|link=Stone Bricks|text=Stone Bricks}} || 1 || 1 || - || - || - || - 
|-
| {{BlockSprite|torch|link=Torch|text=Torch}} || 1 || - || - || - || - || 1 
|}





[[Category:Village blueprints]]