<noinclude>{{structure info}}</noinclude>

[[File:Plains Meeting Point 4.png|thumb|Meeting point 4 (Plains)]]



==== Blueprint ====

{{layered blueprint
|name=Meeting Point 4 meeting_point_4
|default=Layer 1
|p=Dirt Path+top
|g=Grass Block+top
|G=Grass
|c=Cobblestone
|d=Dirt
|o=Oak Planks
|b=Bell
|f=Oak Fence
|w=White Wool
|y=Yellow Wool
|t=Torch
|D=Dandelion
|s=Oak Slab
|z=Tall Grass
|T=Tall Grass+bottom
                  
|----Layer 0|
                  
 gggggggggggggggg 
 gggggpgpggpggpgg 
 ggpppgdgggcgpggp 
 gggcgpcgpgpgcppg 
 ggdgppppcpgpgdgg 
 ggdpccpgcgcgcdgg 
 ggdcpgpppggcpdpg 
 ggdgpppcgpcpgdgg 
 ggpgcgpgpgpgpcgg 
 gpgggpgpcgppgggg 
                  
|----Layer 1|
                  
  G GGTGG    G GG 
 T   G G G  G     
 G    Go G        
   T G  D         
 Gfof        fof  
  Go          oGG 
  Go          o G 
 Gfof        fofG 
               GT 
 G  G        GGDT 
                  
|----Layer 2|
                  
      z           
 z                
       b          
   z              
  ftf        ftf  
                  
                  
  ftf        ftf  
                z 
                z 
                  
|----Layer 3|
                  
                  
                  
                  
                  
  f f        f f  
                  
                  
  f f        f f  
                  
                  
                  
|----Layer 4|
                  
                  
                  
                  
                  
  sss        sss  
  ywy        wyw  
  wyw        ywy  
  sss        sss  
                  
                  
                  
}}

All oak slabs are bottom slabs.



==== Materials ====

{| class="wikitable sortable mw-collapsible"
|-
! Name !! Total !! Layer 0 !! Layer 1 !! Layer 2 !! Layer 3 !! Layer 4 
|-
| {{BlockSprite|bell|link=Bell|text=Bell}} || 1 || - || - || 1 || - || - 
|-
| {{BlockSprite|cobblestone|link=Cobblestone|text=Cobblestone}} || 17 || 17 || - || - || - || - 
|-
| {{BlockSprite|dandelion|link=Flower|text=Dandelion}} || 2 || - || 2 || - || - || - 
|-
| {{BlockSprite|dirt|link=Dirt|text=Dirt}} || 9 || 9 || - || - || - || - 
|-
| {{BlockSprite|dirt path|link=Dirt Path|text=Dirt Path}} || 42 || 42 || - || - || - || - 
|-
| {{BlockSprite|grass|link=Grass|text=Grass}} || 29 || - || 29 || - || - || - 
|-
| {{BlockSprite|grass block|link=Grass Block|text=Grass Block}} || 91 || 91 || - || - || - || - 
|-
| {{BlockSprite|oak fence|link=Fence|text=Oak Fence}} || 24 || - || 8 || 8 || 8 || - 
|-
| {{BlockSprite|oak planks|link=Planks|text=Oak Planks}} || 9 || - || 9 || - || - || - 
|-
| {{BlockSprite|oak slab|link=Slab|text=Oak Slab}} || 12 || - || - || - || - || 12 
|-
| {{BlockSprite|tall grass|link=Grass|text=Tall Grass}} || 5 || - || 5 || - || - || - 
|-
| {{BlockSprite|torch|link=Torch|text=Torch}} || 4 || - || - || 4 || - || - 
|-
| {{BlockSprite|white wool|link=Wool|text=White Wool}} || 6 || - || - || - || - || 6 
|-
| {{BlockSprite|yellow wool|link=Wool|text=Yellow Wool}} || 6 || - || - || - || - || 6 
|}





[[Category:Village blueprints]]