<noinclude>{{structure info}}</noinclude>

[[File:Desert Butcher Shop 1.png|thumb|Butcher shop 1 (Desert)]]



==== Blueprint ====

{{layered blueprint|name=Desert Butcher Shop 1|default=Layer 2
|C=Cut Sandstone
|S=Smooth Sandstone
|G=Grass Block+top
|T=Terracotta
|M=Smooth Stone Slab
|O=Smoker
|A=Sandstone Wall
|H=Smooth Sandstone Slab
|R=Torch
|N=Smooth Sandstone Stairs
|J=Jungle Door+bottom
|U=Jungle Door+top
|W=Wall Torch-rot-180
          
|----Layer 1|
          
 CCCCCCCC 
 CGGGGGGC 
 CGGGGGGC 
 CSSSCGGC 
 CSMSCGGC 
 CSMSCGGC 
 CCSCCCCC 
   N      
          
|----Layer 2|
          
 AAAAAAAA 
 A      A 
 A      A 
 CSJSC  A 
 SO MS  A 
 S  MS  A 
 CSJSCAAA 
          
          
|----Layer 3|
          
 R      R 
          
          
 CSUSC    
 HT  H    
 H   H    
 CSUSC  R 
          
          
|----Layer 4|
          
          
          
          
 CSSSC    
 STW S    
 S   S    
 CSSSC    
   W      
          
|----Layer 5|
          
          
          
          
 HCCCH    
 CTHHC    
 CHHHC    
 HCCCH    
          
          
}}



==== Materials ====

{| class="wikitable sortable mw-collapsible"
|-
! Name !! Total !! Layer 1 !! Layer 2 !! Layer 3 !! Layer 4 !! Layer 5 
|-
| {{BlockSprite|Cut Sandstone|link=Sandstone|text=Cut Sandstone}} || 50 || 28 || 4 || 4 || 4 || 10 
|-
| {{BlockSprite|Grass Block|link=Grass Block|text=Grass Block}} || 18 || 18 || - || - || - || - 
|-
| {{ItemSprite|Jungle Door|link=Door|text=Jungle Door}} || 2 || - || 2 || - || - || - 
|-
| {{BlockSprite|Sandstone Wall|link=Wall|text=Sandstone Wall}} || 18 || - || 18 || - || - || - 
|-
| {{BlockSprite|Smoker|link=Smoker|text=Smoker}} || 1 || - || 1 || - || - || - 
|-
| {{BlockSprite|Smooth Sandstone|link=Sandstone|text=Smooth Sandstone}} || 30 || 8 || 8 || 4 || 10 || - 
|-
| {{BlockSprite|Smooth Sandstone Slab|link=Slab|text=Smooth Sandstone Slab}} || 13 || - || - || 4 || - || 9 
|-
| {{BlockSprite|Smooth Sandstone Stairs|link=Stairs|text=Smooth Sandstone Stairs}} || 1 || 1 || - || - || - || - 
|-
| {{BlockSprite|Smooth Stone Slab|link=Slab|text=Smooth Stone Slab}} || 4 || 2 || 2 || - || - || - 
|-
| {{BlockSprite|Terracotta|link=Terracotta|text=Terracotta}} || 3 || - || - || 1 || 1 || 1 
|-
| {{BlockSprite|Torch|link=Torch|text=Torch}} || 5 || - || - || 3 || 2 || - 
|}





[[Category:Village blueprints]]