<noinclude>{{structure info}}</noinclude>

[[File:Desert Medium House 1.png|thumb|Medium house 1 (Desert)]]



==== Blueprint ====

{{layered blueprint|name=Desert Medium House 1
|default=Layer 1
|S=Sand
|M=Smooth Sandstone
|C=Cut Sandstone
|T=Terracotta
|H=Chest-rot270
|L=Lime Bed+top+foot-rot-90
|I=Lime Bed+top+head-rot-90
|A=Sandstone Slab+Bottom
|a=Sandstone Slab+Top
|P=Potted Cactus
|W=Wall Torch-rot-180
|J=Jungle Door+up+left
|U=Jungle Door+top
|O=Wall Torch
         
|----Layer 0|
         
 SSSSSSS 
 SMMMMMS 
 SMMMMMS 
 SMMMMMS 
 SSSMSSS 
 SSSSSSS 
         
|----Layer 1|
         
 MMMMMMM 
 MI T IM 
 ML   LM 
 MH    M 
 MMMJMMM 
  P      
         
|----Layer 2|
         
 MMAMAMM 
 M  P  M 
 A     A 
 M     M 
 MAMUMAM 
   W W   
         
|----Layer 3|
         
 MMaMaMM 
 MW   WM 
 a     a 
 M  O  M 
 MaMMMaM 
         
         
|----Layer 4|
         
 CCCCCCC 
 CCCCCCC 
 CCCCCCC 
 CCCCCCC 
 CCCCCCC 
         
         
|----Layer 5|
         
 A  A  A 
         
 A     A 
         
 A  A  A 
         
         
}}



==== Materials ====

{| class="wikitable sortable mw-collapsible"
|-
! Name !! Total !! Layer 0 !! Layer 1 !! Layer 2 !! Layer 3 !! Layer 4 !! Layer 5 
|-
| {{BlockSprite|Chest|link=Chest|text=Chest}} || 1 || - || 1 || - || - || - || - 
|-
| {{BlockSprite|Cut Sandstone|link=Sandstone|text=Cut Sandstone}} || 35 || - || - || - || - || 35 || - 
|-
| {{ItemSprite|Jungle Door|link=Door|text=Jungle Door}} || 1 || - || 1 || - || - || - || - 
|-
| {{BlockSprite|Lime Bed|link=Bed|text=Lime Bed}} || 2 || - || 2 || - || - || - || - 
|-
| {{BlockSprite|Potted Cactus|link=Flower Pot|text=Potted Cactus}} || 2 || - || 1 || 1 || - || - || - 
|-
| {{BlockSprite|Sand|link=Sand|text=Sand}} || 26 || 26 || - || - || - || - || - 
|-
| {{BlockSprite|Sandstone Slab|link=Slab|text=Sandstone Slab}} || 20 || - || - || 6 || 6 || - || 8 
|-
| {{BlockSprite|Smooth Sandstone|link=Sandstone|text=Smooth Sandstone}} || 62 || 16 || 19 || 13 || 14 || - || - 
|-
| {{BlockSprite|Terracotta|link=Terracotta|text=Terracotta}} || 1 || - || 1 || - || - || - || - 
|-
| {{BlockSprite|Torch|link=Torch|text=Torch}} || 5 || - || - || 2 || 3 || - || - 
|}





[[Category:Village blueprints]]