<noinclude>{{structure info}}</noinclude>

[[File:Plains butcher shop 2.png|thumb|Butcher shop 2 (Plains)]]



==== Blueprint ====

{{layered blueprint
|name=Butcher Shop 2 butcher-shop-2
|default=Layer 0
|g=Grass Block+top
|d=Dirt
|f=Oak Fence
|D=Double Smooth Stone Slab
|s=Smooth Stone Slab+top
|c=Cobblestone
|p=Oak Planks
|o=Oak Log+top
|O=Oak Log
|l=Oak Log-rot90
|A=Oak Door+top
|a=Oak Door+bottom
|S=Smoker-rot180
|t=Torch
|T=Torch-rot180
|G=Glass Pane
|w=Cobblestone Wall
|v=Oak Stairs
|x=Oak Stairs-rot90
|y=Oak Stairs-rot180
|z=Oak Stairs-rot270
         
|----Layer 0|
         
  ggggg  
  ggggg  
  ggggg  
  ggggg  
  ggggg  
  ggggg  
  ddcdd  
  dcccd  
  dcccd  
  ddssd  
  ddscd  
  dcssd  
  dcccd  
  ddcdd  
         
         
|----Layer 1|
         
  fffff  
  f   f  
  f   f  
  f   f  
  f   f  
  f   f  
  ocaco  
  cz  c  
  cz  c  
  cp  c  
  cv Dc  
  c   c  
  c   c  
  ocaco  
         
         
|----Layer 2|
         
  t   t  
         
         
         
         
         
  ocAco  
  O   O  
  G   G  
  Ov  O  
  O   O  
  G   G  
  O   O  
  ocAco  
         
         
|----Layer 3|
         
         
         
         
         
         
    t    
  occco  
  cpT c  
  cv  c  
  c   c  
  c   c  
  c   c  
  c t c  
  occco  
    T    
         
|----Layer 4|
         
         
         
         
         
         
 xyyyyyz 
 xollloz 
 xOvppOz 
 xO ppOz 
 xO ppOz 
 xO vvOz 
 xO   Oz 
 xO   Oz 
 xollloz 
 xz   xz 
         
|----Layer 5|
         
         
         
         
         
         
         
  occco  
  c   c  
  c   c  
  c  Sc  
  occco  
  xpppz  
  xpppz  
  xpppz  
  xpppz  
         
|----Layer 6|
         
         
         
         
         
         
         
  olGlo  
  O   O  
  G   G  
  O  wO  
  olGlo  
         
         
         
         
         
|----Layer 7|
         
         
         
         
         
         
         
  occco  
  c T c  
  c   c  
  c twc  
  occco  
         
         
         
         
|----Layer 8|
         
         
         
         
         
         
 xz   xz 
 xollloz 
 xO   Oz 
 xO   Oz 
 xO  wOz 
 xollloz 
 xz T xz 
         
         
         
|----Layer 9|
         
         
         
         
         
         
  xz xz  
  xcccz  
  x   z  
  x   z  
  x  wz  
  xcccz  
  xz xz  
         
         
         
|----Layer 10|
         
         
         
         
         
         
   xpz   
   xpz   
   xpz   
   xpz   
   xpc   
   xpz   
   xpz   
         
         
         
         
|----Layer 11|
         
         
         
         
         
         
         
         
         
         
     w   
         
         
         
         
         
}}

All smooth stone slabs in layer 0 are all top slabs. The pair of indoor oak stairs in layer 4 are upside down.



==== Materials ====

{| class="wikitable sortable mw-collapsible"
|-
! Name !! Total !! Layer 0 !! Layer 1 !! Layer 2 !! Layer 3 !! Layer 4 !! Layer 5 !! Layer 6 !! Layer 7 !! Layer 8 !! Layer 9 !! Layer 10!! Layer 11
|-
| {{BlockSprite|cobblestone|link=Cobblestone|text=Cobblestone}} || 82 || 13 || 16 || 4 || 18 || - || 12 || - || 12 || - || 6 || 1 || - 
|-
| {{BlockSprite|cobblestone-wall|link=Wall|text=Cobblestone Wall}} || 5 || - || - || - || - || - || - || 1 || 1 || 1 || 1 || - || 1 
|-
| {{BlockSprite|dirt|link=Dirt|text=Dirt}} || 22 || 22 || - || - || - || - || - || - || - || - || - || - || - 
|-
| {{BlockSprite|grass-block|link=Grass Block|text=Grass Block}} || 30 || 30 || - || - || - || - || - || - || - || - || - || - || - 
|-
| {{BlockSprite|glass-pane|link=Glass Pane|text=Glass Pane}} || 8 || - || - || 4 || - || - || - || 4 || - || - || - || - || - 
|-
| {{ItemSprite|oak-door|link=Door|text=Oak Door}} || 2 || - || 2 || - || - || - || - || - || - || - || - || - || - 
|-
| {{BlockSprite|oak-fence|link=Fence|text=Oak Fence}} || 15 || - || 15 || - || - || - || - || - || - || - || - || - || - 
|-
| {{BlockSprite|oak-log|link=Log|text=Oak Log}} || 78 || - || 4 || 12 || 4 || 22 || 4 || 12 || 4 || 16 || - || - || - 
|-
| {{BlockSprite|oak-planks|link=Oak Planks|text=Oak Planks}} || 27 || - || 1 || - || 1 || 6 || 12 || - || - || - || - || 7 || - 
|-
| {{BlockSprite|oak-stairs|link=Stairs|text=Oak Stairs}} || 92 || - || 3 || 1 || 1 || 30 || 8 || - || - || 18 || 18 || 13 || - 
|-
| {{BlockSprite|smoker|link=Smoker|text=Smoker}} || 1 || - || - || - || - || - || 1 || - || - || - || - || - || - 
|-
| {{BlockSprite|smooth-stone-slab|link=Slab|text=Smooth Stone Slab}} || 7 || 5 || 2 || - || - || - || - || - || - || - || - || - || - 
|-
| {{BlockSprite|torch|link=Torch|text=Torch}} || 9 || - || - || 2 || 4 || - || - || - || 2 || 1 || - || - || - 
|}





[[Category:Village blueprints]]