<noinclude>{{structure info}}</noinclude>

[[File:Plains Medium House 1.png|thumb|Medium house 1 (Plains)]]



==== Blueprint ====

{{layered blueprint
|name=Village Plains Houses plains_medium_house_1
|default=Layer 2
|C=Cobblestone
|O=Oak Log+top
|S=Stripped Oak Log+top
|s=Stripped Oak Log-rot90
|a=Stripped Oak Log
|P=Oak Planks
|L=Oak Stairs
|F=Oak Stairs-rot90
|>=Oak Stairs-rot180
|V=Oak Stairs-rot270
|I=Oak Fence
|h=Oak Pressure Plate
|D=Oak Door+bottom
|d=Oak Door+top
|i=Torch
|T=Torch-rot90
|t=Torch-rot180
|q=torch-rot270
|G=Glass Pane
|g=Glass Pane-rot90
|W=White Bed+top-head-rot270
|w=White Bed+top-foot-rot270
             
|----Layer 1|
             
             
    SCCCCCS  
    CPPPPPC  
    CPPPPPC  
    CPPPPPC  
    CPPPPPC  
  SCCPPPPPC  
  CPPPPPPPC  
  CPPPPPPPC  
  CPPPPPPPC  
  CPPPPPPPC  
  SCCCCCCCS  
    F        
             
|----Layer 2|
             
             
    SCCCCCS  
    CIW WIC  
    C w w C  
    C     C  
    C     C  
  SCC    IC  
  C       C  
  C       C  
  C       C  
  C   LI> C  
  SCDCCCCCS  
             
             
|----Layer 3|
             
       i     
    SCCCCCS  
    Oh t hO  
    G     G  
    G     G  
    O     O  
  SPP    ha  
  O       O  
  G       G  
  G       G  
  O    h  O  
  SsdsOgOsS  
   t t       
             
|----Layer 4|
             
   >P     PL 
   >SCCCCCSL 
   >C     CL 
   >C     CL 
   >C     CL 
 VVPC     CV 
 PSPP    qCP 
  C       C  
  C       C  
  C       C  
  C i     C  
 PSPPPPPPPSP 
 FFFFFFFFFFF 
             
|----Layer 5|
             
    >P   PL  
    >POgOPL  
    >P   PL  
    >P   PL  
    >P   PL  
    >P   PL  
 VVVPP   PVV 
 PPPPP   PPP 
  C      PC  
  C      PC  
 PPPPPPPPPPP 
 FFFFFFFFFFF 
             
             
|----Layer 6|
             
     >P PL   
     >PCPL   
     >P PL   
     >P PL   
     >P PL   
     >P PL   
     >P PL   
 VVVVPP PPVV 
 PPPPPPPPPPP 
 PPPPPPPPPPP 
 FFFFFFFFFFF 
             
             
             
|----Layer 7|
             
      >PL    
      >PL    
      >PL    
      >PL    
      >PL    
      >PL    
      >PL    
      >PL    
 VVVVVPPPVVV 
 FFFFFFFFFFF 
             
             
             
             
}}

This structure resembles the [[Village/Structure (old)/Blueprints/Large_house|old Large House]] seen in [[Village/Structure (old)/Blueprints |pre-1.14 villages]], with some minor changes. It also contains two white beds and some furniture, which the original structure lacked.



==== Materials ====

{| class="wikitable sortable mw-collapsible"
|-
! Name !! Total !! Layer 1 !! Layer 2 !! Layer 3 !! Layer 4 !! Layer 5 !! Layer 6 !! Layer 7 
|-
| {{BlockSprite|cobblestone|link=Cobblestone|text=Cobblestone}} || 93 || 31 || 30 || 5 || 22 || 4 || 1 || - 
|-
| {{BlockSprite|glass-pane|link=Glass Pane|text=Glass Pane}} || 10 || - || - || 9 || - || 1 || - || - 
|-
| {{ItemSprite|oak-door|link=Door|text=Oak Door}} || 1 || - || 1 || - || - || - || - || - 
|-
| {{BlockSprite|oak-fence|link=Fence|text=Oak Fence}} || 4 || - || 4 || - || - || - || - || - 
|-
| {{BlockSprite|oak-log|link=Log|text=Oak Log}} || 12 || - || - || 10 || - || 2 || - || - 
|-
| {{BlockSprite|oak-planks|link=Planks|text=Oak Planks}} || 158 || 53 || - || 2 || 16 || 36 || 40 || 11 
|-
| {{BlockSprite|oak-pressure-plate|link=Pressure Plate|text=Oak Pressure Plate}} || 4 || - || - || 4 || - || - || - || - 
|-
| {{BlockSprite|oak-stairs|link=Stairs|text=Oak Stairs}} || 121 || 1 || 2 || - || 24 || 28 || 31 || 35 
|-
| {{BlockSprite|stripped-oak-log|link=Log|text=Stripped Oak Log}} || 24 || 5 || 5 || 9 || 5 || - || - || - 
|-
| {{BlockSprite|torch|link=Torch|text=Torch}} || 6 || - || - || 4 || 2 || - || - || - 
|-
| {{BlockSprite|white-bed|link=Bed|text=White Bed}} || 2 || - || 2 || - || - || - || - || - 
|}





[[Category:Village blueprints]]