<noinclude>{{structure info}}</noinclude>

[[File:Taiga Large Farm 1.png|thumb|Large Farm 1 (Taiga)]]



==== Blueprint ====

{{layered blueprint|name=
Taiga Large Farm 1|default=Layer 1
|D=Dirt
|P=Pumpkin
|G=Grass Block+top
|S=Spruce Trapdoor
|F=Farmland
|W=Wheat
|A=Water+top
|C=Cobblestone Wall
|T=Torch
|R=Dirt Path+top
|O=Composter
|B=Cobblestone Stairs
            
|----Layer 1|
            
   D   R    
  GGGGGRDGG 
 D  GGRRGG  
   GDGRGGG  
  GGGGRGGG  
  GGGRRGGGD 
  GGGRRGG   
  GGDRGDG   
  DGRRGGGG  
    DD  D   
            
|----Layer 2|
            
   P SS SS  
   CSFF DFS 
 P SFF  FFS 
  SFAF FAFS 
 SFFFF BFS  
 SFFB  FFSP 
 SFAF  FFS  
 SFFO FAFS  
 SDF  FFSC  
  SS PSSP   
            
|----Layer 3|
            
            
   C WW PW  
    WW  WW  
   W W W W  
  WWWW  W   
  WW   WW   
  W W  WW   
  WW  W W   
  PW  WW C  
            
            
|----Layer 4|
            
            
   C        
            
            
            
            
            
            
         C  
            
            
|----Layer 5|
            
            
   T        
            
            
            
            
            
            
         T  
            
            
}}



==== Materials ====

{| class="wikitable sortable mw-collapsible"
|-
! Name !! Total !! Layer 1 !! Layer 2 !! Layer 3 !! Layer 4 !! Layer 5 
|-
| {{BlockSprite|Cobblestone Stairs|link=Cobblestone Stairs|text=Cobblestone Stairs}} || 2 || - || 2 || - || - || - 
|-
| {{BlockSprite|Cobblestone Wall|link=Cobblestone Wall|text=Cobblestone Wall}} || 6 || - || 2 || 2 || 2 || - 
|-
| {{BlockSprite|Composter|link=Composter|text=Composter}} || 1 || - || 1 || - || - || - 
|-
| {{BlockSprite|Dirt|link=Dirt|text=Dirt}} || 13 || 11 || 2 || - || - || - 
|-
| {{BlockSprite|Farmland|link=Farmland|text=Farmland}} || 31 || - || 31 || - || - || - 
|-
| {{BlockSprite|Grass Block|link=Grass Block|text=Grass Block}} || 43 || 43 || - || - || - || - 
|-
| {{BlockSprite|Dirt Path|link=Dirt Path|text=Dirt Path}} || 13 || 13 || - || - || - || - 
|-
| {{BlockSprite|Pumpkin|link=Pumpkin|text=Pumpkin}} || 7 || - || 5 || 2 || - || - 
|-
| {{BlockSprite|Spruce Trapdoor|link=Spruce Trapdoor|text=Spruce Trapdoor}} || 24 || - || 24 || - || - || - 
|-
| {{BlockSprite|Torch|link=Torch|text=Torch}} || 2 || - || - || - || - || 2 
|-
| {{BlockSprite|Water|link=Water|text=Water}} || 4 || - || 4 || - || - || - 
|-
| {{BlockSprite|Wheat|link=Wheat|text=Wheat}} || 31 || - || - || 31 || - || - 
|}





[[Category:Village blueprints]]