<noinclude>{{structure info}}</noinclude>

[[File:Savanna Meeting Point 3.png|thumb|Meeting Point 3 (Savanna)]]



==== Blueprint ====

{{layered blueprint|name=
Savanna Meeting Point 3|default=Layer 1
|A=Acacia Wood
|S=Acacia Slab
|C=Double Acacia Slab
|B=Bell
|D=Dirt Path+top
|T=Torch
|W=Water+top
|I=Acacia Fence
|R=Grass Block+top
             
|----Layer 1|
             
     DDD  R  
  R DDDDD    
  DDDDDDDDD  
 DDDDDDDDDDD 
 DDDADDDADDD 
 DDDDDDDDDDD 
  DDDDDDDDD  
   RDDDDD    
     DDD     
             
|----Layer 2|
             
             
             
             
   AAA AAA   
   AWA AWA   
   AAA AAA   
             
             
             
             
|----Layer 3|
             
             
             
             
   T I I T   
             
   T I I T   
             
             
             
             
|----Layer 4|
             
             
             
             
     I I     
      B      
     I I     
             
             
             
             
|----Layer 5|
             
             
             
             
     SSS     
     SCS     
     SSS     
             
             
             
             
|----Layer 6|
             
             
             
             
             
      T      
             
             
             
             
             
}}



==== Materials ====

{| class="wikitable sortable mw-collapsible"
|-
! Name !! Total !! Layer 1 !! Layer 2 !! Layer 3 !! Layer 4 !! Layer 5 !! Layer 6 
|-
| {{BlockSprite|acacia-fence|link=Acacia Fence|text=Acacia Fence}} || 8 || - || - || 4 || 4 || - || - 
|-
| {{BlockSprite|acacia-slab|link=Acacia Slab|text=Acacia Slab}} || 10 || - || - || - || - || 10 || - 
|-
| {{BlockSprite|acacia-wood|link=Acacia Wood|text=Acacia Wood}} || 18 || 2 || 16 || - || - || - || - 
|-
| {{BlockSprite|bell|link=Bell|text=Bell}} || 1 || - || - || - || 1 || - || - 
|-
| {{BlockSprite|grass-block|link=Grass Block|text=Grass Block}} || 3 || 3 || - || - || - || - || - 
|-
| {{BlockSprite|dirt-path|link=Dirt Path|text=Dirt Path}} || 65 || 65 || - || - || - || - || - 
|-
| {{BlockSprite|torch|link=Torch|text=Torch}} || 5 || - || - || 4 || - || - || 1 
|-
| {{BlockSprite|water|link=Water|text=Water}} || 2 || - || 2 || - || - || - || - 
|}





[[Category:Village blueprints]]