<noinclude>{{structure info}}</noinclude>

[[File:Plains Fletcher House 1.png|thumb|Fletcher house 1 (Plains)]]



==== Blueprint ====

{{layered blueprint
|name=Village Plains Fletcher House 1 plains_fletcher_house_1
|default=Layer 1
|c=Cobblestone
|e=Potted Dandelion
|d=Dirt
|D=Dirt Path+top
|F=Fletching Table-rot270
|P=Glass Pane
|a=Glass Pane-rot90
|g=Grass Block+top
|k=Oak Door+bottom
|K=Oak Door+top
|f=Oak Fence
|l=Oak Log
|O=Oak Log-rot90
|o=Oak Log+top
|p=Oak Planks
|s=Oak Slab
|v=Oak Stairs
|x=Oak Stairs-rot180
|y=Oak Stairs-rot270
|z=Oak Stairs-rot90
|t=Torch
|T=Torch-rot180
|W=White Wool
|r=Yellow Carpet
|Y=Yellow Wool
|b=Grass
|B=Tall Grass
|A=Tall Grass+bottom
             
|----Layer 0|
             
 ggggggggggg 
 gdddddddddg 
 gdpppppppdg 
 gdpppppppdg 
 gddpppppddg 
 gggdpppdggg 
 ggggdpdgggg 
 gggggDggggg 
 gggggDggggg 
             
|----Layer 1|
             
             
  occccccco  
  cF     pc  
  c  rrr pc  
  oc     co  
    p   p    
     pkp     
         b b 
     f f bAA 
             
|----Layer 2|
             
     t t     
  ocacacaco  
  P      eP  
  P       P  
  oc     co  
    p   p    
     pKp     
             
     f f  BB 
             
|----Layer 3|
             
             
  occccccco  
  c       c  
  c       c  
  oc     co  
    p t p    
     ppp     
      T      
     f f     
             
|----Layer 4|
             
 yyyz   xyyy 
 voOOOOOOOov 
  l  T T  l  
  l       l  
 yoc     coy 
 vvxp   pzvv 
    xpppz    
     sWs     
     sYs     
             
|----Layer 5|
             
    xz xz    
 yyyycccyyyy 
 vc x   z cv 
 yc x   z cy 
 vvvv   vvvv 
    xp pz    
     xpz     
             
             
             
|----Layer 6|
             
     xpz     
     xpz     
 yyyyxpzyyyy 
 vvvvvpvvvvv 
     xpz     
     xpz     
             
             
             
             
}}

All oak slabs in layer 4 are bottom slabs.



==== Materials ====

{|class="wikitable sortable mw-collapsible"
|-
! Name !! Total !! Layer 0 !! Layer 1 !! Layer 2 !! Layer 3 !! Layer 4 !! Layer 5 !! Layer 6 
|-
| {{BlockSprite|cobblestone|link=Cobblestone|text=Cobblestone}} || 41 || - || 13 || 6 || 13 || 2 || 7 || - 
|-
| {{BlockSprite|dirt|link=Dirt|text=Dirt}} || 21 || 21 || - || - || - || - || - || - 
|-
| {{BlockSprite|dirt-path|link=Dirt Path|text=Dirt Path}} || 2 || 2 || - || - || - || - || - || - 
|-
| {{BlockSprite|fletching-table|link=Fletching Table|text=Fletching Table}} || 1 || - || 1 || - || - || - || - || - 
|-
| {{BlockSprite|glass-pane|link=Glass Pane|text=Glass Pane}} || 7 || - || - || 7 || - || - || - || - 
|-
| {{BlockSprite|grass|link=Grass|text=Grass}} || 3 || - || 3 || - || - || - || - || - 
|-
| {{BlockSprite|grass-block|link=Grass Block|text=Grass Block}} || 53 || 53 || - || - || - || - || - || - 
|-
| {{ItemSprite|oak-door|link=Door|text=Oak Door}} || 1 || - || 1 || - || - || - || - || - 
|-
| {{BlockSprite|oak-fence|link=Fence|text=Oak Fence}} || 6 || - || 2 || 2 || 2 || - || - || - 
|-
| {{BlockSprite|oak-log|link=Log|text=Oak Log}} || 27 || - || 4 || 4 || 4 || 15 || - || - 
|-
| {{BlockSprite|oak-planks|link=Planks|text=Oak Planks}} || 52 || 23 || 6 || 4 || 5 || 5 || 3 || 6 
|-
| {{BlockSprite|oak-slab|link=Slab|text=Oak Slab}} || 4 || - || - || - || - || 4 || - || - 
|-
| {{BlockSprite|oak-stairs|link=Stairs|text=Oak Stairs}} || 80 || - || - || - || - || 20 || 32 || 28 
|-
| {{BlockSprite|potted-dandelion|link=Flower Pot|text=Potted Dandelion}} || 1 || - || - || 1 || - || - || - || - 
|-
| {{BlockSprite|tall-grass|link=Grass|text=Tall Grass}} || 2 || - || 2 || - || - || - || - || - 
|-
| {{BlockSprite|torch|link=Torch|text=Torch}} || 6 || - || - || 2 || 2 || 2 || - || - 
|-
| {{BlockSprite|white-wool|link=Wool|text=White Wool}} || 1 || - || - || - || - || 1 || - || - 
|-
| {{BlockSprite|yellow-carpet|link=Carpet|text=Yellow Carpet}} || 3 || - || 3 || - || - || - || - || - 
|-
| {{BlockSprite|yellow-wool|link=Wool|text=Yellow Wool}} || 1 || - || - || - || - || 1 || - || - 
|}





[[Category:Village blueprints]]