<noinclude>{{structure info}}</noinclude>

[[File:Plains Meeting Point 3.png|thumb|Meeting point 3 (Plains)]]



==== Blueprint ====

{{layered blueprint
|name=Meeting Point 3 meeting_point_3
|default=Layer 3
|p=Dirt Path+top
|g=Grass Block+top
|G=Grass
|c=Cobblestone
|d=Dirt
|o=Oak Log+top
|D=Dandelion
|l=Oak Leaves
|t=Torch
|T=Torch-rot180
|r=Torch-rot90
|R=Torch-rot270
|f=Oak Fence
|B=Bell+ceiling
|C=Cobblestone Stairs
|s=Cobblestone Stairs-rot90
|b=Cobblestone Stairs-rot180
|S=Cobblestone Stairs-rot270
             
|----Layer 0|
             
 ggcgpcgpggg 
 pgpcgpcgpcg 
 pcppcpgcgpg 
 gpcgppgpggc 
 ggpcdddppcg 
 pccpdddcgpp 
 cpcgdddpcgp 
 gpgccpccgpg 
 pgppgccgcpg 
 cpcggcgcpgp 
 gpppgppgggg 
             
|----Layer 1|
             
    G        
     f f     
       G G   
       G     
  G  sbb     
     soS G   
    GCCC     
 G         G 
  G  G       
    Df f     
        GG G 
             
|----Layer 2|
             
             
     f f     
             
             
             
      o      
             
             
             
     f f     
             
             
|----Layer 3|
             
             
     fBf     
             
             
      t      
     Ror     
      T      
             
             
     fBf     
             
             
|----Layer 4|
             
             
     fcf     
             
             
             
      o      
             
             
             
     fcf     
             
             
|----Layer 5|
             
             
             
             
      l      
    lllll    
    lloll    
    lllll    
      ll     
             
             
             
             
|----Layer 6|
             
             
             
             
     l l     
    lllll    
    lloll    
    lllll    
     lll     
             
             
             
             
|----Layer 7|
             
             
             
             
             
     lll     
     lol     
     lll     
             
             
             
             
             
|----Layer 8|
             
             
             
             
             
      l      
     lll     
      l      
             
             
             
             
             
}}

The oak tree in this structure is always the same. The bells in layer 3 hang beneath the cobblestone above them.



==== Materials ====

{| class="wikitable sortable mw-collapsible"
|-
! Name !! Total !! Layer 0 !! Layer 1 !! Layer 2 !! Layer 3 !! Layer 4 !! Layer 5 !! Layer 6 !! Layer 7 !! Layer 8 
|-
| {{BlockSprite|bell|link=Bell|text=Bell}} || 2 || - || - || - || 2 || - || - || - || - || - 
|-
| {{BlockSprite|cobblestone|link=Cobblestone|text=Cobblestone}} || 31 || 29 || - || - || - || 2 || - || - || - || - 
|-
| {{BlockSprite|cobblestone stairs|link=Stairs|text=Cobblestone Stairs}} || 8 || - || 8 || - || - || - || - || - || - || - 
|-
| {{BlockSprite|dandelion|link=Flower|text=Dandelion}} || 1 || - || 1 || - || - || - || - || - || - || - 
|-
| {{BlockSprite|dirt|link=Dirt|text=Dirt}} || 9 || 9 || - || - || - || - || - || - || - || - 
|-
| {{BlockSprite|dirt path|link=Dirt Path|text=Dirt Path}} || 38 || 38 || - || - || - || - || - || - || - || - 
|-
| {{BlockSprite|grass|link=Grass|text=Grass}} || 14 || - || 14 || - || - || - || - || - || - || - 
|-
| {{BlockSprite|grass block|link=Grass Block|text=Grass Block}} || 43 || 43 || - || - || - || - || - || - || - || - 
|-
| {{BlockSprite|oak fence|link=Fence|text=Oak Fence}} || 16 || - || 4 || 4 || 4 || 4 || - || - || - || - 
|-
| {{BlockSprite|oak leaves|link=Leaves|text=Oak Leaves}} || 49 || - || - || - || - || - || 17 || 19 || 8 || 5 
|-
| {{BlockSprite|oak log|link=Log|text=Oak Log}} || 7 || - || 1 || 1 || 1 || 1 || 1 || 1 || 1 || - 
|-
| {{BlockSprite|torch|link=Torch|text=Torch}} || 4 || - || - || - || 4 || - || - || - || - || - 
|}





[[Category:Village blueprints]]