<noinclude>{{structure info}}</noinclude>

[[File:Taiga Meeting Point 2.png|thumb|Meeting Point 2 (Taiga)]]



==== Blueprint ====

{{layered blueprint|name=
Taiga Meeting Point 2|default=Layer 1
|D=Dirt
|G=Grass Block+top
|C=Cobblestone
|M=Mossy Cobblestone
|S=Spruce Log-rot-90
|P=Spruce Log
|B=Bell+ceiling
|R=Dirt Path+top
|W=Wall Torch-rot-90
|U=Spruce Fence
|A=Water+top
|L=Wall Torch-rot-270
           
|----Layer 1|
           
    DDG D  
  DDDDDDD  
  DDDDDDD  
 DGDCMMDD  
 DDDMMMDAD 
 DDDMMMDDD 
  GDDDDDG  
  GGDDGGDD 
 D  DDD    
           
|----Layer 2|
           
    RRR G  
  RRRRRRR  
  RCCMCCR  
 RRMAAACRR 
 RRCAAACRR 
 RRCAAACRR 
 GRCCCCCR  
  RRRRRRRG 
 G  RRRG   
           
|----Layer 3|
           
           
           
   CCCCC   
   CAAAC   
   CAAAC   
   CAAAC   
   CCCCC   
           
           
|----Layer 4-5|
           
         
  
   U   U   
           
           
           
   U   U   
           
           
           
|----Layer 6|
           
           
           
  WSSSSSL  
   U   U   
   U B U   
   U   U   
  WSSSSSL  
           
           
           
|----Layer 7|
           
           
           
           
   SSSSS   
   SSSSS   
   SSSSS   
           
           
           
           
}}



==== Materials ====

{| class="wikitable sortable mw-collapsible"
|-
! Name !! Total !! Layer 1 !! Layer 2 !! Layer 3 !! Layer 4 !! Layer 5 !! Layer 6 !! Layer 7 
|-
| {{BlockSprite|Bell|link=Bell|text=Bell}} || 1 || - || - || - || - || - || 1 || - 
|-
| {{BlockSprite|Cobblestone|link=Cobblestone|text=Cobblestone}} || 31 || 1 || 14 || 16 || - || - || - || - 
|-
| {{BlockSprite|Dirt|link=Dirt|text=Dirt}} || 45 || 45 || - || - || - || - || - || - 
|-
| {{BlockSprite|Grass Block|link=Grass Block|text=Grass Block}} || 13 || 8 || 5 || - || - || - || - || - 
|-
| {{BlockSprite|Dirt Path|link=Dirt Path|text=Dirt Path}} || 36 || - || 36 || - || - || - || - || - 
|-
| {{BlockSprite|Mossy Cobblestone|link=Mossy Cobblestone|text=Mossy Cobblestone}} || 10 || 8 || 2 || - || - || - || - || - 
|-
| {{BlockSprite|Spruce Fence|link=Spruce Fence|text=Spruce Fence}} || 14 || - || - || - || 4 || 4 || 6 || - 
|-
| {{BlockSprite|Spruce Log|link=Spruce Log|text=Spruce Log}} || 25 || - || - || - || - || - || 10 || 15 
|-
| {{BlockSprite|Torch|link=Torch|text=Torch}} || 4 || - || - || - || - || - || 4 || - 
|-
| {{BlockSprite|Water|link=Water|text=Water}} || 19 || 1 || 9 || 9 || - || - || - || - 
|}





[[Category:Village blueprints]]