<noinclude>{{structure info}}</noinclude>

[[File:Desert Temple 2.png|thumb|Temple 2 (Desert)]]



==== Blueprint ====

{{layered blueprint|name=Desert Temple 2
|default=Layer 1
|S=Sand
|M=Smooth Sandstone
|L=Lime Glazed Terracotta-rot-180
|X=Lime Glazed Terracotta-rot-90
|Y=Lime Glazed Terracotta-rot-270
|Z=Lime Glazed Terracotta
|O=Smooth Sandstone Slab+Bottom
|d=Smooth Sandstone Slab+Top
|o=Double Smooth Sandstone Slab
|B=Brewing Stand
|T=Smooth Sandstone Stairs
|A=Sandstone Slab+Bottom
|a=Sandstone Slab+Top
|P=Potted Cactus
|W=Wall Torch-rot-180
|H=Smooth Sandstone Stairs-rot-180
|R=Wall Torch-rot-270
|C=Wall Torch-rot-90
              
|----Layer 0|
              
 SSSSSSSSSSSS 
 SSSSSMMSSSSS 
 SSSSMLXMSSSS 
 SSSSMYZMSSSS 
 SSSSSMMSSSSS 
 SMMMMMMMMMMS 
 SMMMMMMMMMMS 
 SMMMMMMMMMMS 
 SSSSSSSSSSSS 
 SSSSSSSSSSSS 
              
|----Layer 1|
              
      MM      
     M  M     
    M    M    
    M    M    
 MMMM    MMMM 
 MB OO  OO OM 
 M         OM 
 M          M 
 M M M  M M M 
 T P T  T P T 
              
|----Layer 2|
              
      MM      
     M  M     
    M    M    
    A    A    
 MAMMH  HMMAM 
 M          M 
 A          A 
 M          M 
 M M M  M M M 
              
              
|----Layer 3|
              
      MM      
     MRCM     
    M    M    
    a    a    
 MaMMMHHMMMaM 
 M  W    W  M 
 a          a 
 M          M 
 MdM MHHM MdM 
     W  W     
              
|----Layer 4|
              
      MM      
     M  M     
    M    M    
    M    M    
  OOMMMMMMOO  
 OMMMMMMMMMMO 
 OMMMMOOMMMMO 
 OMMMMOOMMMMO 
 MMMMMTTMMMMM 
              
              
|----Layer 5|
              
              
      OO      
     OMMO     
     OMMO     
      OO      
              
              
              
 TT TT  TT TT 
              
              
}}

For plains look beside the desert materials (the ones with no plains substitute are the same).



==== Materials ====

{| class="wikitable sortable mw-collapsible"
|-
! Name !! Total !! Layer 0 !! Layer 1 !! Layer 2 !! Layer 3 !! Layer 4 !! Layer 5 
|-
| {{BlockSprite|Brewing Stand|link=Brewing Stand|text=Brewing Stand}} || 1 || - || 1 || - || - || - || - 
|-
| {{BlockSprite|Lime Glazed Terracotta|link=Glazed Terracotta|text=Lime Glazed Terracotta}} || 4 || 4 || - || - || - || - || - 
|-
| {{BlockSprite|Potted Cactus|link=Flower Pot|text=Potted Cactus}} || 2 || - || 2 || - || - || - || - 
|-
| {{BlockSprite|Sand|link=Sand|text=Sand}} || 78 || 78 || - || - || - || - || - 
|-
| {{BlockSprite|Sandstone Slab|link=Slab|text=Sandstone Slab}} || 12 || - || - || 6 || 6 || - || - 
|-
| {{BlockSprite|Smooth Sandstone|link=Sandstone|text=Smooth Sandstone}} || 166 || 38 || 28 || 22 || 24 || 50 || 4 
|-
| {{BlockSprite|Smooth Sandstone Slab|link=Slab|text=Smooth Sandstone Slab}} || 30 || - || 6 || - || 2 || 14 || 8 
|-
| {{BlockSprite|Smooth Sandstone Stairs|link=Stairs|text=Smooth Sandstone Stairs}} || 20 || - || 4 || 2 || 4 || 2 || 8 
|-
| {{BlockSprite|Torch|link=Torch|text=Torch}} || 6 || - || - || - || 6 || - || - 
|}





[[Category:Village blueprints]]