<noinclude>{{structure info}}</noinclude>

[[File:Snowy Tundra Shepherds House 1.png|thumb|Shepherds house 1 (Snowy tundra)]]



==== Blueprint ====

{{layered blueprint
|name=Snowy Shepherds House 1 snowy_shepherds_house_1
|default=Layer 2
|l=Stripped Spruce Log+top
|L=Lantern
|f=Spruce Fence
|G=Grass
|g=Grass Block+top
|p=Spruce Planks
|m=Loom-rot270
|c=Chest
|x=Spruce Stairs
|o=Spruce Door+bottom
|O=Spruce Door+top
|t=Torch-rot180
|T=Torch-rot270
|S=Snow
|s=Spruce Slab
|i=Stripped Spruce Log-rot90
            
|----Layer 1|
            
 SSSSSSSSGS 
 SllllllllS 
 SlpppppplS 
 SlpppppplS 
 SlllllpplS 
 lggggglplS 
 lggggglplS 
 lggggglllS 
 llllllSxSS 
            
|----Layer 2|
            
 pppppp   p 
  llllllllp 
  lm    clp 
  lm     lp 
  lloll  lp 
 p     l lp 
 f     l lp 
 f     lolp 
 fffffp   p 
            
|----Layer 3|
            
 pppppp   p 
  llllllllp 
  l t    lp 
  l     Tlp 
  llOll  lp 
 p     l lp 
      Ll lp 
       lOlp 
 L    p   p 
            
|----Layer 4|
            
 s    sp ps 
 ppppppplp  
  l    p p  
  l    p p  
 ppppppp p  
 ssssssp p  
      sp p  
      spip  
      spLps 
            
|----Layer 5|
            
       sps  
 s      p   
 pppppppp   
 pppppppp   
 s      p   
        p   
        p   
        p   
       sps  
            
}}

All spruce slabs are bottom slabs. Also, the looms are put faces to the left.



==== Materials ====

{| class="wikitable sortable mw-collapsible"
|-
! Name !! Total !! Layer 1 !! Layer 2 !! Layer 3 !! Layer 4 !! Layer 5 
|-
| {{BlockSprite|chest|link=Chest|text=Chest}} || 1 || - || 1 || - || - || - 
|-
| {{BlockSprite|grass|link=Grass|text=Grass}} || 1 || 1 || - || - || - || - 
|-
| {{BlockSprite|grass-block|link=Grass Block|text=Grass Block}} || 15 || 15 || - || - || - || - 
|-
| {{BlockSprite|lantern|link=Lantern|text=Lantern}} || 3 || - || - || 2 || 1 || - 
|-
| {{BlockSprite|loom|link=Loom|text=Loom}} || 2 || - || 2 || - || - || - 
|-
| {{BlockSprite|snow|link=Snow|text=Snow}} || 23 || 23 || - || - || - || - 
|-
| {{ItemSprite|spruce-door|link=Door|text=Spruce Door}} || 2 || - || 2 || - || - || - 
|-
| {{BlockSprite|spruce-fence|link=Fence|text=Spruce Fence}} || 7 || - || 7 || - || - || - 
|-
| {{BlockSprite|spruce-planks|link=Planks|text=Spruce Planks}} || 103 || 16 || 17 || 17 || 30 || 23 
|-
| {{BlockSprite|spruce-slab|link=Slab|text=Spruce Slab}} || 19 || - || - || - || 13 || 6 
|-
| {{BlockSprite|spruce-stairs|link=Stairs|text=Spruce Stairs}} || 1 || 1 || - || - || - || - 
|-
| {{BlockSprite|stripped-spruce-log|link=Log|text=Stripped Spruce Log}} || 84 || 34 || 23 || 23 || 4 || - 
|-
| {{BlockSprite|torch|link=Torch|text=Torch}} || 2 || - || - || 2 || - || - 
|}





[[Category:Village blueprints]]