<noinclude>{{structure info}}</noinclude>

[[File:Taiga Animal Pen 1.png|thumb|Animal Pen 1 (Taiga)]]



==== Blueprint ====

{{layered blueprint|name=
Taiga Animal Pen 1|default=Layer 1
|G=Grass Block+top
|S=Spruce Planks
|P=Spruce Trapdoor
|R=Spruce Fence
|U=Spruce Fence Gate
|T=Torch
|C=Spruce Stairs
          
|----Layer 1|
          
  PPPPPP  
 PGGGGGGP 
 PGGGGGGP 
 PGGGGGGP 
 PGGGGGGP 
 PGGGGGGP 
 PGGGGGGC 
 PGGGGGGP 
 PGGGGGGP 
 PGGGGGGP 
 PGGGGGGP 
 PGGGGGGP 
  PPPPPP  
          
|----Layer 2|
          
          
  RRRRRR  
  R    R  
  R    R  
  R    R  
  R    R  
  R    U  
  R P  R  
  RP P R  
  RP P R  
  R P  R  
  RRRRRR  
          
          
|----Layer 3|
          
          
  R    R  
          
          
          
       R  
          
       R  
          
          
          
  R    R  
          
          
|----Layer 4|
          
          
          
          
          
          
       R  
      PSP 
       R  
          
          
          
          
          
          
|----Layer 5|
          
          
          
          
          
          
          
       T  
          
          
          
          
          
          
          
}}



==== Materials ====

{| class="wikitable sortable mw-collapsible"
|-
! Name !! Total !! Layer 1 !! Layer 2 !! Layer 3 !! Layer 4 !! Layer 5 
|-
| {{BlockSprite|Grass Block|link=Grass Block|text=Grass Block}} || 66 || 66 || - || - || - || - 
|-
| {{BlockSprite|Spruce Fence|link=Spruce Fence|text=Spruce Fence}} || 37 || - || 29 || 6 || 2 || - 
|-
| {{BlockSprite|Spruce Fence Gate|link=Spruce Fence Gate|text=Spruce Fence Gate}} || 1 || - || 1 || - || - || - 
|-
| {{BlockSprite|Spruce Planks|link=Spruce Planks|text=Spruce Planks}} || 1 || - || - || - || 1 || - 
|-
| {{BlockSprite|Spruce Stairs|link=Spruce Stairs|text=Spruce Stairs}} || 1 || 1 || - || - || - || - 
|-
| {{BlockSprite|Spruce Trapdoor|link=Spruce Trapdoor|text=Spruce Trapdoor}} || 41 || 33 || 6 || - || 2 || - 
|-
| {{BlockSprite|Torch|link=Torch|text=Torch}} || 1 || - || - || - || - || 1 
|}





[[Category:Village blueprints]]