<noinclude>{{structure info}}</noinclude>

[[File:Taiga Library 1.png|thumb|Library 1 (Taiga)]]



==== Blueprint ====

{{layered blueprint|name=
Taiga Library 1|default=Layer 1
|G=Grass Block+top
|D=Dirt
|S=Spruce Log-rot-90
|C=Cobblestone
|B=Bookshelf
|L=Lectern
|R=Dirt Path+top
|P=Spruce Trapdoor
|O=Cobblestone Wall
|T=Torch
|A=Large Fern
|b=Large Fern+bottom
|Y=Poppy
|W=Wall Torch-rot-90
|U=Spruce Door+bottom
|N=Glass Pane
|E=Spruce Door+top
|e=Red Carpet
|I=Spruce Stairs
|H=Wall Torch-rot-270
|u=Purple Carpet
|o=Cobblestone Stairs
|l=Glass Pane-rot-90
|a=Wall Torch
|r=Wall Torch-rot-180
|F=Fern
          
|----Layer 1|
          
          
 GDDDDDD  
 GDDCCCDG 
 GDDCCCD  
 GGDCCCD  
 RRCCCCD  
 GGDCCCD  
 GDDCCCDG 
 GDDCCCD  
 GDDDDDDG 
 G        
          
|----Layer 2|
          
  P       
 PGCCCCC  
 PGCIILCF 
 PGCeeeC  
 OPC   C  
   U C C  
 OPC C C  
 PGC o C  
 PGC   C  
 PGCCCCC  
  P       
          
|----Layer 3|
          
          
  bCClCC  
  PC   C  
  YN   N  
 T CH WC  
   E C N  
 T C o C  
   N   N  
  PC  WC  
  bCClCC  
          
          
|----Layer 4|
          
          
  ACCCCC  
   CCCCC  
   CCCCC  
   CCCCC  
   CCoCC  
   CC CC  
   CC CC  
   CC CC  
  ACCCCC  
          
          
|----Layer 5|
          
  SSSSSSS 
   CCCCC  
   CBBBC  
  PCuuuC  
 PGCuuuC  
 PGC   C  
 PGC   C  
  PC   C  
   C   C  
   CCCCC  
  SSSSSSS 
          
|----Layer 6|
          
          
  SSSSSSS 
   CBBBC  
  PC   N  
   N   C  
  PC   N  
  YN   C  
  PC   N  
   C   C  
  SSSSSSS 
          
          
|----Layer 7|
          
          
          
  SSSSSSS 
   C r C  
   C   C  
   C   C  
   C   C  
   C a C  
  SSSSSSS 
          
          
          
|----Layer 8|
          
          
          
          
  SSSSSSS 
   C   C  
  WCH WCH 
   C   C  
  SSSSSSS 
          
          
          
          
|----Layer 9|
          
          
          
          
          
  SSSSSSS 
   C   C  
  SSSSSSS 
          
          
          
          
          
|----Layer 10|
          
          
          
          
          
          
  SSSSSSS 
          
          
          
          
          
          
}}



==== Materials ====

{| class="wikitable sortable mw-collapsible"
|-
! Name !! Total !! Layer 1 !! Layer 2 !! Layer 3 !! Layer 4 !! Layer 5 !! Layer 6 !! Layer 7 !! Layer 8 !! Layer 9 !! Layer 10 
|-
| {{BlockSprite|Bookshelf|link=Bookshelf|text=Bookshelf}} || 6 || - || - || - || - || 3 || 3 || - || - || - || - 
|-
| {{BlockSprite|Cobblestone|link=Cobblestone|text=Cobblestone}} || 156 || 22 || 25 || 17 || 41 || 24 || 9 || 10 || 6 || 2 || - 
|-
| {{BlockSprite|Cobblestone Stairs|link=Cobblestone Stairs|text=Cobblestone Stairs}} || 3 || - || 1 || 1 || 1 || - || - || - || - || - || - 
|-
| {{BlockSprite|Cobblestone Wall|link=Cobblestone Wall|text=Cobblestone Wall}} || 2 || - || 2 || - || - || - || - || - || - || - || - 
|-
| {{BlockSprite|Dirt|link=Dirt|text=Dirt}} || 29 || 29 || - || - || - || - || - || - || - || - || - 
|-
| {{BlockSprite|Fern|link=Fern|text=Fern}} || 1 || - || 1 || - || - || - || - || - || - || - || - 
|-
| {{BlockSprite|Glass Pane|link=Glass Pane|text=Glass Pane}} || 12 || - || - || 7 || - || - || 5 || - || - || - || - 
|-
| {{BlockSprite|Grass Block|link=Grass Block|text=Grass Block}} || 23 || 14 || 6 || - || - || 3 || - || - || - || - || - 
|-
| {{BlockSprite|Dirt Path|link=Dirt Path|text=Dirt Path}} || 2 || 2 || - || - || - || - || - || - || - || - || - 
|-
| {{BlockSprite|Large Fern|link=Large Fern|text=Large Fern}} || 4 || - || - || 2 || 2 || - || - || - || - || - || - 
|-
| {{BlockSprite|Lectern|link=Lectern|text=Lectern}} || 1 || - || 1 || - || - || - || - || - || - || - || - 
|-
| {{BlockSprite|Poppy|link=Poppy|text=Poppy}} || 2 || - || - || 1 || - || - || 1 || - || - || - || - 
|-
| {{BlockSprite|Purple Carpet|link=Purple Carpet|text=Purple Carpet}} || 6 || - || - || - || - || 6 || - || - || - || - || - 
|-
| {{BlockSprite|Red Carpet|link=Red Carpet|text=Red Carpet}} || 3 || - || 3 || - || - || - || - || - || - || - || - 
|-
| {{BlockSprite|Spruce Door|link=Spruce Door|text=Spruce Door}} || 1 || - || 1 || - || - || - || - || - || - || - || - 
|-
| {{BlockSprite|Spruce Log|link=Spruce Log|text=Spruce Log}} || 77 || - || - || - || - || 14 || 14 || 14 || 14 || 14 || 7 
|-
| {{BlockSprite|Spruce Stairs|link=Spruce Stairs|text=Spruce Stairs}} || 2 || - || 2 || - || - || - || - || - || - || - || - 
|-
| {{BlockSprite|Spruce Trapdoor|link=Spruce Trapdoor|text=Spruce Trapdoor}} || 20 || - || 10 || 2 || - || 5 || 3 || - || - || - || - 
|-
| {{BlockSprite|Torch|link=Torch|text=Torch}} || 11 || - || - || 5 || - || - || - || 2 || 4 || - || - 
|}





[[Category:Village blueprints]]