<noinclude>{{structure info}}</noinclude>

[[File:Taiga Medium House 4.png|thumb|Medium House 4 (Taiga)]]



==== Blueprint ====

{{layered blueprint|name=
Taiga Medium House 4|default=Layer 1
|S=Spruce Log-rot-90
|D=Dirt
|P=Spruce Log+top
|C=Cobblestone
|R=Spruce Log
|U=Spruce Planks
|L=Purple Bed+top+head-rot-270
|E=Purple Bed+top+foot-rot-270
|B=Purple Bed+top+foot-rot-90
|u=Purple Bed+top+head-rot-90
|F=Furnace
|A=Campfire
|T=Spruce Trapdoor
|W=Wall Torch-rot-90
|G=Glass Pane
|O=Cobblestone Stairs-rot-180
|N=Cobblestone Stairs
|H=Wall Torch-rot-180
|a=Wall Torch
|I=Spruce Stairs
|l=Wall Torch-rot-270
|p=Spruce Door+bottom
|r=Spruce Door+top
|s=Dirt Path+top
           
|----Layer 1|
           
           
  DDDDDDD  
  DUUUUUD  
  DUUUUUD  
  DUUDCUCs 
  DUUUUUD  
  DUUUUUD  
  DDDDDDD  
           
           
|----Layer 2|
           
           
  PCCCCCP  
  Cu  IIC  
  CB T  C  
  CUTF  p  
  CE T  C  
  CL  IIC  
  PCCCCCP  
           
           
|----Layer 3|
           
 SSSSSSSSS 
  PCCCCCP  
 TC     C  
  G  a  C  
 TC  Cl r  
  G  H  C  
 TC     C  
  PCCCCCP  
 SSSSSSSSS 
           
|----Layer 4|
           
           
 SSSSSSSSS 
  R     P  
  C     C  
  C  C  C  
  C     C  
  R     P  
 SSSSSSSSS 
           
           
|----Layer 5|
           
           
           
 SSSSSSSSS 
  R OOO R  
 WR OAO Rl 
  R OOO R  
 SSSSSSSSS 
           
           
           
|----Layer 6|
           
           
           
           
 SSSCCCSSS 
 SSSC CSSS 
 SSSCCCSSS 
           
           
           
           
|----Layer 7|
           
           
           
           
    NNN    
    N N    
    NNN    
           
           
           
           
}}



==== Materials ====

{| class="wikitable sortable mw-collapsible"
|-
! Name !! Total !! Layer 1 !! Layer 2 !! Layer 3 !! Layer 4 !! Layer 5 !! Layer 6 !! Layer 7 
|-
| {{BlockSprite|Campfire|link=Campfire|text=Campfire}} || 1 || - || - || - || - || 1 || - || - 
|-
| {{BlockSprite|Cobblestone|link=Cobblestone|text=Cobblestone}} || 54 || 2 || 19 || 18 || 7 || - || 8 || - 
|-
| {{BlockSprite|Cobblestone Stairs|link=Cobblestone Stairs|text=Cobblestone Stairs}} || 16 || - || - || - || - || 8 || - || 8 
|-
| {{BlockSprite|Dirt|link=Dirt|text=Dirt}} || 24 || 24 || - || - || - || - || - || - 
|-
| {{BlockSprite|Furnace|link=Furnace|text=Furnace}} || 1 || - || 1 || - || - || - || - || - 
|-
| {{BlockSprite|Glass Pane|link=Glass Pane|text=Glass Pane}} || 2 || - || - || 2 || - || - || - || - 
|-
| {{BlockSprite|Dirt Path|link=Dirt Path|text=Dirt Path}} || 1 || 1 || - || - || - || - || - || - 
|-
| {{BlockSprite|Purple Bed|link=Purple Bed|text=Purple Bed}} || 2 || - || 2 || - || - || - || - || - 
|-
| {{BlockSprite|Spruce Door|link=Spruce Door|text=Spruce Door}} || 1 || - || 1 || - || - || - || - || - 
|-
| {{BlockSprite|Spruce Log|link=Spruce Log|text=Spruce Log}} || 90 || - || 4 || 22 || 22 || 24 || 18 || - 
|-
| {{BlockSprite|Spruce Planks|link=Spruce Planks|text=Spruce Planks}} || 24 || 23 || 1 || - || - || - || - || - 
|-
| {{BlockSprite|Spruce Stairs|link=Spruce Stairs|text=Spruce Stairs}} || 4 || - || 4 || - || - || - || - || - 
|-
| {{BlockSprite|Spruce Trapdoor|link=Spruce Trapdoor|text=Spruce Trapdoor}} || 6 || - || 3 || 3 || - || - || - || - 
|-
| {{BlockSprite|Torch|link=Torch|text=Torch}} || 5 || - || - || 3 || - || 2 || - || - 
|}





[[Category:Village blueprints]]