<noinclude>{{structure info}}</noinclude>

[[File:Plains Small House 5.png|thumb|Small house 5 (Plains)]]



==== Blueprint ====

{{layered blueprint
|name=Village Plains Houses plains_small_house_5
|default=Layer 2
|P=Oak Planks
|O=Oak Log+top
|L=Oak Log-rot90
|l=Oak Log
|B=White Bed+top foot-rot270
|b=White Bed+top head-rot270
|C=Cobblestone
|c=Cobblestone Stairs
|s=Oak Stairs
|<=Oak Stairs-rot90
|>=Oak Stairs-rot270
|d=Oak Door+bottom
|D=Oak Door+top
|g=glass Pane
|G=glass Pane-rot90
|T=torch
|t=torch-rot180
|F=Oak Fence
|p=Oak Pressure Plate
|R=green Carpet
|H=Ladder
|----Layer 1|
           
           
  OCCCCCO  
  CPPPPPC  
  CPPPPPC  
  CPPPPPC  
  OPPPPPO  
   CPPPC   
    CCC    
     c     
           
|----Layer 2|
           
           
  OPPPPPO  
  Pb  ssP  
  PB   FP  
  PH RR P  
  O     O  
   C   C   
    CdC    
           
           
|----Layer 3|
           
    T T    
  OPOGOPO  
  P     P  
  g    pg  
  PH    P  
  O     O  
   CT TC   
    CDC    
           
           
|----Layer 4|
           
           
  OPPPPPO  
  P     P  
  P     P  
  PHPPPPP  
  OPPPPPO  
   CPPPC   
    CCC    
     t     
           
|----Layer 5|
           
           
  OPPPPPO  
  l     l  
  l     l  
  l     l  
  OPdPdPO  
   F   F   
    FFF    
           
           
|----Layer 6|
           
    T T    
  OPOGOPO  
  P     P  
  P     P  
  P     P  
  OPDPDPO  
           
           
           
           
|----Layer 7|
           
 <>     <> 
 <OPPPPPO> 
 <P  t  P> 
 <P     P> 
 <P  T  P> 
 <OPPPPPO> 
 <>     <> 
           
           
           
|----Layer 8|
           
  <>   <>  
  <LLLLL>  
  <P   P>  
  <P   P>  
  <P   P>  
  <LLLLL>  
  <>   <>  
           
           
           
|----Layer 9|
           
   <> <>   
   <PPP>   
   <P P>   
   <P P>   
   <P P>   
   <PPP>   
   <> <>   
           
           
           
|----Layer 10|
           
    <P>    
    <P>    
    <P>    
    <P>    
    <P>    
    <P>    
    <P>    
           
           
           
}}



==== Materials ====

{| class="wikitable sortable mw-collapsible"
|-
! Name !! Total !! Layer 1 !! Layer 2 !! Layer 3 !! Layer 4 !! Layer 5 !! Layer 6 !! Layer 7 !! Layer 8 !! Layer 9 !! Layer 10 
|-
| {{BlockSprite|cobblestone|link=Cobblestone|text=Cobblestone}} || 29 || 16 || 4 || 4 || 5 || - || - || - || - || - || - 
|-
| {{BlockSprite|cobblestone-stairs|link=Stairs|text=Cobblestone Stairs}} || 1 || 1 || - || - || - || - || - || - || - || - || - 
|-
| {{BlockSprite|glass-pane|link=Glass Pane|text=Glass Pane}} || 4 || - || - || 3 || - || - || 1 || - || - || - || - 
|-
| {{BlockSprite|green-carpet|link=Carpet|text=Green Carpet}} || 2 || - || 2 || - || - || - || - || - || - || - || - 
|-
| {{BlockSprite|ladder|link=Ladder|text=Ladder}} || 3 || - || 1 || 1 || 1 || - || - || - || - || - || - 
|-
| {{ItemSprite|oak-door|link=Door|text=Oak Door}} || 3 || - || 1 || - || - || 2 || - || - || - || - || - 
|-
| {{BlockSprite|oak-fence|link=Fence|text=Oak Fence}} || 6 || - || 1 || - || - || 5 || - || - || - || - || - 
|-
| {{BlockSprite|oak-log|link=Log|text=Oak Log}} || 48 || 4 || 4 || 6 || 4 || 10 || 6 || 4 || 10 || - || - 
|-
| {{BlockSprite|oak-planks|link=Planks|text=Oak Planks}} || 123 || 23 || 11 || 6 || 23 || 8 || 11 || 16 || 6 || 12 || 7 
|-
| {{BlockSprite|oak-pressure-plate|link=Pressure Plate|text=Oak Pressure Plate}} || 1 || - || - || 1 || - || - || - || - || - || - || - 
|-
| {{BlockSprite|oak-stairs|link=Stairs|text=Oak Stairs}} || 70 || - || 2 || - || - || - || - || 18 || 18 || 18 || 14 
|-
| {{BlockSprite|torch|link=Torch|text=Torch}} || 9 || - || - || 4 || 1 || - || 2 || 2 || - || - || - 
|-
| {{BlockSprite|white-bed|link=Bed|text=White Bed}} || 1 || - || 1 || - || - || - || - || - || - || - || - 
|}





[[Category:Village blueprints]]