<noinclude>{{structure info}}</noinclude>

[[File:Desert Weaponsmith 1.png|thumb|Weaponsmith 1 (Desert)]]



==== Blueprint ====

{{layered blueprint|name=Desert Weaponsmith 1
|default=Layer 1
|C=Cut Sandstone
|S=Smooth Sandstone
|O=Cobblestone
|H=Chest-rot-180
|F=Furnace
|M=Smooth Sandstone Stairs
|A=Sandstone Slab+Bottom
|a=Sandstone Slab+Top
|T=Smooth Sandstone Slab
|N=Sandstone Wall
|D=Smooth Sandstone Stairs-rot-180
|I=Iron Bars
|P=Potted Cactus
|W=Wall Torch-rot-180
|G=Grindstone
|L=Lava+top
         
|----Layer 0|
         
  CCCCCC 
  CCCCCC 
 MCCCCCC 
 MCCCCCC 
 MCCCCCC 
 CCCCCCC 
 CSSSSC  
 CSSSSC  
 CSSSSC  
 CCCCCC  
         
|----Layer 1|
         
  CCCCCC 
  COOOOS 
    OLOS 
    OLOS 
    OOOS 
 C  CSCC 
 S    S  
 S   GS  
 SMH  S  
 CSSSSC  
         
|----Layer 2|
         
   P  CC 
  NIIIOS 
      OS 
      OS 
     FOS 
 C  CSCC 
 S    S  
 A    A  
 S    S  
 CSSSSC  
         
|----Layer 3|
         
      CC 
  NIIIOS 
      OS 
      OS 
     FOS 
 CDDCSCC 
 S  W S  
 a    a  
 S    S  
 CSSSSC  
         
|----Layer 4|
         
      CC 
  NIIIOS 
      OS 
      OS 
      OS 
 CSSCSSC 
 S    S  
 S    S  
 S    S  
 CSSSSC  
         
|----Layer 5|
         
      CC 
  TTTTTT 
  TT  TT 
  TT  TT 
  TTTTTT 
 CTTTTTC 
 TTTTTT  
 TTTTTT  
 TTTTTT  
 CTTTTC  
         
}}



==== Materials ====

{| class="wikitable sortable mw-collapsible"
|-
! Name !! Total !! Layer 0 !! Layer 1 !! Layer 2 !! Layer 3 !! Layer 4 !! Layer 5 
|-
| {{BlockSprite|Chest|link=Chest|text=Chest}} || 1 || - || 1 || - || - || - || - 
|-
| {{BlockSprite|Cobblestone|link=Cobblestone|text=Cobblestone}} || 23 || - || 11 || 4 || 4 || 4 || - 
|-
| {{BlockSprite|Cut Sandstone|link=Sandstone|text=Cut Sandstone}} || 91 || 49 || 13 || 8 || 8 || 7 || 6 
|-
| {{BlockSprite|Furnace|link=Furnace|text=Furnace}} || 2 || - || - || 1 || 1 || - || - 
|-
| {{BlockSprite|Grindstone|link=Grindstone|text=Grindstone}} || 1 || - || 1 || - || - || - || - 
|-
| {{BlockSprite|Iron Bars|link=Iron Bars|text=Iron Bars}} || 9 || - || - || 3 || 3 || 3 || - 
|-
| {{BlockSprite|Lava|link=Lava|text=Lava}} || 2 || - || 2 || - || - || - || - 
|-
| {{BlockSprite|Potted Cactus|link=Flower Pot|text=Potted Cactus}} || 1 || - || - || 1 || - || - || - 
|-
| {{BlockSprite|Sandstone Slab|link=Slab|text=Sandstone Slab}} || 4 || - || - || 2 || 2 || - || - 
|-
| {{BlockSprite|Sandstone Wall|link=Wall|text=Sandstone Wall}} || 3 || - || - || 1 || 1 || 1 || - 
|-
| {{BlockSprite|Smooth Sandstone|link=Sandstone|text=Smooth Sandstone}} || 71 || 12 || 15 || 13 || 13 || 18 || - 
|-
| {{BlockSprite|Smooth Sandstone Slab|link=Slab|text=Smooth Sandstone Slab}} || 47 || - || - || - || - || - || 47 
|-
| {{BlockSprite|Smooth Sandstone Stairs|link=Stairs|text=Smooth Sandstone Stairs}} || 6 || 3 || 1 || - || 2 || - || - 
|-
| {{BlockSprite|Torch|link=Torch|text=Torch}} || 1 || - || - || - || 1 || - || - 
|}





[[Category:Village blueprints]]