<noinclude>{{structure info}}</noinclude>

[[File:Plains Fountain 1.png|thumb|Fountain 1 (Plains)]]



==== Blueprint ====

{{layered blueprint
|name=Fountain 01 fountain_01
|default=Layer 2
|d=Dirt Path+top
|c=Cobblestone
|w=Water+top
|b=Bell
|t=Torch
           
|----Layer 0|
           
  ddddddd  
 ddddddddd 
 ddcccccdd 
 ddcccccdd 
 ddcccccdd 
 ddcccccdd 
 ddcccccdd 
 ddddddddd 
  ddddddd  
           
|----Layer 1|
           
           
           
   tccct   
   c   c   
   c c c   
   c   c   
   tccct   
           
           
           
|----Layer 2|
           
           
           
           
           
   b c     
           
           
           
           
           
|----Layer 3|
           
           
           
           
           
     w     
           
           
           
           
           
}}



==== Materials ====

{| class="wikitable sortable mw-collapsible"
|-
! Name !! Total !! Layer 0 !! Layer 1 !! Layer 2 !! Layer 3 
|-
| {{BlockSprite|bell|link=Bell|text=Bell}} || 1 || - || - || 1 || - 
|-
| {{BlockSprite|cobblestone|link=Cobblestone|text=Cobblestone}} || 39 || 25 || 13 || 1 || - 
|-
| {{BlockSprite|dirt-path|link=Dirt Path|text=Dirt Path}} || 52 || 52 || - || - || - 
|-
| {{BlockSprite|torch|link=Torch|text=Torch}} || 4 || - || 4 || - || - 
|-
| {{BlockSprite|water|link=Water|text=Water}} || 1 || - || - || - || 1 
|}





[[Category:Village blueprints]]