<noinclude>{{structure info}}</noinclude>

[[File:Desert Meeting Point 1.png|thumb|Meeting point 1 (Desert)]]



==== Blueprint ====

{{layered blueprint|name=Desert Meeting Point 1
|default=Layer 1
|S=Smooth Sandstone
|A=Sand
|C=Cut Sandstone
|T=Terracotta
|B=Bell
|P=Potted Cactus
|W=Water+top
|O=Torch
           
|----Layer 0|
           
    SSS    
  SSSSSSS  
  SSAAASS  
 SSASSSASS 
 SSASASASS 
 SSASSSASS 
 SSSAAASSS 
 SSSSSSSSS 
 SSSSSSSSS 
 SSSSSSSSS 
           
|----Layer 1|
           
           
           
    CCC    
   CWWWC   
   CWCWC   
   CWWWC   
    CCC    
           
           
           
           
|----Layer 2|
           
           
           
           
           
     C     
   P       
     B     
           
           
           
           
|----Layer 3|
           
           
           
           
           
     C     
           
           
           
           
           
           
|----Layer 4|
           
           
           
           
           
     T     
           
           
           
           
           
           
|----Layer 5|
           
           
           
           
           
     O     
           
           
           
           
           
           
}}

==== Materials ====

{| class="wikitable sortable mw-collapsible"
|-
! Name !! Total !! Layer 0 !! Layer 1 !! Layer 2 !! Layer 3 !! Layer 4 !! Layer 5 
|-
| {{BlockSprite|Bell|link=Bell|text=Bell}} || 1 || - || - || 1 || - || - || - 
|-
| {{BlockSprite|Cut Sandstone|link=Sandstone|text=Cut Sandstone}} || 15 || - || 13 || 1 || 1 || - || - 
|-
| {{BlockSprite|Potted Cactus|link=Flower Pot|text=Potted Cactus}} || 1 || - || - || 1 || - || - || - 
|-
| {{BlockSprite|Sand|link=Sand|text=Sand}} || 13 || 13 || - || - || - || - || - 
|-
| {{BlockSprite|Smooth Sandstone|link=Sandstone|text=Smooth Sandstone}} || 67 || 67 || - || - || - || - || - 
|-
| {{BlockSprite|Terracotta|link=Terracotta|text=Terracotta}} || 1 || - || - || - || - || 1 || - 
|-
| {{BlockSprite|Torch|link=Torch|text=Torch}} || 1 || - || - || - || - || - || 1 
|-
| {{BlockSprite|Water|link=Water|text=Water}} || 8 || - || 8 || - || - || - || - 
|}





[[Category:Village blueprints]]