<noinclude>{{structure info}}</noinclude>

[[File:Savanna Fisher Cottage 1.png|thumb|Fisher Cottage 1 (Savanna)]]



==== Blueprint ====

{{layered blueprint|name=
Savanna Fisher Cottage 1|default=Layer 1
|D=Dirt
|G=Grass Block+top
|A=Acacia Planks
|C=Acacia Slab
|I=Acacia Wood
|L=Acacia Log
|O=Acacia Log-rot-90
|B=Barrel
|S=Acacia Stairs
|R=Grass
|F=Acacia Fence
|W=Wall Torch-rot-90
|T=Water+top
|c=Acacia Door+bottom
|a=Acacia Door+top
|H=Wall Torch-rot-270
|P=Glass Pane
           
|----Layer 1|
           
    DDDDDD 
   DDDDDDD 
   DDDDDDD 
 DDDDDDDDD 
 DDDDDDDDD 
 DDDDDDDDD 
    DDDDDD 
      DDDD 
           
|----Layer 2|
           
    GGGGGG 
   DGTTTTG 
   GGTTFTG 
 GDGGTTTTG 
 DDGGGTFTG 
 GDGGDGTTG 
    GGGGGG 
      GGGG 
           
|----Layer 3|
           
    R      
   BR      
    F  F   
 SA        
 SA F  F   
 SAR B   R 
    F  FR  
       R   
           
|----Layer 4|
           
           
           
    F  F   
  SA       
  SAF  F   
  SA B     
    F  F   
           
           
|----Layer 5|
           
           
           
    F  F   
   SA      
   SF  F   
   SA      
    F  F   
           
           
|----Layer 6|
           
           
           
    AAAA   
    CAAA   
    CAAA   
    CAAA   
    AAAA   
           
           
|----Layer 7|
           
           
           
    ILLI   
     O O   
     c O   
     O O   
    ILLI   
           
           
|----Layer 8|
           
           
           
    ILLI   
    WO O   
     a P   
    WO O   
    ILLI   
           
           
|----Layer 9|
           
           
           
    ILLI   
     O O   
     OHO   
     O O   
    ILLI   
           
           
|----Layer 10|
           
           
   SSSSSS  
   SAAAAS  
   SAA AS  
   SAA AS  
   SAA AS  
   SAAAAS  
   SSSSSS  
           
|----Layer 11|
           
           
           
    SSSS   
    SAAS   
    SAAS   
    SAAS   
    SSSS   
           
           
}}



==== Materials ====

{| class="wikitable sortable mw-collapsible"
|-
! Name !! Total !! Layer 1 !! Layer 2 !! Layer 3 !! Layer 4 !! Layer 5 !! Layer 6 !! Layer 7 !! Layer 8 !! Layer 9 !! Layer 10 !! Layer 11 
|-
| {{BlockSprite|acacia-door|link=Acacia Door|text=Acacia Door}} || 1 || - || - || - || - || - || - || 1 || - || - || - || - 
|-
| {{BlockSprite|acacia-fence|link=Acacia Fence|text=Acacia Fence}} || 20 || - || 2 || 6 || 6 || 6 || - || - || - || - || - || - 
|-
| {{BlockSprite|acacia-log|link=Acacia Log|text=Acacia Log}} || 27 || - || - || - || - || - || - || 9 || 8 || 10 || - || - 
|-
| {{BlockSprite|acacia-planks|link=Acacia Planks|text=Acacia Planks}} || 31 || - || - || 3 || 3 || 2 || - || - || - || - || 17 || 6 
|-
| {{BlockSprite|acacia-slab|link=Acacia Slab|text=Acacia Slab}} || 37 || - || - || - || - || - || 37 || - || - || - || - || - 
|-
| {{BlockSprite|acacia-stairs|link=Acacia Stairs|text=Acacia Stairs}} || 45 || - || - || 3 || 3 || 3 || - || - || - || - || 22 || 14 
|-
| {{BlockSprite|acacia-wood|link=Acacia Wood|text=Acacia Wood}} || 12 || - || - || - || - || - || - || 4 || 4 || 4 || - || - 
|-
| {{BlockSprite|barrel|link=Barrel|text=Barrel}} || 3 || - || - || 2 || 1 || - || - || - || - || - || - || - 
|-
| {{BlockSprite|dirt|link=Dirt|text=Dirt}} || 63 || 57 || 6 || - || - || - || - || - || - || - || - || - 
|-
| {{BlockSprite|glass-pane|link=Glass Pane|text=Glass Pane}} || 1 || - || - || - || - || - || - || - || 1 || - || - || - 
|-
| {{BlockSprite|grass|link=Grass|text=Grass}} || 6 || - || - || 6 || - || - || - || - || - || - || - || - 
|-
| {{BlockSprite|grass-block|link=Grass Block|text=Grass Block}} || 34 || - || 34 || - || - || - || - || - || - || - || - || - 
|-
| {{BlockSprite|torch|link=Torch|text=Torch}} || 3 || - || - || - || - || - || - || - || 2 || 1 || - || - 
|-
| {{BlockSprite|water|link=Water|text=Water}} || 15 || - || 15 || - || - || - || - || - || - || - || - || - 
|}





[[Category:Village blueprints]]