<noinclude>{{structure info}}</noinclude>

[[File:Snowy Tundra Meeting Point 1.png|thumb|Meeting point 1 (Snowy tundra)]]



==== Blueprint ====

{{layered blueprint
|name=Snowy Meeting Point 1 snowy_meeting_point_1
|default=Layer 2
|g=Grass Block+top
|d=Dirt
|p=Dirt Path+top
|w=Stripped Spruce Wood
|P=Packed Ice
|s=Snow
|b=Bell
              
|----Layer 0|
              
 ggpppggggggg 
 pppppppppppp 
 ppdppddddppp 
 pppppddddppp 
 gppppddddppg 
 ggpppddddppg 
 gggppppppppg 
 ggggggggpppg 
              
|----Layer 1|
              
 s       s ss 
   P  wwww    
      wPPw    
 s    wPPw  s 
 s    wwww  s 
 s          s 
 ssssss     s 
              
|----Layer 2|
              
              
   b  ssss    
      sPPs    
      sPPs    
      ssss    
|----Layer 3-5|
              
       P      
        P     
|----Layer 6-7|
              
       P      
              
}}



==== Materials ====

{| class="wikitable sortable mw-collapsible"
|-
! Name !! Total !! Layer 0 !! Layer 1 !! Layer 2 !! Layer 3 !! Layer 4 !! Layer 5 !! Layer 6 !! Layer 7 
|-
| {{BlockSprite|bell|link=Bell|text=Bell}} || 1 || - || - || 1 || - || - || - || - || - 
|-
| {{BlockSprite|dirt|link=Dirt|text=Dirt}} || 17 || 17 || - || - || - || - || - || - || - 
|-
| {{BlockSprite|dirt-path|link=Dirt Path|text=Dirt Path}} || 52 || 52 || - || - || - || - || - || - || - 
|-
| {{BlockSprite|grass-block|link=Grass Block|text=Grass Block}} || 27 || 27 || - || - || - || - || - || - || - 
|-
| {{BlockSprite|packed-ice|link=Packed Ice|text=Packed Ice}} || 17 || - || 5 || 4 || 2 || 2 || 2 || 1 || 1 
|-
| {{BlockSprite|snow|link=Snow|text=Snow}} || 29 || - || 17 || 12 || - || - || - || - || - 
|-
| {{BlockSprite|stripped-spruce-wood|link=Wood|text=Stripped Spruce Wood}} || 12 || - || 12 || - || - || - || - || - || - 
|}





[[Category:Village blueprints]]