<noinclude>{{structure info}}</noinclude>

[[File:Plains library 1.png|thumb|Library 1 (Plains)]]



==== Blueprint ====

{{layered blueprint|name=
Plains Library 1|default=Layer 1
|O=Oak Planks
|A=Oak Log+top
|C=Cobblestone
|B=Bookshelf
|L=Lectern
|K=Oak Stairs
|S=Oak Stairs-rot-180
|W=Wall Torch-rot-180
|G=Glass Pane
|T=Wall Torch-rot-270
|E=Cobblestone Stairs
|P=Glass Pane-rot-90
|R=Wall Torch
|F=Oak Fence
|D=Oak Door+bottom
|a=Oak Door+top
|H=Wall Torch-rot-90
                   
|----Layer 1|
                   
                   
  ACCCCCCCCCCCCCA  
  CCCCCCCCCCCCCCC  
  CCCCCCCCCCCCCCC  
  CCCCCCCCCCCCCCC  
  CCCCCCCCCCCCCCC  
  CCCCCCCCCCCCCCC  
  ACCCACCCCCACCCA  
       CCCCC       
        CCC        
         E         
                   
|----Layer 2|
                   
                   
  AOOOOOOOOOOOOOA  
  OKKKBBB BBBKKKO  
  OK           KO  
  O             O  
  O ECCL   LCCE O  
  O             O  
  AOOOA     AOOOA  
       C   C       
        CDC        
                   
                   
|----Layer 3|
                   
       R   R       
  AOAPAOAPAOAPAOA  
  O    B   B    O  
  A             A  
  G             G  
  A  EC     CE  A  
  O             O  
  AOPOA     AOPOA  
  W    C   C    W  
        CaC        
        W W        
                   
|----Layer 4|
                   
                   
  AOOOOOOOOOOOOOA  
  O             O  
  O             O  
  O    R   R    O  
  O   EOOOOOE   O  
  O    OOOOO    O  
  AOOOAOOOOOAOOOA  
       COOOC       
        CCC        
                   
                   
|----Layer 5|
                   
                   
  AAAAAAAAAAAAAAA  
  A             A  
  A             A  
  A             A  
  A             A  
  A      K      A  
  AAAAAODODOAAAAA  
       F   F       
        FFF        
                   
                   
|----Layer 6|
                   
 KKKKKKKKKKKKKKKKK 
 SAOOOOOOOOOOOOOAS 
  O             O  
  O             O  
  O             O  
  O             O  
  O             O  
 SAOOOAOaOaOAOOOAS 
 KKKKK       KKKKK 
                   
                   
                   
|----Layer 7|
                   
                   
 KKKKKKKKKKKKKKKKK 
 SOOOOOOOOOOOOOOOS 
  O             O  
  OT           HO  
  O             O  
 SOOOOO     OOOOOS 
 KKKKKAOOOOOAKKKKK 
                   
                   
                   
                   
|----Layer 8|
                   
                   
                   
 KKKKKKKKKKKKKKKKK 
 SAOOOOOOOOOOOOOAS 
  A             A  
 SAOOOOO   OOOOOAS 
 KKKKKKO   OKKKKKK 
      KAAAAAK      
      KS   SK      
                   
                   
                   
|----Layer 9|
                   
                   
                   
                   
 KKKKKKKKKKKKKKKKK 
 OOOOOOOOOOOOOOOOO 
 KKKKKKKO OKKKKKKK 
       KO OK       
       KOOOK       
       KS SK       
                   
                   
                   
|----Layer 10|
                   
                   
                   
                   
                   
        KKK        
        KOK        
        KOK        
        KOK        
        KOK        
                   
                   
                   
}}

This structure resembles the [[Village/Structure_(old)/Blueprints/Library|old Library]] seen in [[Village/Structure (old)/Blueprints |pre-1.14 villages]], with significant changes.



==== Materials ====

{| class="wikitable sortable mw-collapsible"
|-
! Name !! Total !! Layer 1 !! Layer 2 !! Layer 3 !! Layer 4 !! Layer 5 !! Layer 6 !! Layer 7 !! Layer 8 !! Layer 9 !! Layer 10 
|-
| {{BlockSprite|bookshelf|link=Bookshelf|text=Bookshelf}} || 8 || - || 6 || 2 || - || - || - || - || - || - || - 
|-
| {{BlockSprite|cobblestone|link=Cobblestone|text=Cobblestone}} || 126 || 107 || 8 || 6 || 5 || - || - || - || - || - || - 
|-
| {{BlockSprite|cobblestone-stairs|link=Stairs|text=Cobblestone Stairs}} || 7 || 1 || 2 || 2 || 2 || - || - || - || - || - || - 
|-
| {{BlockSprite|glass-pane|link=Glass Pane|text=Glass Pane}} || 7 || - || - || 7 || - || - || - || - || - || - || - 
|-
| {{BlockSprite|lectern|link=Lectern|text=Lectern}} || 2 || - || 2 || - || - || - || - || - || - || - || - 
|-
| {{ItemSprite|oak-door|link=Door|text=Oak Door}} || 3 || - || 1 || - || - || 2 || - || - || - || - || - 
|-
| {{BlockSprite|oak-fence|link=Fence|text=Oak Fence}} || 5 || - || - || - || - || 5 || - || - || - || - || - 
|-
| {{BlockSprite|oak-log|link=Log|text=Oak Log}} || 88 || 6 || 6 || 16 || 6 || 35 || 6 || 2 || 11 || - || - 
|-
| {{BlockSprite|oak-planks|link=Planks|text=Oak Planks}} || 212 || - || 29 || 12 || 47 || 3 || 32 || 36 || 25 || 24 || 4 
|-
| {{BlockSprite|oak-stairs|link=Stairs|text=Oak Stairs}} || 160 || - || 8 || - || - || 1 || 31 || 31 || 39 || 39 || 11 
|-
| {{BlockSprite|torch|link=Torch|text=Torch}} || 10 || - || - || 6 || 2 || - || - || 2 || - || - || - 
|}





[[Category:Village blueprints]]