<noinclude>{{structure info}}</noinclude>

[[File:Savanna Small House 2.png|thumb|Small House 2 (Savanna)]]



==== Blueprint ====

{{layered blueprint|name=Savanna Small House 2|default=Layer 1
|G=grass block+top
|D=dirt
|R=red terracotta
|A=acacia planks
|C=acacia wood
|I=acacia wood-rot-90
|H=chest-rot-90
|E=Red Bed+side+head-rot-180
|B=Red Bed+side+foot-rot-180
|S=grass
|L=glass pane
|s=acacia stairs
|>=acacia stairs-rot-90
|^=acacia stairs-rot-180
|<=acacia stairs-rot-270
|W=Wall Torch-rot-270
|P=glass pane-rot-90
|O=acacia door+bottom
|d=acacia door+top
|g=Dirt path+top
         
|----Layer 1|
         
 GGGGGGG 
 GGDDDGG 
 GDCCCDD 
 GDCCCIg 
 GDCICDG 
 GGDDDGG 
 GGGGGGG 
         
|----Layer 2|
         
 S S S   
 SSRRR   
 SREB R  
 SR   O  
  RH  R  
 SSRRRSS 
 S     S 
         
|----Layer 3|
         
         
   RPR   
  R   R  
  L   d  
  R   R  
   RPR   
         
         
|----Layer 4|
         
         
   RRR   
  R   R  
  RW  RW 
  R   R  
   RRR   
         
         
|----Layer 5|
         
  ^^^^^  
 <AAAAA> 
 <A   A> 
 <A   A> 
 <A   A> 
 <AAAAA> 
  sssss  
         
|----Layer 6|
         
         
  <^^^>  
  <AAA>  
  <AAA>  
  <AAA>  
  sssss  
         
         
|----Layer 7|
         
         
         
   ^^>   
   <A>   
   <ss   
         
         
         
}}



==== Materials ====

{| class="wikitable sortable mw-collapsible"
|-
! Name !! Total !! Layer 1 !! Layer 2 !! Layer 3 !! Layer 4 !! Layer 5 !! Layer 6 !! Layer 7 
|-
| {{BlockSprite|acacia-door|link=Acacia Door|text=Acacia Door}} || 1 || - || 1 || - || - || - || - || - 
|-
| {{BlockSprite|acacia-planks|link=Acacia Planks|text=Acacia Planks}} || 26 || - || - || - || - || 16 || 9 || 1 
|-
| {{BlockSprite|acacia-stairs|link=Acacia Stairs|text=Acacia Stairs}} || 44 || - || - || - || - || 20 || 16 || 8 
|-
| {{BlockSprite|acacia-wood|link=Acacia Wood|text=Acacia Wood}} || 10 || 10 || - || - || - || - || - || - 
|-
| {{BlockSprite|chest|link=Chest|text=Chest}} || 1 || - || 1 || - || - || - || - || - 
|-
| {{BlockSprite|dirt|link=Dirt|text=Dirt}} || 12 || 12 || - || - || - || - || - || - 
|-
| {{BlockSprite|glass-pane|link=Glass Pane|text=Glass Pane}} || 3 || - || - || 3 || - || - || - || - 
|-
| {{BlockSprite|grass|link=Grass|text=Grass}} || 13 || - || 13 || - || - || - || - || - 
|-
| {{BlockSprite|grass-block|link=Grass Block|text=Grass Block}} || 26 || 26 || - || - || - || - || - || - 
|-
| {{BlockSprite|dirt-path|link=Dirt Path|text=Dirt Path}} || 1 || 1 || - || - || - || - || - || - 
|-
| {{BlockSprite|red-bed|link=Red Bed|text=Red Bed}} || 1 || - || 1 || - || - || - || - || - 
|-
| {{BlockSprite|red-terracotta|link=Red Terracotta|text=Red Terracotta}} || 31 || - || 11 || 8 || 12 || - || - || - 
|-
| {{BlockSprite|torch|link=Torch|text=Torch}} || 2 || - || - || - || 2 || - || - || - 
|}





[[Category:Village blueprints]]