<noinclude>{{structure info}}</noinclude>

[[File:Taiga Masons House 1.png|thumb|Masons House 1 (Taiga)]]



==== Blueprint ====

{{layered blueprint|name=
Taiga Masons House 1|default=Layer 1
|G=Grass Block+top
|S=Spruce Log
|D=Dirt
|C=Cobblestone
|P=Spruce Planks
|R=Spruce Fence
|U=Spruce Trapdoor
|O=Potted Spruce Sapling
|W=Wall Torch-rot-180
|E=Spruce Door+bottom
|T=Stonecutter
|p=Spruce Door+top
|L=Glass Pane-rot-90
|B=Cobblestone Stairs
           
|----Layer 1|
           
 G       G 
  DDDDDDDG 
  DDDDDDDG 
  DDDDDDDG 
  DDDDDDDG 
  GGDDDGGG 
 GGGGDGGGG 
 GGGGGGGGG 
           
|----Layer 2|
           
 R       R 
  CCCCCCC  
  CPPPPPC  
  CPPPPPC  
  CCPPPCC  
   UCCCU   
 RU UBU UR 
   U   U   
           
|----Layer 3|
           
 S       S 
 SCCCCCCCS 
 SR  T  RS 
 SR     RS 
 SCCO BCCS 
 S  CEC  S 
 S       S 
           
           
|----Layer 4|
           
  S U U S  
  SCCLCCS  
  S     S  
  S     S  
  SC   CS  
  S CpC S  
  S W W S  
           
           
|----Layer 5|
           
   S   S   
   SCCCS   
   S W S   
   S   S   
   S   S   
   SCCCS   
   S   S   
           
           
|----Layer 6|
           
    S S    
    SCS    
    S S    
    S S    
    S S    
    SCS    
    S S    
           
           
|----Layer 7|
           
     S     
     S     
     S     
     S     
     S     
     S     
     S     
           
           
}}



==== Materials ====

{| class="wikitable sortable mw-collapsible"
|-
! Name !! Total !! Layer 1 !! Layer 2 !! Layer 3 !! Layer 4 !! Layer 5 !! Layer 6 !! Layer 7 
|-
| {{BlockSprite|Cobblestone|link=Cobblestone|text=Cobblestone}} || 47 || - || 18 || 13 || 8 || 6 || 2 || - 
|-
| {{BlockSprite|Cobblestone Stairs|link=Cobblestone Stairs|text=Cobblestone Stairs}} || 2 || - || 1 || 1 || - || - || - || - 
|-
| {{BlockSprite|Dirt|link=Dirt|text=Dirt}} || 32 || 32 || - || - || - || - || - || - 
|-
| {{BlockSprite|Glass Pane|link=Glass Pane|text=Glass Pane}} || 1 || - || - || - || 1 || - || - || - 
|-
| {{BlockSprite|Grass Block|link=Grass Block|text=Grass Block}} || 28 || 28 || - || - || - || - || - || - 
|-
| {{BlockSprite|Potted Spruce Sapling|link=Potted Spruce Sapling|text=Potted Spruce Sapling}} || 1 || - || - || 1 || - || - || - || - 
|-
| {{BlockSprite|Spruce Door|link=Spruce Door|text=Spruce Door}} || 1 || - || - || 1 || - || - || - || - 
|-
| {{BlockSprite|Spruce Fence|link=Spruce Fence|text=Spruce Fence}} || 8 || - || 4 || 4 || - || - || - || - 
|-
| {{BlockSprite|Spruce Log|link=Spruce Log|text=Spruce Log}} || 63 || - || - || 14 || 14 || 14 || 14 || 7 
|-
| {{BlockSprite|Spruce Planks|link=Spruce Planks|text=Spruce Planks}} || 13 || - || 13 || - || - || - || - || - 
|-
| {{BlockSprite|Spruce Trapdoor|link=Spruce Trapdoor|text=Spruce Trapdoor}} || 10 || - || 8 || - || 2 || - || - || - 
|-
| {{BlockSprite|Stonecutter|link=Stonecutter|text=Stonecutter}} || 1 || - || - || 1 || - || - || - || - 
|-
| {{BlockSprite|Torch|link=Torch|text=Torch}} || 3 || - || - || - || 2 || 1 || - || - 
|}





[[Category:Village blueprints]]