<noinclude>{{structure info}}</noinclude>

[[File:Plains tool smith house 1.png|thumb|Tool smith house 1 (Plains)]]



==== Blueprint ====

{{layered blueprint
|name=Village Plains Houses plains_tool_smith_house_1
|default=Layer 3
|O=Oak Log+top
|L=Oak Log-rot90
|l=Oak Log
|P=Oak Planks
|d=Oak Door+bottom
|D=Oak Door+top
|s=Oak Stairs
|<=Oak Stairs-rot90
|^=Oak Stairs-rot180
|>=Oak Stairs-rot270
|C=Cobblestone
|c=Cobblestone Stairs
|T=torch
|t=torch-rot180
|k=torch-rot270
|G=glass Pane-rot90
|Q=Smithing Table-rot270
|----Layer 1|
              
              
  OCCCCCCCCO  
  CCCCCCCCCC  
  CCCCCCCCCC  
  OCCCCCOCCC  
        CCCC  
        OCCO  
         cc   
              
|----Layer 2|
              
              
  OPPPPPPPPO  
  PQ       P  
  PP       P  
  OPPPPPO  P  
        P  P  
        OddO  
              
              
|----Layer 3|
              
              
 kOPLGLLGLPO  
  P        P  
  P        P  
 kOPLGLPO  P  
        P  P  
        ODDO  
        t  t  
              
|----Layer 4|
              
 ^^^^^^^^^^^^ 
 sOPPPPPPPPOs 
  P  t  t  P  
  P        P  
 ^OPPPPPO  P^ 
 sssssssP  P> 
       <OPPO> 
       <>  <> 
              
|----Layer 5|
              
              
 ^^^^^^^^^^^^ 
 sP        Ps 
 ^P        P^ 
 ssssssssTTss 
        <PP>  
        <PP>  
        <><>  
|----Layer 6|
              
              
              
 ^^^^^^^^^^^^ 
 sssssssss>ss 
         <>   
         <>   
         <>   
         <>   
              
}}



==== Materials ====

{| class="wikitable sortable mw-collapsible"
|-
! Name !! Total !! Layer 1 !! Layer 2 !! Layer 3 !! Layer 4 !! Layer 5 !! Layer 6 
|-
| {{BlockSprite|cobblestone|link=Cobblestone|text=Cobblestone}} || 42 || 42 || - || - || - || - || - 
|-
| {{BlockSprite|cobblestone-stairs|link=Stairs|text=Cobblestone Stairs}} || 2 || 2 || - || - || - || - || - 
|-
| {{BlockSprite|glass-pane|link=Glass Pane|text=Glass Pane}} || 3 || - || - || 3 || - || - || - 
|-
| {{ItemSprite|oak-door|link=Door|text=Oak Door}} || 2 || - || 2 || - || - || - || - 
|-
| {{BlockSprite|oak-log|link=Log|text=Oak Log}} || 30 || 6 || 6 || 12 || 6 || - || - 
|-
| {{BlockSprite|oak-planks|link=Planks|text=Oak Planks}} || 62 || - || 21 || 11 || 22 || 8 || - 
|-
| {{BlockSprite|oak-stairs|link=Stairs|text=Oak Stairs}} || 96 || - || - || - || 30 || 34 || 32 
|-
| {{BlockSprite|smithing-table|link=Smithing Table|text=Smithing Table}} || 1 || - || 1 || - || - || - || - 
|-
| {{BlockSprite|torch|link=Torch|text=Torch}} || 8 || - || - || 4 || 2 || 2 || - 
|}





[[Category:Village blueprints]]