<noinclude>{{structure info}}</noinclude>

[[File:Snowy Tundra Tannery.png|thumb|Tannery (Snowy tundra)]]



==== Blueprint ====

{{layered blueprint|name=Village Snowy Houses snowy_tannery_1
|default=Layer 2
|x=Snow
|y=Snow Block
|z=Grass
|S=Stripped Spruce Log+top
|L=Stripped Spruce Log-rot180
|P=Spruce Planks
|s=Spruce Slab
|o=Spruce Stairs
|(=Spruce Stairs-rot90
|)=Spruce Stairs-rot270
|f=Spruce Fence
|h=Spruce Door+bottom
|H=Spruce Door+top
|D=Diorite
|d=Diorite Wall
|g=Glass Pane
|t=Torch
|l=Lantern
|w=Water Cauldron
|c=Chest
|F=Furnace
|----Layer 1|
           
 xxxzzxxxx 
 xSSSSSSSx 
 xSSDDDSSx 
 ySSDDDSSx 
 xSSDDDSSx 
 xSSSSSSSx 
 xLSSSSSLx 
 yxxxoyyxx 
           
|----Layer 2|
           
 s       s 
 PSSSSSSSP 
 PS) S cSP 
 sS) F  Ss 
 sS     Ss 
 PSw   wSP 
 PSLShSLSP 
 s     y s 
           
|----Layer 3|
           
 P       P 
 PSSLSLSSP 
 PS     SP 
 PS  d  SP 
 PS     SP 
 PS     SP 
 PSSLHLSSP 
 P       P 
           
|----Layer 4|
           
 sP     Ps 
  PLgLgLP  
  P     P  
 xP  d  P  
  P     P  
 xP     P  
 yPSLLLSP  
 sP  l  Ps 
           
|----Layer 5|
           
  Ps   sP  
  PSLSLSP  
  P  t  P  
  P  d  P  
  P     P  
  P  t  P  
  PSSLSSP  
  Ps f sP  
           
|----Layer 6|
           
   P   P   
   PSSSP   
   P   P   
   P d P   
   P   Px  
   P   Py  
   PLLLPx  
  xP   P   
           
|----Layer 7|
           
   sP Ps   
    PSP    
    PSP    
    PdP    
    PSP    
   xPSP    
    PLP    
   sP Ps   
           
|----Layer 8|
           
    sPs    
     P     
    )P(    
    )D(    
    )P(    
     P     
     P     
    sPs    
           
|----Layer 9|
           
           
           
           
     d     
           
}}



==== Materials ====

{| class="wikitable sortable mw-collapsible"
|-
! Name !! Total !! Layer 1 !! Layer 2 !! Layer 3 !! Layer 4 !! Layer 5 !! Layer 6 !! Layer 7 !! Layer 8 !! Layer 9 
|-
| {{BlockSprite|chest|link=Chest|text=Chest}} || 1 || - || 1 || - || - || - || - || - || - || - 
|-
| {{BlockSprite|diorite|link=Diorite|text=Diorite}} || 10 || 9 || - || - || - || - || - || - || 1 || - 
|-
| {{BlockSprite|diorite-wall|link=Wall|text=Diorite Wall}} || 6 || - || - || 1 || 1 || 1 || 1 || 1 || - || 1 
|-
| {{BlockSprite|furnace|link=Furnace|text=Furnace}} || 1 || - || 1 || - || - || - || - || - || - || - 
|-
| {{BlockSprite|grass|link=Grass|text=Grass}} || 2 || 2 || - || - || - || - || - || - || - || - 
|-
| {{BlockSprite|glass-pane|link=Glass Pane|text=Glass Pane}} || 2 || - || - || - || 2 || - || - || - || - || - 
|-
| {{BlockSprite|lantern|link=Lantern|text=Lantern}} || 1 || - || - || - || 1 || - || - || - || - || - 
|-
| {{BlockSprite|snow|link=Snow|text=Snow}} || 64 || 46 || - || - || 5 || - || 9 || 4 || - || - 
|-
| {{BlockSprite|snow-block|link=Snow Block|text=Snow Block}} || 7 || 4 || 1 || - || 1 || - || 1 || - || - || - 
|-
| {{ItemSprite|spruce-door|link=Door|text=Spruce Door}} || 1 || - || 1 || - || - || - || - || - || - || - 
|-
| {{BlockSprite|spruce-fence|link=Fence|text=Spruce Fence}} || 1 || - || - || - || - || 1 || - || - || - || - 
|-
| {{BlockSprite|spruce-planks|link=Planks|text=Spruce Planks}} || 95 || - || 8 || 16 || 16 || 16 || 16 || 16 || 7 || - 
|-
| {{BlockSprite|spruce-slab|link=Slab|text=Spruce Slab}} || 24 || - || 8 || - || 4 || 4 || - || 4 || 4 || - 
|-
| {{BlockSprite|spruce-stairs|link=Stairs|text=Spruce Stairs}} || 9 || 1 || 2 || - || - || - || - || - || 6 || - 
|-
| {{BlockSprite|stripped-spruce-log|link=Log|text=Stripped Spruce Log}} || 102 || 33 || 22 || 21 || 8 || 10 || 6 || 5 || - || - 
|-
| {{BlockSprite|torch|link=Torch|text=Torch}} || 2 || - || - || - || - || 2 || - || - || - || - 
|-
| {{BlockSprite|water-cauldron|link=Cauldron|text=Water Cauldron}} || 2 || - || 2 || - || - || - || - || - || - || - 
|}





[[Category:Village blueprints]]