<noinclude>{{structure info}}</noinclude>

[[File:Savanna Animal Pen 2.png|thumb|Animal Pen 2 (Savanna)]]



==== Blueprint ====

{{layered blueprint|name=
Savanna Animal Pen 2|default=Layer 3
|D=dirt
|G=grass block+top
|A=acacia fence
|C=acacia fence
|F=acacia fence
|E=acacia fence
|N=acacia fence
|a=acacia fence
|T=torch
|c=acacia fence
|R=grass
|i=acacia fence
|f=acacia fence
|L=tall grass+bottom
|S=tall grass
|W=water+top
|e=acacia fence gate
              
|----Layer 1|
              
     DDDD     
     DDDD     
    DDDDDDDDD 
  DDDDDDDDDDD 
  DDDDDDDDDDD 
  DDDDDDDDDDD 
 DDDDDDDDDDDD 
 DDDDDDDDDDDD 
 DDDDDDDDD    
 DDDDDDDDD    
 DDDDDDDDD    
   DDDDDD  D  
   D DDDD     
              
|----Layer 2|
              
     GGGG     
     GGGG     
    GGGGGGGGG 
  GGGGGGGGGGG 
  GGGGGWGGGGG 
  GGGGWGGGGGG 
 GGGGGGGGGGGG 
 GGGGGGGGGGGG 
 DGGGGGGGG    
 GGGGGGWGG    
 GGGGGGGGG    
   GGGGGG  G  
   G GGGG     
              
|----Layer 3|
              
     Fccf     
     CRRC     
    Fi LAcccf 
  Fci RR RR C 
  CRRRR   LLC 
  C R    R RC 
 Fi  L R RLLC 
 C RRR R Fcci 
 eRRR RRRC    
 CRRL R  C    
 Acf  R Fi    
   AcfRRC     
     Acci     
              
|----Layer 4|
              
     T        
              
       S      
              
          SS  
              
     S    SS  
 E       T    
              
 E  S         
              
              
     T        
              
|----Layer 5|
              
              
              
              
              
              
              
              
 a            
 C            
 N            
              
              
              
              
|----Layer 6|
              
              
              
              
              
              
              
              
 T            
              
 T            
              
              
              
              
}}



==== Materials ====

{| class="wikitable sortable mw-collapsible"
|-
! Name !! Total !! Layer 1 !! Layer 2 !! Layer 3 !! Layer 4 !! Layer 5 !! Layer 6 
|-
| {{BlockSprite|acacia-fence|link=Acacia Fence|text=Acacia Fence}} || 50 || - || - || 45 || 2 || 3 || - 
|-
| {{BlockSprite|acacia-fence-gate|link=Acacia Fence Gate|text=Acacia Fence Gate}} || 1 || - || - || 1 || - || - || - 
|-
| {{BlockSprite|dirt|link=Dirt|text=Dirt}} || 114 || 113 || 1 || - || - || - || - 
|-
| {{BlockSprite|grass|link=Grass|text=Grass}} || 31 || - || - || 31 || - || - || - 
|-
| {{BlockSprite|grass-block|link=Grass Block|text=Grass Block}} || 109 || - || 109 || - || - || - || - 
|-
| {{BlockSprite|tall-grass|link=Tall Grass|text=Tall Grass}} || 7 || - || - || 7 || - || - || - 
|-
| {{BlockSprite|torch|link=Torch|text=Torch}} || 5 || - || - || - || 3 || - || 2 
|-
| {{BlockSprite|water|link=Water|text=Water}} || 3 || - || 3 || - || - || - || - 
|}





[[Category:Village blueprints]]