<noinclude>{{structure info}}</noinclude>

[[File:Savanna Small House 7.png|thumb|Small House 7 (Savanna)]]



==== Blueprint ====

{{layered blueprint|name=Savanna Small House 7|default=Layer 1
|G=Grass Block+top
|D=Dirt
|A=Acacia Log+top
|C=Acacia Log
|c=Acacia Log-rot-90
|I=Acacia Planks
|W=Acacia Wood
|w=Acacia Wood-rot-90
|O=Orange Bed+side+head-rot-180
|R=Orange Bed+side+foot-rot-180
|H=Chest-rot-180
|S=Grass
|s=Acacia Stairs
|>=Acacia Stairs-rot-90
|^=Acacia Stairs-rot-180
|<=Acacia Stairs-rot-270
|L=Glass Pane
|P=Glass Pane-rot-90
|o=Torch
|d=Acacia Door+bottom
|a=Acacia Door+top
|r=Dirt Path+top
|l=Wall Torch-rot-270
         
|----Layer 1|
         
 GGGGGGG 
 GGDDDGG 
 GDWWWDG 
 GDWWWwr 
 GDWwWDD 
 GGDDDGG 
 GGGGGGG 
         
|----Layer 2|
         
 S S     
 SSAcA   
  A>W<AS 
  C   d  
  AORHA  
 SSAcASS 
 S  S  S 
         
|----Layer 3|
         
         
   APA   
  A o A  
  L   a  
  A   A  
   APA   
         
         
|----Layer 4|
         
         
   AcA   
  A   A  
  C   Cl 
  A   A  
   AcA   
         
         
|----Layer 5|
         
  ^^^^^  
 <IIIII> 
 <I   I> 
 <I   I> 
 <I   I> 
 <IIIII> 
  sssss  
         
|----Layer 6|
         
         
  <^^^>  
  <III>  
  <III>  
  <III>  
  sssss  
         
         
|----Layer 7|
         
         
         
   ^^>   
   <I>   
   <ss   
         
         
         
}}



==== Materials ====

{| class="wikitable sortable mw-collapsible"
|-
! Name !! Total !! Layer 1 !! Layer 2 !! Layer 3 !! Layer 4 !! Layer 5 !! Layer 6 !! Layer 7 
|-
| {{BlockSprite|acacia-door|link=Acacia Door|text=Acacia Door}} || 1 || - || 1 || - || - || - || - || - 
|-
| {{BlockSprite|acacia-log|link=Acacia Log|text=Acacia Log}} || 31 || - || 11 || 8 || 12 || - || - || - 
|-
| {{BlockSprite|acacia-planks|link=Acacia Planks|text=Acacia Planks}} || 26 || - || - || - || - || 16 || 9 || 1 
|-
| {{BlockSprite|acacia-stairs|link=Acacia Stairs|text=Acacia Stairs}} || 46 || - || 2 || - || - || 20 || 16 || 8 
|-
| {{BlockSprite|acacia-wood|link=Acacia Wood|text=Acacia Wood}} || 11 || 10 || 1 || - || - || - || - || - 
|-
| {{BlockSprite|chest|link=Chest|text=Chest}} || 1 || - || 1 || - || - || - || - || - 
|-
| {{BlockSprite|dirt|link=Dirt|text=Dirt}} || 12 || 12 || - || - || - || - || - || - 
|-
| {{BlockSprite|glass-pane|link=Glass Pane|text=Glass Pane}} || 3 || - || - || 3 || - || - || - || - 
|-
| {{BlockSprite|grass|link=Grass|text=Grass}} || 12 || - || 12 || - || - || - || - || - 
|-
| {{BlockSprite|grass-block|link=Grass Block|text=Grass Block}} || 26 || 26 || - || - || - || - || - || - 
|-
| {{BlockSprite|dirt-path|link=Dirt Path|text=Dirt Path}} || 1 || 1 || - || - || - || - || - || - 
|-
| {{BlockSprite|orange-bed|link=Orange Bed|text=Orange Bed}} || 1 || - || 1 || - || - || - || - || - 
|-
| {{BlockSprite|torch|link=Torch|text=Torch}} || 2 || - || - || 1 || 1 || - || - || - 
|}





[[Category:Village blueprints]]