<noinclude>{{structure info}}</noinclude>

[[File:Plains fisher cottage 1.png|thumb|Fisher cottage 1 (Plains)]]



==== Blueprint ====
* [[Java Edition]]
{{layered blueprint|name=
Plains Fisher Cottage 1 (JE)
|default=Layer 1
|O=oak planks
|l=Oak Log
|L=Oak Log+top
|k=Oak Log-rot90
|s=Oak Stairs-rot180
|b=Oak Stairs-rot90
|B=Oak Stairs-rot270
|f=Oak Fence
|S=Oak Slab
|g=Glass Pane
|r=Barrel+top
|h=Chest
|w=Water+top
|d=Oak Door+bottom
|D=Oak Door+top
|t=Oak Trapdoor
|T=Torch
|u=Torch-rot180
|C=Cobblestone
|c=Cobblestone Stairs
|a=Cobblestone Stairs-rot90
|A=Cobblestone Stairs-rot270
|G=Grass Block+top
|i=Dirt
            
|----Layer 0|
            
 GGGGGGGGGG 
 GGGGGwwGGG 
 GGGGwwwwGG 
 GGwwwfwwwG 
 GwwwwfwwwG 
 GwwiiiiiwG 
 GwwiCiiiwG 
 GGwiCiiiGG 
 GGiiCiiiGG 
 GGGiiiiiGG 
 GGGGiiiGGG 
            
|----Layer 1|
            
            
        r   
            
      S     
      s     
    LCCCL   
    CwOOC   
    CwOOC   
   rCwOOC   
    LCCCL   
     acA    
            
|----Layer 2|
            
            
            
            
            
            
    LCdCL   
    C thC   
    C t C   
    C t C   
    LCdCL   
            
            
|----Layer 3|
            
            
            
            
            
            
    LCDCL   
    C   C   
    g   g   
    C   C   
    LCDCL   
            
            
|----Layer 4|
            
            
            
            
            
      T     
    LCCCL   
    C   C   
    C   C   
    C   C   
    LCCCL   
      u     
            
|----Layer 5|
            
            
            
            
            
   bB   bB  
   bLkkkLB  
   bl   lB  
   bl   lB  
   bl   lB  
   bLkkkLB  
   bB   bB  
            
|----Layer 6|
            
            
            
            
            
    bB bB   
    bCCCB   
    b   B   
    b   B   
    b   B   
    bCCCB   
    bB bB   
            
|----Layer 7|
            
            
            
            
            
     bOB    
     bOB    
     bOB    
     bOB    
     bOB    
     bOB    
     bOB    
            
}}

* [[Bedrock Edition]]
{{layered blueprint|name=
Plains Fisher Cottage 1 (BE)
|default=Layer 1
|O=oak planks
|l=Oak Log
|L=Oak Log+top
|k=Oak Log-rot90
|s=Oak Stairs-rot180
|b=Oak Stairs-rot90
|B=Oak Stairs-rot270
|f=Oak Fence
|S=Oak Slab
|g=Glass Pane
|r=Barrel+top
|h=Crafting Table
|w=Water+top
|d=Oak Door+bottom
|D=Oak Door+top
|t=Oak Trapdoor
|T=Torch
|u=Torch-rot180
|C=Cobblestone
|c=Cobblestone Stairs
|a=Cobblestone Stairs-rot90
|A=Cobblestone Stairs-rot270
|G=Grass Block+top
|i=Dirt
            
|----Layer 0|
            
 GGGGGGGGGG 
 GGGGGwwGGG 
 GGGGwwwwGG 
 GGwwwfwwwG 
 GwwwwfwwwG 
 GwwiiiiiwG 
 GwwiCiiiwG 
 GGwiCiiiGG 
 GGiiCiiiGG 
 GGGiiiiiGG 
 GGGGiiiGGG 
            
|----Layer 1|
            
            
            
            
      S     
      s     
    LCCCL   
    CwOOC   
    CwOOC   
    CwOOC   
    LCCCL   
     acA    
            
|----Layer 2|
            
            
            
            
            
            
    LCdCL   
    C thC   
    C t C   
    C trC   
    LCdCL   
            
            
|----Layer 3|
            
            
            
            
            
            
    LCDCL   
    C   C   
    g   g   
    C   C   
    LCDCL   
            
            
|----Layer 4|
            
            
            
            
            
      T     
    LCCCL   
    C   C   
    C   C   
    C   C   
    LCCCL   
      u     
            
|----Layer 5|
            
            
            
            
            
   bB   bB  
   bLkkkLB  
   bl   lB  
   bl   lB  
   bl   lB  
   bLkkkLB  
   bB   bB  
            
|----Layer 6|
            
            
            
            
            
    bB bB   
    bCCCB   
    b   B   
    b   B   
    b   B   
    bCCCB   
    bB bB   
            
|----Layer 7|
            
            
            
            
            
     bOB    
     bOB    
     bOB    
     bOB    
     bOB    
     bOB    
     bOB    
            
}}

Note that the Oak Fences in Layer 0 should be waterlogged. {{IN|bedrock}}, the two Barrels in Layer 1 are not generated unlike in ''[[Java Edition]]''.  A barrel generates in Layer 2 inside the cottage {{info needed|where does that layer 2 barrel generate in BE?}} and the chest is replaced with a crafting table.



==== Materials ====

{| class="wikitable sortable mw-collapsible"
|-
! Name !! Total !! Layer 0 !! Layer 1 !! Layer 2 !! Layer 3 !! Layer 4 !! Layer 5 !! Layer 6 !! Layer 7 
|-
| {{BlockSprite|barrel|link=barrel|text=Barrel}} || 2{{only|JE|short=1}} 1{{only|BE|short=1}} || 2{{only|JE|short=1}} || 1{{only|BE|short=1}} || - || - || - || - || - || - 
|-
| {{BlockSprite|chest|link=Chest|text=Chest}}|| 1 || - || - || 1 || - || - || - || - || - 
|-
| {{BlockSprite|cobblestone|link=Cobblestone|text=Cobblestone}} || 51 || 3 || 12 || 10 || 8 || 12 || - || 6 || - 
|-
| {{BlockSprite|cobblestone-stairs|link=Stairs|text=Cobblestone Stairs}} || 3 || - || 3 || - || - || - || - || - || - 
|-
| {{BlockSprite|crafting-table|link=Crafting Table|text=Crafting Table}}|| 1 || - || - || 1 || - || - || - || - || - 
|-
| {{BlockSprite|dirt|link=Dirt|text=Dirt}} || 26 || 26 || - || - || - || - || - || - || - 
|-
| {{BlockSprite|glass-pane|link=Glass Pane|text=Glass Pane}} || 2 || - || - || - || 2 || - || - || - || - 
|-
| {{BlockSprite|grass-block|link=Grass Block|text=Grass Block}} || 53 || 53 || - || - || - || - || - || - || - 
|-
| {{ItemSprite|oak-door|link=Door|text=Oak Door}} || 2 || - || - || 2 || - || - || - || - || - 
|-
| {{BlockSprite|oak-fence|link=Fence|text=Oak Fence}} || 2 || 2 || - || - || - || - || - || - || - 
|- 
| {{BlockSprite|oak-log|link=Log|text=Oak Log}} || 32 || - || 4 || 4 || 4 || 4 || 16 || - || - 
|- 
| {{BlockSprite|oak-planks|link=Planks|text=Oak Planks}} || 13 || - || 6 || - || - || - || - || - || 7 
|-
| {{BlockSprite|oak-slab|link=Slab|text=Oak Slab}} || 1 || - || 1 || - || - || - || - || - || - 
|-
| {{BlockSprite|oak-stairs|link=Stairs|text=Oak Stairs}} || 51 || - || 1 || - || - || - || 18 || 18 || 14 
|-
| {{BlockSprite|oak-trapdoor|link=Trapdoor|text=Oak Trapdoor}} || 3 || - || - || 3 || - || - || - || - || - 
|-
| {{BlockSprite|torch|link=Torch|text=Torch}} || 2 || - || - || - || - || 2 || - || - || - 
|- 
| {{BlockSprite|water|link=Water|text=Water}} || 31 || 28 || 3 || - || - || - || - || - || - 
|}





[[Category:Village blueprints]]