<noinclude>{{structure info}}</noinclude>

[[File:Savanna Cartographer 1.png|thumb|Cartographer 1 (Savanna)]]



==== Blueprint ====

{{layered blueprint|name=
Savanna Cartographer 1|default=Layer 1
|A=Acacia Slab
|C=Acacia Wood
|I=Acacia Log
|P=Acacia Planks
|R=Cartography Table
|B=Brown Wall Banner
|H=Chest-rot-270
|S=Acacia Stairs
|F=Acacia Fence
|T=Torch
|G=Glass Pane-rot-90
|D=Acacia Door+bottom
|O=Acacia Door+top
|W=Wall Torch-rot-180
|U=Double Acacia Slab
           
|----Layer 1|
           
           
  F F F F  
           
  F     F  
           
  F F F F  
    PPP    
    SSS    
           
|----Layer 2|
           
           
  F F F F  
           
  F     F  
           
  F FPF F  
    SSS    
           
           
|----Layer 3|
           
           
  UUUUUUU  
  UUUUUUU  
  UUUUUUU  
  UUUUUUU  
  UAAAAAU  
           
           
           
|----Layer 4|
           
           
  CIIIIIC  
 BIR   CIB 
 BIC   HIB 
 BIIIDIIIB 
  C     C  
           
           
           
|----Layer 5|
           
           
  CIGIGIC  
  I    TI  
  IT    I  
  IIIOIII  
  C     C  
           
           
           
|----Layer 6|
           
           
  CIIIIIC  
  I     I  
  I     I  
  IIIIIII  
  C BWB C  
           
           
           
|----Layer 7|
           
 SSSSSSSSS 
 SPPPPPPPS 
 SP     PS 
 SP     PS 
 SPPPPPPPS 
 SPPPPPPPS 
 SSSSSSSSS 
           
           
|----Layer 8|
           
           
  SSSSSSS  
  SPPPPPS  
  SPPPPPS  
  SPPPPPS  
  SSSSSSS  
           
           
           
}}



==== Materials ====

{| class="wikitable sortable mw-collapsible"
|-
! Name !! Total !! Layer 1 !! Layer 2 !! Layer 3 !! Layer 4 !! Layer 5 !! Layer 6 !! Layer 7 !! Layer 8 
|-
| {{BlockSprite|acacia-door|link=Acacia Door|text=Acacia Door}} || 1 || - || - || - || 1 || - || - || - || - 
|-
| {{BlockSprite|acacia-fence|link=Acacia Fence|text=Acacia Fence}} || 20 || 10 || 10 || - || - || - || - || - || - 
|-
| {{BlockSprite|acacia-log|link=Acacia Log|text=Acacia Log}} || 44 || - || - || - || 15 || 13 || 16 || - || - 
|-
| {{BlockSprite|acacia-planks|link=Acacia Planks|text=Acacia Planks}} || 44 || 3 || 1 || - || - || - || - || 25 || 15 
|-
| {{BlockSprite|acacia-slab|link=Acacia Slab|text=Acacia Slab}} || 65 || - || - || 65 || - || - || - || - || - 
|-
| {{BlockSprite|acacia-stairs|link=Acacia Stairs|text=Acacia Stairs}} || 54 || 3 || 3 || - || - || - || - || 28 || 20 
|-
| {{BlockSprite|acacia-wood|link=Acacia Wood|text=Acacia Wood}} || 14 || - || - || - || 6 || 4 || 4 || - || - 
|-
| {{BlockSprite|brown-wall-banner|link=Brown Wall Banner|text=Brown Wall Banner}} || 8 || - || - || - || 6 || - || 2 || - || - 
|-
| {{BlockSprite|cartography-table|link=Cartography Table|text=Cartography Table}} || 1 || - || - || - || 1 || - || - || - || - 
|-
| {{BlockSprite|chest|link=Chest|text=Chest}} || 1 || - || - || - || 1 || - || - || - || - 
|-
| {{BlockSprite|glass-pane|link=Glass Pane|text=Glass Pane}} || 2 || - || - || - || - || 2 || - || - || - 
|-
| {{BlockSprite|torch|link=Torch|text=Torch}} || 3 || - || - || - || - || 2 || 1 || - || - 
|}





[[Category:Village blueprints]]