<noinclude>{{structure info}}</noinclude>

[[File:Savanna Meeting Point 1.png|thumb|Meeting Point 1 (Savanna)]]



==== Blueprint ====

{{layered blueprint|name=
Savanna Meeting Point 1|default=Layer 1
|G=Grass Block+top
|D=Dirt
|A=Acacia Log+top
|B=Brown Wall Banner
|E=Bell
|R=Dirt Path+top
|C=Acacia Fence
|S=Grass
|T=Torch
|I=Acacia Slab
|c=Acacia Stairs
|t=Tall Grass
|L=Tall Grass+bottom
              
|----Layer 1|
              
 GGGGGGGGGGGG 
 GRRRGGGGGGGG 
 GGRGGDDRGRGG 
 RRRRGRRGRGRG 
 GGRRGRRRRRRR 
 RRRRRGRRRGRR 
 RGRGRRGRGRRG 
 RRGRGGGRGRGR 
 GGRGRRGRRRRR 
 RGGGRRRRGGGG 
 RGDRRRGRRDRG 
 RGDRRGRRRDRR 
 RGRGRRRRGGGR 
 RGRRRRRGRGRG 
              
|----Layer 2|
              
      L       
     C  C     
 SS   AA   C  
     C  C S   
 SS  S        
      S       
       S S    
   S   E S S  
 CS S  S      
  CSC    CSCS 
   A      A S 
  SA  S   A   
  C C    CSC  
  S     S S C 
              
|----Layer 3|
              
      t       
     C  C     
           T  
     C  C     
              
              
              
              
 T            
  C C    C C  
              
              
  C C    C C  
            T 
              
|----Layer 4|
              
              
     C  C     
              
     C  C     
              
              
              
              
              
  C C    C C  
              
              
  C C    C C  
              
              
|----Layer 5|
              
      BB      
     IccI     
     IccI     
     IccI     
              
              
              
              
              
  III    III  
 Bccc    cccB 
 Bccc    cccB 
  III    III  
              
              
}}



==== Materials ====

{| class="wikitable sortable mw-collapsible"
|-
! Name !! Total !! Layer 1 !! Layer 2 !! Layer 3 !! Layer 4 !! Layer 5 
|-
| {{BlockSprite|acacia-fence|link=Acacia Fence|text=Acacia Fence}} || 39 || - || 15 || 12 || 12 || - 
|-
| {{BlockSprite|acacia-log|link=Acacia Log|text=Acacia Log}} || 6 || - || 6 || - || - || - 
|-
| {{BlockSprite|acacia-slab|link=Acacia Slab|text=Acacia Slab}} || 18 || - || - || - || - || 18 
|-
| {{BlockSprite|acacia-stairs|link=Acacia Stairs|text=Acacia Stairs}} || 18 || - || - || - || - || 18 
|-
| {{BlockSprite|bell|link=Bell|text=Bell}} || 1 || - || 1 || - || - || - 
|-
| {{BlockSprite|brown-wall-banner|link=Brown Wall Banner|text=Brown Wall Banner}} || 6 || - || - || - || - || 6 
|-
| {{BlockSprite|dirt|link=Dirt|text=Dirt}} || 6 || 6 || - || - || - || - 
|-
| {{BlockSprite|grass|link=Grass|text=Grass}} || 25 || - || 25 || - || - || - 
|-
| {{BlockSprite|grass-block|link=Grass Block|text=Grass Block}} || 73 || 73 || - || - || - || - 
|-
| {{BlockSprite|dirt-path|link=Dirt Path|text=Dirt Path}} || 89 || 89 || - || - || - || - 
|-
| {{BlockSprite|tall-grass|link=Tall Grass|text=Tall Grass}} || 1 || - || 1 || - || - || - 
|-
| {{BlockSprite|torch|link=Torch|text=Torch}} || 3 || - || - || 3 || - || - 
|}





[[Category:Village blueprints]]