<noinclude>{{structure info}}</noinclude>

[[File:Taiga Tool Smith 1.png|thumb|Tool Smith 1 (Taiga)]]



==== Blueprint ====

{{layered blueprint|name=
Taiga Tool Smith 1|default=Layer 1
|S=Spruce Log
|D=Dirt
|C=Cobblestone
|M=Smithing Table
|P=Spruce Log-rot-90
|R=Spruce Planks
|H=Chest-rot-270
|U=Spruce Trapdoor
|G=Glass Pane
|O=Cobblestone Stairs
|W=Wall Torch
|A=Wall Torch-rot-180
|L=Wall Torch-rot-90
|E=Spruce Door+bottom
|p=Spruce Door+top
|T=Dirt Path+top
|a=Wall Torch-rot-270
|B=Grass Block+top
          
|----Layer 1|
          
          
  DDDD  B 
  DCCD    
  DCCD    
  DCCDDD  
  DCCCRRT 
  DCCDDD  
  DCCD    
  DCCD    
  DDDD  B 
          
          
|----Layer 2|
          
          
  CCCC    
  COOC    
  C  C    
  C HCRR  
  C  E E  
  C  CRR  
  C  C    
  CMCC    
  CCCC    
          
          
|----Layer 3|
          
          
  CCCCU   
 UC  G    
  G  CU   
 UC  CRR  
  G  p p  
 UC  CRR  
  G  CU   
 UC  G    
  CCCCU   
          
          
|----Layer 4|
          
 S    S   
 SCCCCS   
 SC  CS   
 SC  CSPP 
 SC  CRR  
 SC LC Ra 
 SC  CRR  
 SC  CSPP 
 SC  CS   
 SCCCCS   
 S    S   
          
|----Layer 5|
          
  S  S    
  SCCS    
  SAAS    
  S  S    
  S  PPPP 
  S  SRR  
  S  PPPP 
  S  S    
  SWWS    
  SCCS    
  S  S    
          
|----Layer 6|
          
   SS     
   SS     
   SS     
   SS     
   SS     
   SSPPPP 
   SS     
   SS     
   SS     
   SS     
   SS     
          
}}



==== Materials ====

{| class="wikitable sortable mw-collapsible"
|-
! Name !! Total !! Layer 1 !! Layer 2 !! Layer 3 !! Layer 4 !! Layer 5 !! Layer 6 
|-
| {{BlockSprite|Chest|link=Chest|text=Chest}} || 1 || - || 1 || - || - || - || - 
|-
| {{BlockSprite|Cobblestone|link=Cobblestone|text=Cobblestone}} || 79 || 15 || 22 || 16 || 22 || 4 || - 
|-
| {{BlockSprite|Cobblestone Stairs|link=Cobblestone Stairs|text=Cobblestone Stairs}} || 2 || - || 2 || - || - || - || - 
|-
| {{BlockSprite|Dirt|link=Dirt|text=Dirt}} || 25 || 25 || - || - || - || - || - 
|-
| {{BlockSprite|Glass Pane|link=Glass Pane|text=Glass Pane}} || 5 || - || - || 5 || - || - || - 
|-
| {{BlockSprite|Grass Block|link=Grass Block|text=Grass Block}} || 2 || 2 || - || - || - || - || - 
|-
| {{BlockSprite|Dirt Path|link=Dirt Path|text=Dirt Path}} || 1 || 1 || - || - || - || - || - 
|-
| {{BlockSprite|Smithing Table|link=Smithing Table|text=Smithing Table}} || 1 || - || 1 || - || - || - || - 
|-
| {{BlockSprite|Spruce Door|link=Spruce Door|text=Spruce Door}} || 2 || - || 2 || - || - || - || - 
|-
| {{BlockSprite|Spruce Log|link=Spruce Log|text=Spruce Log}} || 77 || - || - || - || 23 || 28 || 26 
|-
| {{BlockSprite|Spruce Planks|link=Spruce Planks|text=Spruce Planks}} || 17 || 2 || 4 || 4 || 5 || 2 || - 
|-
| {{BlockSprite|Spruce Trapdoor|link=Spruce Trapdoor|text=Spruce Trapdoor}} || 8 || - || - || 8 || - || - || - 
|-
| {{BlockSprite|Torch|link=Torch|text=Torch}} || 6 || - || - || - || 2 || 4 || - 
|}





[[Category:Village blueprints]]