<noinclude>{{structure info}}</noinclude>

[[File:Plains Armorer House 1.png|thumb|Armorer house 1 (Plains)]]



==== Blueprint ====

{{layered blueprint
|name=Village Plains Houses plains_armorer_house_1
|default=Layer 2
|O=Oak Log+top
|L=Oak Log-rot90
|l=Oak Log
|C=Cobblestone
|c=Cobblestone Stairs
|B=Bricks
|X=Smooth Stone
|F=Blast Furnace-rot90
|d=Oak Door+bottom
|D=Oak Door+top
|)=Cobblestone Stairs-rot270
|^=Cobblestone Stairs-rot180
|(=Cobblestone Stairs-rot90
|T=torch-rot180
|t=torch-rot90
|k=torch-rot270
|<=Oak Stairs-rot90
|>=Oak Stairs-rot270
|s=Oak Stairs
|S=Oak Stairs-rot180
|p=Oak Slab
|o=Cobblestone Wall
|g=glass Pane
|G=glass Pane-rot90
|----Layer 1|
          
          
  OCCCCO  
  CCCCCC  
  CCCCCCC 
  CCCCBCC 
  CCCCCCC 
  CCCCCC  
  OCCCCO  
    cc    
          
|----Layer 2|
          
          
  OCCCCO  
  CXXXXC  
  CX  CCC 
  CX   FC 
  CX  CCC 
  CX   C  
  OCddCO  
          
|----Layer 3|
          
          
  OLGGLO  
  l    C  
  g   CC^ 
  lt   B) 
  g   CCc 
  l    C  
  OCDDCO  
   T  T   
          
|----Layer 4|
          
 <>    <> 
 <OCCCCO> 
 <C    Cs 
 <C   ^Cp 
 <C   CCp 
 <C   cCp 
 <C    CS 
 <OCCCCO> 
 <>    <> 
          
|----Layer 5|
          
  <>  <>  
  <CCCC>  
  <   k>  
  <    >  
  <   (C  
  <    >  
  <   k>  
  <CCCC>  
  <>  <>  
          
|----Layer 6|
          
   <><>   
   <CC>   
   <  >   
   <  >   
   <  >C  
   <  >   
   <  >   
   <CC>   
   <><>   
          
|----Layer 7|
          
    <>    
    <>    
    <>    
    <>    
    <> C  
    <>    
    <>    
    <>    
    <>    
          
|----Layer 8|
          
          
          
          
          
       o  
          
          
          
          
}}



==== Materials ====

{| class="wikitable sortable mw-collapsible"
|-
! Name !! Total !! Layer 1 !! Layer 2 !! Layer 3 !! Layer 4 !! Layer 5 !! Layer 6 !! Layer 7 !! Layer 8 
|-
| {{BlockSprite|blast-furnace|link=Blast Furnace|text=Blast Furnace}} || 1 || - || 1 || - || - || - || - || - || - 
|-
| {{BlockSprite|bricks|link=Bricks|text=Bricks}} || 2 || 1 || - || 1 || - || - || - || - || - 
|-
| {{BlockSprite|cobblestone|link=Cobblestone|text=Cobblestone}} || 102 || 40 || 20 || 8 || 19 || 9 || 5 || 1 || - 
|-
| {{BlockSprite|cobblestone-stairs|link=Stairs|text=Cobblestone Stairs}} || 8 || 2 || - || 3 || 2 || 1 || - || - || - 
|-
| {{BlockSprite|cobblestone-wall|link=Wall|text=Cobblestone Wall}} || 1 || - || - || - || - || - || - || - || 1 
|-
| {{BlockSprite|glass-pane|link=Glass Pane|text=Glass Pane}} || 4 || - || - || 4 || - || - || - || - || - 
|-
| {{ItemSprite|oak-door|link=Door|text=Oak Door}} || 2 || - || 2 || - || - || - || - || - || - 
|-
| {{BlockSprite|oak-log|link=Log|text=Oak Log}} || 21 || 4 || 4 || 9 || 4 || - || - || - || - 
|-
| {{BlockSprite|oak-slab|link=Slabs|text=Oak Slab}} || 3 || - || - || - || 3 || - || - || - || - 
|-
| {{BlockSprite|oak-stairs|link=Stairs|text=Oak Stairs}} || 80 || - || - || - || 19 || 21 || 22 || 18 || - 
|-
| {{BlockSprite|smooth-stone|link=Smooth Stone|text=Smooth Stone}} || 8 || - || 8 || - || - || - || - || - || - 
|-
| {{BlockSprite|torch|link=Torch|text=Torch}} || 5 || - || - || 3 || - || 2 || - || - || - 
|}





[[Category:Village blueprints]]