<noinclude>{{structure info}}</noinclude>

[[File:Plains Small House 7.png|thumb|Small house 7 (Plains)]]



==== Blueprint ====

{{layered blueprint
|name=Village Plains Houses plains_small_house_7
|default=Layer 2
|O=Oak Log+top
|L=Oak Log-rot90
|l=Oak Log
|C=Cobblestone
|c=Cobblestone Stairs
|U=Chest-rot90
|d=Oak Door+bottom
|D=Oak Door+top
|)=Cobblestone Stairs-rot270
|(=Cobblestone Stairs-rot90
|T=torch-rot180
|t=torch
|<=Oak Stairs-rot90
|>=Oak Stairs-rot270
|g=glass Pane
|G=glass Pane-rot90
|P=Oak Planks
|Y=Yellow Bed+top foot-rot90
|y=Yellow Bed+top head-rot90
|----Layer 1|
          
          
  OCCCCO  
  COPPOC  
  CPPPPC  
  COPPOC  
  OCCCCO  
   (cc)   
          
|----Layer 2|
          
          
  OCCCCO  
  C>  UC  
  CY   C  
  Cy   C  
  OCddCO  
          
|----Layer 3|
          
          
  OLGGLO  
  l    l  
  g    g  
  l    l  
  OLDDLO  
   T  T   
          
|----Layer 4|
          
 <>    <> 
 <OCCCCO> 
 <C    C> 
 <C    C> 
 <C tt C> 
 <OCCCCO> 
 <>    <> 
          
|----Layer 5|
          
  <>  <>  
  <CCCC>  
  <    >  
  <    >  
  <    >  
  <CCCC>  
  <>  <>  
          
|----Layer 6|
          
   <><>   
   <CC>   
   <  >   
   <  >   
   <  >   
   <CC>   
   <><>   
|----Layer 7|
          
    <>    
    <>    
    <>    
    <>    
    <>    
    <>    
    <>    
          
}}


This structure has a lot of similarities from the [[Village/Structure/Blueprints/Plains armorer house 1 blueprint|Armorer House]].



==== Materials ====

{| class="wikitable sortable mw-collapsible"
|-
! Name !! Total !! Layer 1 !! Layer 2 !! Layer 3 !! Layer 4 !! Layer 5 !! Layer 6 !! Layer 7 
|-
| {{BlockSprite|chest|link=Chest|text=Chest}} || 1 || - || 1 || - || - || - || - || - 
|-
| {{BlockSprite|cobblestone|link=Cobblestone|text=Cobblestone}} || 52 || 14 || 12 || - || 14 || 8 || 4 || - 
|-
| {{BlockSprite|cobblestone-stairs|link=Stairs|text=Cobblestone Stairs}} || 4 || 4 || - || - || - || - || - || - 
|-
| {{BlockSprite|glass-pane|link=Glass Pane|text=Glass Pane}} || 4 || - || - || 4 || - || - || - || - 
|-
| {{ItemSprite|oak-door|link=Door|text=Oak Door}} || 2 || - || 2 || - || - || - || - || - 
|-
| {{BlockSprite|oak-log|link=Log|text=Oak Log}} || 28 || 8 || 4 || 12 || 4 || - || - || - 
|-
| {{BlockSprite|oak-planks|link=Planks|text=Oak Planks}} || 8 || 8 || - || - || - || - || - || - 
|-
| {{BlockSprite|oak-stairs|link=Stairs|text=Oak Stairs}} || 69 || - || 1 || - || 18 || 18 || 18 || 14 
|-
| {{BlockSprite|torch|link=Torch|text=Torch}} || 4 || - || - || 2 || 2 || - || - || - 
|-
| {{BlockSprite|yellow-bed|link=Bed|text=Yellow Bed}} || 1 || - || 1 || - || - || - || - || - 
|}





[[Category:Village blueprints]]