<noinclude>{{structure info}}</noinclude>

[[File:Savanna Butchers Shop 1.png|thumb|Butchers Shop 1 (Savanna)]]



==== Blueprint ====

{{layered blueprint|name=
Savanna Butchers Shop 1|default=Layer 1
|A=Acacia Log+top
|C=Acacia Planks
|Y=Yellow Terracotta
|O=Orange Terracotta
|B=Cobblestone
|G=Grass Block+top
|I=Acacia Log
|S=Smooth Stone Slab
|M=Smoker
|R=Grass
|T=Acacia Stairs
|F=Acacia Fence
|L=Cobblestone Wall
|H=Torch
|W=Wall Torch-rot-180
|P=Glass Pane-rot-90
|D=Acacia Door+bottom
|c=Acacia Door+top
|a=Wall Torch
|i=Dirt
             
|----Layer 1|
             
 R AAAAAAR   
  RAGGGGAR   
 RRAGGiGA    
  RAGGGGAR R 
  RAAAAAAAR  
 RAOYOYOSOAR 
 RAYOYOYSYAR 
  RAYOYAAA R 
 RRAOYI      
   RAIAR RRR 
 R RTTT      
             
|----Layer 2|
             
   FFFFFF    
   F    F    
   F    F    
   F    F    
   AAADAAA   
  AB     SA  
  AM     SA  
   A   AAA   
   A  A      
    ADA      
             
             
|----Layer 3|
             
   H    H    
             
             
             
   APAcAPA   
  A       A  
  AL      A  
   A   APA   
   A  A      
    AcA      
    W W      
             
|----Layer 4|
             
             
             
             
             
   AIAIAIA   
  A   W   A  
  AL      A  
   A   AIA   
   A aA      
    AIA      
             
             
|----Layer 5|
             
             
             
             
  TTTTTTTTT  
 TCCCCCCCCCT 
 TC       CT 
 TCL      CT 
 TCC   CCCCT 
 TTC  CCTTT  
  TCCCCT     
  TTTTTT     
             
|----Layer 6|
             
             
             
             
             
  TTTTTTTTT  
  TCCCCCCCT  
  TLCCCCCCT  
  TTCCCTTTT  
   TCCTT     
   TTTT      
             
             
|----Layer 7|
             
             
             
             
             
             
             
   L         
             
             
             
             
             
}}



==== Materials ====

{| class="wikitable sortable mw-collapsible"
|-
! Name !! Total !! Layer 1 !! Layer 2 !! Layer 3 !! Layer 4 !! Layer 5 !! Layer 6 !! Layer 7 
|-
| {{BlockSprite|acacia-door|link=Acacia Door|text=Acacia Door}} || 2 || - || 2 || - || - || - || - || - 
|-
| {{BlockSprite|acacia-fence|link=Acacia Fence|text=Acacia Fence}} || 12 || - || 12 || - || - || - || - || - 
|-
| {{BlockSprite|acacia-log|link=Acacia Log|text=Acacia Log}} || 85 || 32 || 18 || 15 || 20 || - || - || - 
|-
| {{BlockSprite|acacia-planks|link=Acacia Planks|text=Acacia Planks}} || 44 || - || - || - || - || 26 || 18 || - 
|-
| {{BlockSprite|acacia-stairs|link=Acacia Stairs|text=Acacia Stairs}} || 59 || 3 || - || - || - || 30 || 26 || - 
|-
| {{BlockSprite|cobblestone|link=Cobblestone|text=Cobblestone}} || 1 || - || 1 || - || - || - || - || - 
|-
| {{BlockSprite|cobblestone-wall|link=Cobblestone Wall|text=Cobblestone Wall}} || 5 || - || - || 1 || 1 || 1 || 1 || 1 
|-
| {{BlockSprite|dirt|link=Dirt|text=Dirt}} || 1 || 1 || - || - || - || - || - || - 
|-
| {{BlockSprite|glass-pane|link=Glass Pane|text=Glass Pane}} || 3 || - || - || 3 || - || - || - || - 
|-
| {{BlockSprite|grass|link=Grass|text=Grass}} || 26 || 26 || - || - || - || - || - || - 
|-
| {{BlockSprite|grass-block|link=Grass Block|text=Grass Block}} || 11 || 11 || - || - || - || - || - || - 
|-
| {{BlockSprite|orange-terracotta|link=Orange Terracotta|text=Orange Terracotta}} || 8 || 8 || - || - || - || - || - || - 
|-
| {{BlockSprite|smoker|link=Smoker|text=Smoker}} || 1 || - || 1 || - || - || - || - || - 
|-
| {{BlockSprite|smooth-stone-slab|link=Smooth Stone Slab|text=Smooth Stone Slab}} || 6 || 2 || 4 || - || - || - || - || - 
|-
| {{BlockSprite|torch|link=Torch|text=Torch}} || 6 || - || - || 4 || 2 || - || - || - 
|-
| {{BlockSprite|yellow-terracotta|link=Yellow Terracotta|text=Yellow Terracotta}} || 9 || 9 || - || - || - || - || - || - 
|}





[[Category:Village blueprints]]